Workbook
Name _P1: [1]钢轨桩计算!$C$10
Name _P1: [2]钢轨桩计算!$C$10
Name D0: [2]钢轨桩计算!$H$25
Name D0: [1]钢轨桩计算!$H$25
Name D0: [3]钢轨桩计算!$H$25
Name gj: #REF!
Name gjzj: #REF!
Name H: [2]钢轨桩计算!$C$2
Name H: [1]钢轨桩计算!$C$2
Name H: [3]钢轨桩计算!$C$2
Name jd: SIN(RADIANS([3]框架结构!$B$2))
Name name: [4]工字钢数据!$A$2:$A$3
Name subject: [4]工字钢数据!$B$1:$C$1
Name x: [5]后背钢轨桩计算!$J$16
Name y: [2]钢轨桩计算!$D$17
Name y: [1]钢轨桩计算!$D$17
Name y: [3]钢轨桩计算!$D$17
Name γ: [1]钢轨桩计算!$C$5
Name γ: [2]钢轨桩计算!$C$5
Name θ: [1]钢轨桩计算!$C$8
Name θ: [2]钢轨桩计算!$C$8
Name λ: [1]钢轨桩计算!$C$9
Name λ: [2]钢轨桩计算!$C$9
Name σh: [2]钢轨桩计算!$C$11
Name σh: [1]钢轨桩计算!$C$11
Name σh: [3]钢轨桩计算!$C$11
Name φ: [1]钢轨桩计算!$C$6
Name φ: [2]钢轨桩计算!$C$6
Name 边墙厚度: [3]框架结构!$C$10
Name 打入工作坑以下H: [2]钢轨桩计算!$C$3
Name 打入工作坑以下H: [1]钢轨桩计算!$C$3
Name 打入工作坑以下H: [3]钢轨桩计算!$C$3
Name 底板厚度: [3]框架结构!$C$9
Name 第1页________共1页: #REF!
Name 顶板厚度: [3]框架结构!$C$8
Name 钢筋直径: #REF!
Name 钢筋直径: #REF!
Name 钢筋直径: #REF!
Name 工字钢长度H: [1]钢轨桩计算!$C$2
Name 工字钢长度H: [2]钢轨桩计算!$C$2
Name 工作坑底面以上主动土动力P1: [1]钢轨桩计算!$C$10
Name 工作坑底面以上主动土动力P1: [2]钢轨桩计算!$C$10
Name 结构净高: [3]框架结构!$C$7
Name 结构总高: [3]框架结构!$C$4
Name 结构总宽: [3]框架结构!$C$3
Name 孔数: [2]框架结构!$F$1
Name 孔数: [1]框架结构!$F$1
Name 孔数: [3]框架结构!$F$1
Name 面坡斜度: #REF!
Name 内摩擦角φ: [1]钢轨桩计算!$C$6
Name 内摩擦角φ: [2]钢轨桩计算!$C$6
Name 破裂角θ: [1]钢轨桩计算!$C$8
Name 破裂角θ: [2]钢轨桩计算!$C$8
Name 刃角长度: [3]框架结构!$D$17
Name 填土高度h: [1]钢轨桩计算!$C$4
Name 填土高度h: [2]钢轨桩计算!$C$4
Name 土容重γ: [1]钢轨桩计算!$C$5
Name 土容重γ: [2]钢轨桩计算!$C$5
Name 推力系数λ: [1]钢轨桩计算!$C$9
Name 推力系数λ: [2]钢轨桩计算!$C$9

Sheet 0.结构参数
B2: 一、从CAD中读取平面、纵断面原始数据 单位：m
A3: 序号 | B3: U型槽编号 | C3: 里程L | E3: L | G3: 顶高程E1 | I3: 底板顶高程E2 | K3: 机非分隔带 | P3: 中央分隔带 | U3: 水位高程E5 | V3: 净宽
K4: 高程E3 | M4: 宽度b1 | O4: 数量 | P4: 高程E4 | R4: 宽度b2 | T4: 数量
A5: 1 | B5: ZU1-2 | C5: 109.9395 | D5: 129.9395 | E5: =ABS(D5-C5) -> 20 | F5: =E5 -> 20 | G5: 3.61863 | H5: 3.348 | I5: 2.92747 | J5: 2.48762 | K5: 3.42747 | L5: 2.98771 | M5: 1.75 | N5: 1.75 | O5: 0 | P5: 3.42747 | Q5: 2.98307 | R5: 0.45 | S5: 0.45 | T5: 0 | U5: 3.1 | V5: 8 | W5: 8 | X5: =(K5+L5)/2*M5*O5 -> 0 | Y5: =(P5+Q5)/2*R5*T5 -> 0
A6: 2 | B6: ZU2-2 | C6: 129.9695 | D6: 149.9695 | E6: =ABS(D6-C6) -> 20 | F6: =E6 -> 20 | G6: 3.348 | H6: 3.348 | I6: 2.48696 | J6: 1.98696 | K6: 2.98696 | L6: 2.48696 | M6: 1.75 | N6: 1.75 | O6: 0 | P6: 2.98226 | Q6: 2.33756 | R6: 0.45 | S6: 0.45 | T6: 0 | U6: 3.1 | V6: 8 | W6: 8 | X6: =(K6+L6)/2*M6*O6 -> 0 | Y6: =(P6+Q6)/2*R6*T6 -> 0
A7: 3 | B7: ZU3-2 | C7: 149.9995 | D7: 169.9995 | E7: =ABS(D7-C7) -> 20 | F7: =E7 -> 20 | G7: 3.348 | H7: 3.348 | I7: 1.98621 | J7: 1.48621 | K7: 2.48621 | L7: 1.98621 | M7: 1.75 | N7: 1.75 | O7: 0 | P7: 2.33644 | Q7: 1.55151 | R7: 0.45 | S7: 0.45 | T7: 0 | U7: 3.1 | V7: 8 | W7: 8 | X7: =(K7+L7)/2*M7*O7 -> 0 | Y7: =(P7+Q7)/2*R7*T7 -> 0
A8: 4 | B8: ZU4-2 | C8: 170.0295 | D8: 190.0295 | E8: =ABS(D8-C8) -> 20 | F8: =E8 -> 20 | G8: 3.348 | H8: 3.348 | I8: 1.48546 | J8: 0.98546 | K8: 1.98546 | L8: 1.48546 | M8: 1.75 | N8: 1.75 | O8: 0 | P8: 1.55032 | Q8: 0.76032 | R8: 0.45 | S8: 0.45 | T8: 0 | U8: 3.1 | V8: 8 | W8: 8 | X8: =(K8+L8)/2*M8*O8 -> 0 | Y8: =(P8+Q8)/2*R8*T8 -> 0
A9: 5 | B9: ZU5-2 | C9: 190.0595 | D9: 210.0595 | E9: =ABS(D9-C9) -> 20 | F9: =E9 -> 20 | G9: 3.348 | H9: 3.348 | I9: 0.98471 | J9: 0.48471 | K9: 1.48471 | L9: 0.98471 | M9: 1.75 | N9: 1.75 | O9: 0 | P9: 0.75914 | Q9: -0.03086 | R9: 0.45 | S9: 0.45 | T9: 0 | U9: 3.1 | V9: 8 | W9: 8 | X9: =(K9+L9)/2*M9*O9 -> 0 | Y9: =(P9+Q9)/2*R9*T9 -> 0
A10: 6 | B10: ZU6-2 | C10: 210.0895 | D10: 230.0895 | E10: =ABS(D10-C10) -> 20 | F10: =E10 -> 20 | G10: 3.348 | H10: 3.348 | I10: 0.48396 | J10: -0.01604 | K10: 0.98396 | L10: 0.48396 | M10: 1.75 | N10: 1.75 | O10: 0 | P10: -0.03205 | Q10: -0.82205 | R10: 0.45 | S10: 0.45 | T10: 0 | U10: 3.1 | V10: 8 | W10: 8 | X10: =(K10+L10)/2*M10*O10 -> 0 | Y10: =(P10+Q10)/2*R10*T10 -> 0
A11: 7 | B11: ZU7-2 | C11: 230.1195 | D11: 250.1195 | E11: =ABS(D11-C11) -> 20 | F11: =E11 -> 20 | G11: 3.348 | H11: 3.348 | I11: -0.01679 | J11: -0.51679 | K11: 0.48321 | L11: -0.01679 | M11: 1.75 | N11: 1.75 | O11: 0 | P11: -0.82323 | Q11: -1.58337 | R11: 0.45 | S11: 0.45 | T11: 0 | U11: 3.1 | V11: 8 | W11: 8 | X11: =(K11+L11)/2*M11*O11 -> 0 | Y11: =(P11+Q11)/2*R11*T11 -> 0
A12: 8 | B12: ZU8-2 | C12: 250.1495 | D12: 270.1495 | E12: =ABS(D12-C12) -> 20 | F12: =E12 -> 20 | G12: 3.348 | H12: 3.348 | I12: -0.51754 | J12: -1.01754 | K12: -0.01754 | L12: -0.51754 | M12: 1.75 | N12: 1.75 | O12: 0 | P12: -1.58438 | Q12: -2.14771 | R12: 0.45 | S12: 0.45 | T12: 0 | U12: 3.1 | V12: 8 | W12: 8 | X12: =(K12+L12)/2*M12*O12 -> 0 | Y12: =(P12+Q12)/2*R12*T12 -> 0
A13: 9 | B13: ZU9-2 | C13: 270.1795 | D13: 290.1795 | E13: =ABS(D13-C13) -> 20 | F13: =E13 -> 20 | G13: 3.348 | H13: 3.348 | I13: -1.01829 | J13: -1.51829 | K13: -0.51829 | L13: -0.91873 | M13: 1.75 | N13: 1.75 | O13: 0 | P13: -2.14839 | Q13: -2.48917 | R13: 0.45 | S13: 0.45 | T13: 0 | U13: 3.1 | V13: 8 | W13: 8 | X13: =(K13+L13)/2*M13*O13 -> 0 | Y13: =(P13+Q13)/2*R13*T13 -> 0
A14: 10 | B14: ZU10-2 | C14: 290.2095 | D14: 310.2095 | E14: =ABS(D14-C14) -> 20 | F14: =E14 -> 20 | G14: 3.348 | H14: 3.348 | I14: -1.51844 | J14: -1.61933 | K14: -0.91919 | L14: -1.11933 | M14: 1.75 | N14: 1.75 | O14: 0 | P14: -2.48952 | Q14: -2.60775 | R14: 0.45 | S14: 0.45 | T14: 0 | U14: 3.1 | V14: 8 | W14: 8 | X14: =(K14+L14)/2*M14*O14 -> 0 | Y14: =(P14+Q14)/2*R14*T14 -> 0
A15: 11 | B15: ZU11-2 | C15: 389.2295 | D15: 404.2295 | E15: 20 | F15: 20 | G15: 3.348 | H15: 3.348 | I15: -1.452 | J15: -1.452 | K15: -0.93138 | L15: -0.90138 | M15: 1.75 | N15: 1.75 | O15: 0 | P15: -2.36582 | Q15: -2.33582 | R15: 0.45 | S15: 0.45 | T15: 0 | U15: 3.1 | V15: 8 | W15: 8 | X15: =(K15+L15)/2*M15*O15 -> 0 | Y15: =(P15+Q15)/2*R15*T15 -> 0
A16: 12 | B16: ZU12-2 | C16: 449.3195 | D16: 469.3195 | E16: =ABS(D16-C16) -> 20 | F16: =E16 -> 20 | G16: 3.348 | H16: 3.348 | I16: -1.45125 | J16: -0.95564 | K16: -0.72133 | L16: -0.42748 | M16: 1.75 | N16: 1.75 | O16: 0 | P16: -2.14478 | Q16: -1.81623 | R16: 0.45 | S16: 0.45 | T16: 0 | U16: 3.1 | V16: 8 | W16: 8 | X16: =(K16+L16)/2*M16*O16 -> 0 | Y16: =(P16+Q16)/2*R16*T16 -> 0
A17: 13 | B17: ZU13-2 | C17: 469.3495 | D17: 489.3495 | E17: =ABS(D17-C17) -> 20 | F17: =E17 -> 20 | G17: 3.348 | H17: 3.348 | I17: -0.9549 | J17: -0.4549 | K17: -0.42689 | L17: 0.0451 | M17: 1.75 | N17: 1.75 | O17: 0 | P17: -1.81557 | Q17: -1.26446 | R17: 0.45 | S17: 0.45 | T17: 0 | U17: 3.1 | V17: 8 | W17: 8 | X17: =(K17+L17)/2*M17*O17 -> 0 | Y17: =(P17+Q17)/2*R17*T17 -> 0
A18: 14 | B18: ZU14-2 | C18: 489.3795 | D18: 509.3795 | E18: =ABS(D18-C18) -> 20 | F18: =E18 -> 20 | G18: 3.348 | H18: 3.348 | I18: -0.45415 | J18: 0.04585 | K18: 0.04585 | L18: 0.54585 | M18: 1.75 | N18: 1.75 | O18: 0 | P18: -1.26347 | Q18: -0.51002 | R18: 0.45 | S18: 0.45 | T18: 0 | U18: 3.1 | V18: 8 | W18: 8 | X18: =(K18+L18)/2*M18*O18 -> 0 | Y18: =(P18+Q18)/2*R18*T18 -> 0
A19: 15 | B19: ZU15-2 | C19: 509.4095 | D19: 529.4095 | E19: =ABS(D19-C19) -> 20 | F19: =E19 -> 20 | G19: 3.348 | H19: 3.348 | I19: 0.0466 | J19: 0.5466 | K19: 0.5466 | L19: 1.0466 | M19: 1.75 | N19: 1.75 | O19: 0 | P19: -0.50883 | Q19: 0.28117 | R19: 0.45 | S19: 0.45 | T19: 0 | U19: 3.1 | V19: 8 | W19: 8 | X19: =(K19+L19)/2*M19*O19 -> 0 | Y19: =(P19+Q19)/2*R19*T19 -> 0
A20: 16 | B20: ZU16-2 | C20: 529.4395 | D20: 549.4395 | E20: =ABS(D20-C20) -> 20 | F20: =E20 -> 20 | G20: 3.348 | H20: 3.348 | I20: 0.54735 | J20: 1.04735 | K20: 1.04735 | L20: 1.54735 | M20: 1.75 | N20: 1.75 | O20: 0 | P20: 0.28235 | Q20: 1.07235 | R20: 0.45 | S20: 0.45 | T20: 0 | U20: 3.1 | V20: 8 | W20: 8 | X20: =(K20+L20)/2*M20*O20 -> 0 | Y20: =(P20+Q20)/2*R20*T20 -> 0
A21: 17 | B21: ZU17-2 | C21: 549.4695 | D21: 569.4695 | E21: =ABS(D21-C21) -> 20 | F21: =E21 -> 20 | G21: 3.348 | H21: 3.348 | I21: 1.0481 | J21: 1.5481 | K21: 1.5481 | L21: 2.0481 | M21: 1.75 | N21: 1.75 | O21: 0 | P21: 1.07354 | Q21: 1.86351 | R21: 0.45 | S21: 0.45 | T21: 0 | U21: 3.1 | V21: 8 | W21: 8 | X21: =(K21+L21)/2*M21*O21 -> 0 | Y21: =(P21+Q21)/2*R21*T21 -> 0
A22: 18 | B22: ZU18-2 | C22: 569.4995 | D22: 589.4995 | E22: =ABS(D22-C22) -> 20 | F22: =E22 -> 20 | G22: 3.348 | H22: 3.348 | I22: 1.54885 | J22: 2.04885 | K22: 2.04885 | L22: 2.54885 | M22: 1.75 | N22: 1.75 | O22: 0 | P22: 1.86469 | Q22: 2.53969 | R22: 0.45 | S22: 0.45 | T22: 0 | U22: 3.1 | V22: 8 | W22: 8 | X22: =(K22+L22)/2*M22*O22 -> 0 | Y22: =(P22+Q22)/2*R22*T22 -> 0
A23: 19 | B23: ZU19-2 | C23: 589.5295 | D23: 605 | E23: =ABS(D23-C23) -> 15.4705 | F23: =E23 -> 15.4705 | G23: 3.348 | H23: 3.348 | I23: 2.04955 | J23: 2.40998 | K23: 2.5496 | L23: 2.90998 | M23: 1.75 | N23: 1.75 | O23: 0 | P23: 2.54054 | Q23: 2.90998 | R23: 0.45 | S23: 0.45 | T23: 0 | U23: 3.1 | V23: 8 | W23: 8 | X23: =(K23+L23)/2*M23*O23 -> 0 | Y23: =(P23+Q23)/2*R23*T23 -> 0
A24: 20 | B24: 东U10 | C24: 594.2491 | D24: 614.2491 | E24: =ABS(D24-C24) -> 20 | F24: =E24 -> 20 | G24: 3.914 | H24: 3.914 | I24: 2.27743 | J24: 2.65934 | K24: 3.19858 | L24: 3.67645 | M24: 1.75 | N24: 1.75 | O24: 1 | P24: 3.17395 | Q24: 3.67645 | R24: 0.45 | S24: 0.45 | T24: 0 | U24: 3.1 | V24: 8 | W24: 8 | X24: =(K24+L24)/2*M24*O24 -> 6.0156513 | Y24: =(P24+Q24)/2*R24*T24 -> 0
A25: 21 | B25: 西U10-1 | C25: 111.6591 | D25: 131.6591 | E25: =ABS(D25-C25) -> 20 | F25: =E25 -> 20 | G25: 3.59828 | H25: 3.348 | I25: 2.29828 | J25: 1.73674 | K25: 3.39828 | L25: 2.95311 | M25: 1.75 | N25: 1.75 | O25: 1 | P25: 3.39828 | Q25: 2.94818 | R25: 0.45 | S25: 0.45 | T25: 0 | U25: 3.1 | V25: 22.25 | W25: 22.25 | X25: =(K25+L25)/2*M25*O25 -> 5.5574663 | Y25: =(P25+Q25)/2*R25*T25 -> 0
A26: 22 | B26: 西U9-1 | C26: 131.6891 | D26: 151.6891 | E26: =ABS(D26-C26) -> 20 | F26: =E26 -> 20 | G26: 3.348 | H26: 3.348 | I26: 1.7359 | J26: 1.17435 | K26: 2.95236 | L26: 2.45236 | M26: 1.75 | N26: 1.75 | O26: 1 | P26: 2.94734 | Q26: 2.27469 | R26: 0.45 | S26: 0.45 | T26: 0 | U26: 3.1 | V26: 22.25 | W26: 22.25 | X26: =(K26+L26)/2*M26*O26 -> 4.72913 | Y26: =(P26+Q26)/2*R26*T26 -> 0
A27: 23 | B27: 西U6-1 | C27: 191.7791 | D27: 211.7791 | E27: =ABS(D27-C27) -> 20 | F27: =E27 -> 20 | G27: 3.348 | H27: 3.348 | I27: -0.40882 | J27: -1.19881 | K27: 1.45011 | L27: 0.95011 | M27: 1.75 | N27: 1.75 | O27: 0 | P27: 0.69122 | Q27: -0.09878 | R27: 0.45 | S27: 0.45 | T27: 0 | U27: 3.1 | V27: 12.5 | W27: 12.5 | X27: =(K27+L27)/2*M27*O27 -> 0 | Y27: =(P27+Q27)/2*R27*T27 -> 0
... A31: 27 | B31: 西U2-1 | C31: 271.8991 | D31: 291.8991 | E31: =ABS(D31-C31) -> 20 | F31: =E31 -> 20 | G31: 3.348 | H31: 3.348 | I31: -3.3461 | J31: -3.90902 | K31: -0.55289 | L31: -0.95704 | M31: 1.75 | N31: 1.75 | O31: 1 | P31: -2.13034 | Q31: -2.41868 | R31: 0.45 | S31: 0.45 | T31: 0 | U31: 3.1 | V31: 28.29 | W31: 22.25 | X31: =(K31+L31)/2*M31*O31 -> -1.3211887 | Y31: =(P31+Q31)/2*R31*T31 -> 0
A32: 28 | B32: 西U6-2 | C32: 191.7791 | D32: 211.7791 | E32: 20 | F32: 20 | G32: 3.348 | H32: 3.348 | I32: -0.40882 | J32: -1.19881 | K32: 1.45011 | L32: 0.95011 | M32: 1.75 | N32: 1.75 | O32: 0 | P32: 0.69122 | Q32: -0.09878 | R32: 0.45 | S32: 0.45 | T32: 0 | U32: 3.1 | V32: 8 | W32: 9.09 | X32: =(K32+L32)/2*M32*O32 -> 0 | Y32: =(P32+Q32)/2*R32*T32 -> 0
A33: 29 | B33: 西U5-2 | C33: 211.8091 | D33: 231.8091 | E33: 20 | F33: 20 | G33: 3.348 | H33: 3.348 | I33: -1.19999 | J33: -1.98997 | K33: 0.94936 | L33: 0.44936 | M33: 1.75 | N33: 1.75 | O33: 0 | P33: -0.09997 | Q33: -0.88997 | R33: 0.45 | S33: 0.45 | T33: 0 | U33: 3.1 | V33: 9.09 | W33: 8 | X33: =(K33+L33)/2*M33*O33 -> 0 | Y33: =(P33+Q33)/2*R33*T33 -> 0
A34: 30 | B34: 西U4-2 | C34: 231.8391 | D34: 251.8391 | E34: 20 | F34: 20 | G34: 3.348 | H34: 3.348 | I34: -1.99116 | J34: -2.78114 | K34: 0.44861 | L34: -0.05139 | M34: 1.75 | N34: 1.75 | O34: 0 | P34: -0.89115 | Q34: -1.61791 | R34: 0.45 | S34: 0.45 | T34: 0 | U34: 3.1 | V34: 8 | W34: 8 | X34: =(K34+L34)/2*M34*O34 -> 0 | Y34: =(P34+Q34)/2*R34*T34 -> 0
A35: 31 | B35: 西U3-2 | C35: 251.8691 | D35: 271.8691 | E35: 20 | F35: 20 | G35: 3.348 | H35: 3.348 | I35: -2.78233 | J35: -3.34525 | K35: -0.05214 | L35: -0.55214 | M35: 1.75 | N35: 1.75 | O35: 0 | P35: -1.61884 | Q35: -2.12974 | R35: 0.45 | S35: 0.45 | T35: 0 | U35: 3.1 | V35: 8 | W35: 14.06 | X35: =(K35+L35)/2*M35*O35 -> 0 | Y35: =(P35+Q35)/2*R35*T35 -> 0
A36: 32
X37: =SUM(X5:X36) -> 14.981059
B38: 二、命名并形成U型槽结构参数表 单位：m
A39: U型槽编号 | B39: 起讫点里程 | D39: 中心长度L | E39: 顶高程E1 | G39: 底板顶高程E2 | I39: 结构净高H | K39: 底板厚T | L39: 边墙厚B | M39: D | O39: 机非分隔带 | T39: 中央分隔带
O40: 高度h1 | Q40: 宽度b1 | S40: 数量 | T40: 高度h2 | V40: 宽度b2 | X40: 数量
A41: =B5 -> ZU1-2 | B41: =C5 -> 109.9395 | C41: =D5 -> 129.9395 | D41: =ABS(C41-B41) -> 20 | E41: =G5 -> 3.61863 | F41: =H5 -> 3.348 | G41: =I5 -> 2.92747 | H41: =J5 -> 2.48762 | I41: =E41-G41 -> 0.69116 | J41: =F41-H41 -> 0.86038 | K41: =L41+0.1 -> 0.4 | L41: =LOOKUP(MAX(J41,I41),{0,3,4,5,6.5,7.5,9,10},{0.3,0.4,0.5,0.6,0.7,0.8,0.9}) -> 0.3 | M41: =V5+L41*2 -> 8.6 | N41: =W5+L41*2 -> 8.6 | O41: =K5-I5+0.2 -> 0.7 | P41: =L5-J5+0.2 -> 0.70009 | Q41: =M5 -> 1.75 | R41: =N5 -> 1.75 | S41: =O5 -> 0 | T41: =P5-I5+1 -> 1.5 | U41: =Q5-J5 -> 0.49545 | V41: =R5 -> 0.45 | W41: =S5 -> 0.45 | X41: =T5 -> 0 | Y41: =(O41+P41)/2*Q41*S41 -> 0 | Z41: =(T41+U41)/2*V41*X41 -> 0
A42: =B6 -> ZU2-2 | B42: =C6 -> 129.9695 | C42: =D6 -> 149.9695 | D42: =ABS(C42-B42) -> 20 | E42: =G6 -> 3.348 | F42: =H6 -> 3.348 | G42: =I6 -> 2.48696 | H42: =J6 -> 1.98696 | I42: =E42-G42 -> 0.86104 | J42: =F42-H42 -> 1.36104 | K42: =L42+0.1 -> 0.4 | L42: =LOOKUP(MAX(J42,I42),{0,3,4,5,6.5,7.5,9,10},{0.3,0.4,0.5,0.6,0.7,0.8,0.9}) -> 0.3 | M42: =V6+L42*2 -> 8.6 | N42: =W6+L42*2 -> 8.6 | O42: =K6-I6+0.2 -> 0.7 | P42: =L6-J6+0.2 -> 0.7 | Q42: =M6 -> 1.75 | R42: =N6 -> 1.75 | S42: =O6 -> 0 | T42: =P6-I6+1 -> 1.4953 | U42: =Q6-J6 -> 0.3506 | V42: =R6 -> 0.45 | W42: =S6 -> 0.45 | X42: =T6 -> 0 | Y42: =(O42+P42)/2*Q42*S42 -> 0 | Z42: =(T42+U42)/2*V42*X42 -> 0
A43: =B7 -> ZU3-2 | B43: =C7 -> 149.9995 | C43: =D7 -> 169.9995 | D43: =ABS(C43-B43) -> 20 | E43: =G7 -> 3.348 | F43: =H7 -> 3.348 | G43: =I7 -> 1.98621 | H43: =J7 -> 1.48621 | I43: =E43-G43 -> 1.36179 | J43: =F43-H43 -> 1.86179 | K43: =L43+0.1 -> 0.4 | L43: =LOOKUP(MAX(J43,I43),{0,3,4,5,6.5,7.5,9,10},{0.3,0.4,0.5,0.6,0.7,0.8,0.9}) -> 0.3 | M43: =V7+L43*2 -> 8.6 | N43: =W7+L43*2 -> 8.6 | O43: =K7-I7+0.2 -> 0.7 | P43: =L7-J7+0.2 -> 0.7 | Q43: =M7 -> 1.75 | R43: =N7 -> 1.75 | S43: =O7 -> 0 | T43: =P7-I7+1 -> 1.35023 | U43: =Q7-J7 -> 0.0653 | V43: =R7 -> 0.45 | W43: =S7 -> 0.45 | X43: =T7 -> 0 | Y43: =(O43+P43)/2*Q43*S43 -> 0 | Z43: =(T43+U43)/2*V43*X43 -> 0
A44: =B8 -> ZU4-2 | B44: =C8 -> 170.0295 | C44: =D8 -> 190.0295 | D44: =ABS(C44-B44) -> 20 | E44: =G8 -> 3.348 | F44: =H8 -> 3.348 | G44: =I8 -> 1.48546 | H44: =J8 -> 0.98546 | I44: =E44-G44 -> 1.86254 | J44: =F44-H44 -> 2.36254 | K44: =L44+0.1 -> 0.4 | L44: =LOOKUP(MAX(J44,I44),{0,3,4,5,6.5,7.5,9,10},{0.3,0.4,0.5,0.6,0.7,0.8,0.9}) -> 0.3 | M44: =V8+L44*2 -> 8.6 | N44: =W8+L44*2 -> 8.6 | O44: =K8-I8+0.2 -> 0.7 | P44: =L8-J8+0.2 -> 0.7 | Q44: =M8 -> 1.75 | R44: =N8 -> 1.75 | S44: =O8 -> 0 | T44: =P8-I8+1 -> 1.06486 | U44: =Q8-J8 -> -0.22514 | V44: =R8 -> 0.45 | W44: =S8 -> 0.45 | X44: =T8 -> 0 | Y44: =(O44+P44)/2*Q44*S44 -> 0 | Z44: =(T44+U44)/2*V44*X44 -> 0
...

Sheet 1.U型槽主筋验算
I1: 边墙厚度 | J1: 结构净高 | K1: 水位高 | L1: 钢筋
H2: ='0.结构参数'!A41 -> ZU1-2 | I2: ='0.结构参数'!L41 -> 0.3 | J2: =MAX('0.结构参数'!I41,'0.结构参数'!J41) -> 0.86038 | K2: =3.1-MIN('0.结构参数'!I5,'0.结构参数'!J5) -> 0.61238 | L2: 14
H3: ='0.结构参数'!A42 -> ZU2-2 | I3: ='0.结构参数'!L42 -> 0.3 | J3: =MAX('0.结构参数'!I42,'0.结构参数'!J42) -> 1.36104 | K3: =3.1-MIN('0.结构参数'!I6,'0.结构参数'!J6) -> 1.11304 | L3: 14
H4: ='0.结构参数'!A43 -> ZU3-2 | I4: ='0.结构参数'!L43 -> 0.3 | J4: =MAX('0.结构参数'!I43,'0.结构参数'!J43) -> 1.86179 | K4: =3.1-MIN('0.结构参数'!I7,'0.结构参数'!J7) -> 1.61379 | L4: 14
H5: ='0.结构参数'!A44 -> ZU4-2 | I5: ='0.结构参数'!L44 -> 0.3 | J5: =MAX('0.结构参数'!I44,'0.结构参数'!J44) -> 2.36254 | K5: =3.1-MIN('0.结构参数'!I8,'0.结构参数'!J8) -> 2.11454 | L5: 14
H6: ='0.结构参数'!A45 -> ZU5-2 | I6: ='0.结构参数'!L45 -> 0.3 | J6: =MAX('0.结构参数'!I45,'0.结构参数'!J45) -> 2.86329 | K6: =3.1-MIN('0.结构参数'!I9,'0.结构参数'!J9) -> 2.61529 | L6: 18
H7: ='0.结构参数'!A46 -> ZU6-2 | I7: ='0.结构参数'!L46 -> 0.4 | J7: =MAX('0.结构参数'!I46,'0.结构参数'!J46) -> 3.36404 | K7: =3.1-MIN('0.结构参数'!I10,'0.结构参数'!J10) -> 3.11604 | L7: 18
H8: ='0.结构参数'!A47 -> ZU7-2 | I8: ='0.结构参数'!L47 -> 0.4 | J8: =MAX('0.结构参数'!I47,'0.结构参数'!J47) -> 3.86479 | K8: =3.1-MIN('0.结构参数'!I11,'0.结构参数'!J11) -> 3.61679 | L8: 22
H9: ='0.结构参数'!A48 -> ZU8-2 | I9: ='0.结构参数'!L48 -> 0.5 | J9: =MAX('0.结构参数'!I48,'0.结构参数'!J48) -> 4.36554 | K9: =3.1-MIN('0.结构参数'!I12,'0.结构参数'!J12) -> 4.11754 | L9: 25
B10: ZU1-2~ZU4-2、ZU1-17~ZU19-2计算书 | H10: ='0.结构参数'!A49 -> ZU9-2 | I10: ='0.结构参数'!L49 -> 0.5 | J10: =MAX('0.结构参数'!I49,'0.结构参数'!J49) -> 4.86629 | K10: =3.1-MIN('0.结构参数'!I13,'0.结构参数'!J13) -> 4.61829 | L10: 20 | M10: 2*20
H11: ='0.结构参数'!A50 -> ZU10-2 | I11: ='0.结构参数'!L50 -> 0.5 | J11: =MAX('0.结构参数'!I50,'0.结构参数'!J50) -> 4.96733 | K11: =3.1-MIN('0.结构参数'!I14,'0.结构参数'!J14) -> 4.71933 | L11: 20 | M11: 2*20
H12: ='0.结构参数'!A51 -> ZU11-2 | I12: ='0.结构参数'!L51 -> 0.5 | J12: =MAX('0.结构参数'!I51,'0.结构参数'!J51) -> 4.8 | K12: =3.1-MIN('0.结构参数'!I15,'0.结构参数'!J15) -> 4.552 | L12: 18 | M12: 2*18
B13: 1、 | C13: 结构描述 | H13: ='0.结构参数'!A52 -> ZU12-2 | I13: ='0.结构参数'!L52 -> 0.5 | J13: =MAX('0.结构参数'!I52,'0.结构参数'!J52) -> 4.79925 | K13: =3.1-MIN('0.结构参数'!I16,'0.结构参数'!J16) -> 4.55125 | L13: 18 | M13: 2*18
H14: ='0.结构参数'!A53 -> ZU13-2 | I14: ='0.结构参数'!L53 -> 0.5 | J14: =MAX('0.结构参数'!I53,'0.结构参数'!J53) -> 4.3029 | K14: =3.1-MIN('0.结构参数'!I17,'0.结构参数'!J17) -> 4.0549 | L14: 25
H15: ='0.结构参数'!A54 -> ZU14-2 | I15: ='0.结构参数'!L54 -> 0.4 | J15: =MAX('0.结构参数'!I54,'0.结构参数'!J54) -> 3.80215 | K15: =3.1-MIN('0.结构参数'!I18,'0.结构参数'!J18) -> 3.55415 | L15: 22
H16: ='0.结构参数'!A55 -> ZU15-2 | I16: ='0.结构参数'!L55 -> 0.4 | J16: =MAX('0.结构参数'!I55,'0.结构参数'!J55) -> 3.3014 | K16: =3.1-MIN('0.结构参数'!I19,'0.结构参数'!J19) -> 3.0534 | L16: 18
H17: ='0.结构参数'!A56 -> ZU16-2 | I17: ='0.结构参数'!L56 -> 0.3 | J17: =MAX('0.结构参数'!I56,'0.结构参数'!J56) -> 2.80065 | K17: =3.1-MIN('0.结构参数'!I20,'0.结构参数'!J20) -> 2.55265 | L17: 16
H18: ='0.结构参数'!A57 -> ZU17-2 | I18: ='0.结构参数'!L57 -> 0.3 | J18: =MAX('0.结构参数'!I57,'0.结构参数'!J57) -> 2.2999 | K18: =3.1-MIN('0.结构参数'!I21,'0.结构参数'!J21) -> 2.0519 | L18: 14
H19: ='0.结构参数'!A58 -> ZU18-2 | I19: ='0.结构参数'!L58 -> 0.3 | J19: =MAX('0.结构参数'!I58,'0.结构参数'!J58) -> 1.79915 | K19: =3.1-MIN('0.结构参数'!I22,'0.结构参数'!J22) -> 1.55115 | L19: 14
H20: ='0.结构参数'!A59 -> ZU19-2 | I20: ='0.结构参数'!L59 -> 0.3 | J20: =MAX('0.结构参数'!I59,'0.结构参数'!J59) -> 1.29845 | K20: =3.1-MIN('0.结构参数'!I23,'0.结构参数'!J23) -> 1.05045 | L20: 14
H21: ='0.结构参数'!A60 -> 东U10 | I21: ='0.结构参数'!L60 -> 0.3 | J21: =MAX('0.结构参数'!I60,'0.结构参数'!J60) -> 1.63657 | K21: =3.15-MIN('0.结构参数'!I24,'0.结构参数'!J24) -> 0.87257 | L21: 14
H22: ='0.结构参数'!A61 -> 西U10-1 | I22: ='0.结构参数'!L61 -> 0.3 | J22: =MAX('0.结构参数'!I61,'0.结构参数'!J61) -> 1.61126 | K22: =3.15-MIN('0.结构参数'!I25,'0.结构参数'!J25) -> 1.41326 | L22: 14
H23: ='0.结构参数'!A62 -> 西U9-1 | I23: ='0.结构参数'!L62 -> 0.3 | J23: =MAX('0.结构参数'!I62,'0.结构参数'!J62) -> 2.17365 | K23: =3.15-MIN('0.结构参数'!I26,'0.结构参数'!J26) -> 1.97565 | L23: 14
H24: ='0.结构参数'!A63 -> 西U6-1 | I24: ='0.结构参数'!L63 -> 0.5 | J24: =MAX('0.结构参数'!I63,'0.结构参数'!J63) -> 4.54681 | K24: =3.15-MIN('0.结构参数'!I27,'0.结构参数'!J27) -> 4.34881 | L24: 22
H25: ='0.结构参数'!A64 -> 西U5-1 | I25: ='0.结构参数'!L64 -> 0.6 | J25: =MAX('0.结构参数'!I64,'0.结构参数'!J64) -> 5.33797 | K25: =3.15-MIN('0.结构参数'!I28,'0.结构参数'!J28) -> 5.13997 | L25: 25
H26: ='0.结构参数'!A65 -> 西U4-1 | I26: ='0.结构参数'!L65 -> 0.6 | J26: =MAX('0.结构参数'!I65,'0.结构参数'!J65) -> 6.12914 | K26: =3.15-MIN('0.结构参数'!I29,'0.结构参数'!J29) -> 5.93114 | L26: 20
H27: ='0.结构参数'!A66 -> 西U3-1 | I27: ='0.结构参数'!L66 -> 0.7 | J27: =MAX('0.结构参数'!I66,'0.结构参数'!J66) -> 6.69325 | K27: =3.15-MIN('0.结构参数'!I30,'0.结构参数'!J30) -> 6.49525 | L27: 22
H28: ='0.结构参数'!A67 -> 西U2-1 | I28: ='0.结构参数'!L67 -> 0.7 | J28: =MAX('0.结构参数'!I67,'0.结构参数'!J67) -> 7.25702 | K28: =3.15-MIN('0.结构参数'!I31,'0.结构参数'!J31) -> 7.05902 | L28: 25
H29: ='0.结构参数'!A68 -> 西U6-2 | I29: ='0.结构参数'!L68 -> 0.5 | J29: =MAX('0.结构参数'!I68,'0.结构参数'!J68) -> 4.54681 | K29: =3.15-MIN('0.结构参数'!I32,'0.结构参数'!J32) -> 4.34881 | L29: 22
B30: 结构尺寸 | C30: 顶宽： | D30: b1= | E30: 0.3 | H30: ='0.结构参数'!A69 -> 西U5-2 | I30: ='0.结构参数'!L69 -> 0.6 | J30: =MAX('0.结构参数'!I69,'0.结构参数'!J69) -> 5.33797 | K30: =3.15-MIN('0.结构参数'!I33,'0.结构参数'!J33) -> 5.13997 | L30: 25
C31: 底宽： | D31: b2= | E31: =E30 -> 0.3 | H31: ='0.结构参数'!A70 -> 西U4-2 | I31: ='0.结构参数'!L70 -> 0.6 | J31: =MAX('0.结构参数'!I70,'0.结构参数'!J70) -> 6.12914 | K31: =3.15-MIN('0.结构参数'!I34,'0.结构参数'!J34) -> 5.93114 | L31: 20
C32: 桥高： | D32: h= | E32: 2.4 | H32: ='0.结构参数'!A71 -> 西U3-2 | I32: ='0.结构参数'!L71 -> 0.7 | J32: =MAX('0.结构参数'!I71,'0.结构参数'!J71) -> 6.69325 | K32: =3.15-MIN('0.结构参数'!I35,'0.结构参数'!J35) -> 6.49525 | L32: 22
C33: 水高： | D33: H= | E33: 2.1
B35: 2、 | C35: 荷载计算
C37: 结构重要性系数： | D37: r0= | E37: =IF(E32>5,IF(F37="二级及以下公路",1,1.05),IF(F37="二级及以下公路",0.95,1)) -> 1 | F37: 高速公路、一级公路 | H37: 结构重要性系数
C38: 土压力分项系数： | D38: γt= | E38: 1.4 | H38: 墙高 | I38: 高速公路、一级公路 | J38: 二级及以下公路
C39: 水压力分项系数： | D39: γs= | E39: 1 | H39: ≤5.0m | I39: 1 | J39: 0.95
C40: 活载分项系数： | D40: γQ= | E40: 1.4 | H40: >5.0m | I40: 1.05 | J40: 1
B42: 2.1 | C42: 土压力计算
B44: 土压力 参数 | C44: 填土坡角 | D44: β= | E44: 0
...

Sheet 2.U型槽钢筋
A2: U型槽尺寸表 | B2: 节段 | C2: 净高不含底板厚 | E2: 节段宽 | G2: 边墙厚B | H2: 底板厚T | I2: D | J2: hmin+T | K2: hmax+T | N2: 角度 | O2: 净保护层
C3: Hmin | D3: Hmax | E3: Lmax | F3: Lmin | N3: 90 | O3: 4 | P3: 4
B4: ='0.结构参数'!A41 -> ZU1-2 | C4: =MIN('0.结构参数'!I41,'0.结构参数'!J41)*100 -> 69.116 | D4: =MAX('0.结构参数'!I41,'0.结构参数'!J41)*100 -> 86.038 | E4: =MAX('0.结构参数'!E5,'0.结构参数'!F5)*100 -> 2000 | F4: =MIN('0.结构参数'!E5,'0.结构参数'!F5)*100 -> 2000 | G4: ='0.结构参数'!L41*100 -> 30 | H4: ='0.结构参数'!K41*100 -> 40 | I4: =('0.结构参数'!M41+'0.结构参数'!N41)/2*100 -> 860 | J4: =(C4+$H4) -> 109.116 | K4: =(D4+$H4) -> 126.038
B5: ='0.结构参数'!A42 -> ZU2-2 | C5: =MIN('0.结构参数'!I42,'0.结构参数'!J42)*100 -> 86.104 | D5: =MAX('0.结构参数'!I42,'0.结构参数'!J42)*100 -> 136.104 | E5: =MAX('0.结构参数'!E6,'0.结构参数'!F6)*100 -> 2000 | F5: =MIN('0.结构参数'!E6,'0.结构参数'!F6)*100 -> 2000 | G5: ='0.结构参数'!L42*100 -> 30 | H5: ='0.结构参数'!K42*100 -> 40 | I5: =('0.结构参数'!M42+'0.结构参数'!N42)/2*100 -> 860 | J5: =(C5+$H5) -> 126.104 | K5: =(D5+$H5) -> 176.104
B6: ='0.结构参数'!A43 -> ZU3-2 | C6: =MIN('0.结构参数'!I43,'0.结构参数'!J43)*100 -> 136.179 | D6: =MAX('0.结构参数'!I43,'0.结构参数'!J43)*100 -> 186.179 | E6: =MAX('0.结构参数'!E7,'0.结构参数'!F7)*100 -> 2000 | F6: =MIN('0.结构参数'!E7,'0.结构参数'!F7)*100 -> 2000 | G6: ='0.结构参数'!L43*100 -> 30 | H6: ='0.结构参数'!K43*100 -> 40 | I6: =('0.结构参数'!M43+'0.结构参数'!N43)/2*100 -> 860 | J6: =(C6+$H6) -> 176.179 | K6: =(D6+$H6) -> 226.179
B7: ='0.结构参数'!A44 -> ZU4-2 | C7: =MIN('0.结构参数'!I44,'0.结构参数'!J44)*100 -> 186.254 | D7: =MAX('0.结构参数'!I44,'0.结构参数'!J44)*100 -> 236.254 | E7: =MAX('0.结构参数'!E8,'0.结构参数'!F8)*100 -> 2000 | F7: =MIN('0.结构参数'!E8,'0.结构参数'!F8)*100 -> 2000 | G7: ='0.结构参数'!L44*100 -> 30 | H7: ='0.结构参数'!K44*100 -> 40 | I7: =('0.结构参数'!M44+'0.结构参数'!N44)/2*100 -> 860 | J7: =(C7+$H7) -> 226.254 | K7: =(D7+$H7) -> 276.254
B8: ='0.结构参数'!A45 -> ZU5-2 | C8: =MIN('0.结构参数'!I45,'0.结构参数'!J45)*100 -> 236.329 | D8: =MAX('0.结构参数'!I45,'0.结构参数'!J45)*100 -> 286.329 | E8: =MAX('0.结构参数'!E9,'0.结构参数'!F9)*100 -> 2000 | F8: =MIN('0.结构参数'!E9,'0.结构参数'!F9)*100 -> 2000 | G8: ='0.结构参数'!L45*100 -> 30 | H8: ='0.结构参数'!K45*100 -> 40 | I8: =('0.结构参数'!M45+'0.结构参数'!N45)/2*100 -> 860 | J8: =(C8+$H8) -> 276.329 | K8: =(D8+$H8) -> 326.329 | N8: 4、e2数值改为定值8，但仍需注意表格外e2取值区间
B9: ='0.结构参数'!A46 -> ZU6-2 | C9: =MIN('0.结构参数'!I46,'0.结构参数'!J46)*100 -> 286.404 | D9: =MAX('0.结构参数'!I46,'0.结构参数'!J46)*100 -> 336.404 | E9: =MAX('0.结构参数'!E10,'0.结构参数'!F10)*100 -> 2000 | F9: =MIN('0.结构参数'!E10,'0.结构参数'!F10)*100 -> 2000 | G9: ='0.结构参数'!L46*100 -> 40 | H9: ='0.结构参数'!K46*100 -> 50 | I9: =('0.结构参数'!M46+'0.结构参数'!N46)/2*100 -> 880 | J9: =(C9+$H9) -> 336.404 | K9: =(D9+$H9) -> 386.404
B10: ='0.结构参数'!A47 -> ZU7-2 | C10: =MIN('0.结构参数'!I47,'0.结构参数'!J47)*100 -> 336.479 | D10: =MAX('0.结构参数'!I47,'0.结构参数'!J47)*100 -> 386.479 | E10: =MAX('0.结构参数'!E11,'0.结构参数'!F11)*100 -> 2000 | F10: =MIN('0.结构参数'!E11,'0.结构参数'!F11)*100 -> 2000 | G10: ='0.结构参数'!L47*100 -> 40 | H10: ='0.结构参数'!K47*100 -> 50 | I10: =('0.结构参数'!M47+'0.结构参数'!N47)/2*100 -> 880 | J10: =(C10+$H10) -> 386.479 | K10: =(D10+$H10) -> 436.479
B11: ='0.结构参数'!A48 -> ZU8-2 | C11: =MIN('0.结构参数'!I48,'0.结构参数'!J48)*100 -> 386.554 | D11: =MAX('0.结构参数'!I48,'0.结构参数'!J48)*100 -> 436.554 | E11: =MAX('0.结构参数'!E12,'0.结构参数'!F12)*100 -> 2000 | F11: =MIN('0.结构参数'!E12,'0.结构参数'!F12)*100 -> 2000 | G11: ='0.结构参数'!L48*100 -> 50 | H11: ='0.结构参数'!K48*100 -> 60 | I11: =('0.结构参数'!M48+'0.结构参数'!N48)/2*100 -> 900 | J11: =(C11+$H11) -> 446.554 | K11: =(D11+$H11) -> 496.554
B12: ='0.结构参数'!A49 -> ZU9-2 | C12: =MIN('0.结构参数'!I49,'0.结构参数'!J49)*100 -> 436.629 | D12: =MAX('0.结构参数'!I49,'0.结构参数'!J49)*100 -> 486.629 | E12: =MAX('0.结构参数'!E13,'0.结构参数'!F13)*100 -> 2000 | F12: =MIN('0.结构参数'!E13,'0.结构参数'!F13)*100 -> 2000 | G12: ='0.结构参数'!L49*100 -> 50 | H12: ='0.结构参数'!K49*100 -> 60 | I12: =('0.结构参数'!M49+'0.结构参数'!N49)/2*100 -> 900 | J12: =(C12+$H12) -> 496.629 | K12: =(D12+$H12) -> 546.629
B13: ='0.结构参数'!A50 -> ZU10-2 | C13: =MIN('0.结构参数'!I50,'0.结构参数'!J50)*100 -> 486.644 | D13: =MAX('0.结构参数'!I50,'0.结构参数'!J50)*100 -> 496.733 | E13: =MAX('0.结构参数'!E14,'0.结构参数'!F14)*100 -> 2000 | F13: =MIN('0.结构参数'!E14,'0.结构参数'!F14)*100 -> 2000 | G13: ='0.结构参数'!L50*100 -> 50 | H13: ='0.结构参数'!K50*100 -> 60 | I13: =('0.结构参数'!M50+'0.结构参数'!N50)/2*100 -> 900 | J13: =(C13+$H13) -> 546.644 | K13: =(D13+$H13) -> 556.733
B14: ='0.结构参数'!A51 -> ZU11-2 | C14: =MIN('0.结构参数'!I51,'0.结构参数'!J51)*100 -> 480 | D14: =MAX('0.结构参数'!I51,'0.结构参数'!J51)*100 -> 480 | E14: =MAX('0.结构参数'!E15,'0.结构参数'!F15)*100 -> 2000 | F14: =MIN('0.结构参数'!E15,'0.结构参数'!F15)*100 -> 2000 | G14: ='0.结构参数'!L51*100 -> 50 | H14: ='0.结构参数'!K51*100 -> 60 | I14: =('0.结构参数'!M51+'0.结构参数'!N51)/2*100 -> 900 | J14: =(C14+$H14) -> 540 | K14: =(D14+$H14) -> 540
B15: ='0.结构参数'!A52 -> ZU12-2 | C15: =MIN('0.结构参数'!I52,'0.结构参数'!J52)*100 -> 430.364 | D15: =MAX('0.结构参数'!I52,'0.结构参数'!J52)*100 -> 479.925 | E15: =MAX('0.结构参数'!E16,'0.结构参数'!F16)*100 -> 2000 | F15: =MIN('0.结构参数'!E16,'0.结构参数'!F16)*100 -> 2000 | G15: ='0.结构参数'!L52*100 -> 50 | H15: ='0.结构参数'!K52*100 -> 60 | I15: =('0.结构参数'!M52+'0.结构参数'!N52)/2*100 -> 900 | J15: =(C15+$H15) -> 490.364 | K15: =(D15+$H15) -> 539.925
B16: ='0.结构参数'!A53 -> ZU13-2 | C16: =MIN('0.结构参数'!I53,'0.结构参数'!J53)*100 -> 380.29 | D16: =MAX('0.结构参数'!I53,'0.结构参数'!J53)*100 -> 430.29 | E16: =MAX('0.结构参数'!E17,'0.结构参数'!F17)*100 -> 2000 | F16: =MIN('0.结构参数'!E17,'0.结构参数'!F17)*100 -> 2000 | G16: ='0.结构参数'!L53*100 -> 50 | H16: ='0.结构参数'!K53*100 -> 60 | I16: =('0.结构参数'!M53+'0.结构参数'!N53)/2*100 -> 900 | J16: =(C16+$H16) -> 440.29 | K16: =(D16+$H16) -> 490.29
B17: ='0.结构参数'!A54 -> ZU14-2 | C17: =MIN('0.结构参数'!I54,'0.结构参数'!J54)*100 -> 330.215 | D17: =MAX('0.结构参数'!I54,'0.结构参数'!J54)*100 -> 380.215 | E17: =MAX('0.结构参数'!E18,'0.结构参数'!F18)*100 -> 2000 | F17: =MIN('0.结构参数'!E18,'0.结构参数'!F18)*100 -> 2000 | G17: ='0.结构参数'!L54*100 -> 40 | H17: ='0.结构参数'!K54*100 -> 50 | I17: =('0.结构参数'!M54+'0.结构参数'!N54)/2*100 -> 880 | J17: =(C17+$H17) -> 380.215 | K17: =(D17+$H17) -> 430.215
B18: ='0.结构参数'!A55 -> ZU15-2 | C18: =MIN('0.结构参数'!I55,'0.结构参数'!J55)*100 -> 280.14 | D18: =MAX('0.结构参数'!I55,'0.结构参数'!J55)*100 -> 330.14 | E18: =MAX('0.结构参数'!E19,'0.结构参数'!F19)*100 -> 2000 | F18: =MIN('0.结构参数'!E19,'0.结构参数'!F19)*100 -> 2000 | G18: ='0.结构参数'!L55*100 -> 40 | H18: ='0.结构参数'!K55*100 -> 50 | I18: =('0.结构参数'!M55+'0.结构参数'!N55)/2*100 -> 880 | J18: =(C18+$H18) -> 330.14 | K18: =(D18+$H18) -> 380.14
B19: ='0.结构参数'!A56 -> ZU16-2 | C19: =MIN('0.结构参数'!I56,'0.结构参数'!J56)*100 -> 230.065 | D19: =MAX('0.结构参数'!I56,'0.结构参数'!J56)*100 -> 280.065 | E19: =MAX('0.结构参数'!E20,'0.结构参数'!F20)*100 -> 2000 | F19: =MIN('0.结构参数'!E20,'0.结构参数'!F20)*100 -> 2000 | G19: ='0.结构参数'!L56*100 -> 30 | H19: ='0.结构参数'!K56*100 -> 40 | I19: =('0.结构参数'!M56+'0.结构参数'!N56)/2*100 -> 860 | J19: =(C19+$H19) -> 270.065 | K19: =(D19+$H19) -> 320.065
B20: ='0.结构参数'!A57 -> ZU17-2 | C20: =MIN('0.结构参数'!I57,'0.结构参数'!J57)*100 -> 179.99 | D20: =MAX('0.结构参数'!I57,'0.结构参数'!J57)*100 -> 229.99 | E20: =MAX('0.结构参数'!E21,'0.结构参数'!F21)*100 -> 2000 | F20: =MIN('0.结构参数'!E21,'0.结构参数'!F21)*100 -> 2000 | G20: ='0.结构参数'!L57*100 -> 30 | H20: ='0.结构参数'!K57*100 -> 40 | I20: =('0.结构参数'!M57+'0.结构参数'!N57)/2*100 -> 860 | J20: =(C20+$H20) -> 219.99 | K20: =(D20+$H20) -> 269.99
... B35: ='0.结构参数'!A72 -> 0 | C35: =MIN('0.结构参数'!I72,'0.结构参数'!J72)*100 -> 0 | D35: =MAX('0.结构参数'!I72,'0.结构参数'!J72)*100 -> 0 | E35: =MAX('0.结构参数'!E36,'0.结构参数'!F36)*100 -> 0 | F35: =MIN('0.结构参数'!E36,'0.结构参数'!F36)*100 -> 0 | G35: ='0.结构参数'!L72*100 -> 30 | H35: ='0.结构参数'!K72*100 -> 40 | I35: =('0.结构参数'!M72+'0.结构参数'!N72)/2*100 -> 60 | J35: =(C35+$H35) -> 40 | K35: =(D35+$H35) -> 40
F37: 此处若为负值，则公式改为“B21/D21-2” | P37: 若e2小于8，则在n1公式后减1
A38: 钢筋图参数表 | B38: U型槽 编号 | C38: D (cm) | D38: n | E38: d (cm) | F38: a 0~12.5 | G38: B (cm) | H38: m | I38: b (cm) | J38: e1 (cm) | K38: Hmin (cm) | L38: Hmax (cm) | M38: n1 | N38: d1 (cm) | O38: d2 (cm) | P38: e2 | Q38: T | R38: n1' | S38: d1' | T38: L1 (cm) | U38: m1 | V38: b1 (cm) | W38: L2 (cm) | X38: m2 | Y38: b2 (cm) | Z38: e3 (cm) | AA38: e2 7~20.5
B39: =B4 -> ZU1-2 | C39: =VLOOKUP(B39,$B$4:$K$36,8,0) -> 860 | D39: =ROUNDDOWN((C39/E39-1),0) -> 67 | E39: =12.5 -> 12.5 | F39: =C39-D39*E39-2*J39 -> 6.5 | G39: =VLOOKUP(B39,$B$4:$J$72,6,0) -> 30 | H39: 2 | I39: =(G39-J39*2)/H39 -> 7 | J39: 8 | K39: =VLOOKUP(B39,$B$4:$K$36,2,0) -> 69.116 | L39: =VLOOKUP(B39,$B$4:$K$36,3,0) -> 86.038 | M39: =ROUND((L39-5)/12.5,0)-1 -> 5 | N39: =(L39-5-P39)/M39 -> 14.6076 | O39: =(K39-P39-5)/M39 -> 11.2232 | P39: 8 | Q39: =VLOOKUP($B39,$B$4:$K$36,7,0) -> 40 | R39: 3 | S39: =(Q39-2*J39)/R39 -> 8 | T39: =VLOOKUP($B39,$B$4:$K$36,4,0) -> 2000 | U39: =ROUNDDOWN(T39/V39,0)-1 -> 159 | V39: 12.5 | W39: =VLOOKUP($B39,$B$4:$K$36,5,0) -> 2000 | X39: =U39 -> 159 | Y39: =(W39-Z39*2)/X39 -> 12.5 | Z39: =(T39-U39*V39)/2 -> 6.25 | AA39: =L39-M39*12.5-5 -> 18.538
B40: =B5 -> ZU2-2 | C40: =VLOOKUP(B40,$B$4:$K$36,8,0) -> 860 | D40: =ROUNDDOWN((C40/E40-1),0) -> 67 | E40: =12.5 -> 12.5 | F40: =C40-D40*E40-2*J40 -> 6.5 | G40: =VLOOKUP(B40,$B$4:$J$72,6,0) -> 30 | H40: 2 | I40: =(G40-J40*2)/H40 -> 7 | J40: 8 | K40: =VLOOKUP(B40,$B$4:$K$36,2,0) -> 86.104 | L40: =VLOOKUP(B40,$B$4:$K$36,3,0) -> 136.104 | M40: =ROUND((L40-5)/12.5,0)-1 -> 9 | N40: =(L40-5-P40)/M40 -> 13.678222 | O40: =(K40-P40-5)/M40 -> 8.1226667 | P40: 8 | Q40: =VLOOKUP($B40,$B$4:$K$36,7,0) -> 40 | R40: 3 | S40: =(Q40-2*J40)/R40 -> 8 | T40: =VLOOKUP($B40,$B$4:$K$36,4,0) -> 2000 | U40: =ROUNDDOWN(T40/V40,0)-1 -> 159 | V40: 12.5 | W40: =VLOOKUP($B40,$B$4:$K$36,5,0) -> 2000 | X40: =U40 -> 159 | Y40: =(W40-Z40*2)/X40 -> 12.5 | Z40: =(T40-U40*V40)/2 -> 6.25 | AA40: =L40-M40*12.5-5 -> 18.604
B41: =B6 -> ZU3-2 | C41: =VLOOKUP(B41,$B$4:$K$36,8,0) -> 860 | D41: =ROUNDDOWN((C41/E41-1),0) -> 67 | E41: =12.5 -> 12.5 | F41: =C41-D41*E41-2*J41 -> 6.5 | G41: =VLOOKUP(B41,$B$4:$J$72,6,0) -> 30 | H41: 2 | I41: =(G41-J41*2)/H41 -> 7 | J41: 8 | K41: =VLOOKUP(B41,$B$4:$K$36,2,0) -> 136.179 | L41: =VLOOKUP(B41,$B$4:$K$36,3,0) -> 186.179 | M41: =ROUND((L41-5)/12.5,0)-1 -> 13 | N41: =(L41-5-P41)/M41 -> 13.321462 | O41: =(K41-P41-5)/M41 -> 9.4753077 | P41: 8 | Q41: =VLOOKUP($B41,$B$4:$K$36,7,0) -> 40 | R41: 3 | S41: =(Q41-2*J41)/R41 -> 8 | T41: =VLOOKUP($B41,$B$4:$K$36,4,0) -> 2000 | U41: =ROUNDDOWN(T41/V41,0)-1 -> 159 | V41: 12.5 | W41: =VLOOKUP($B41,$B$4:$K$36,5,0) -> 2000 | X41: =U41 -> 159 | Y41: =(W41-Z41*2)/X41 -> 12.5 | Z41: =(T41-U41*V41)/2 -> 6.25 | AA41: =L41-M41*12.5-5 -> 18.679
B42: =B7 -> ZU4-2 | C42: =VLOOKUP(B42,$B$4:$K$36,8,0) -> 860 | D42: =ROUNDDOWN((C42/E42-1),0) -> 67 | E42: =12.5 -> 12.5 | F42: =C42-D42*E42-2*J42 -> 6.5 | G42: =VLOOKUP(B42,$B$4:$J$72,6,0) -> 30 | H42: 2 | I42: =(G42-J42*2)/H42 -> 7 | J42: 8 | K42: =VLOOKUP(B42,$B$4:$K$36,2,0) -> 186.254 | L42: =VLOOKUP(B42,$B$4:$K$36,3,0) -> 236.254 | M42: =ROUND((L42-5)/12.5,0)-1 -> 18 | N42: =(L42-5-P42)/M42 -> 12.403 | O42: =(K42-P42-5)/M42 -> 9.6252222 | P42: 8 | Q42: =VLOOKUP($B42,$B$4:$K$36,7,0) -> 40 | R42: 4 | S42: =(Q42-2*J42)/R42 -> 6 | T42: =VLOOKUP($B42,$B$4:$K$36,4,0) -> 2000 | U42: =ROUNDDOWN(T42/V42,0)-1 -> 159 | V42: 12.5 | W42: =VLOOKUP($B42,$B$4:$K$36,5,0) -> 2000 | X42: =U42 -> 159 | Y42: =(W42-Z42*2)/X42 -> 12.5 | Z42: =(T42-U42*V42)/2 -> 6.25 | AA42: =L42-M42*12.5-5 -> 6.254
B43: =B8 -> ZU5-2 | C43: =VLOOKUP(B43,$B$4:$K$36,8,0) -> 860 | D43: =ROUNDDOWN((C43/E43-1),0) -> 67 | E43: =12.5 -> 12.5 | F43: =C43-D43*E43-2*J43 -> 6.5 | G43: =VLOOKUP(B43,$B$4:$J$72,6,0) -> 30 | H43: 2 | I43: =(G43-J43*2)/H43 -> 7 | J43: 8 | K43: =VLOOKUP(B43,$B$4:$K$36,2,0) -> 236.329 | L43: =VLOOKUP(B43,$B$4:$K$36,3,0) -> 286.329 | M43: =ROUND((L43-5)/12.5,0)-1 -> 22 | N43: =(L43-5-P43)/M43 -> 12.424045 | O43: =(K43-P43-5)/M43 -> 10.151318 | P43: 8 | Q43: =VLOOKUP($B43,$B$4:$K$36,7,0) -> 40 | R43: 4 | S43: =(Q43-2*J43)/R43 -> 6 | T43: =VLOOKUP($B43,$B$4:$K$36,4,0) -> 2000 | U43: =ROUNDDOWN(T43/V43,0)-1 -> 159 | V43: 12.5 | W43: =VLOOKUP($B43,$B$4:$K$36,5,0) -> 2000 | X43: =U43 -> 159 | Y43: =(W43-Z43*2)/X43 -> 12.5 | Z43: =(T43-U43*V43)/2 -> 6.25 | AA43: =L43-M43*12.5-5 -> 6.329
B44: =B9 -> ZU6-2 | C44: =VLOOKUP(B44,$B$4:$K$36,8,0) -> 880 | D44: =ROUNDDOWN((C44/E44-1),0) -> 69 | E44: =12.5 -> 12.5 | F44: =C44-D44*E44-2*J44 -> 1.5 | G44: =VLOOKUP(B44,$B$4:$J$72,6,0) -> 40 | H44: 3 | I44: =(G44-J44*2)/H44 -> 8 | J44: 8 | K44: =VLOOKUP(B44,$B$4:$K$36,2,0) -> 286.404 | L44: =VLOOKUP(B44,$B$4:$K$36,3,0) -> 336.404 | M44: =ROUND((L44-5)/12.5,0)-1 -> 26 | N44: =(L44-5-P44)/M44 -> 12.438615 | O44: =(K44-P44-5)/M44 -> 10.515538 | P44: 8 | Q44: =VLOOKUP($B44,$B$4:$K$36,7,0) -> 50 | R44: 4 | S44: =(Q44-2*J44)/R44 -> 8.5 | T44: =VLOOKUP($B44,$B$4:$K$36,4,0) -> 2000 | U44: =ROUNDDOWN(T44/V44,0)-1 -> 159 | V44: 12.5 | W44: =VLOOKUP($B44,$B$4:$K$36,5,0) -> 2000 | X44: =U44 -> 159 | Y44: =(W44-Z44*2)/X44 -> 12.5 | Z44: =(T44-U44*V44)/2 -> 6.25 | AA44: =L44-M44*12.5-5 -> 6.404
B45: =B10 -> ZU7-2 | C45: =VLOOKUP(B45,$B$4:$K$36,8,0) -> 880 | D45: =ROUNDDOWN((C45/E45-1),0) -> 69 | E45: =12.5 -> 12.5 | F45: =C45-D45*E45-2*J45 -> 1.5 | G45: =VLOOKUP(B45,$B$4:$J$72,6,0) -> 40 | H45: 3 | I45: =(G45-J45*2)/H45 -> 8 | J45: 8 | K45: =VLOOKUP(B45,$B$4:$K$36,2,0) -> 336.479 | L45: =VLOOKUP(B45,$B$4:$K$36,3,0) -> 386.479 | M45: =ROUND((L45-5)/12.5,0)-1 -> 30 | N45: =(L45-5-P45)/M45 -> 12.4493 | O45: =(K45-P45-5)/M45 -> 10.782633 | P45: 8 | Q45: =VLOOKUP($B45,$B$4:$K$36,7,0) -> 50 | R45: 4 | S45: =(Q45-2*J45)/R45 -> 8.5 | T45: =VLOOKUP($B45,$B$4:$K$36,4,0) -> 2000 | U45: =ROUNDDOWN(T45/V45,0)-1 -> 159 | V45: 12.5 | W45: =VLOOKUP($B45,$B$4:$K$36,5,0) -> 2000 | X45: =U45 -> 159 | Y45: =(W45-Z45*2)/X45 -> 12.5 | Z45: =(T45-U45*V45)/2 -> 6.25 | AA45: =L45-M45*12.5-5 -> 6.479
B46: =B11 -> ZU8-2 | C46: =VLOOKUP(B46,$B$4:$K$36,8,0) -> 900 | D46: =ROUNDDOWN((C46/E46-2),0) -> 70 | E46: =12.5 -> 12.5 | F46: =C46-D46*E46-2*J46 -> 9 | G46: =VLOOKUP(B46,$B$4:$J$72,6,0) -> 50 | H46: 4 | I46: =(G46-J46*2)/H46 -> 8.5 | J46: 8 | K46: =VLOOKUP(B46,$B$4:$K$36,2,0) -> 386.554 | L46: =VLOOKUP(B46,$B$4:$K$36,3,0) -> 436.554 | M46: =ROUND((L46-5)/12.5,0)-1 -> 34 | N46: =(L46-5-P46)/M46 -> 12.457471 | O46: =(K46-P46-5)/M46 -> 10.986882 | P46: 8 | Q46: =VLOOKUP($B46,$B$4:$K$36,7,0) -> 60 | R46: 4 | S46: =(Q46-2*J46)/R46 -> 11 | T46: =VLOOKUP($B46,$B$4:$K$36,4,0) -> 2000 | U46: =ROUNDDOWN(T46/V46,0)-1 -> 159 | V46: 12.5 | W46: =VLOOKUP($B46,$B$4:$K$36,5,0) -> 2000 | X46: =U46 -> 159 | Y46: =(W46-Z46*2)/X46 -> 12.5 | Z46: =(T46-U46*V46)/2 -> 6.25 | AA46: =L46-M46*12.5-5 -> 6.554
B47: =B12 -> ZU9-2 | C47: =VLOOKUP(B47,$B$4:$K$36,8,0) -> 900 | D47: =ROUNDDOWN((C47/E47-2),0) -> 70 | E47: =12.5 -> 12.5 | F47: =C47-D47*E47-2*J47 -> 9 | G47: =VLOOKUP(B47,$B$4:$J$72,6,0) -> 50 | H47: 4 | I47: =(G47-J47*2)/H47 -> 8.5 | J47: 8 | K47: =VLOOKUP(B47,$B$4:$K$36,2,0) -> 436.629 | L47: =VLOOKUP(B47,$B$4:$K$36,3,0) -> 486.629 | M47: =ROUND((L47-5)/12.5,0)-1 -> 38 | N47: =(L47-5-P47)/M47 -> 12.463921 | O47: =(K47-P47-5)/M47 -> 11.148132 | P47: 8 | Q47: =VLOOKUP($B47,$B$4:$K$36,7,0) -> 60 | R47: 4 | S47: =(Q47-2*J47)/R47 -> 11 | T47: =VLOOKUP($B47,$B$4:$K$36,4,0) -> 2000 | U47: =ROUNDDOWN(T47/V47,0)-1 -> 159 | V47: 12.5 | W47: =VLOOKUP($B47,$B$4:$K$36,5,0) -> 2000 | X47: =U47 -> 159 | Y47: =(W47-Z47*2)/X47 -> 12.5 | Z47: =(T47-U47*V47)/2 -> 6.25 | AA47: =L47-M47*12.5-5 -> 6.629
B48: =B13 -> ZU10-2 | C48: =VLOOKUP(B48,$B$4:$K$36,8,0) -> 900 | D48: =ROUNDDOWN((C48/E48-2),0) -> 70 | E48: =12.5 -> 12.5 | F48: =C48-D48*E48-2*J48 -> 9 | G48: =VLOOKUP(B48,$B$4:$J$72,6,0) -> 50 | H48: 4 | I48: =(G48-J48*2)/H48 -> 8.5 | J48: 8 | K48: =VLOOKUP(B48,$B$4:$K$36,2,0) -> 486.644 | L48: =VLOOKUP(B48,$B$4:$K$36,3,0) -> 496.733 | M48: =ROUND((L48-5)/12.5,0)-1 -> 38 | N48: =(L48-5-P48)/M48 -> 12.729816 | O48: =(K48-P48-5)/M48 -> 12.464316 | P48: 8 | Q48: =VLOOKUP($B48,$B$4:$K$36,7,0) -> 60 | R48: 4 | S48: =(Q48-2*J48)/R48 -> 11 | T48: =VLOOKUP($B48,$B$4:$K$36,4,0) -> 2000 | U48: =ROUNDDOWN(T48/V48,0)-1 -> 159 | V48: 12.5 | W48: =VLOOKUP($B48,$B$4:$K$36,5,0) -> 2000 | X48: =U48 -> 159 | Y48: =(W48-Z48*2)/X48 -> 12.5 | Z48: =(T48-U48*V48)/2 -> 6.25 | AA48: =L48-M48*12.5-5 -> 16.733
B49: =B14 -> ZU11-2 | C49: =VLOOKUP(B49,$B$4:$K$36,8,0) -> 900 | D49: =ROUNDDOWN((C49/E49-2),0) -> 70 | E49: =12.5 -> 12.5 | F49: =C49-D49*E49-2*J49 -> 9 | G49: =VLOOKUP(B49,$B$4:$J$72,6,0) -> 50 | H49: 4 | I49: =(G49-J49*2)/H49 -> 8.5 | J49: 8 | K49: =VLOOKUP(B49,$B$4:$K$36,2,0) -> 480 | L49: =VLOOKUP(B49,$B$4:$K$36,3,0) -> 480 | M49: =ROUND((L49-5)/12.5,0)-1 -> 37 | N49: =(L49-5-P49)/M49 -> 12.621622 | O49: =(K49-P49-5)/M49 -> 12.621622 | P49: 8 | Q49: =VLOOKUP($B49,$B$4:$K$36,7,0) -> 60 | R49: 4 | S49: =(Q49-2*J49)/R49 -> 11 | T49: =VLOOKUP($B49,$B$4:$K$36,4,0) -> 2000 | U49: =ROUNDDOWN(T49/V49,0)-1 -> 159 | V49: 12.5 | W49: =VLOOKUP($B49,$B$4:$K$36,5,0) -> 2000 | X49: =U49 -> 159 | Y49: =(W49-Z49*2)/X49 -> 12.5 | Z49: =(T49-U49*V49)/2 -> 6.25 | AA49: =L49-M49*12.5-5 -> 12.5
B50: =B15 -> ZU12-2 | C50: =VLOOKUP(B50,$B$4:$K$36,8,0) -> 900 | D50: =ROUNDDOWN((C50/E50-2),0) -> 70 | E50: =12.5 -> 12.5 | F50: =C50-D50*E50-2*J50 -> 9 | G50: =VLOOKUP(B50,$B$4:$J$72,6,0) -> 50 | H50: 4 | I50: =(G50-J50*2)/H50 -> 8.5 | J50: 8 | K50: =VLOOKUP(B50,$B$4:$K$36,2,0) -> 430.364 | L50: =VLOOKUP(B50,$B$4:$K$36,3,0) -> 479.925 | M50: =ROUND((L50-5)/12.5,0)-1 -> 37 | N50: =(L50-5-P50)/M50 -> 12.619595 | O50: =(K50-P50-5)/M50 -> 11.280108 | P50: 8 | Q50: =VLOOKUP($B50,$B$4:$K$36,7,0) -> 60 | R50: 4 | S50: =(Q50-2*J50)/R50 -> 11 | T50: =VLOOKUP($B50,$B$4:$K$36,4,0) -> 2000 | U50: =ROUNDDOWN(T50/V50,0)-1 -> 159 | V50: 12.5 | W50: =VLOOKUP($B50,$B$4:$K$36,5,0) -> 2000 | X50: =U50 -> 159 | Y50: =(W50-Z50*2)/X50 -> 12.5 | Z50: =(T50-U50*V50)/2 -> 6.25 | AA50: =L50-M50*12.5-5 -> 12.425
B51: =B16 -> ZU13-2 | C51: =VLOOKUP(B51,$B$4:$K$36,8,0) -> 900 | D51: =ROUNDDOWN((C51/E51-2),0) -> 70 | E51: =12.5 -> 12.5 | F51: =C51-D51*E51-2*J51 -> 9 | G51: =VLOOKUP(B51,$B$4:$J$72,6,0) -> 50 | H51: 4 | I51: =(G51-J51*2)/H51 -> 8.5 | J51: 8 | K51: =VLOOKUP(B51,$B$4:$K$36,2,0) -> 380.29 | L51: =VLOOKUP(B51,$B$4:$K$36,3,0) -> 430.29 | M51: =ROUND((L51-5)/12.5,0)-1 -> 33 | N51: =(L51-5-P51)/M51 -> 12.645152 | O51: =(K51-P51-5)/M51 -> 11.13 | P51: 8 | Q51: =VLOOKUP($B51,$B$4:$K$36,7,0) -> 60 | R51: 4 | S51: =(Q51-2*J51)/R51 -> 11 | T51: =VLOOKUP($B51,$B$4:$K$36,4,0) -> 2000 | U51: =ROUNDDOWN(T51/V51,0)-1 -> 159 | V51: 12.5 | W51: =VLOOKUP($B51,$B$4:$K$36,5,0) -> 2000 | X51: =U51 -> 159 | Y51: =(W51-Z51*2)/X51 -> 12.5 | Z51: =(T51-U51*V51)/2 -> 6.25 | AA51: =L51-M51*12.5-5 -> 12.79
B52: =B17 -> ZU14-2 | C52: =VLOOKUP(B52,$B$4:$K$36,8,0) -> 880 | D52: =ROUNDDOWN((C52/E52-1),0) -> 69 | E52: =12.5 -> 12.5 | F52: =C52-D52*E52-2*J52 -> 1.5 | G52: =VLOOKUP(B52,$B$4:$J$72,6,0) -> 40 | H52: 3 | I52: =(G52-J52*2)/H52 -> 8 | J52: 8 | K52: =VLOOKUP(B52,$B$4:$K$36,2,0) -> 330.215 | L52: =VLOOKUP(B52,$B$4:$K$36,3,0) -> 380.215 | M52: =ROUND((L52-5)/12.5,0)-1 -> 29 | N52: =(L52-5-P52)/M52 -> 12.662586 | O52: =(K52-P52-5)/M52 -> 10.938448 | P52: 8 | Q52: =VLOOKUP($B52,$B$4:$K$36,7,0) -> 50 | R52: 4 | S52: =(Q52-2*J52)/R52 -> 8.5 | T52: =VLOOKUP($B52,$B$4:$K$36,4,0) -> 2000 | U52: =ROUNDDOWN(T52/V52,0)-1 -> 159 | V52: 12.5 | W52: =VLOOKUP($B52,$B$4:$K$36,5,0) -> 2000 | X52: =U52 -> 159 | Y52: =(W52-Z52*2)/X52 -> 12.5 | Z52: =(T52-U52*V52)/2 -> 6.25 | AA52: =L52-M52*12.5-5 -> 12.715
B53: =B18 -> ZU15-2 | C53: =VLOOKUP(B53,$B$4:$K$36,8,0) -> 880 | D53: =ROUNDDOWN((C53/E53-1),0) -> 69 | E53: =12.5 -> 12.5 | F53: =C53-D53*E53-2*J53 -> 1.5 | G53: =VLOOKUP(B53,$B$4:$J$72,6,0) -> 40 | H53: 3 | I53: =(G53-J53*2)/H53 -> 8 | J53: 8 | K53: =VLOOKUP(B53,$B$4:$K$36,2,0) -> 280.14 | L53: =VLOOKUP(B53,$B$4:$K$36,3,0) -> 330.14 | M53: =ROUND((L53-5)/12.5,0)-1 -> 25 | N53: =(L53-5-P53)/M53 -> 12.6856 | O53: =(K53-P53-5)/M53 -> 10.6856 | P53: 8 | Q53: =VLOOKUP($B53,$B$4:$K$36,7,0) -> 50 | R53: 4 | S53: =(Q53-2*J53)/R53 -> 8.5 | T53: =VLOOKUP($B53,$B$4:$K$36,4,0) -> 2000 | U53: =ROUNDDOWN(T53/V53,0)-1 -> 159 | V53: 12.5 | W53: =VLOOKUP($B53,$B$4:$K$36,5,0) -> 2000 | X53: =U53 -> 159 | Y53: =(W53-Z53*2)/X53 -> 12.5 | Z53: =(T53-U53*V53)/2 -> 6.25 | AA53: =L53-M53*12.5-5 -> 12.64
B54: =B19 -> ZU16-2 | C54: =VLOOKUP(B54,$B$4:$K$36,8,0) -> 860 | D54: =ROUNDDOWN((C54/E54-1),0) -> 67 | E54: =12.5 -> 12.5 | F54: =C54-D54*E54-2*J54 -> 6.5 | G54: =VLOOKUP(B54,$B$4:$J$72,6,0) -> 30 | H54: 2 | I54: =(G54-J54*2)/H54 -> 7 | J54: 8 | K54: =VLOOKUP(B54,$B$4:$K$36,2,0) -> 230.065 | L54: =VLOOKUP(B54,$B$4:$K$36,3,0) -> 280.065 | M54: =ROUND((L54-5)/12.5,0)-1 -> 21 | N54: =(L54-5-P54)/M54 -> 12.717381 | O54: =(K54-P54-5)/M54 -> 10.336429 | P54: 8 | Q54: =VLOOKUP($B54,$B$4:$K$36,7,0) -> 40 | R54: 3 | S54: =(Q54-2*J54)/R54 -> 8 | T54: =VLOOKUP($B54,$B$4:$K$36,4,0) -> 2000 | U54: =ROUNDDOWN(T54/V54,0)-1 -> 159 | V54: 12.5 | W54: =VLOOKUP($B54,$B$4:$K$36,5,0) -> 2000 | X54: =U54 -> 159 | Y54: =(W54-Z54*2)/X54 -> 12.5 | Z54: =(T54-U54*V54)/2 -> 6.25 | AA54: =L54-M54*12.5-5 -> 12.565
B55: =B20 -> ZU17-2 | C55: =VLOOKUP(B55,$B$4:$K$36,8,0) -> 860 | D55: =ROUNDDOWN((C55/E55-1),0) -> 67 | E55: =12.5 -> 12.5 | F55: =C55-D55*E55-2*J55 -> 6.5 | G55: =VLOOKUP(B55,$B$4:$J$72,6,0) -> 30 | H55: 2 | I55: =(G55-J55*2)/H55 -> 7 | J55: 8 | K55: =VLOOKUP(B55,$B$4:$K$36,2,0) -> 179.99 | L55: =VLOOKUP(B55,$B$4:$K$36,3,0) -> 229.99 | M55: =ROUND((L55-5)/12.5,0)-1 -> 17 | N55: =(L55-5-P55)/M55 -> 12.764118 | O55: =(K55-P55-5)/M55 -> 9.8229412 | P55: 8 | Q55: =VLOOKUP($B55,$B$4:$K$36,7,0) -> 40 | R55: 3 | S55: =(Q55-2*J55)/R55 -> 8 | T55: =VLOOKUP($B55,$B$4:$K$36,4,0) -> 2000 | U55: =ROUNDDOWN(T55/V55,0)-1 -> 159 | V55: 12.5 | W55: =VLOOKUP($B55,$B$4:$K$36,5,0) -> 2000 | X55: =U55 -> 159 | Y55: =(W55-Z55*2)/X55 -> 12.5 | Z55: =(T55-U55*V55)/2 -> 6.25 | AA55: =L55-M55*12.5-5 -> 12.49
B56: =B21 -> ZU18-2 | C56: =VLOOKUP(B56,$B$4:$K$36,8,0) -> 860 | D56: =ROUNDDOWN((C56/E56-1),0) -> 67 | E56: =12.5 -> 12.5 | F56: =C56-D56*E56-2*J56 -> 6.5 | G56: =VLOOKUP(B56,$B$4:$J$72,6,0) -> 30 | H56: 2 | I56: =(G56-J56*2)/H56 -> 7 | J56: 8 | K56: =VLOOKUP(B56,$B$4:$K$36,2,0) -> 129.915 | L56: =VLOOKUP(B56,$B$4:$K$36,3,0) -> 179.915 | M56: =ROUND((L56-5)/12.5,0)-1 -> 13 | N56: =(L56-5-P56)/M56 -> 12.839615 | O56: =(K56-P56-5)/M56 -> 8.9934615 | P56: 8 | Q56: =VLOOKUP($B56,$B$4:$K$36,7,0) -> 40 | R56: 3 | S56: =(Q56-2*J56)/R56 -> 8 | T56: =VLOOKUP($B56,$B$4:$K$36,4,0) -> 2000 | U56: =ROUNDDOWN(T56/V56,0)-1 -> 159 | V56: 12.5 | W56: =VLOOKUP($B56,$B$4:$K$36,5,0) -> 2000 | X56: =U56 -> 159 | Y56: =(W56-Z56*2)/X56 -> 12.5 | Z56: =(T56-U56*V56)/2 -> 6.25 | AA56: =L56-M56*12.5-5 -> 12.415
...

Sheet U型槽主体数量
B2: 变更设计修改后 | G2: 施工图设计修改后 | L2: 施工图设计修改前
B3: U型槽工程量 | G3: U型槽工程量 | L3: U型槽工程量
B4: 节段 | C4: C35 | D4: HPB300 | E4: HRB400 | G4: 节段 | H4: C35 | I4: HPB300 | J4: HRB400 | L4: 节段 | M4: C35 | N4: HPB300 | O4: HRB400 | Q4: C35 | R4: HPB300 | S4: HRB400
B5: YU1 | C5: 197 | D5: 1334.4 | E5: 22752.8 | G5: YU1 | H5: 210.6 | I5: 1416.4 | J5: 24155.2 | L5: YU1 | M5: 210.6 | N5: 1416.4 | O5: 24155.2 | Q5: 78.31 | R5: 478.11 | S5: 5331.15
B6: YU2 | C6: 202.6 | D6: 1375.8 | E6: 25006 | G6: YU2 | H6: 215.1 | I6: 1457.8 | J6: 28460.4 | L6: YU2 | M6: 215.1 | N6: 1457.8 | O6: 28460.4 | Q6: 79.88 | R6: 478.11 | S6: 5366.66
B7: YU3 | C7: 267.1 | D7: 1794.7 | E7: 28314.3 | G7: YU3 | H7: 281.8 | I7: 1883.7 | J7: 32133 | L7: YU3 | M7: 281.8 | N7: 1883.7 | O7: 32133 | Q7: 80.4 | R7: 478.11 | S7: 5492.87
B8: YU4 | C8: 276.7 | D8: 1862.3 | E8: 34137.9 | G8: YU4 | H8: 290.1 | I8: 1937.7 | J8: 40223.8 | L8: YU4 | M8: 290.1 | N8: 1937.7 | O8: 40223.8 | Q8: 80.91 | R8: 478.11 | S8: 5504.31
B9: YU5 | C9: 349.2 | D9: 2324.4 | E9: 40460.1 | G9: YU5 | H9: 363.8 | I9: 2423.9 | J9: 42023.1 | L9: YU5 | M9: 363.8 | N9: 2423.9 | O9: 42023.1 | Q9: 81.43 | R9: 506.23 | S9: 5694.67
B10: YU6 | C10: 429.5 | D10: 2852.8 | E10: 42610.3 | G10: YU6 | H10: 445.6 | I10: 2956.6 | J10: 43856.4 | L10: YU6 | M10: 445.6 | N10: 2956.6 | O10: 43856.4 | Q10: 86.56 | R10: 562.48 | S10: 6053.22
B11: YU7 | C11: 312.5 | D11: 2086.1 | E11: 50271.7 | G11: YU7 | H11: 464.3 | I11: 3075 | J11: 59271 | L11: YU7 | M11: 464.3 | N11: 3075 | O11: 59271 | Q11: 96.29 | R11: 618.73 | S11: 6400.61
B12: YU8 | C12: 541 | D12: 3552.6 | E12: 64884.1 | G12: YU8 | H12: 556.4 | I12: 3657.5 | J12: 65987.3 | L12: YU8 | M12: 556.4 | N12: 3657.5 | O12: 65218.5 | Q12: 102.9 | R12: 646.85 | S12: 6728.08
B13: YU9 | C13: 564 | D13: 3706.7 | E13: 81022.5 | G13: YU9 | H13: 573.2 | I13: 3772.2 | J13: 81763.7 | L13: YU9 | M13: 573.2 | N13: 3772.2 | O13: 80933.4 | Q13: 108.16 | R13: 674.98 | S13: 6910.95
B14: YU10 | C14: 578.5 | D14: 3746 | E14: 84368.1 | G14: YU10 | H14: 581.6 | I14: 3772.2 | J14: 84613.7 | L14: YU10 | M14: 581.6 | N14: 3772.2 | O14: 83752.7 | Q14: 108.1 | R14: 674.98 | S14: 6910.56
B15: YU11 | C15: 646.7 | D15: 4211.9 | E15: 83383.8 | G15: YU11 | H15: 662.4 | I15: 4314.8 | J15: 84536.6 | L15: YU11 | M15: 662.4 | N15: 4314.8 | O15: 83662.6 | Q15: 117.55 | R15: 787.47 | S15: 7493.66
B16: YU12 | C16: 472.7 | D16: 3110.1 | E16: 68820.4 | G16: YU12 | H16: 564.8 | I16: 3703.6 | J16: 67413.8 | L16: YU12 | M16: 564.8 | N16: 3703.6 | O16: 66614.4 | Q16: 102.03 | R16: 674.98 | S16: 6773.06
... B23: YU19 | C23: 164.7 | D23: 1109.8 | E23: 21851.2 | G23: YU19 | H23: 166.5 | I23: 1120.3 | J23: 22077.8 | L23: YU19 | M23: 166.5 | N23: 1120.3 | O23: 22077.8 | Q23: 60.73 | R23: 370.53 | S23: 4137.69
B24: ZU1-1 | C24: 128.2 | D24: 865.6 | E24: 12485.4 | G24: ZU1-1 | H24: 132.6 | I24: 886.4 | J24: 12881.8 | L24: ZU1-1 | M24: 132.6 | N24: 886.4 | O24: 12881.8
B25: ZU2-1 | C25: 133.8 | D25: 907 | E25: 14229.1 | G25: ZU2-1 | H25: 137.1 | I25: 927.9 | J25: 15953.9 | L25: ZU2-1 | M25: 137.1 | N25: 927.9 | O25: 15953.9 | Q25: =SUM(Q5:Q23) -> 1701.4 | R25: =SUM(R5:R23) -> 10635.81 | S25: =SUM(S5:S23) -> 114246.18
B26: ZU3-1 | C26: 181.1 | D26: 1216.9 | E26: 16919.8 | G26: ZU3-1 | H26: 184.3 | I26: 1230.5 | J26: 18820.3 | L26: ZU3-1 | M26: 184.3 | N26: 1230.5 | O26: 18820.3
B27: ZU4-1 | C27: 181 | D27: 1203.6 | E27: 20241.1 | G27: ZU4-1 | H27: 192.6 | I27: 1284.5 | J27: 24783.2 | L27: ZU4-1 | M27: 192.6 | N27: 1284.5 | O27: 24783.2
B28: ZU5-1 | C28: 228.9 | D28: 1514.4 | E28: 24575.1 | G28: ZU5-1 | H28: 246.8 | I28: 1647.5 | J28: 26542.2 | L28: ZU5-1 | M28: 246.8 | N28: 1647.5 | O28: 26542.2
B29: ZU6-1 | C29: 282.6 | D29: 2056.9 | E29: 29603 | G29: ZU6-1 | H29: 309.1 | I29: 2056.9 | J29: 30497.9 | L29: ZU6-1 | M29: 309.1 | N29: 2056.9 | O29: 30497.9
B30: ZU7-1 | C30: 295.2 | D30: 1938 | E30: 34082.5 | G30: ZU7-1 | H30: 327.8 | I30: 2175.4 | J30: 47348.8 | L30: ZU7-1 | M30: 327.8 | N30: 2175.4 | O30: 47348.8
B31: ZU8-1 | C31: 355.4 | D31: 2634.6 | E31: 49599.2 | G31: ZU8-1 | H31: 400.4 | I31: 2634.6 | J31: 51781.1 | L31: ZU8-1 | M31: 400.4 | N31: 2634.6 | O31: 51012.3
B32: ZU9-1 | C32: 365.9 | D32: 2394.1 | E32: 46231.6 | G32: ZU9-1 | H32: 417.2 | I32: 2749.3 | J32: 66202 | L32: ZU9-1 | M32: 417.2 | N32: 2749.3 | O32: 65371.7
B33: ZU10-1 | C33: 370.1 | D33: 2394.1 | E33: 47656.8 | G33: ZU10-1 | H33: 425.6 | I33: 2749.3 | J33: 69053.3 | L33: ZU10-1 | M33: 425.6 | N33: 2749.3 | O33: 68192.4
B34: ZU11-1 | C34: 427.3 | D34: 2777.8 | E34: 48201.5 | G34: ZU11-1 | H34: 486.9 | I34: 3168.7 | J34: 68863 | L34: ZU11-1 | M34: 486.9 | N34: 3168.7 | O34: 67988.8
B35: ZU12-1 | C35: 359.2 | D35: 2680.7 | E35: 28737.1 | G35: ZU12-1 | H35: 408.8 | I35: 2680.7 | J35: 53207.9 | L35: ZU12-1 | M35: 408.8 | N35: 2680.7 | O35: 52408.6
B36: ZU13-1 | C36: 298.4 | D36: 1948.2 | E36: 30902.1 | G36: ZU13-1 | H36: 336.4 | I36: 2215.2 | J36: 42542.7 | L36: ZU13-1 | M36: 336.4 | N36: 2215.2 | O36: 42542.7
B37: ZU14-1 | C37: 308.8 | D37: 2037 | E37: 30379.7 | G37: ZU14-1 | H37: 322.2 | I37: 2116.1 | J37: 35982.3 | L37: ZU14-1 | M37: 322.2 | N37: 2116.1 | O37: 35982.3
... B42: ZU19-1 | C42: 184.8 | D42: 1230.5 | E42: 18862.3 | G42: ZU19-1 | H42: 109.9 | I42: 739 | J42: 12762.9 | L42: ZU19-1 | M42: 109.9 | N42: 739 | O42: 12762.9
C43: 78.1 | D43: 507.1 | E43: 7869.9 | G43: ZU1-2 | H43: 78.1 | I43: 507.1 | J43: 7881.5 | L43: ZU1-2 | M43: 78.1 | N43: 507.1 | O43: 7881.5
C44: 88.1 | D44: 590 | E44: 9005.3 | G44: ZU2-2 | H44: 82.1 | I44: 548.5 | J44: 8394.1 | L44: ZU2-2 | M44: 82.1 | N44: 548.5 | O44: 8394.1
C45: 82.1 | D45: 548.5 | E45: 8382.5 | G45: ZU3-2 | H45: 88.1 | I45: 590 | J45: 9016.9 | L45: ZU3-2 | M45: 88.1 | N45: 590 | O45: 9016.9
C46: 86.9 | D46: 579.7 | E46: 8898.9 | G46: ZU4-2 | H46: 94.2 | I46: 641.9 | J46: 9747.6 | L46: ZU4-2 | M46: 94.2 | N46: 641.9 | O46: 9747.6
C47: 89.9 | D47: 600.4 | E47: 10928 | G47: ZU5-2 | H47: 100.2 | I47: 683.3 | J47: 12310.5 | L47: ZU5-2 | M47: 100.2 | N47: 683.3 | O47: 12310.5
C48: 124.1 | D48: 821 | E48: 14577.4 | G48: ZU6-2 | H48: 137.8 | I48: 929.1 | J48: 13536.1 | L48: ZU6-2 | M48: 137.8 | N48: 929.1 | O48: 13536.1
C49: 120.1 | D49: 794 | E49: 11778.1 | G49: ZU7-2 | H49: 145.8 | I49: 983.1 | J49: 17146.1 | L49: ZU7-2 | M49: 145.8 | N49: 983.1 | O49: 17146.1
C50: 158.2 | D50: 1039.8 | E50: 17863.9 | G50: ZU8-2 | H50: 190.3 | I50: 1272.8 | J50: 21341 | L50: ZU8-2 | M50: 190.3 | N50: 1272.8 | O50: 21341
C51: 163.7 | D51: 1081.2 | E51: 21286.5 | G51: ZU9-2 | H51: 200.3 | I51: 1339.4 | J51: 25848.1 | L51: ZU9-2 | M51: 200.3 | N51: 1339.4 | O51: 25848.1
...

Sheet Sheet2
C3: 施工图设计修改前 | D3: 施工图设计修改后 | E3: 变更设计修改后
A4: U型槽主体 | B4: C35 | C4: 15711.8 | D4: 15711.8 | E4: 14571.6
B5: HPB300 | C5: 103887.5 | D5: 103887.5 | E5: 97030.6
B6: HRB400 | C6: 1882901.3 | D6: 1891168.3 | E6: 1698285.1
A7: 机非分隔带 | B7: C35 | C7: 1701.5 | D7: 1307.0075 | E7: 1277.0076
B8: HPB300 | C8: 10635.81 | D8: 9290.1827 | E8: 9085.4147
B9: HRB400 | C9: 114246.18 | D9: 164685.88 | E9: 162000.52
A10: 排水沟 | B10: C40防水混凝土 | C10: 411.88992 | D10: =K21 -> 281.72637 | E10: =D10 -> 281.72637
B11: HPB300钢筋 | C11: 1504.9824 | D11: =K22 -> 375.75054 | E11: =D11 -> 375.75054
B12: HRB400钢筋 | C12: 161052.92 | D12: =K23 -> 118807.36 | E12: =D12 -> 118807.36
B13: 聚氨酯防水涂料 | C13: 2673.324 | D13: =K24 -> 2763.1408 | E13: =D13 -> 2763.1408
A14: 防撞墩 | B14: C35防水混凝土 | C14: 0 | D14: 492.4894 | E14: 492.4894
B15: HPB300钢筋 | C15: 0 | D15: 2598.804 | E15: 2598.804
B16: HRB400钢筋 | C16: 0 | D16: 83274.022 | E16: 83274.022
B17: 钢管 | C17: 0 | D17: 16025.958 | E17: 16025.958
A19: 计算过程
C20: 非机水沟 | D20: 机动车道水沟 | E20: 盖板一 | F20: 盖板二 | G20: 泵站排水沟 | I20: 非机动车长度 | J20: 机动车长度 | K20: 合计
A21: 排水沟 | B21: C35防水混凝土 | C21: 0.09 | D21: 0.13 | E21: =0.049*2 -> 0.098 | F21: 0.029 | G21: =6.1*2 -> 12.2 | H21: =7.7*2 -> 15.4 | I21: =495.06*2-40 -> 950.12 | J21: =495.06*2-40 -> 950.12 | K21: =C21*I21+D21*J21+E21*495.06/10*9+F21*495.06/10+G21+H21 -> 281.72637
B22: HPB300钢筋 | C22: 0 | D22: 0 | E22: =0.38*2 -> 0.76 | F22: 0.75 | G22: 0 | H22: 0 | I22: =495.06*2-40 -> 950.12 | J22: =495.06*2 -> 990.12 | K22: =C22*I22+D22*J22+E22*495.06/10*9+F22*495.06/10+G22+H22 -> 375.75054
B23: HRB400钢筋 | C23: 40.49 | D23: 53.77 | E23: =(10.16+6.94)*2 -> 34.2 | F23: =2.85+9.89 -> 12.74 | G23: =2621.3*2 -> 5242.6 | H23: =2993.5*2 -> 5987 | I23: =495.06*2-40 -> 950.12 | J23: =495.06*2 -> 990.12 | K23: =C23*I23+D23*J23+E23*495.06/10*9+F23*495.06/10+G23+H23 -> 118807.36
B24: 聚氨酯防水涂料 | C24: =(35*2+12+40)/100 -> 1.22 | D24: =(55*2+12+40)/100 -> 1.62 | E24: 0 | F24: 0 | G24: 0 | H24: 0 | I24: =495.06*2-40 -> 950.12 | J24: =495.06*2 -> 990.12 | K24: =C24*I24+D24*J24+E24*495.06/10*9+F24*495.06/10+G24+H24 -> 2763.1408
A26: 防撞墩 | B26: =495.06*3+119.02 -> 1604.2 | C26: 0.307 | D26: =C26*1604.2 -> 492.4894
C27: 1.62 | D27: =C27*1604.2 -> 2598.804
C28: 51.91 | D28: =C28*1604.2 -> 83274.022
C29: 9.99 | D29: =C29*1604.2 -> 16025.958
