Workbook
Name _P1: [1]钢轨桩计算!$C$10
Name _P1: [2]钢轨桩计算!$C$10
Name D0: [2]钢轨桩计算!$H$25
Name D0: [1]钢轨桩计算!$H$25
Name D0: [2]钢轨桩计算!$H$25
Name D0: [3]钢轨桩计算!$H$25
Name gj: #REF!
Name gj: #REF!
Name gjzj: #REF!
Name gjzj: #REF!
Name gjzj: #REF!
Name H: [2]钢轨桩计算!$C$2
Name H: [1]钢轨桩计算!$C$2
Name H: [2]钢轨桩计算!$C$2
Name H: [3]钢轨桩计算!$C$2
Name jd: SIN(RADIANS([3]框架结构!$B$2))
Name name: [4]工字钢数据!$A$2:$A$3
Name subject: [4]工字钢数据!$B$1:$C$1
Name x: [5]后背钢轨桩计算!$J$16
Name y: [2]钢轨桩计算!$D$17
Name y: [1]钢轨桩计算!$D$17
Name y: [2]钢轨桩计算!$D$17
Name y: [3]钢轨桩计算!$D$17
Name γ: [1]钢轨桩计算!$C$5
Name γ: [2]钢轨桩计算!$C$5
Name θ: [1]钢轨桩计算!$C$8
Name θ: [2]钢轨桩计算!$C$8
Name λ: [1]钢轨桩计算!$C$9
Name λ: [2]钢轨桩计算!$C$9
Name σh: [2]钢轨桩计算!$C$11
Name σh: [1]钢轨桩计算!$C$11
Name σh: [2]钢轨桩计算!$C$11
Name σh: [3]钢轨桩计算!$C$11
Name φ: [1]钢轨桩计算!$C$6
Name φ: [2]钢轨桩计算!$C$6
Name 边墙厚度: [3]框架结构!$C$10
Name 打入工作坑以下H: [2]钢轨桩计算!$C$3
Name 打入工作坑以下H: [1]钢轨桩计算!$C$3
Name 打入工作坑以下H: [2]钢轨桩计算!$C$3
Name 打入工作坑以下H: [3]钢轨桩计算!$C$3
Name 底板厚度: [3]框架结构!$C$9
Name 第1页________共1页: #REF!
Name 第1页________共1页: #REF!
Name 顶板厚度: [3]框架结构!$C$8
Name 钢筋直径: #REF!
Name 钢筋直径: #REF!
Name 钢筋直径: #REF!
Name 钢筋直径: #REF!
Name 钢筋直径: #REF!
Name 工字钢长度H: [1]钢轨桩计算!$C$2
Name 工字钢长度H: [2]钢轨桩计算!$C$2
Name 工作坑底面以上主动土动力P1: [1]钢轨桩计算!$C$10
Name 工作坑底面以上主动土动力P1: [2]钢轨桩计算!$C$10
Name 结构净高: [3]框架结构!$C$7
Name 结构总高: [3]框架结构!$C$4
Name 结构总宽: [3]框架结构!$C$3
Name 孔数: [2]框架结构!$F$1
Name 孔数: [1]框架结构!$F$1
Name 孔数: [2]框架结构!$F$1
Name 孔数: [3]框架结构!$F$1

Sheet 0.结构参数
B2: 一、从CAD中读取平面、纵断面原始数据 单位：m
A3: 序号 | B3: U型槽编号 | C3: 里程L | E3: L | G3: 顶高程E1 | I3: 底板顶高程E2 | K3: 中央分隔带 | P3: 机非分隔带 | U3: 水位高程E5 | V3: 净宽
K4: 高程E3 | M4: 宽度b1 | O4: 数量 | P4: 高程E4 | R4: 宽度b2 | T4: 数量
A5: 1 | B5: 西U10 | C5: 111.6591 | D5: 131.6591 | E5: =ABS(D5-C5) -> 20 | F5: =E5 -> 20 | G5: 3.59828 | H5: 3.348 | I5: 2.29828 | J5: 1.73674 | K5: 3.39828 | L5: 2.95311 | M5: 1.75 | N5: 1.75 | O5: 1 | P5: 3.39828 | Q5: 2.94818 | R5: 0.45 | S5: 0.45 | T5: 0 | U5: 3.1 | V5: 23.67 | W5: 22.75 | X5: =(K5+L5)/2*M5*O5 -> 5.5574663 | Y5: =(P5+Q5)/2*R5*T5 -> 0
A6: 2 | B6: 西U9 | C6: 131.6891 | D6: 151.6891 | E6: =ABS(D6-C6) -> 20 | F6: =E6 -> 20 | G6: 3.348 | H6: 3.348 | I6: 1.7359 | J6: 1.17435 | K6: 2.95236 | L6: 2.45236 | M6: 1.75 | N6: 1.75 | O6: 1 | P6: 2.94734 | Q6: 2.27469 | R6: 0.45 | S6: 0.45 | T6: 0 | U6: 3.1 | V6: 22.75 | W6: 22.25 | X6: =(K6+L6)/2*M6*O6 -> 4.72913 | Y6: =(P6+Q6)/2*R6*T6 -> 0
A7: 3 | B7: 西U8 | C7: 151.7191 | D7: 171.7191 | E7: =ABS(D7-C7) -> 20 | F7: =E7 -> 20 | G7: 3.348 | H7: 3.348 | I7: 1.17351 | J7: 0.38353 | K7: 2.45161 | L7: 1.95161 | M7: 1.75 | N7: 1.75 | O7: 1 | P7: 2.27351 | Q7: 1.48359 | R7: 0.45 | S7: 0.45 | T7: 0 | U7: 3.1 | V7: 22.25 | W7: 22.25 | X7: =(K7+L7)/2*M7*O7 -> 3.8528175 | Y7: =(P7+Q7)/2*R7*T7 -> 0
A8: 4 | B8: 西U7 | C8: 171.7491 | D8: 191.7491 | E8: =ABS(D8-C8) -> 20 | F8: =E8 -> 20 | G8: 3.348 | H8: 3.348 | I8: 0.38234 | J8: -0.40764 | K8: 1.95086 | L8: 1.45086 | M8: 1.75 | N8: 1.75 | O8: 1 | P8: 1.4824 | Q8: 0.6924 | R8: 0.45 | S8: 0.45 | T8: 0 | U8: 3.1 | V8: 22.25 | W8: 22.25 | X8: =(K8+L8)/2*M8*O8 -> 2.976505 | Y8: =(P8+Q8)/2*R8*T8 -> 0
A9: 5 | B9: 西U6 | C9: 191.7791 | D9: 211.7791 | E9: =ABS(D9-C9) -> 20 | F9: =E9 -> 20 | G9: 3.348 | H9: 3.348 | I9: -0.40882 | J9: -1.19881 | K9: 1.45011 | L9: 0.95011 | M9: 1.75 | N9: 1.75 | O9: 1 | P9: 0.69122 | Q9: -0.09878 | R9: 0.45 | S9: 0.45 | T9: 0 | U9: 3.1 | V9: 22.25 | W9: 22.25 | X9: =(K9+L9)/2*M9*O9 -> 2.1001925 | Y9: =(P9+Q9)/2*R9*T9 -> 0
A10: 6 | B10: 西U5 | C10: 211.8091 | D10: 231.8091 | E10: =ABS(D10-C10) -> 20 | F10: =E10 -> 20 | G10: 3.348 | H10: 3.348 | I10: -1.19999 | J10: -1.98997 | K10: 0.94936 | L10: 0.44936 | M10: 1.75 | N10: 1.75 | O10: 1 | P10: -0.09997 | Q10: -0.88997 | R10: 0.45 | S10: 0.45 | T10: 0 | U10: 3.1 | V10: 22.25 | W10: 22.25 | X10: =(K10+L10)/2*M10*O10 -> 1.22388 | Y10: =(P10+Q10)/2*R10*T10 -> 0
A11: 7 | B11: 西U4 | C11: 231.8391 | D11: 251.8391 | E11: =ABS(D11-C11) -> 20 | F11: =E11 -> 20 | G11: 3.348 | H11: 3.348 | I11: -1.99116 | J11: -2.78114 | K11: 0.44861 | L11: -0.05139 | M11: 1.75 | N11: 1.75 | O11: 1 | P11: -0.89115 | Q11: -1.61791 | R11: 0.45 | S11: 0.45 | T11: 0 | U11: 3.1 | V11: 22.25 | W11: 22.25 | X11: =(K11+L11)/2*M11*O11 -> 0.3475675 | Y11: =(P11+Q11)/2*R11*T11 -> 0
A12: 8 | B12: 西U3 | C12: 251.8691 | D12: 271.8691 | E12: =ABS(D12-C12) -> 20 | F12: =E12 -> 20 | G12: 3.348 | H12: 3.348 | I12: -2.78233 | J12: -3.34525 | K12: -0.05214 | L12: -0.55214 | M12: 1.75 | N12: 1.75 | O12: 1 | P12: -1.61884 | Q12: -2.12974 | R12: 0.45 | S12: 0.45 | T12: 0 | U12: 3.1 | V12: 22.25 | W12: 22.25 | X12: =(K12+L12)/2*M12*O12 -> -0.528745 | Y12: =(P12+Q12)/2*R12*T12 -> 0
A13: 9 | B13: 西U2 | C13: 271.8991 | D13: 291.8991 | E13: =ABS(D13-C13) -> 20 | F13: =E13 -> 20 | G13: 3.348 | H13: 3.348 | I13: -3.3461 | J13: -3.90902 | K13: -0.55289 | L13: -0.95704 | M13: 1.75 | N13: 1.75 | O13: 1 | P13: -2.13034 | Q13: -2.41868 | R13: 0.45 | S13: 0.45 | T13: 0 | U13: 3.1 | V13: 22.25 | W13: 22.25 | X13: =(K13+L13)/2*M13*O13 -> -1.3211887 | Y13: =(P13+Q13)/2*R13*T13 -> 0
A14: 10 | B14: 西U1 | C14: 291.9291 | D14: 316.9291 | E14: =ABS(D14-C14) -> 25 | F14: =E14 -> 25 | G14: 3.348 | H14: 3.348 | I14: -3.90902 | J14: -3.90902 | K14: -0.95748 | L14: -1.15046 | M14: 1.75 | N14: 1.75 | O14: 1 | P14: -2.41895 | Q14: -2.47022 | R14: 0.45 | S14: 0.45 | T14: 0 | U14: 3.1 | V14: 22.25 | W14: 22.25 | X14: =(K14+L14)/2*M14*O14 -> -1.8444475 | Y14: =(P14+Q14)/2*R14*T14 -> 0
A15: 11 | B15: 东U1 | C15: 400.9491 | D15: 408.9491 | E15: =ABS(D15-C15) -> 8 | F15: =E15 -> 8 | G15: 3.348 | H15: 3.348 | I15: -4.33477 | J15: -3.72017 | K15: -0.91122 | L15: -0.88722 | M15: 1.75 | N15: 1.75 | O15: 1 | P15: -2.21816 | Q15: -2.19416 | R15: 0.45 | S15: 0.45 | T15: 0 | U15: 3.1 | V15: 22.25 | W15: 22.25 | X15: =(K15+L15)/2*M15*O15 -> -1.573635 | Y15: =(P15+Q15)/2*R15*T15 -> 0
A16: 12 | B16: 东U2 | C16: 434.0091 | D16: 454.0091 | E16: =ABS(D16-C16) -> 20 | F16: =E16 -> 20 | G16: 3.348 | H16: 3.914 | I16: -3.71932 | J16: -3.15332 | K16: -0.68872 | L16: -0.30662 | M16: 1.75 | N16: 1.75 | O16: 1 | P16: -2.10592 | Q16: -1.85859 | R16: 0.45 | S16: 0.45 | T16: 0 | U16: 3.1 | V16: 22.25 | W16: 22.25 | X16: =(K16+L16)/2*M16*O16 -> -0.8709225 | Y16: =(P16+Q16)/2*R16*T16 -> 0
... A31: 27 | B31: 西U2-1 | C31: 271.8991 | D31: 291.8991 | E31: =ABS(D31-C31) -> 20 | F31: =E31 -> 20 | G31: 3.348 | H31: 3.348 | I31: -3.3461 | J31: -3.90902 | K31: -0.55289 | L31: -0.95704 | M31: 1.75 | N31: 1.75 | O31: 1 | P31: -2.13034 | Q31: -2.41868 | R31: 0.45 | S31: 0.45 | T31: 0 | U31: 3.1 | V31: 28.29 | W31: 22.25 | X31: =(K31+L31)/2*M31*O31 -> -1.3211887 | Y31: =(P31+Q31)/2*R31*T31 -> 0
A32: 28 | B32: 西U6-2 | C32: 191.7791 | D32: 211.7791 | E32: 20 | F32: 20 | G32: 3.348 | H32: 3.348 | I32: -0.40882 | J32: -1.19881 | K32: 1.45011 | L32: 0.95011 | M32: 1.75 | N32: 1.75 | O32: 0 | P32: 0.69122 | Q32: -0.09878 | R32: 0.45 | S32: 0.45 | T32: 0 | U32: 3.1 | V32: 8 | W32: 9.09 | X32: =(K32+L32)/2*M32*O32 -> 0 | Y32: =(P32+Q32)/2*R32*T32 -> 0
A33: 29 | B33: 西U5-2 | C33: 211.8091 | D33: 231.8091 | E33: 20 | F33: 20 | G33: 3.348 | H33: 3.348 | I33: -1.19999 | J33: -1.98997 | K33: 0.94936 | L33: 0.44936 | M33: 1.75 | N33: 1.75 | O33: 0 | P33: -0.09997 | Q33: -0.88997 | R33: 0.45 | S33: 0.45 | T33: 0 | U33: 3.1 | V33: 9.09 | W33: 8 | X33: =(K33+L33)/2*M33*O33 -> 0 | Y33: =(P33+Q33)/2*R33*T33 -> 0
A34: 30 | B34: 西U4-2 | C34: 231.8391 | D34: 251.8391 | E34: 20 | F34: 20 | G34: 3.348 | H34: 3.348 | I34: -1.99116 | J34: -2.78114 | K34: 0.44861 | L34: -0.05139 | M34: 1.75 | N34: 1.75 | O34: 0 | P34: -0.89115 | Q34: -1.61791 | R34: 0.45 | S34: 0.45 | T34: 0 | U34: 3.1 | V34: 8 | W34: 8 | X34: =(K34+L34)/2*M34*O34 -> 0 | Y34: =(P34+Q34)/2*R34*T34 -> 0
A35: 31 | B35: 西U3-2 | C35: 251.8691 | D35: 271.8691 | E35: 20 | F35: 20 | G35: 3.348 | H35: 3.348 | I35: -2.78233 | J35: -3.34525 | K35: -0.05214 | L35: -0.55214 | M35: 1.75 | N35: 1.75 | O35: 0 | P35: -1.61884 | Q35: -2.12974 | R35: 0.45 | S35: 0.45 | T35: 0 | U35: 3.1 | V35: 8 | W35: 14.06 | X35: =(K35+L35)/2*M35*O35 -> 0 | Y35: =(P35+Q35)/2*R35*T35 -> 0
A36: 32
X37: =SUM(X5:X36) -> 47.338707
B38: 二、命名并形成U型槽结构参数表 单位：m
A39: U型槽编号 | B39: 起讫点里程 | D39: 中心长度L | E39: 顶高程E1 | G39: 底板顶高程E2 | I39: 结构净高H | K39: 底板厚T | L39: 边墙厚B | M39: D | O39: 中央分隔带 | U39: 机非分隔带
O40: 高度h1 | Q40: 宽度b1 | S40: 数量 | T40: 高度h2 | V40: 宽度b2 | X40: 数量
A41: =B5 -> 西U10 | B41: =C5 -> 111.6591 | C41: =D5 -> 131.6591 | D41: =ABS(C41-B41) -> 20 | E41: =G5 -> 3.59828 | F41: =H5 -> 3.348 | G41: =I5 -> 2.29828 | H41: =J5 -> 1.73674 | I41: =E41-G41 -> 1.3 | J41: =F41-H41 -> 1.61126 | K41: =L41+0.1 -> 0.4 | L41: =LOOKUP(MAX(J41,I41),{0,3,4,5,6.5,7.5,9,10},{0.3,0.4,0.5,0.6,0.7,0.8,0.9}) -> 0.3 | M41: =V5+L41*2 -> 24.27 | N41: =W5+L41*2 -> 23.35 | O41: =K5-I5+0.2 -> 1.3 | P41: =L5-J5+0.2 -> 1.41637 | Q41: =M5 -> 1.75 | R41: =N5 -> 1.75 | S41: =O5 -> 1 | T41: =P5-I5+1 -> 2.1 | U41: =Q5-J5 -> 1.21144 | V41: =R5 -> 0.45 | W41: =S5 -> 0.45 | X41: =T5 -> 0 | Y41: =(O41+P41)/2*Q41*S41 -> 2.3768237 | Z41: =(T41+U41)/2*V41*X41 -> 0
A42: =B6 -> 西U9 | B42: =C6 -> 131.6891 | C42: =D6 -> 151.6891 | D42: =ABS(C42-B42) -> 20 | E42: =G6 -> 3.348 | F42: =H6 -> 3.348 | G42: =I6 -> 1.7359 | H42: =J6 -> 1.17435 | I42: =E42-G42 -> 1.6121 | J42: =F42-H42 -> 2.17365 | K42: =L42+0.1 -> 0.4 | L42: =LOOKUP(MAX(J42,I42),{0,3,4,5,6.5,7.5,9,10},{0.3,0.4,0.5,0.6,0.7,0.8,0.9}) -> 0.3 | M42: =V6+L42*2 -> 23.35 | N42: =W6+L42*2 -> 22.85 | O42: =K6-I6+0.2 -> 1.41646 | P42: =L6-J6+0.2 -> 1.47801 | Q42: =M6 -> 1.75 | R42: =N6 -> 1.75 | S42: =O6 -> 1 | T42: =P6-I6+1 -> 2.21144 | U42: =Q6-J6 -> 1.10034 | V42: =R6 -> 0.45 | W42: =S6 -> 0.45 | X42: =T6 -> 0 | Y42: =(O42+P42)/2*Q42*S42 -> 2.5326612 | Z42: =(T42+U42)/2*V42*X42 -> 0
A43: =B7 -> 西U8 | B43: =C7 -> 151.7191 | C43: =D7 -> 171.7191 | D43: =ABS(C43-B43) -> 20 | E43: =G7 -> 3.348 | F43: =H7 -> 3.348 | G43: =I7 -> 1.17351 | H43: =J7 -> 0.38353 | I43: =E43-G43 -> 2.17449 | J43: =F43-H43 -> 2.96447 | K43: =L43+0.1 -> 0.4 | L43: =LOOKUP(MAX(J43,I43),{0,3,4,5,6.5,7.5,9,10},{0.3,0.4,0.5,0.6,0.7,0.8,0.9}) -> 0.3 | M43: =V7+L43*2 -> 22.85 | N43: =W7+L43*2 -> 22.85 | O43: =K7-I7+0.2 -> 1.4781 | P43: =L7-J7+0.2 -> 1.76808 | Q43: =M7 -> 1.75 | R43: =N7 -> 1.75 | S43: =O7 -> 1 | T43: =P7-I7+1 -> 2.1 | U43: =Q7-J7 -> 1.10006 | V43: =R7 -> 0.45 | W43: =S7 -> 0.45 | X43: =T7 -> 0 | Y43: =(O43+P43)/2*Q43*S43 -> 2.8404075 | Z43: =(T43+U43)/2*V43*X43 -> 0
A44: =B8 -> 西U7 | B44: =C8 -> 171.7491 | C44: =D8 -> 191.7491 | D44: =ABS(C44-B44) -> 20 | E44: =G8 -> 3.348 | F44: =H8 -> 3.348 | G44: =I8 -> 0.38234 | H44: =J8 -> -0.40764 | I44: =E44-G44 -> 2.96566 | J44: =F44-H44 -> 3.75564 | K44: =L44+0.1 -> 0.5 | L44: =LOOKUP(MAX(J44,I44),{0,3,4,5,6.5,7.5,9,10},{0.3,0.4,0.5,0.6,0.7,0.8,0.9}) -> 0.4 | M44: =V8+L44*2 -> 23.05 | N44: =W8+L44*2 -> 23.05 | O44: =K8-I8+0.2 -> 1.76852 | P44: =L8-J8+0.2 -> 2.0585 | Q44: =M8 -> 1.75 | R44: =N8 -> 1.75 | S44: =O8 -> 1 | T44: =P8-I8+1 -> 2.10006 | U44: =Q8-J8 -> 1.10004 | V44: =R8 -> 0.45 | W44: =S8 -> 0.45 | X44: =T8 -> 0 | Y44: =(O44+P44)/2*Q44*S44 -> 3.3486425 | Z44: =(T44+U44)/2*V44*X44 -> 0
A45: =B9 -> 西U6 | B45: =C9 -> 191.7791 | C45: =D9 -> 211.7791 | D45: =ABS(C45-B45) -> 20 | E45: =G9 -> 3.348 | F45: =H9 -> 3.348 | G45: =I9 -> -0.40882 | H45: =J9 -> -1.19881 | I45: =E45-G45 -> 3.75682 | J45: =F45-H45 -> 4.54681 | K45: =L45+0.1 -> 0.6 | L45: =LOOKUP(MAX(J45,I45),{0,3,4,5,6.5,7.5,9,10},{0.3,0.4,0.5,0.6,0.7,0.8,0.9}) -> 0.5 | M45: =V9+L45*2 -> 23.25 | N45: =W9+L45*2 -> 23.25 | O45: =K9-I9+0.2 -> 2.05893 | P45: =L9-J9+0.2 -> 2.34892 | Q45: =M9 -> 1.75 | R45: =N9 -> 1.75 | S45: =O9 -> 1 | T45: =P9-I9+1 -> 2.10004 | U45: =Q9-J9 -> 1.10003 | V45: =R9 -> 0.45 | W45: =S9 -> 0.45 | X45: =T9 -> 0 | Y45: =(O45+P45)/2*Q45*S45 -> 3.8568687 | Z45: =(T45+U45)/2*V45*X45 -> 0
A46: =B10 -> 西U5 | B46: =C10 -> 211.8091 | C46: =D10 -> 231.8091 | D46: =ABS(C46-B46) -> 20 | E46: =G10 -> 3.348 | F46: =H10 -> 3.348 | G46: =I10 -> -1.19999 | H46: =J10 -> -1.98997 | I46: =E46-G46 -> 4.54799 | J46: =F46-H46 -> 5.33797 | K46: =L46+0.1 -> 0.7 | L46: =LOOKUP(MAX(J46,I46),{0,3,4,5,6.5,7.5,9,10},{0.3,0.4,0.5,0.6,0.7,0.8,0.9}) -> 0.6 | M46: =V10+L46*2 -> 23.45 | N46: =W10+L46*2 -> 23.45 | O46: =K10-I10+0.2 -> 2.34935 | P46: =L10-J10+0.2 -> 2.63933 | Q46: =M10 -> 1.75 | R46: =N10 -> 1.75 | S46: =O10 -> 1 | T46: =P10-I10+1 -> 2.10002 | U46: =Q10-J10 -> 1.1 | V46: =R10 -> 0.45 | W46: =S10 -> 0.45 | X46: =T10 -> 0 | Y46: =(O46+P46)/2*Q46*S46 -> 4.365095 | Z46: =(T46+U46)/2*V46*X46 -> 0
A47: =B11 -> 西U4 | B47: =C11 -> 231.8391 | C47: =D11 -> 251.8391 | D47: =ABS(C47-B47) -> 20 | E47: =G11 -> 3.348 | F47: =H11 -> 3.348 | G47: =I11 -> -1.99116 | H47: =J11 -> -2.78114 | I47: =E47-G47 -> 5.33916 | J47: =F47-H47 -> 6.12914 | K47: =L47+0.1 -> 0.7 | L47: =LOOKUP(MAX(J47,I47),{0,3,4,5,6.5,7.5,9,10},{0.3,0.4,0.5,0.6,0.7,0.8,0.9}) -> 0.6 | M47: =V11+L47*2 -> 23.45 | N47: =W11+L47*2 -> 23.45 | O47: =K11-I11+0.2 -> 2.63977 | P47: =L11-J11+0.2 -> 2.92975 | Q47: =M11 -> 1.75 | R47: =N11 -> 1.75 | S47: =O11 -> 1 | T47: =P11-I11+1 -> 2.10001 | U47: =Q11-J11 -> 1.16323 | V47: =R11 -> 0.45 | W47: =S11 -> 0.45 | X47: =T11 -> 0 | Y47: =(O47+P47)/2*Q47*S47 -> 4.87333 | Z47: =(T47+U47)/2*V47*X47 -> 0
A48: =B12 -> 西U3 | B48: =C12 -> 251.8691 | C48: =D12 -> 271.8691 | D48: =ABS(C48-B48) -> 20 | E48: =G12 -> 3.348 | F48: =H12 -> 3.348 | G48: =I12 -> -2.78233 | H48: =J12 -> -3.34525 | I48: =E48-G48 -> 6.13033 | J48: =F48-H48 -> 6.69325 | K48: =L48+0.1 -> 0.8 | L48: =LOOKUP(MAX(J48,I48),{0,3,4,5,6.5,7.5,9,10},{0.3,0.4,0.5,0.6,0.7,0.8,0.9}) -> 0.7 | M48: =V12+L48*2 -> 23.65 | N48: =W12+L48*2 -> 23.65 | O48: =K12-I12+0.2 -> 2.93019 | P48: =L12-J12+0.2 -> 2.99311 | Q48: =M12 -> 1.75 | R48: =N12 -> 1.75 | S48: =O12 -> 1 | T48: =P12-I12+1 -> 2.16349 | U48: =Q12-J12 -> 1.21551 | V48: =R12 -> 0.45 | W48: =S12 -> 0.45 | X48: =T12 -> 0 | Y48: =(O48+P48)/2*Q48*S48 -> 5.1828875 | Z48: =(T48+U48)/2*V48*X48 -> 0
A49: =B13 -> 西U2 | B49: =C13 -> 271.8991 | C49: =D13 -> 291.8991 | D49: =ABS(C49-B49) -> 20 | E49: =G13 -> 3.348 | F49: =H13 -> 3.348 | G49: =I13 -> -3.3461 | H49: =J13 -> -3.90902 | I49: =E49-G49 -> 6.6941 | J49: =F49-H49 -> 7.25702 | K49: =L49+0.1 -> 0.8 | L49: =LOOKUP(MAX(J49,I49),{0,3,4,5,6.5,7.5,9,10},{0.3,0.4,0.5,0.6,0.7,0.8,0.9}) -> 0.7 | M49: =V13+L49*2 -> 23.65 | N49: =W13+L49*2 -> 23.65 | O49: =K13-I13+0.2 -> 2.99321 | P49: =L13-J13+0.2 -> 3.15198 | Q49: =M13 -> 1.75 | R49: =N13 -> 1.75 | S49: =O13 -> 1 | T49: =P13-I13+1 -> 2.21576 | U49: =Q13-J13 -> 1.49034 | V49: =R13 -> 0.45 | W49: =S13 -> 0.45 | X49: =T13 -> 0 | Y49: =(O49+P49)/2*Q49*S49 -> 5.3770413 | Z49: =(T49+U49)/2*V49*X49 -> 0
A50: =B14 -> 西U1 | B50: =C14 -> 291.9291 | C50: =D14 -> 316.9291 | D50: =ABS(C50-B50) -> 25 | E50: =G14 -> 3.348 | F50: =H14 -> 3.348 | G50: =I14 -> -3.90902 | H50: =J14 -> -3.90902 | I50: =E50-G50 -> 7.25702 | J50: =F50-H50 -> 7.25702 | K50: =L50+0.1 -> 0.8 | L50: =LOOKUP(MAX(J50,I50),{0,3,4,5,6.5,7.5,9,10},{0.3,0.4,0.5,0.6,0.7,0.8,0.9}) -> 0.7 | M50: =V14+L50*2 -> 23.65 | N50: =W14+L50*2 -> 23.65 | O50: =K14-I14+0.2 -> 3.15154 | P50: =L14-J14+0.2 -> 2.95856 | Q50: =M14 -> 1.75 | R50: =N14 -> 1.75 | S50: =O14 -> 1 | T50: =P14-I14+1 -> 2.49007 | U50: =Q14-J14 -> 1.4388 | V50: =R14 -> 0.45 | W50: =S14 -> 0.45 | X50: =T14 -> 0 | Y50: =(O50+P50)/2*Q50*S50 -> 5.3463375 | Z50: =(T50+U50)/2*V50*X50 -> 0
A51: =B15 -> 东U1 | B51: =C15 -> 400.9491 | C51: =D15 -> 408.9491 | D51: =ABS(C51-B51) -> 8 | E51: =G15 -> 3.348 | F51: =H15 -> 3.348 | G51: =I15 -> -4.33477 | H51: =J15 -> -3.72017 | I51: =E51-G51 -> 7.68277 | J51: =F51-H51 -> 7.06817 | K51: =L51+0.1 -> 0.9 | L51: =LOOKUP(MAX(J51,I51),{0,3,4,5,6.5,7.5,9,10},{0.3,0.4,0.5,0.6,0.7,0.8,0.9}) -> 0.8 | M51: =V15+L51*2 -> 23.85 | N51: =W15+L51*2 -> 23.85 | O51: =K15-I15+0.2 -> 3.62355 | P51: =L15-J15+0.2 -> 3.03295 | Q51: =M15 -> 1.75 | R51: =N15 -> 1.75 | S51: =O15 -> 1 | T51: =P15-I15+1 -> 3.11661 | U51: =Q15-J15 -> 1.52601 | V51: =R15 -> 0.45 | W51: =S15 -> 0.45 | X51: =T15 -> 0 | Y51: =(O51+P51)/2*Q51*S51 -> 5.8244375 | Z51: =(T51+U51)/2*V51*X51 -> 0
A52: =B16 -> 东U2 | B52: =C16 -> 434.0091 | C52: =D16 -> 454.0091 | D52: =ABS(C52-B52) -> 20 | E52: =G16 -> 3.348 | F52: =H16 -> 3.914 | G52: =I16 -> -3.71932 | H52: =J16 -> -3.15332 | I52: =E52-G52 -> 7.06732 | J52: =F52-H52 -> 7.06732 | K52: =L52+0.1 -> 0.8 | L52: =LOOKUP(MAX(J52,I52),{0,3,4,5,6.5,7.5,9,10},{0.3,0.4,0.5,0.6,0.7,0.8,0.9}) -> 0.7 | M52: =V16+L52*2 -> 23.65 | N52: =W16+L52*2 -> 23.65 | O52: =K16-I16+0.2 -> 3.2306 | P52: =L16-J16+0.2 -> 3.0467 | Q52: =M16 -> 1.75 | R52: =N16 -> 1.75 | S52: =O16 -> 1 | T52: =P16-I16+1 -> 2.6134 | U52: =Q16-J16 -> 1.29473 | V52: =R16 -> 0.45 | W52: =S16 -> 0.45 | X52: =T16 -> 0 | Y52: =(O52+P52)/2*Q52*S52 -> 5.4926375 | Z52: =(T52+U52)/2*V52*X52 -> 0
A53: =B17 -> 东U3 | B53: =C17 -> 454.0391 | C53: =D17 -> 474.0391 | D53: =ABS(C53-B53) -> 20 | E53: =G17 -> 3.914 | F53: =H17 -> 3.914 | G53: =I17 -> -3.15247 | H53: =J17 -> -2.58647 | I53: =E53-G53 -> 7.06647 | J53: =F53-H53 -> 6.50047 | K53: =L53+0.1 -> 0.8 | L53: =LOOKUP(MAX(J53,I53),{0,3.5,4,5,6.5,7.5,9,10},{0.3,0.4,0.5,0.6,0.7,0.8,0.9}) -> 0.7 | M53: =V17+L53*2 -> 23.65 | N53: =W17+L53*2 -> 23.65 | O53: =K17-I17+0.2 -> 3.04657 | P53: =L17-J17+0.2 -> 2.9798 | Q53: =M17 -> 1.75 | R53: =N17 -> 1.75 | S53: =O17 -> 1 | T53: =P17-I17+1 -> 2.29442 | U53: =Q17-J17 -> 1.19829 | V53: =R17 -> 0.45 | W53: =S17 -> 0.45 | X53: =T17 -> 0 | Y53: =(O53+P53)/2*Q53*S53 -> 5.2730738 | Z53: =(T53+U53)/2*V53*X53 -> 0
A54: =B18 -> 东U4 | B54: =C18 -> 474.0691 | C54: =D18 -> 494.0691 | D54: =ABS(C54-B54) -> 20 | E54: =G18 -> 3.914 | F54: =H18 -> 3.914 | G54: =I18 -> -2.58528 | H54: =J18 -> -1.79528 | I54: =E54-G54 -> 6.49928 | J54: =F54-H54 -> 5.70928 | K54: =L54+0.1 -> 0.7 | L54: =LOOKUP(MAX(J54,I54),{0,3.5,4,5,6.5,7.5,9,10},{0.3,0.4,0.5,0.6,0.7,0.8,0.9}) -> 0.6 | M54: =V18+L54*2 -> 23.45 | N54: =W18+L54*2 -> 23.45 | O54: =K18-I18+0.2 -> 2.97936 | P54: =L18-J18+0.2 -> 2.68936 | Q54: =M18 -> 1.75 | R54: =N18 -> 1.75 | S54: =O18 -> 1 | T54: =P18-I18+1 -> 2.19797 | U54: =Q18-J18 -> 1.1 | V54: =R18 -> 0.45 | W54: =S18 -> 0.45 | X54: =T18 -> 0 | Y54: =(O54+P54)/2*Q54*S54 -> 4.96013 | Z54: =(T54+U54)/2*V54*X54 -> 0
A55: =B19 -> 东U5 | B55: =C19 -> 494.0991 | C55: =D19 -> 514.0991 | D55: =ABS(C55-B55) -> 20 | E55: =G19 -> 3.914 | F55: =H19 -> 3.914 | G55: =I19 -> -1.7941 | H55: =J19 -> -1.0041 | I55: =E55-G55 -> 5.7081 | J55: =F55-H55 -> 4.9181 | K55: =L55+0.1 -> 0.7 | L55: =LOOKUP(MAX(J55,I55),{0,3.5,4,5,6.5,7.5,9,10},{0.3,0.4,0.5,0.6,0.7,0.8,0.9}) -> 0.6 | M55: =V19+L55*2 -> 23.45 | N55: =W19+L55*2 -> 23.45 | O55: =K19-I19+0.2 -> 2.68893 | P55: =L19-J19+0.2 -> 2.39893 | Q55: =M19 -> 1.75 | R55: =N19 -> 1.75 | S55: =O19 -> 1 | T55: =P19-I19+1 -> 2.1 | U55: =Q19-J19 -> 1.1 | V55: =R19 -> 0.45 | W55: =S19 -> 0.45 | X55: =T19 -> 0 | Y55: =(O55+P55)/2*Q55*S55 -> 4.4518775 | Z55: =(T55+U55)/2*V55*X55 -> 0
...

Sheet 0.地勘及桩计算
B2: 四、输入钻孔资料
C4: 土层编号 | D4: ρ | E4: c | F4: φ | G4: 桩周土摩阻力 | H4: 基本承载力 | I4: 渗透系数 | J4: FLBZ-3 | L4: FLBZ-5 | M4: zk4 | N4: zk5 | O4: zk6 | P4: zk7
J5: 4.17 | L5: 4.6 | M5: 4.5 | N5: 4.8 | O5: 4 | P5: 3.82 | Q5: 孔口高程
D6: g/cm3 | E6: kPa | F6: 度 | G6: kPa | H6: kPa | I6: cm/s | K6: 土层厚 | L6: 2.8 | M6: 2.5 | N6: 3.1 | O6: 2.1 | P6: 1.6 | Q6: 水位高程
B7: 杂填土 | C7: 1 | D7: 18.4 | E7: 24.4 | F7: 4.6 | G7: 1 | J7: 1.97 | K7: =J5-J7 -> 2.2 | L7: 0 | M7: 0 | N7: 1 | O7: 0 | P7: 0
B8: 黏土 | C8: 2 | D8: 16.9 | E8: 21.2 | F8: 5.7 | G8: 38 | J8: 0.07 | K8: =J7-J8 -> 1.9 | L8: 1.6 | M8: 3 | N8: 3.1 | O8: 3.1 | P8: 3.2
B9: 淤泥 | C9: 3 | D9: 17 | E9: 8.6 | F9: 2 | G9: 12 | J9: -7.23 | K9: =J8-J9 -> 7.3 | L9: 1.4 | M9: 2 | N9: 1.9 | O9: 2 | P9: 1.8
B10: 粉土 | C10: 4 | D10: 16.8 | E10: 10 | F10: 1.9 | G10: 37 | J10: -8.13 | K10: =J9-J10 -> 0.9 | L10: 2.5 | M10: 2 | N10: 2 | O10: 0 | P10: 3
B11: 粉细砂 | C11: 5-1 | D11: 18.2 | E11: 20.5 | F11: 4.8 | G11: 1 | J11: -8.13 | K11: =J10-J11 -> 0 | L11: 1.2 | M11: 0 | N11: 0 | O11: 0 | P11: 1
B12: 中粗砂 | C12: 5-2 | D12: 18.2 | E12: 20.5 | F12: 4.8 | G12: 122 | J12: -11.33 | K12: =J11-J12 -> 3.2 | L12: 5.4 | M12: 4.7 | N12: 4.3 | O12: 5.9 | P12: 3
B13: 含砂姜黏土 | C13: 6 | D13: 19.2 | E13: 42.4 | F13: 12.6 | G13: 117 | J13: -13.33 | K13: =J12-J13 -> 2 | L13: 3.9 | M13: 3.3 | N13: 4.9 | O13: 6 | P13: 5
B14: 黏土 | C14: 7 | D14: 19.2 | E14: 48.0 | F14: 15.0 | G14: 141 | J14: -13.83 | K14: =J13-J14 -> 0.5 | L14: 3 | M14: 0 | N14: 1.9 | O14: 1.5 | P14: 2
B15: 含砂姜黏土 | C15: 8 | D15: 19.5 | E15: 52.5 | F15: 15.4 | G15: 122 | J15: -15.91 | K15: =J14-J15 -> 2.08 | L15: 14.5 | M15: 0 | N15: 14.9 | O15: 14.7 | P15: 15.9
B16: 含砂姜黏土 | C16: 9 | D16: 19.8 | E16: 66.0 | F16: 18.1 | G16: 367 | L16: 8.3 | M16: 0 | N16: 8.1 | O16: 8.7 | P16: 7.1
B17: 含碎石黏土 | C17: 10 | D17: 20.1 | E17: 70.5 | F17: 21.0 | L17: 0 | M17: 0 | N17: 0 | O17: 0 | P17: 0
B18: 全风化片麻岩 | C18: 11 | L18: 4.8 | M18: 0 | N18: 6.1 | O18: 3.1 | P18: 3.9
B19: 强风化片麻岩 | C19: 12 | L19: 2.4 | M19: 0 | N19: 2.25 | O19: 0 | P19: 4.1
C21: 用于抗浮桩计算
C22: 用于基坑防护桩计算
C23: 用于工作坑后背桩 防护桩计算
C27: 土层编号 | D27: ρ | E27: c | F27: φ | G27: 桩周土摩阻力 | H27: 基本承载力 | I27: 渗透系数 | J27: zk1 | K27: zk2 | L27: zk3 | M27: zk4 | N27: zk5 | O27: zk6 | P27: zk7
J28: 4.2 | K28: 4.6 | L28: 3.8 | M28: 4.5 | N28: 4.8 | O28: 4 | P28: 3.82 | Q28: 孔口高程
D29: g/cm3 | E29: kPa | F29: 度 | G29: kPa | H29: kPa | I29: cm/s | J29: 2.2 | K29: 2.8 | L29: 2 | M29: 2.5 | N29: 3.1 | O29: 2.1 | P29: 1.6 | Q29: 水位高程
B30: 杂填土 | C30: 1 | D30: 19.4 | E30: 5 | F30: 10 | J30: 0 | K30: 0 | L30: 0 | M30: 0 | N30: 1 | O30: 0 | P30: 0
B31: 粉土 | C31: 2-31 | D31: 18.7 | E31: 14.8 | F31: 27 | G31: 40 | H31: 120 | I31: 0.5 | J31: 2.2 | K31: 1.6 | L31: 3.2 | M31: 3 | N31: 3.1 | O31: 3.1 | P31: 3.2
B32: 粉质粘土 | C32: 2-21 | D32: 18.7 | E32: 22 | F32: 12.8 | G32: 38 | H32: 100 | I32: 0.01 | J32: 1.8 | K32: 1.4 | L32: 0 | M32: 2 | N32: 1.9 | O32: 2 | P32: 1.8
B33: 淤泥质粉质黏土 | C33: 3-61 | E33: 13.8 | F33: 5.5 | G33: 15 | H33: 60 | I33: 0.1 | J33: 3.2 | K33: 2.5 | L33: 0 | M33: 2 | N33: 2 | O33: 0 | P33: 3
B34: 粉质粘土 | C34: 3-21 | D34: 17 | E34: 24.7 | F34: 17.4 | G34: 38 | H34: 100 | I34: 0.01 | J34: 1.9 | K34: 1.2 | L34: 3.8 | M34: 0 | N34: 0 | O34: 0 | P34: 1
B35: 粉土 | C35: 3-31 | D35: 18.7 | E35: 16 | F35: 24.1 | G35: 35 | H35: 100 | I35: 0.5 | J35: 2.9 | K35: 5.4 | L35: 4.9 | M35: 4.7 | N35: 4.3 | O35: 5.9 | P35: 3
B36: 粉质粘土 | C36: 4-21 | D36: 19.2 | E36: 28.9 | F36: 14 | G36: 45 | H36: 120 | I36: 0.005 | J36: 3.45 | K36: 3.9 | L36: 3.6 | M36: 3.3 | N36: 4.9 | O36: 6 | P36: 5
B37: 粉土 | C37: 4-31 | D37: 18.7 | E37: 14 | F37: 25 | G37: 45 | H37: 140 | I37: 0.5 | J37: 0 | K37: 3 | L37: 2.8 | M37: 0 | N37: 1.9 | O37: 1.5 | P37: 2
B38: 粉砂 | C38: 4-71 | D38: 19.3 | E38: 2 | F38: 25 | G38: 45 | H38: 110 | J38: 0 | K38: 14.5 | L38: 15.8 | M38: 0 | N38: 14.9 | O38: 14.7 | P38: 15.9
B39: 粉质粘土 | C39: 8-21 | D39: 19.3 | E39: 36.2 | F39: 15.8 | G39: 65 | H39: 160 | J39: 0 | K39: 8.3 | L39: 7.9 | M39: 0 | N39: 8.1 | O39: 8.7 | P39: 7.1
B40: 粉土 | C40: 8-31 | D40: 19 | E40: 16 | F40: 26.7 | G40: 50 | H40: 160 | J40: 0 | K40: 0 | L40: 1 | M40: 0 | N40: 0 | O40: 0 | P40: 0
B41: 粉质粘土 | C41: 8-22 | D41: 19.5 | E41: 65.1 | F41: 16.2 | G41: 70 | H41: 180 | J41: 0 | K41: 4.8 | L41: 2.45 | M41: 0 | N41: 6.1 | O41: 3.1 | P41: 3.9
B42: 粉质粘土与粉砂互层 | C42: 8-271 | D42: 19.7 | E42: 14 | F42: 12.2 | G42: 45 | H42: 140 | J42: 0 | K42: 2.4 | L42: 0 | M42: 0 | N42: 2.25 | O42: 0 | P42: 4.1
C44: 用于抗浮桩计算

Sheet 1.U型槽主筋验算
H1: 边墙厚度 | I1: 结构净高 | J1: 水位高 | K1: 钢筋
G2: ='0.结构参数'!A41 -> 西U10 | H2: ='0.结构参数'!L41 -> 0.3 | I2: =MAX('0.结构参数'!I41,'0.结构参数'!J41) -> 1.61126 | J2: =3.15-MIN('0.结构参数'!I5,'0.结构参数'!J5) -> 1.41326 | K2: 14
G3: ='0.结构参数'!A42 -> 西U9 | H3: ='0.结构参数'!L42 -> 0.3 | I3: =MAX('0.结构参数'!I42,'0.结构参数'!J42) -> 2.17365 | J3: =3.15-MIN('0.结构参数'!I6,'0.结构参数'!J6) -> 1.97565 | K3: 14
G4: ='0.结构参数'!A43 -> 西U8 | H4: ='0.结构参数'!L43 -> 0.3 | I4: =MAX('0.结构参数'!I43,'0.结构参数'!J43) -> 2.96447 | J4: =3.15-MIN('0.结构参数'!I7,'0.结构参数'!J7) -> 2.76647 | K4: 14
G5: ='0.结构参数'!A44 -> 西U7 | H5: ='0.结构参数'!L44 -> 0.4 | I5: =MAX('0.结构参数'!I44,'0.结构参数'!J44) -> 3.75564 | J5: =3.15-MIN('0.结构参数'!I8,'0.结构参数'!J8) -> 3.55764 | K5: 18
G6: ='0.结构参数'!A45 -> 西U6 | H6: ='0.结构参数'!L45 -> 0.5 | I6: =MAX('0.结构参数'!I45,'0.结构参数'!J45) -> 4.54681 | J6: =3.15-MIN('0.结构参数'!I9,'0.结构参数'!J9) -> 4.34881 | K6: 22
G7: ='0.结构参数'!A46 -> 西U5 | H7: ='0.结构参数'!L46 -> 0.6 | I7: =MAX('0.结构参数'!I46,'0.结构参数'!J46) -> 5.33797 | J7: =3.15-MIN('0.结构参数'!I10,'0.结构参数'!J10) -> 5.13997 | K7: 25
G8: ='0.结构参数'!A47 -> 西U4 | H8: ='0.结构参数'!L47 -> 0.6 | I8: =MAX('0.结构参数'!I47,'0.结构参数'!J47) -> 6.12914 | J8: =3.15-MIN('0.结构参数'!I11,'0.结构参数'!J11) -> 5.93114 | K8: 20
G9: ='0.结构参数'!A48 -> 西U3 | H9: ='0.结构参数'!L48 -> 0.7 | I9: =MAX('0.结构参数'!I48,'0.结构参数'!J48) -> 6.69325 | J9: =3.15-MIN('0.结构参数'!I12,'0.结构参数'!J12) -> 6.49525 | K9: 22
G10: ='0.结构参数'!A49 -> 西U2 | H10: ='0.结构参数'!L49 -> 0.7 | I10: =MAX('0.结构参数'!I49,'0.结构参数'!J49) -> 7.25702 | J10: =3.15-MIN('0.结构参数'!I13,'0.结构参数'!J13) -> 7.05902 | K10: 25
G11: ='0.结构参数'!A50 -> 西U1 | H11: ='0.结构参数'!L50 -> 0.7 | I11: =MAX('0.结构参数'!I50,'0.结构参数'!J50) -> 7.25702 | J11: =3.15-MIN('0.结构参数'!I14,'0.结构参数'!J14) -> 7.05902 | K11: 25
G12: ='0.结构参数'!A51 -> 东U1 | H12: ='0.结构参数'!L51 -> 0.8 | I12: =MAX('0.结构参数'!I51,'0.结构参数'!J51) -> 7.68277 | J12: =3.15-MIN('0.结构参数'!I15,'0.结构参数'!J15) -> 7.48477 | K12: 25
B13: 1、 | C13: 结构描述 | G13: ='0.结构参数'!A52 -> 东U2 | H13: ='0.结构参数'!L52 -> 0.7 | I13: =MAX('0.结构参数'!I52,'0.结构参数'!J52) -> 7.06732 | J13: =3.15-MIN('0.结构参数'!I16,'0.结构参数'!J16) -> 6.86932 | K13: 25
G14: ='0.结构参数'!A53 -> 东U3 | H14: ='0.结构参数'!L53 -> 0.7 | I14: =MAX('0.结构参数'!I53,'0.结构参数'!J53) -> 7.06647 | J14: =3.15-MIN('0.结构参数'!I17,'0.结构参数'!J17) -> 6.30247 | K14: 25
G15: ='0.结构参数'!A54 -> 东U4 | H15: ='0.结构参数'!L54 -> 0.6 | I15: =MAX('0.结构参数'!I54,'0.结构参数'!J54) -> 6.49928 | J15: =3.15-MIN('0.结构参数'!I18,'0.结构参数'!J18) -> 5.73528 | K15: 22
G16: ='0.结构参数'!A55 -> 东U5 | H16: ='0.结构参数'!L55 -> 0.6 | I16: =MAX('0.结构参数'!I55,'0.结构参数'!J55) -> 5.7081 | J16: =3.15-MIN('0.结构参数'!I19,'0.结构参数'!J19) -> 4.9441 | K16: 25
G17: ='0.结构参数'!A56 -> 东U6 | H17: ='0.结构参数'!L56 -> 0.5 | I17: =MAX('0.结构参数'!I56,'0.结构参数'!J56) -> 4.91691 | J17: =3.15-MIN('0.结构参数'!I20,'0.结构参数'!J20) -> 4.15291 | K17: 22
G18: ='0.结构参数'!A57 -> 东U7 | H18: ='0.结构参数'!L57 -> 0.5 | I18: =MAX('0.结构参数'!I57,'0.结构参数'!J57) -> 4.12573 | J18: =3.15-MIN('0.结构参数'!I21,'0.结构参数'!J21) -> 3.36173 | K18: 18
G19: ='0.结构参数'!A58 -> 东U8 | H19: ='0.结构参数'!L58 -> 0.3 | I19: =MAX('0.结构参数'!I58,'0.结构参数'!J58) -> 3.33454 | J19: =3.15-MIN('0.结构参数'!I22,'0.结构参数'!J22) -> 2.57054 | K19: 16
G20: ='0.结构参数'!A59 -> 东U9 | H20: ='0.结构参数'!L59 -> 0.3 | I20: =MAX('0.结构参数'!I59,'0.结构参数'!J59) -> 2.54364 | J20: =3.15-MIN('0.结构参数'!I23,'0.结构参数'!J23) -> 1.77964 | K20: 14
G21: ='0.结构参数'!A60 -> 东U10 | H21: ='0.结构参数'!L60 -> 0.3 | I21: =MAX('0.结构参数'!I60,'0.结构参数'!J60) -> 1.94014 | J21: =3.15-MIN('0.结构参数'!I24,'0.结构参数'!J24) -> 1.17614 | K21: 14
G22: ='0.结构参数'!A61 -> 西U10-1 | H22: ='0.结构参数'!L61 -> 0.3 | I22: =MAX('0.结构参数'!I61,'0.结构参数'!J61) -> 1.61126 | J22: =3.15-MIN('0.结构参数'!I25,'0.结构参数'!J25) -> 1.41326 | K22: 14
G23: ='0.结构参数'!A62 -> 西U9-1 | H23: ='0.结构参数'!L62 -> 0.3 | I23: =MAX('0.结构参数'!I62,'0.结构参数'!J62) -> 2.17365 | J23: =3.15-MIN('0.结构参数'!I26,'0.结构参数'!J26) -> 1.97565 | K23: 14
G24: ='0.结构参数'!A63 -> 西U6-1 | H24: ='0.结构参数'!L63 -> 0.5 | I24: =MAX('0.结构参数'!I63,'0.结构参数'!J63) -> 4.54681 | J24: =3.15-MIN('0.结构参数'!I27,'0.结构参数'!J27) -> 4.34881 | K24: 22
G25: ='0.结构参数'!A64 -> 西U5-1 | H25: ='0.结构参数'!L64 -> 0.6 | I25: =MAX('0.结构参数'!I64,'0.结构参数'!J64) -> 5.33797 | J25: =3.15-MIN('0.结构参数'!I28,'0.结构参数'!J28) -> 5.13997 | K25: 25
... G29: ='0.结构参数'!A68 -> 西U6-2 | H29: ='0.结构参数'!L68 -> 0.5 | I29: =MAX('0.结构参数'!I68,'0.结构参数'!J68) -> 4.54681 | J29: =3.15-MIN('0.结构参数'!I32,'0.结构参数'!J32) -> 4.34881 | K29: 22
B30: 结构尺寸 | C30: 顶宽： | D30: b1= | E30: 0.8 | G30: ='0.结构参数'!A69 -> 西U5-2 | H30: ='0.结构参数'!L69 -> 0.6 | I30: =MAX('0.结构参数'!I69,'0.结构参数'!J69) -> 5.33797 | J30: =3.15-MIN('0.结构参数'!I33,'0.结构参数'!J33) -> 5.13997 | K30: 25
C31: 底宽： | D31: b2= | E31: =E30 -> 0.8 | G31: ='0.结构参数'!A70 -> 西U4-2 | H31: ='0.结构参数'!L70 -> 0.6 | I31: =MAX('0.结构参数'!I70,'0.结构参数'!J70) -> 6.12914 | J31: =3.15-MIN('0.结构参数'!I34,'0.结构参数'!J34) -> 5.93114 | K31: 20
C32: 桥高： | D32: h= | E32: 7.7 | G32: ='0.结构参数'!A71 -> 西U3-2 | H32: ='0.结构参数'!L71 -> 0.7 | I32: =MAX('0.结构参数'!I71,'0.结构参数'!J71) -> 6.69325 | J32: =3.15-MIN('0.结构参数'!I35,'0.结构参数'!J35) -> 6.49525 | K32: 22
C33: 水高： | D33: H= | E33: 7.5
B35: 2、 | C35: 荷载计算
C37: 结构重要性系数： | D37: r0= | E37: =IF(E32>5,IF(F37="二级及以下公路",1,1.05),IF(F37="二级及以下公路",0.95,1)) -> 1.05 | F37: 高速公路、一级公路 | G37: 结构重要性系数
C38: 土压力分项系数： | D38: γt= | E38: 1.4 | G38: 墙高 | H38: 高速公路、一级公路 | I38: 二级及以下公路
C39: 水压力分项系数： | D39: γs= | E39: 1 | G39: ≤5.0m | H39: 1 | I39: 0.95
C40: 活载分项系数： | D40: γQ= | E40: 1.4 | G40: >5.0m | H40: 1.05 | I40: 1
B42: 2.1 | C42: 土压力计算
B44: 土压力 参数 | C44: 填土坡角 | D44: β= | E44: 0
C45: 内摩擦角 | D45: φ= | E45: 23
C46: 墙与填土摩擦角 | D46: δ= | E46: 11.5
C47: 墙背俯斜 | D47: α= | E47: 0
...

Sheet 2.U型槽钢筋
A2: U型槽尺寸表 | B2: 节段 | C2: 净高不含底板厚 | E2: 节段宽 | G2: 边墙厚B | H2: 底板厚T | I2: D | J2: hmin+T | K2: hmax+T | N2: 角度 | O2: 净保护层
C3: Hmin | D3: Hmax | E3: Lmax | F3: Lmin | N3: 90 | O3: 4 | P3: 4
B4: ='0.结构参数'!A41 -> 西U10 | C4: =MIN('0.结构参数'!I41,'0.结构参数'!J41)*100 -> 130 | D4: =MAX('0.结构参数'!I41,'0.结构参数'!J41)*100 -> 161.126 | E4: =MAX('0.结构参数'!E5,'0.结构参数'!F5)*100 -> 2000 | F4: =MIN('0.结构参数'!E5,'0.结构参数'!F5)*100 -> 2000 | G4: ='0.结构参数'!L41*100 -> 30 | H4: ='0.结构参数'!K41*100 -> 40 | I4: =('0.结构参数'!M41+'0.结构参数'!N41)/2*100 -> 2381 | J4: =(C4+$H4) -> 170 | K4: =(D4+$H4) -> 201.126
B5: ='0.结构参数'!A42 -> 西U9 | C5: =MIN('0.结构参数'!I42,'0.结构参数'!J42)*100 -> 161.21 | D5: =MAX('0.结构参数'!I42,'0.结构参数'!J42)*100 -> 217.365 | E5: =MAX('0.结构参数'!E6,'0.结构参数'!F6)*100 -> 2000 | F5: =MIN('0.结构参数'!E6,'0.结构参数'!F6)*100 -> 2000 | G5: ='0.结构参数'!L42*100 -> 30 | H5: ='0.结构参数'!K42*100 -> 40 | I5: =('0.结构参数'!M42+'0.结构参数'!N42)/2*100 -> 2310 | J5: =(C5+$H5) -> 201.21 | K5: =(D5+$H5) -> 257.365
B6: ='0.结构参数'!A43 -> 西U8 | C6: =MIN('0.结构参数'!I43,'0.结构参数'!J43)*100 -> 217.449 | D6: =MAX('0.结构参数'!I43,'0.结构参数'!J43)*100 -> 296.447 | E6: =MAX('0.结构参数'!E7,'0.结构参数'!F7)*100 -> 2000 | F6: =MIN('0.结构参数'!E7,'0.结构参数'!F7)*100 -> 2000 | G6: ='0.结构参数'!L43*100 -> 30 | H6: ='0.结构参数'!K43*100 -> 40 | I6: =('0.结构参数'!M43+'0.结构参数'!N43)/2*100 -> 2285 | J6: =(C6+$H6) -> 257.449 | K6: =(D6+$H6) -> 336.447
B7: ='0.结构参数'!A44 -> 西U7 | C7: =MIN('0.结构参数'!I44,'0.结构参数'!J44)*100 -> 296.566 | D7: =MAX('0.结构参数'!I44,'0.结构参数'!J44)*100 -> 375.564 | E7: =MAX('0.结构参数'!E8,'0.结构参数'!F8)*100 -> 2000 | F7: =MIN('0.结构参数'!E8,'0.结构参数'!F8)*100 -> 2000 | G7: ='0.结构参数'!L44*100 -> 40 | H7: ='0.结构参数'!K44*100 -> 50 | I7: =('0.结构参数'!M44+'0.结构参数'!N44)/2*100 -> 2305 | J7: =(C7+$H7) -> 346.566 | K7: =(D7+$H7) -> 425.564
B8: ='0.结构参数'!A45 -> 西U6 | C8: =MIN('0.结构参数'!I45,'0.结构参数'!J45)*100 -> 375.682 | D8: =MAX('0.结构参数'!I45,'0.结构参数'!J45)*100 -> 454.681 | E8: =MAX('0.结构参数'!E9,'0.结构参数'!F9)*100 -> 2000 | F8: =MIN('0.结构参数'!E9,'0.结构参数'!F9)*100 -> 2000 | G8: ='0.结构参数'!L45*100 -> 50 | H8: ='0.结构参数'!K45*100 -> 60 | I8: =('0.结构参数'!M45+'0.结构参数'!N45)/2*100 -> 2325 | J8: =(C8+$H8) -> 435.682 | K8: =(D8+$H8) -> 514.681 | N8: 4、e2数值改为定值8，但仍需注意表格外e2取值区间
B9: ='0.结构参数'!A46 -> 西U5 | C9: =MIN('0.结构参数'!I46,'0.结构参数'!J46)*100 -> 454.799 | D9: =MAX('0.结构参数'!I46,'0.结构参数'!J46)*100 -> 533.797 | E9: =MAX('0.结构参数'!E10,'0.结构参数'!F10)*100 -> 2000 | F9: =MIN('0.结构参数'!E10,'0.结构参数'!F10)*100 -> 2000 | G9: ='0.结构参数'!L46*100 -> 60 | H9: ='0.结构参数'!K46*100 -> 70 | I9: =('0.结构参数'!M46+'0.结构参数'!N46)/2*100 -> 2345 | J9: =(C9+$H9) -> 524.799 | K9: =(D9+$H9) -> 603.797
B10: ='0.结构参数'!A47 -> 西U4 | C10: =MIN('0.结构参数'!I47,'0.结构参数'!J47)*100 -> 533.916 | D10: =MAX('0.结构参数'!I47,'0.结构参数'!J47)*100 -> 612.914 | E10: =MAX('0.结构参数'!E11,'0.结构参数'!F11)*100 -> 2000 | F10: =MIN('0.结构参数'!E11,'0.结构参数'!F11)*100 -> 2000 | G10: ='0.结构参数'!L47*100 -> 60 | H10: ='0.结构参数'!K47*100 -> 70 | I10: =('0.结构参数'!M47+'0.结构参数'!N47)/2*100 -> 2345 | J10: =(C10+$H10) -> 603.916 | K10: =(D10+$H10) -> 682.914
B11: ='0.结构参数'!A48 -> 西U3 | C11: =MIN('0.结构参数'!I48,'0.结构参数'!J48)*100 -> 613.033 | D11: =MAX('0.结构参数'!I48,'0.结构参数'!J48)*100 -> 669.325 | E11: =MAX('0.结构参数'!E12,'0.结构参数'!F12)*100 -> 2000 | F11: =MIN('0.结构参数'!E12,'0.结构参数'!F12)*100 -> 2000 | G11: ='0.结构参数'!L48*100 -> 70 | H11: ='0.结构参数'!K48*100 -> 80 | I11: =('0.结构参数'!M48+'0.结构参数'!N48)/2*100 -> 2365 | J11: =(C11+$H11) -> 693.033 | K11: =(D11+$H11) -> 749.325
B12: ='0.结构参数'!A49 -> 西U2 | C12: =MIN('0.结构参数'!I49,'0.结构参数'!J49)*100 -> 669.41 | D12: =MAX('0.结构参数'!I49,'0.结构参数'!J49)*100 -> 725.702 | E12: =MAX('0.结构参数'!E13,'0.结构参数'!F13)*100 -> 2000 | F12: =MIN('0.结构参数'!E13,'0.结构参数'!F13)*100 -> 2000 | G12: ='0.结构参数'!L49*100 -> 70 | H12: ='0.结构参数'!K49*100 -> 80 | I12: =('0.结构参数'!M49+'0.结构参数'!N49)/2*100 -> 2365 | J12: =(C12+$H12) -> 749.41 | K12: =(D12+$H12) -> 805.702
B13: ='0.结构参数'!A50 -> 西U1 | C13: =MIN('0.结构参数'!I50,'0.结构参数'!J50)*100 -> 725.702 | D13: =MAX('0.结构参数'!I50,'0.结构参数'!J50)*100 -> 725.702 | E13: =MAX('0.结构参数'!E14,'0.结构参数'!F14)*100 -> 2500 | F13: =MIN('0.结构参数'!E14,'0.结构参数'!F14)*100 -> 2500 | G13: ='0.结构参数'!L50*100 -> 70 | H13: ='0.结构参数'!K50*100 -> 80 | I13: =('0.结构参数'!M50+'0.结构参数'!N50)/2*100 -> 2365 | J13: =(C13+$H13) -> 805.702 | K13: =(D13+$H13) -> 805.702
B14: ='0.结构参数'!A51 -> 东U1 | C14: =MIN('0.结构参数'!I51,'0.结构参数'!J51)*100 -> 706.817 | D14: =MAX('0.结构参数'!I51,'0.结构参数'!J51)*100 -> 768.277 | E14: =MAX('0.结构参数'!E15,'0.结构参数'!F15)*100 -> 800 | F14: =MIN('0.结构参数'!E15,'0.结构参数'!F15)*100 -> 800 | G14: ='0.结构参数'!L51*100 -> 80 | H14: ='0.结构参数'!K51*100 -> 90 | I14: =('0.结构参数'!M51+'0.结构参数'!N51)/2*100 -> 2385 | J14: =(C14+$H14) -> 796.817 | K14: =(D14+$H14) -> 858.277
B15: ='0.结构参数'!A52 -> 东U2 | C15: =MIN('0.结构参数'!I52,'0.结构参数'!J52)*100 -> 706.732 | D15: =MAX('0.结构参数'!I52,'0.结构参数'!J52)*100 -> 706.732 | E15: =MAX('0.结构参数'!E16,'0.结构参数'!F16)*100 -> 2000 | F15: =MIN('0.结构参数'!E16,'0.结构参数'!F16)*100 -> 2000 | G15: ='0.结构参数'!L52*100 -> 70 | H15: ='0.结构参数'!K52*100 -> 80 | I15: =('0.结构参数'!M52+'0.结构参数'!N52)/2*100 -> 2365 | J15: =(C15+$H15) -> 786.732 | K15: =(D15+$H15) -> 786.732
B16: ='0.结构参数'!A53 -> 东U3 | C16: =MIN('0.结构参数'!I53,'0.结构参数'!J53)*100 -> 650.047 | D16: =MAX('0.结构参数'!I53,'0.结构参数'!J53)*100 -> 706.647 | E16: =MAX('0.结构参数'!E17,'0.结构参数'!F17)*100 -> 2000 | F16: =MIN('0.结构参数'!E17,'0.结构参数'!F17)*100 -> 2000 | G16: ='0.结构参数'!L53*100 -> 70 | H16: ='0.结构参数'!K53*100 -> 80 | I16: =('0.结构参数'!M53+'0.结构参数'!N53)/2*100 -> 2365 | J16: =(C16+$H16) -> 730.047 | K16: =(D16+$H16) -> 786.647
B17: ='0.结构参数'!A54 -> 东U4 | C17: =MIN('0.结构参数'!I54,'0.结构参数'!J54)*100 -> 570.928 | D17: =MAX('0.结构参数'!I54,'0.结构参数'!J54)*100 -> 649.928 | E17: =MAX('0.结构参数'!E18,'0.结构参数'!F18)*100 -> 2000 | F17: =MIN('0.结构参数'!E18,'0.结构参数'!F18)*100 -> 2000 | G17: ='0.结构参数'!L54*100 -> 60 | H17: ='0.结构参数'!K54*100 -> 70 | I17: =('0.结构参数'!M54+'0.结构参数'!N54)/2*100 -> 2345 | J17: =(C17+$H17) -> 640.928 | K17: =(D17+$H17) -> 719.928
B18: ='0.结构参数'!A55 -> 东U5 | C18: =MIN('0.结构参数'!I55,'0.结构参数'!J55)*100 -> 491.81 | D18: =MAX('0.结构参数'!I55,'0.结构参数'!J55)*100 -> 570.81 | E18: =MAX('0.结构参数'!E19,'0.结构参数'!F19)*100 -> 2000 | F18: =MIN('0.结构参数'!E19,'0.结构参数'!F19)*100 -> 2000 | G18: ='0.结构参数'!L55*100 -> 60 | H18: ='0.结构参数'!K55*100 -> 70 | I18: =('0.结构参数'!M55+'0.结构参数'!N55)/2*100 -> 2345 | J18: =(C18+$H18) -> 561.81 | K18: =(D18+$H18) -> 640.81
B19: ='0.结构参数'!A56 -> 东U6 | C19: =MIN('0.结构参数'!I56,'0.结构参数'!J56)*100 -> 412.691 | D19: =MAX('0.结构参数'!I56,'0.结构参数'!J56)*100 -> 491.691 | E19: =MAX('0.结构参数'!E20,'0.结构参数'!F20)*100 -> 2000 | F19: =MIN('0.结构参数'!E20,'0.结构参数'!F20)*100 -> 2000 | G19: ='0.结构参数'!L56*100 -> 50 | H19: ='0.结构参数'!K56*100 -> 60 | I19: =('0.结构参数'!M56+'0.结构参数'!N56)/2*100 -> 2325 | J19: =(C19+$H19) -> 472.691 | K19: =(D19+$H19) -> 551.691
B20: ='0.结构参数'!A57 -> 东U7 | C20: =MIN('0.结构参数'!I57,'0.结构参数'!J57)*100 -> 333.573 | D20: =MAX('0.结构参数'!I57,'0.结构参数'!J57)*100 -> 412.573 | E20: =MAX('0.结构参数'!E21,'0.结构参数'!F21)*100 -> 2000 | F20: =MIN('0.结构参数'!E21,'0.结构参数'!F21)*100 -> 2000 | G20: ='0.结构参数'!L57*100 -> 50 | H20: ='0.结构参数'!K57*100 -> 60 | I20: =('0.结构参数'!M57+'0.结构参数'!N57)/2*100 -> 2325 | J20: =(C20+$H20) -> 393.573 | K20: =(D20+$H20) -> 472.573
... B35: ='0.结构参数'!A72 -> 0 | C35: =MIN('0.结构参数'!I72,'0.结构参数'!J72)*100 -> 0 | D35: =MAX('0.结构参数'!I72,'0.结构参数'!J72)*100 -> 0 | E35: =MAX('0.结构参数'!E36,'0.结构参数'!F36)*100 -> 0 | F35: =MIN('0.结构参数'!E36,'0.结构参数'!F36)*100 -> 0 | G35: ='0.结构参数'!L72*100 -> 30 | H35: ='0.结构参数'!K72*100 -> 40 | I35: =('0.结构参数'!M72+'0.结构参数'!N72)/2*100 -> 60 | J35: =(C35+$H35) -> 40 | K35: =(D35+$H35) -> 40
F37: 此处若为负值，则公式改为“B21/D21-2” | P37: 若e2小于8，则在n1公式后减1
A38: 钢筋图参数表 | B38: U型槽 编号 | C38: D (cm) | D38: n | E38: d (cm) | F38: a 0~12.5 | G38: B (cm) | H38: m | I38: b (cm) | J38: e1 (cm) | K38: Hmin (cm) | L38: Hmax (cm) | M38: n1 | N38: d1 (cm) | O38: d2 (cm) | P38: e2 | Q38: T | R38: n1' | S38: d1' | T38: L1 (cm) | U38: m1 | V38: b1 (cm) | W38: L2 (cm) | X38: m2 | Y38: b2 (cm) | Z38: e3 (cm) | AA38: e2 7~20.5
B39: =B4 -> 西U10 | C39: =VLOOKUP(B39,$B$4:$K$36,8,0) -> 2381 | D39: =ROUNDDOWN((C39/E39-1),0) -> 189 | E39: =12.5 -> 12.5 | F39: =C39-D39*E39-2*J39 -> 2.5 | G39: =VLOOKUP(B39,$B$4:$J$72,6,0) -> 30 | H39: 2 | I39: =(G39-J39*2)/H39 -> 7 | J39: 8 | K39: =VLOOKUP(B39,$B$4:$K$36,2,0) -> 130 | L39: =VLOOKUP(B39,$B$4:$K$36,3,0) -> 161.126 | M39: =ROUND((L39-5)/12.5,0)-1 -> 11 | N39: =(L39-5-P39)/M39 -> 13.466 | O39: =(K39-P39-5)/M39 -> 10.636364 | P39: 8 | Q39: =VLOOKUP($B39,$B$4:$K$36,7,0) -> 40 | R39: 3 | S39: =(Q39-2*J39)/R39 -> 8 | T39: =VLOOKUP($B39,$B$4:$K$36,4,0) -> 2000 | U39: =ROUNDDOWN(T39/V39,0)-1 -> 159 | V39: 12.5 | W39: =VLOOKUP($B39,$B$4:$K$36,5,0) -> 2000 | X39: =U39 -> 159 | Y39: =(W39-Z39*2)/X39 -> 12.5 | Z39: =(T39-U39*V39)/2 -> 6.25 | AA39: =L39-M39*12.5-5 -> 18.626
B40: =B5 -> 西U9 | C40: =VLOOKUP(B40,$B$4:$K$36,8,0) -> 2310 | D40: =ROUNDDOWN((C40/E40-1),0) -> 183 | E40: =12.5 -> 12.5 | F40: =C40-D40*E40-2*J40 -> 6.5 | G40: =VLOOKUP(B40,$B$4:$J$72,6,0) -> 30 | H40: 2 | I40: =(G40-J40*2)/H40 -> 7 | J40: 8 | K40: =VLOOKUP(B40,$B$4:$K$36,2,0) -> 161.21 | L40: =VLOOKUP(B40,$B$4:$K$36,3,0) -> 217.365 | M40: =ROUND((L40-5)/12.5,0)-1 -> 16 | N40: =(L40-5-P40)/M40 -> 12.772813 | O40: =(K40-P40-5)/M40 -> 9.263125 | P40: 8 | Q40: =VLOOKUP($B40,$B$4:$K$36,7,0) -> 40 | R40: 3 | S40: =(Q40-2*J40)/R40 -> 8 | T40: =VLOOKUP($B40,$B$4:$K$36,4,0) -> 2000 | U40: =ROUNDDOWN(T40/V40,0)-1 -> 147 | V40: 13.5 | W40: =VLOOKUP($B40,$B$4:$K$36,5,0) -> 2000 | X40: =U40 -> 147 | Y40: =(W40-Z40*2)/X40 -> 13.5 | Z40: =(T40-U40*V40)/2 -> 7.75 | AA40: =L40-M40*12.5-5 -> 12.365
B41: =B6 -> 西U8 | C41: =VLOOKUP(B41,$B$4:$K$36,8,0) -> 2285 | D41: =ROUNDDOWN((C41/E41-1),0) -> 181 | E41: =12.5 -> 12.5 | F41: =C41-D41*E41-2*J41 -> 6.5 | G41: =VLOOKUP(B41,$B$4:$J$72,6,0) -> 30 | H41: 2 | I41: =(G41-J41*2)/H41 -> 7 | J41: 8 | K41: =VLOOKUP(B41,$B$4:$K$36,2,0) -> 217.449 | L41: =VLOOKUP(B41,$B$4:$K$36,3,0) -> 296.447 | M41: =ROUND((L41-5)/12.5,0)-1 -> 22 | N41: =(L41-5-P41)/M41 -> 12.883955 | O41: =(K41-P41-5)/M41 -> 9.2931364 | P41: 8 | Q41: =VLOOKUP($B41,$B$4:$K$36,7,0) -> 40 | R41: 3 | S41: =(Q41-2*J41)/R41 -> 8 | T41: =VLOOKUP($B41,$B$4:$K$36,4,0) -> 2000 | U41: =ROUNDDOWN(T41/V41,0)-1 -> 136 | V41: 14.5 | W41: =VLOOKUP($B41,$B$4:$K$36,5,0) -> 2000 | X41: =U41 -> 136 | Y41: =(W41-Z41*2)/X41 -> 14.5 | Z41: =(T41-U41*V41)/2 -> 14 | AA41: =L41-M41*12.5-5 -> 16.447
B42: =B7 -> 西U7 | C42: =VLOOKUP(B42,$B$4:$K$36,8,0) -> 2305 | D42: =ROUNDDOWN((C42/E42-1),0) -> 183 | E42: =12.5 -> 12.5 | F42: =C42-D42*E42-2*J42 -> 1.5 | G42: =VLOOKUP(B42,$B$4:$J$72,6,0) -> 40 | H42: 3 | I42: =(G42-J42*2)/H42 -> 8 | J42: 8 | K42: =VLOOKUP(B42,$B$4:$K$36,2,0) -> 296.566 | L42: =VLOOKUP(B42,$B$4:$K$36,3,0) -> 375.564 | M42: =ROUND((L42-5)/12.5,0)-1 -> 29 | N42: =(L42-5-P42)/M42 -> 12.502207 | O42: =(K42-P42-5)/M42 -> 9.7781379 | P42: 8 | Q42: =VLOOKUP($B42,$B$4:$K$36,7,0) -> 50 | R42: 4 | S42: =(Q42-2*J42)/R42 -> 8.5 | T42: =VLOOKUP($B42,$B$4:$K$36,4,0) -> 2000 | U42: =ROUNDDOWN(T42/V42,0)-1 -> 128 | V42: 15.5 | W42: =VLOOKUP($B42,$B$4:$K$36,5,0) -> 2000 | X42: =U42 -> 128 | Y42: =(W42-Z42*2)/X42 -> 15.5 | Z42: =(T42-U42*V42)/2 -> 8 | AA42: =L42-M42*12.5-5 -> 8.064
B43: =B8 -> 西U6 | C43: =VLOOKUP(B43,$B$4:$K$36,8,0) -> 2325 | D43: =ROUNDDOWN((C43/E43-2),0) -> 184 | E43: =12.5 -> 12.5 | F43: =C43-D43*E43-2*J43 -> 9 | G43: =VLOOKUP(B43,$B$4:$J$72,6,0) -> 50 | H43: 4 | I43: =(G43-J43*2)/H43 -> 8.5 | J43: 8 | K43: =VLOOKUP(B43,$B$4:$K$36,2,0) -> 375.682 | L43: =VLOOKUP(B43,$B$4:$K$36,3,0) -> 454.681 | M43: =ROUND((L43-5)/12.5,0)-1 -> 35 | N43: =(L43-5-P43)/M43 -> 12.619457 | O43: =(K43-P43-5)/M43 -> 10.362343 | P43: 8 | Q43: =VLOOKUP($B43,$B$4:$K$36,7,0) -> 60 | R43: 4 | S43: =(Q43-2*J43)/R43 -> 11 | T43: =VLOOKUP($B43,$B$4:$K$36,4,0) -> 2000 | U43: =ROUNDDOWN(T43/V43,0)-1 -> 120 | V43: 16.5 | W43: =VLOOKUP($B43,$B$4:$K$36,5,0) -> 2000 | X43: =U43 -> 120 | Y43: =(W43-Z43*2)/X43 -> 16.5 | Z43: =(T43-U43*V43)/2 -> 10 | AA43: =L43-M43*12.5-5 -> 12.181
B44: =B9 -> 西U5 | C44: =VLOOKUP(B44,$B$4:$K$36,8,0) -> 2345 | D44: =ROUNDDOWN((C44/E44-1),0) -> 186 | E44: =12.5 -> 12.5 | F44: =C44-D44*E44-2*J44 -> 4 | G44: =VLOOKUP(B44,$B$4:$J$72,6,0) -> 60 | H44: 4 | I44: =(G44-J44*2)/H44 -> 11 | J44: 8 | K44: =VLOOKUP(B44,$B$4:$K$36,2,0) -> 454.799 | L44: =VLOOKUP(B44,$B$4:$K$36,3,0) -> 533.797 | M44: =ROUND((L44-5)/12.5,0)-1 -> 41 | N44: =(L44-5-P44)/M44 -> 12.702366 | O44: =(K44-P44-5)/M44 -> 10.775585 | P44: 8 | Q44: =VLOOKUP($B44,$B$4:$K$36,7,0) -> 70 | R44: 6 | S44: =(Q44-2*J44)/R44 -> 9 | T44: =VLOOKUP($B44,$B$4:$K$36,4,0) -> 2000 | U44: =ROUNDDOWN(T44/V44,0)-1 -> 113 | V44: 17.5 | W44: =VLOOKUP($B44,$B$4:$K$36,5,0) -> 2000 | X44: =U44 -> 113 | Y44: =(W44-Z44*2)/X44 -> 17.5 | Z44: =(T44-U44*V44)/2 -> 11.25 | AA44: =L44-M44*12.5-5 -> 16.297
B45: =B10 -> 西U4 | C45: =VLOOKUP(B45,$B$4:$K$36,8,0) -> 2345 | D45: =ROUNDDOWN((C45/E45-1),0) -> 186 | E45: =12.5 -> 12.5 | F45: =C45-D45*E45-2*J45 -> 4 | G45: =VLOOKUP(B45,$B$4:$J$72,6,0) -> 60 | H45: 4 | I45: =(G45-J45*2)/H45 -> 11 | J45: 8 | K45: =VLOOKUP(B45,$B$4:$K$36,2,0) -> 533.916 | L45: =VLOOKUP(B45,$B$4:$K$36,3,0) -> 612.914 | M45: =ROUND((L45-5)/12.5,0)-1 -> 48 | N45: =(L45-5-P45)/M45 -> 12.498208 | O45: =(K45-P45-5)/M45 -> 10.852417 | P45: 8 | Q45: =VLOOKUP($B45,$B$4:$K$36,7,0) -> 70 | R45: 6 | S45: =(Q45-2*J45)/R45 -> 9 | T45: =VLOOKUP($B45,$B$4:$K$36,4,0) -> 2000 | U45: =ROUNDDOWN(T45/V45,0)-1 -> 107 | V45: 18.5 | W45: =VLOOKUP($B45,$B$4:$K$36,5,0) -> 2000 | X45: =U45 -> 107 | Y45: =(W45-Z45*2)/X45 -> 18.5 | Z45: =(T45-U45*V45)/2 -> 10.25 | AA45: =L45-M45*12.5-5 -> 7.914
B46: =B11 -> 西U3 | C46: =VLOOKUP(B46,$B$4:$K$36,8,0) -> 2365 | D46: =ROUNDDOWN((C46/E46-2),0) -> 187 | E46: =12.5 -> 12.5 | F46: =C46-D46*E46-2*J46 -> 11.5 | G46: =VLOOKUP(B46,$B$4:$J$72,6,0) -> 70 | H46: 6 | I46: =(G46-J46*2)/H46 -> 9 | J46: 8 | K46: =VLOOKUP(B46,$B$4:$K$36,2,0) -> 613.033 | L46: =VLOOKUP(B46,$B$4:$K$36,3,0) -> 669.325 | M46: =ROUND((L46-5)/12.5,0)-1 -> 52 | N46: =(L46-5-P46)/M46 -> 12.621635 | O46: =(K46-P46-5)/M46 -> 11.539096 | P46: 8 | Q46: =VLOOKUP($B46,$B$4:$K$36,7,0) -> 80 | R46: 8 | S46: =(Q46-2*J46)/R46 -> 8 | T46: =VLOOKUP($B46,$B$4:$K$36,4,0) -> 2000 | U46: =ROUNDDOWN(T46/V46,0)-1 -> 101 | V46: 19.5 | W46: =VLOOKUP($B46,$B$4:$K$36,5,0) -> 2000 | X46: =U46 -> 101 | Y46: =(W46-Z46*2)/X46 -> 19.5 | Z46: =(T46-U46*V46)/2 -> 15.25 | AA46: =L46-M46*12.5-5 -> 14.325
B47: =B12 -> 西U2 | C47: =VLOOKUP(B47,$B$4:$K$36,8,0) -> 2365 | D47: =ROUNDDOWN((C47/E47-2),0) -> 187 | E47: =12.5 -> 12.5 | F47: =C47-D47*E47-2*J47 -> 11.5 | G47: =VLOOKUP(B47,$B$4:$J$72,6,0) -> 70 | H47: 6 | I47: =(G47-J47*2)/H47 -> 9 | J47: 8 | K47: =VLOOKUP(B47,$B$4:$K$36,2,0) -> 669.41 | L47: =VLOOKUP(B47,$B$4:$K$36,3,0) -> 725.702 | M47: =ROUND((L47-5)/12.5,0)-1 -> 57 | N47: =(L47-5-P47)/M47 -> 12.503544 | O47: =(K47-P47-5)/M47 -> 11.515965 | P47: 8 | Q47: =VLOOKUP($B47,$B$4:$K$36,7,0) -> 80 | R47: 8 | S47: =(Q47-2*J47)/R47 -> 8 | T47: =VLOOKUP($B47,$B$4:$K$36,4,0) -> 2000 | U47: =ROUNDDOWN(T47/V47,0)-1 -> 96 | V47: 20.5 | W47: =VLOOKUP($B47,$B$4:$K$36,5,0) -> 2000 | X47: =U47 -> 96 | Y47: =(W47-Z47*2)/X47 -> 20.5 | Z47: =(T47-U47*V47)/2 -> 16 | AA47: =L47-M47*12.5-5 -> 8.202
B48: =B13 -> 西U1 | C48: =VLOOKUP(B48,$B$4:$K$36,8,0) -> 2365 | D48: =ROUNDDOWN((C48/E48-2),0) -> 187 | E48: =12.5 -> 12.5 | F48: =C48-D48*E48-2*J48 -> 11.5 | G48: =VLOOKUP(B48,$B$4:$J$72,6,0) -> 70 | H48: 6 | I48: =(G48-J48*2)/H48 -> 9 | J48: 8 | K48: =VLOOKUP(B48,$B$4:$K$36,2,0) -> 725.702 | L48: =VLOOKUP(B48,$B$4:$K$36,3,0) -> 725.702 | M48: =ROUND((L48-5)/12.5,0)-1 -> 57 | N48: =(L48-5-P48)/M48 -> 12.503544 | O48: =(K48-P48-5)/M48 -> 12.503544 | P48: 8 | Q48: =VLOOKUP($B48,$B$4:$K$36,7,0) -> 80 | R48: 8 | S48: =(Q48-2*J48)/R48 -> 8 | T48: =VLOOKUP($B48,$B$4:$K$36,4,0) -> 2500 | U48: =ROUNDDOWN(T48/V48,0)-1 -> 115 | V48: 21.5 | W48: =VLOOKUP($B48,$B$4:$K$36,5,0) -> 2500 | X48: =U48 -> 115 | Y48: =(W48-Z48*2)/X48 -> 21.5 | Z48: =(T48-U48*V48)/2 -> 13.75 | AA48: =L48-M48*12.5-5 -> 8.202
B49: =B14 -> 东U1 | C49: =VLOOKUP(B49,$B$4:$K$36,8,0) -> 2385 | D49: =ROUNDDOWN((C49/E49-1),0) -> 189 | E49: =12.5 -> 12.5 | F49: =C49-D49*E49-2*J49 -> 6.5 | G49: =VLOOKUP(B49,$B$4:$J$72,6,0) -> 80 | H49: 8 | I49: =(G49-J49*2)/H49 -> 8 | J49: 8 | K49: =VLOOKUP(B49,$B$4:$K$36,2,0) -> 706.817 | L49: =VLOOKUP(B49,$B$4:$K$36,3,0) -> 768.277 | M49: =ROUND((L49-5)/12.5,0)-1 -> 60 | N49: =(L49-5-P49)/M49 -> 12.58795 | O49: =(K49-P49-5)/M49 -> 11.563617 | P49: 8 | Q49: =VLOOKUP($B49,$B$4:$K$36,7,0) -> 90 | R49: 8 | S49: =(Q49-2*J49)/R49 -> 9.25 | T49: =VLOOKUP($B49,$B$4:$K$36,4,0) -> 800 | U49: =ROUNDDOWN(T49/V49,0)-1 -> 34 | V49: 22.5 | W49: =VLOOKUP($B49,$B$4:$K$36,5,0) -> 800 | X49: =U49 -> 34 | Y49: =(W49-Z49*2)/X49 -> 22.5 | Z49: =(T49-U49*V49)/2 -> 17.5 | AA49: =L49-M49*12.5-5 -> 13.277
B50: =B15 -> 东U2 | C50: =VLOOKUP(B50,$B$4:$K$36,8,0) -> 2365 | D50: =ROUNDDOWN((C50/E50-2),0) -> 187 | E50: =12.5 -> 12.5 | F50: =C50-D50*E50-2*J50 -> 11.5 | G50: =VLOOKUP(B50,$B$4:$J$72,6,0) -> 70 | H50: 6 | I50: =(G50-J50*2)/H50 -> 9 | J50: 8 | K50: =VLOOKUP(B50,$B$4:$K$36,2,0) -> 706.732 | L50: =VLOOKUP(B50,$B$4:$K$36,3,0) -> 706.732 | M50: =ROUND((L50-5)/12.5,0)-1 -> 55 | N50: =(L50-5-P50)/M50 -> 12.613309 | O50: =(K50-P50-5)/M50 -> 12.613309 | P50: 8 | Q50: =VLOOKUP($B50,$B$4:$K$36,7,0) -> 80 | R50: 8 | S50: =(Q50-2*J50)/R50 -> 8 | T50: =VLOOKUP($B50,$B$4:$K$36,4,0) -> 2000 | U50: =ROUNDDOWN(T50/V50,0)-1 -> 84 | V50: 23.5 | W50: =VLOOKUP($B50,$B$4:$K$36,5,0) -> 2000 | X50: =U50 -> 84 | Y50: =(W50-Z50*2)/X50 -> 23.5 | Z50: =(T50-U50*V50)/2 -> 13 | AA50: =L50-M50*12.5-5 -> 14.232
B51: =B16 -> 东U3 | C51: =VLOOKUP(B51,$B$4:$K$36,8,0) -> 2365 | D51: =ROUNDDOWN((C51/E51-2),0) -> 187 | E51: =12.5 -> 12.5 | F51: =C51-D51*E51-2*J51 -> 11.5 | G51: =VLOOKUP(B51,$B$4:$J$72,6,0) -> 70 | H51: 6 | I51: =(G51-J51*2)/H51 -> 9 | J51: 8 | K51: =VLOOKUP(B51,$B$4:$K$36,2,0) -> 650.047 | L51: =VLOOKUP(B51,$B$4:$K$36,3,0) -> 706.647 | M51: =ROUND((L51-5)/12.5,0)-1 -> 55 | N51: =(L51-5-P51)/M51 -> 12.611764 | O51: =(K51-P51-5)/M51 -> 11.582673 | P51: 8 | Q51: =VLOOKUP($B51,$B$4:$K$36,7,0) -> 80 | R51: 8 | S51: =(Q51-2*J51)/R51 -> 8 | T51: =VLOOKUP($B51,$B$4:$K$36,4,0) -> 2000 | U51: =ROUNDDOWN(T51/V51,0)-1 -> 80 | V51: 24.5 | W51: =VLOOKUP($B51,$B$4:$K$36,5,0) -> 2000 | X51: =U51 -> 80 | Y51: =(W51-Z51*2)/X51 -> 24.5 | Z51: =(T51-U51*V51)/2 -> 20 | AA51: =L51-M51*12.5-5 -> 14.147
B52: =B17 -> 东U4 | C52: =VLOOKUP(B52,$B$4:$K$36,8,0) -> 2345 | D52: =ROUNDDOWN((C52/E52-1),0) -> 186 | E52: =12.5 -> 12.5 | F52: =C52-D52*E52-2*J52 -> 4 | G52: =VLOOKUP(B52,$B$4:$J$72,6,0) -> 60 | H52: 4 | I52: =(G52-J52*2)/H52 -> 11 | J52: 8 | K52: =VLOOKUP(B52,$B$4:$K$36,2,0) -> 570.928 | L52: =VLOOKUP(B52,$B$4:$K$36,3,0) -> 649.928 | M52: =ROUND((L52-5)/12.5,0)-1 -> 51 | N52: =(L52-5-P52)/M52 -> 12.488784 | O52: =(K52-P52-5)/M52 -> 10.939765 | P52: 8 | Q52: =VLOOKUP($B52,$B$4:$K$36,7,0) -> 70 | R52: 6 | S52: =(Q52-2*J52)/R52 -> 9 | T52: =VLOOKUP($B52,$B$4:$K$36,4,0) -> 2000 | U52: =ROUNDDOWN(T52/V52,0)-1 -> 77 | V52: 25.5 | W52: =VLOOKUP($B52,$B$4:$K$36,5,0) -> 2000 | X52: =U52 -> 77 | Y52: =(W52-Z52*2)/X52 -> 25.5 | Z52: =(T52-U52*V52)/2 -> 18.25 | AA52: =L52-M52*12.5-5 -> 7.428
B53: =B18 -> 东U5 | C53: =VLOOKUP(B53,$B$4:$K$36,8,0) -> 2345 | D53: =ROUNDDOWN((C53/E53-1),0) -> 186 | E53: =12.5 -> 12.5 | F53: =C53-D53*E53-2*J53 -> 4 | G53: =VLOOKUP(B53,$B$4:$J$72,6,0) -> 60 | H53: 4 | I53: =(G53-J53*2)/H53 -> 11 | J53: 8 | K53: =VLOOKUP(B53,$B$4:$K$36,2,0) -> 491.81 | L53: =VLOOKUP(B53,$B$4:$K$36,3,0) -> 570.81 | M53: =ROUND((L53-5)/12.5,0)-1 -> 44 | N53: =(L53-5-P53)/M53 -> 12.6775 | O53: =(K53-P53-5)/M53 -> 10.882045 | P53: 8 | Q53: =VLOOKUP($B53,$B$4:$K$36,7,0) -> 70 | R53: 6 | S53: =(Q53-2*J53)/R53 -> 9 | T53: =VLOOKUP($B53,$B$4:$K$36,4,0) -> 2000 | U53: =ROUNDDOWN(T53/V53,0)-1 -> 74 | V53: 26.5 | W53: =VLOOKUP($B53,$B$4:$K$36,5,0) -> 2000 | X53: =U53 -> 74 | Y53: =(W53-Z53*2)/X53 -> 26.5 | Z53: =(T53-U53*V53)/2 -> 19.5 | AA53: =L53-M53*12.5-5 -> 15.81
B54: =B19 -> 东U6 | C54: =VLOOKUP(B54,$B$4:$K$36,8,0) -> 2325 | D54: =ROUNDDOWN((C54/E54-2),0) -> 184 | E54: =12.5 -> 12.5 | F54: =C54-D54*E54-2*J54 -> 9 | G54: =VLOOKUP(B54,$B$4:$J$72,6,0) -> 50 | H54: 4 | I54: =(G54-J54*2)/H54 -> 8.5 | J54: 8 | K54: =VLOOKUP(B54,$B$4:$K$36,2,0) -> 412.691 | L54: =VLOOKUP(B54,$B$4:$K$36,3,0) -> 491.691 | M54: =ROUND((L54-5)/12.5,0)-1 -> 38 | N54: =(L54-5-P54)/M54 -> 12.597132 | O54: =(K54-P54-5)/M54 -> 10.518184 | P54: 8 | Q54: =VLOOKUP($B54,$B$4:$K$36,7,0) -> 60 | R54: 4 | S54: =(Q54-2*J54)/R54 -> 11 | T54: =VLOOKUP($B54,$B$4:$K$36,4,0) -> 2000 | U54: =ROUNDDOWN(T54/V54,0)-1 -> 71 | V54: 27.5 | W54: =VLOOKUP($B54,$B$4:$K$36,5,0) -> 2000 | X54: =U54 -> 71 | Y54: =(W54-Z54*2)/X54 -> 27.5 | Z54: =(T54-U54*V54)/2 -> 23.75 | AA54: =L54-M54*12.5-5 -> 11.691
B55: =B20 -> 东U7 | C55: =VLOOKUP(B55,$B$4:$K$36,8,0) -> 2325 | D55: =ROUNDDOWN((C55/E55-2),0) -> 184 | E55: =12.5 -> 12.5 | F55: =C55-D55*E55-2*J55 -> 9 | G55: =VLOOKUP(B55,$B$4:$J$72,6,0) -> 50 | H55: 4 | I55: =(G55-J55*2)/H55 -> 8.5 | J55: 8 | K55: =VLOOKUP(B55,$B$4:$K$36,2,0) -> 333.573 | L55: =VLOOKUP(B55,$B$4:$K$36,3,0) -> 412.573 | M55: =ROUND((L55-5)/12.5,0)-1 -> 32 | N55: =(L55-5-P55)/M55 -> 12.486656 | O55: =(K55-P55-5)/M55 -> 10.017906 | P55: 8 | Q55: =VLOOKUP($B55,$B$4:$K$36,7,0) -> 60 | R55: 4 | S55: =(Q55-2*J55)/R55 -> 11 | T55: =VLOOKUP($B55,$B$4:$K$36,4,0) -> 2000 | U55: =ROUNDDOWN(T55/V55,0)-1 -> 69 | V55: 28.5 | W55: =VLOOKUP($B55,$B$4:$K$36,5,0) -> 2000 | X55: =U55 -> 69 | Y55: =(W55-Z55*2)/X55 -> 28.5 | Z55: =(T55-U55*V55)/2 -> 16.75 | AA55: =L55-M55*12.5-5 -> 7.573
B56: =B21 -> 东U8 | C56: =VLOOKUP(B56,$B$4:$K$36,8,0) -> 2285 | D56: =ROUNDDOWN((C56/E56-1),0) -> 181 | E56: =12.5 -> 12.5 | F56: =C56-D56*E56-2*J56 -> 6.5 | G56: =VLOOKUP(B56,$B$4:$J$72,6,0) -> 30 | H56: 2 | I56: =(G56-J56*2)/H56 -> 7 | J56: 8 | K56: =VLOOKUP(B56,$B$4:$K$36,2,0) -> 254.454 | L56: =VLOOKUP(B56,$B$4:$K$36,3,0) -> 333.454 | M56: =ROUND((L56-5)/12.5,0)-1 -> 25 | N56: =(L56-5-P56)/M56 -> 12.81816 | O56: =(K56-P56-5)/M56 -> 9.65816 | P56: 8 | Q56: =VLOOKUP($B56,$B$4:$K$36,7,0) -> 40 | R56: 4 | S56: =(Q56-2*J56)/R56 -> 6 | T56: =VLOOKUP($B56,$B$4:$K$36,4,0) -> 2000 | U56: =ROUNDDOWN(T56/V56,0)-1 -> 66 | V56: 29.5 | W56: =VLOOKUP($B56,$B$4:$K$36,5,0) -> 2000 | X56: =U56 -> 66 | Y56: =(W56-Z56*2)/X56 -> 29.5 | Z56: =(T56-U56*V56)/2 -> 26.5 | AA56: =L56-M56*12.5-5 -> 15.954
...

Sheet 3.抗浮桩
B2: 名称 | D2: ='0.结构参数'!$B5 -> 西U10 | E2: ='0.结构参数'!$B6 -> 西U9 | F2: ='0.结构参数'!$B7 -> 西U8 | G2: ='0.结构参数'!$B8 -> 西U7 | H2: ='0.结构参数'!$B9 -> 西U6 | I2: ='0.结构参数'!$B10 -> 西U5 | J2: ='0.结构参数'!$B11 -> 西U4 | K2: ='0.结构参数'!$B12 -> 西U3 | L2: ='0.结构参数'!$B13 -> 西U2 | M2: ='0.结构参数'!$B14 -> 西U1 | N2: ='0.结构参数'!$B15 -> 东U1 | O2: ='0.结构参数'!$B16 -> 东U2 | P2: ='0.结构参数'!$B17 -> 东U3 | Q2: ='0.结构参数'!$B18 -> 东U4 | R2: ='0.结构参数'!$B19 -> 东U5 | S2: ='0.结构参数'!$B20 -> 东U6
B3: 节段长度 | D3: ='0.结构参数'!$D41 -> 20 | E3: ='0.结构参数'!$D42 -> 20 | F3: ='0.结构参数'!$D43 -> 20 | G3: ='0.结构参数'!$D44 -> 20 | H3: ='0.结构参数'!$D45 -> 20 | I3: ='0.结构参数'!$D46 -> 20 | J3: ='0.结构参数'!$D47 -> 20 | K3: ='0.结构参数'!$D48 -> 20 | L3: ='0.结构参数'!$D49 -> 20 | M3: ='0.结构参数'!$D50 -> 25 | N3: ='0.结构参数'!$D51 -> 8 | O3: ='0.结构参数'!$D52 -> 20 | P3: ='0.结构参数'!$D53 -> 20 | Q3: ='0.结构参数'!$D54 -> 20 | R3: ='0.结构参数'!$D55 -> 20 | S3: ='0.结构参数'!$D56 -> 20
B4: 边墙 | C4: 边墙高 | D4: =('0.结构参数'!$I41+'0.结构参数'!$J41)/2 -> 1.45563 | E4: =('0.结构参数'!$I42+'0.结构参数'!$J42)/2 -> 1.892875 | F4: =('0.结构参数'!$I43+'0.结构参数'!$J43)/2 -> 2.56948 | G4: =('0.结构参数'!$I44+'0.结构参数'!$J44)/2 -> 3.36065 | H4: =('0.结构参数'!$I45+'0.结构参数'!$J45)/2 -> 4.151815 | I4: =('0.结构参数'!$I46+'0.结构参数'!$J46)/2 -> 4.94298 | J4: =('0.结构参数'!$I47+'0.结构参数'!$J47)/2 -> 5.73415 | K4: =('0.结构参数'!$I48+'0.结构参数'!$J48)/2 -> 6.41179 | L4: =('0.结构参数'!$I49+'0.结构参数'!$J49)/2 -> 6.97556 | M4: =('0.结构参数'!$I50+'0.结构参数'!$J50)/2 -> 7.25702 | N4: =('0.结构参数'!$I51+'0.结构参数'!$J51)/2 -> 7.37547 | O4: =('0.结构参数'!$I52+'0.结构参数'!$J52)/2 -> 7.06732 | P4: =('0.结构参数'!$I53+'0.结构参数'!$J53)/2 -> 6.78347 | Q4: =('0.结构参数'!$I54+'0.结构参数'!$J54)/2 -> 6.10428 | R4: =('0.结构参数'!$I55+'0.结构参数'!$J55)/2 -> 5.3131 | S4: =('0.结构参数'!$I56+'0.结构参数'!$J56)/2 -> 4.52191
C5: 边墙宽度 | D5: ='0.结构参数'!$L41 -> 0.3 | E5: ='0.结构参数'!$L42 -> 0.3 | F5: ='0.结构参数'!$L43 -> 0.3 | G5: ='0.结构参数'!$L44 -> 0.4 | H5: ='0.结构参数'!$L45 -> 0.5 | I5: ='0.结构参数'!$L46 -> 0.6 | J5: ='0.结构参数'!$L47 -> 0.6 | K5: ='0.结构参数'!$L48 -> 0.7 | L5: ='0.结构参数'!$L49 -> 0.7 | M5: ='0.结构参数'!$L50 -> 0.7 | N5: ='0.结构参数'!$L51 -> 0.8 | O5: ='0.结构参数'!$L52 -> 0.7 | P5: ='0.结构参数'!$L53 -> 0.7 | Q5: ='0.结构参数'!$L54 -> 0.6 | R5: ='0.结构参数'!$L55 -> 0.6 | S5: ='0.结构参数'!$L56 -> 0.5
C6: 底板长度 | D6: =('0.结构参数'!$M41+'0.结构参数'!$N41)/2 -> 23.81 | E6: =('0.结构参数'!$M42+'0.结构参数'!$N42)/2 -> 23.1 | F6: =('0.结构参数'!$M43+'0.结构参数'!$N43)/2 -> 22.85 | G6: =('0.结构参数'!$M44+'0.结构参数'!$N44)/2 -> 23.05 | H6: =('0.结构参数'!$M45+'0.结构参数'!$N45)/2 -> 23.25 | I6: =('0.结构参数'!$M46+'0.结构参数'!$N46)/2 -> 23.45 | J6: =('0.结构参数'!$M47+'0.结构参数'!$N47)/2 -> 23.45 | K6: =('0.结构参数'!$M48+'0.结构参数'!$N48)/2 -> 23.65 | L6: =('0.结构参数'!$M49+'0.结构参数'!$N49)/2 -> 23.65 | M6: =('0.结构参数'!$M50+'0.结构参数'!$N50)/2 -> 23.65 | N6: =('0.结构参数'!$M51+'0.结构参数'!$N51)/2 -> 23.85 | O6: =('0.结构参数'!$M52+'0.结构参数'!$N52)/2 -> 23.65 | P6: =('0.结构参数'!$M53+'0.结构参数'!$N53)/2 -> 23.65 | Q6: =('0.结构参数'!$M54+'0.结构参数'!$N54)/2 -> 23.45 | R6: =('0.结构参数'!$M55+'0.结构参数'!$N55)/2 -> 23.45 | S6: =('0.结构参数'!$M56+'0.结构参数'!$N56)/2 -> 23.25
C7: 底板厚度 | D7: ='0.结构参数'!$K41 -> 0.4 | E7: ='0.结构参数'!$K42 -> 0.4 | F7: ='0.结构参数'!$K43 -> 0.4 | G7: ='0.结构参数'!$K44 -> 0.5 | H7: ='0.结构参数'!$K45 -> 0.6 | I7: ='0.结构参数'!$K46 -> 0.7 | J7: ='0.结构参数'!$K47 -> 0.7 | K7: ='0.结构参数'!$K48 -> 0.8 | L7: ='0.结构参数'!$K49 -> 0.8 | M7: ='0.结构参数'!$K50 -> 0.8 | N7: ='0.结构参数'!$K51 -> 0.9 | O7: ='0.结构参数'!$K52 -> 0.8 | P7: ='0.结构参数'!$K53 -> 0.8 | Q7: ='0.结构参数'!$K54 -> 0.7 | R7: ='0.结构参数'!$K55 -> 0.7 | S7: ='0.结构参数'!$K56 -> 0.6
B8: 机非分隔带 | C8: 高度 | D8: =('0.结构参数'!$T41+'0.结构参数'!$U41)/2 -> 1.65572 | E8: =('0.结构参数'!$T42+'0.结构参数'!$U42)/2 -> 1.65589 | F8: =('0.结构参数'!$T43+'0.结构参数'!$U43)/2 -> 1.60003 | G8: =('0.结构参数'!$T44+'0.结构参数'!$U44)/2 -> 1.60005 | H8: =('0.结构参数'!$T45+'0.结构参数'!$U45)/2 -> 1.600035 | I8: =('0.结构参数'!$T46+'0.结构参数'!$U46)/2 -> 1.60001 | J8: =('0.结构参数'!$T47+'0.结构参数'!$U47)/2 -> 1.63162 | K8: =('0.结构参数'!$T48+'0.结构参数'!$U48)/2 -> 1.6895 | L8: =('0.结构参数'!$T49+'0.结构参数'!$U499)/2 -> 1.10788 | M8: =('0.结构参数'!$T50+'0.结构参数'!$U50)/2 -> 1.964435 | N8: =('0.结构参数'!$T51+'0.结构参数'!$U51)/2 -> 2.32131 | O8: =('0.结构参数'!$T52+'0.结构参数'!$U52)/2 -> 1.954065 | P8: =('0.结构参数'!$T53+'0.结构参数'!$U53)/2 -> 1.746355 | Q8: =('0.结构参数'!$T54+'0.结构参数'!$U54)/2 -> 1.648985 | R8: =('0.结构参数'!$T55+'0.结构参数'!$U55)/2 -> 1.6 | S8: =('0.结构参数'!$T56+'0.结构参数'!$U56)/2 -> 1.6
C9: 厚度 | D9: =('0.结构参数'!$V41+'0.结构参数'!$W41)/2 -> 0.45 | E9: =('0.结构参数'!$V42+'0.结构参数'!$W42)/2 -> 0.45 | F9: =('0.结构参数'!$V43+'0.结构参数'!$W43)/2 -> 0.45 | G9: =('0.结构参数'!$V44+'0.结构参数'!$W44)/2 -> 0.45 | H9: =('0.结构参数'!$V45+'0.结构参数'!$W45)/2 -> 0.45 | I9: =('0.结构参数'!$V46+'0.结构参数'!$W46)/2 -> 0.45 | J9: =('0.结构参数'!$V47+'0.结构参数'!$W47)/2 -> 0.45 | K9: =('0.结构参数'!$V48+'0.结构参数'!$W48)/2 -> 0.45 | L9: =('0.结构参数'!$V49+'0.结构参数'!$W49)/2 -> 0.45 | M9: =('0.结构参数'!$V50+'0.结构参数'!$W50)/2 -> 0.45 | N9: =('0.结构参数'!$V51+'0.结构参数'!$W51)/2 -> 0.45 | O9: =('0.结构参数'!$V52+'0.结构参数'!$W52)/2 -> 0.45 | P9: =('0.结构参数'!$V53+'0.结构参数'!$W53)/2 -> 0.45 | Q9: =('0.结构参数'!$V54+'0.结构参数'!$W54)/2 -> 0.45 | R9: =('0.结构参数'!$V55+'0.结构参数'!$W55)/2 -> 0.45 | S9: =('0.结构参数'!$V56+'0.结构参数'!$W56)/2 -> 0.45
B10: 中分带 | C10: 高度 | D10: =('0.结构参数'!$O41+'0.结构参数'!$P41)/2 -> 1.358185 | E10: =('0.结构参数'!$O42+'0.结构参数'!$P42)/2 -> 1.447235 | F10: =('0.结构参数'!$O43+'0.结构参数'!$P43)/2 -> 1.62309 | G10: =('0.结构参数'!$O44+'0.结构参数'!$P44)/2 -> 1.91351 | H10: =('0.结构参数'!$O45+'0.结构参数'!$P45)/2 -> 2.203925 | I10: =('0.结构参数'!$O46+'0.结构参数'!$P46)/2 -> 2.49434 | J10: =('0.结构参数'!$O47+'0.结构参数'!$P47)/2 -> 2.78476 | K10: =('0.结构参数'!$O48+'0.结构参数'!$P48)/2 -> 2.96165 | L10: =('0.结构参数'!$O49+'0.结构参数'!$P49)/2 -> 3.072595 | M10: =('0.结构参数'!$O50+'0.结构参数'!$P50)/2 -> 3.05505 | N10: =('0.结构参数'!$O51+'0.结构参数'!$P51)/2 -> 3.32825 | O10: =('0.结构参数'!$O52+'0.结构参数'!$P52)/2 -> 3.13865 | P10: =('0.结构参数'!$O53+'0.结构参数'!$P53)/2 -> 3.013185 | Q10: =('0.结构参数'!$O54+'0.结构参数'!$P54)/2 -> 2.83436 | R10: =('0.结构参数'!$O55+'0.结构参数'!$P55)/2 -> 2.54393 | S10: =('0.结构参数'!$O56+'0.结构参数'!$P56)/2 -> 2.25349
C11: 厚度 | D11: =('0.结构参数'!$Q41+'0.结构参数'!$R41)/2 -> 1.75 | E11: =('0.结构参数'!$Q42+'0.结构参数'!$R42)/2 -> 1.75 | F11: =('0.结构参数'!$Q43+'0.结构参数'!$R43)/2 -> 1.75 | G11: =('0.结构参数'!$Q44+'0.结构参数'!$R44)/2 -> 1.75 | H11: =('0.结构参数'!$Q45+'0.结构参数'!$R45)/2 -> 1.75 | I11: =('0.结构参数'!$Q46+'0.结构参数'!$R46)/2 -> 1.75 | J11: =('0.结构参数'!$Q47+'0.结构参数'!$R47)/2 -> 1.75 | K11: =('0.结构参数'!$Q48+'0.结构参数'!$R48)/2 -> 1.75 | L11: =('0.结构参数'!$Q49+'0.结构参数'!$R49)/2 -> 1.75 | M11: =('0.结构参数'!$Q50+'0.结构参数'!$R50)/2 -> 1.75 | N11: =('0.结构参数'!$Q51+'0.结构参数'!$R51)/2 -> 1.75 | O11: =('0.结构参数'!$Q52+'0.结构参数'!$R52)/2 -> 1.75 | P11: =('0.结构参数'!$Q53+'0.结构参数'!$R53)/2 -> 1.75 | Q11: =('0.结构参数'!$Q54+'0.结构参数'!$R54)/2 -> 1.75 | R11: =('0.结构参数'!$Q55+'0.结构参数'!$R55)/2 -> 1.75 | S11: =('0.结构参数'!$Q56+'0.结构参数'!$R56)/2 -> 1.75
B12: 自重 | C12: 系数 | D12: 0.9 | E12: 0.9 | F12: 0.9 | G12: 0.9 | H12: 0.9 | I12: 0.9 | J12: 0.9 | K12: 0.9 | L12: 0.9 | M12: 0.9 | N12: 0.9 | O12: 0.9 | P12: 0.9 | Q12: 0.9 | R12: 0.9 | S12: 0.9
C13: 结构自重 | D13: =(D4*D5*2+D6*D7+D8*D9*2+D10*D11*2)*D3*25*D12 -> 7488.5281 | E13: =(E4*E5*2+E6*E7+E8*E9*2+E10*E11*2)*E3*25*E12 -> 7619.1068 | F13: =(F4*F5*2+F6*F7+F8*F9*2+F10*F11*2)*F3*25*F12 -> 8011.1385 | G13: =(G4*G5*2+G6*G7+G8*G9*2+G10*G11*2)*G3*25*G12 -> 10057.882 | H13: =(H4*H5*2+H6*H7+H8*H9*2+H10*H11*2)*H3*25*H12 -> 12265.013 | I13: =(I4*I5*2+I6*I7+I8*I9*2+I10*I11*2)*I3*25*I12 -> 14632.549 | J13: =(J4*J5*2+J6*J7+J8*J9*2+J10*J11*2)*J3*25*J12 -> 15529.994 | K13: =(K4*K5*2+K6*K7+K8*K9*2+K10*K11*2)*K3*25*K12 -> 17902.274 | ... S13: =(S4*S5*2+S6*S7+S8*S9*2+S10*S11*2)*S3*25*S12 -> 12509.606
B14: 浮力 | C14: 水位高度 | D14: =D4-1.2 -> 0.25563 | E14: =E4-1.2 -> 0.692875 | F14: =F4-1.2 -> 1.36948 | G14: =G4-1.2 -> 2.16065 | H14: =H4-1.2 -> 2.951815 | I14: =I4-1.2 -> 3.74298 | J14: =J4-1.2 -> 4.53415 | K14: =K4-1.2 -> 5.21179 | ... S14: =S4-1.2 -> 3.32191
C15: 计算宽度 | D15: =D6 -> 23.81 | E15: =E6 -> 23.1 | F15: =F6 -> 22.85 | G15: =G6 -> 23.05 | H15: =H6 -> 23.25 | I15: =I6 -> 23.45 | J15: =J6 -> 23.45 | K15: =K6 -> 23.65 | ... S15: =S6 -> 23.25
C16: 系数 | D16: 1.2 | E16: 1.2 | F16: 1.2 | G16: 1.2 | H16: 1.2 | I16: 1.2 | J16: 1.2 | K16: 1.2 | L16: 1.2 | M16: 1.2 | N16: 1.2 | O16: 1.2 | P16: 1.2 | Q16: 1.2 | R16: 1.2 | S16: 1.2
C17: 浮力 | D17: =D14*D15*D3*10*D16 -> 1460.7721 | E17: =E14*E15*E3*10*E16 -> 3841.299 | F17: =F14*F15*F3*10*F16 -> 7510.2283 | G17: =G14*G15*G3*10*G16 -> 11952.716 | H17: =H14*H15*H3*10*H16 -> 16471.128 | I17: =I14*I15*I3*10*I16 -> 21065.491 | J17: =J14*J15*J3*10*J16 -> 25518.196 | K17: =K14*K15*K3*10*K16 -> 29582.12 | ... S17: =S14*S15*S3*10*S16 -> 18536.258
B18: 是否需要设抗浮桩 | D18: =IF(D17>D13,"YES","NO") -> NO | E18: =IF(E17>E13,"YES","NO") -> NO | F18: =IF(F17>F13,"YES","NO") -> NO | G18: =IF(G17>G13,"YES","NO") -> YES | H18: =IF(H17>H13,"YES","NO") -> YES | I18: =IF(I17>I13,"YES","NO") -> YES | J18: =IF(J17>J13,"YES","NO") -> YES | K18: =IF(K17>K13,"YES","NO") -> YES | ... S18: =IF(S17>S13,"YES","NO") -> YES
B19: 桩长 | D19: 15 | E19: 15 | F19: 15 | G19: 15 | H19: 15 | I19: 15 | J19: 15 | K19: 15 | L19: 15 | M19: 15 | N19: 15 | O19: 15 | P19: 15 | Q19: 15 | R19: 15 | S19: 15
B20: 桩径 | D20: 1 | E20: 1 | F20: 1 | G20: 1 | H20: 1 | I20: 1 | J20: 1 | K20: 1 | L20: 1 | M20: 1 | N20: 1 | O20: 1 | P20: 1 | Q20: 1 | R20: 1 | S20: 1
