Workbook
Name _P1: [1]钢轨桩计算!$C$10
Name _P1: [2]钢轨桩计算!$C$10
Name D0: [2]钢轨桩计算!$H$25
Name D0: [1]钢轨桩计算!$H$25
Name D0: [3]钢轨桩计算!$H$25
Name gj: #REF!
Name gjzj: #REF!
Name H: [2]钢轨桩计算!$C$2
Name H: [1]钢轨桩计算!$C$2
Name H: [3]钢轨桩计算!$C$2
Name jd: SIN(RADIANS([3]框架结构!$B$2))
Name name: [4]工字钢数据!$A$2:$A$3
Name subject: [4]工字钢数据!$B$1:$C$1
Name x: [5]后背钢轨桩计算!$J$16
Name y: [2]钢轨桩计算!$D$17
Name y: [1]钢轨桩计算!$D$17
Name y: [3]钢轨桩计算!$D$17
Name γ: [1]钢轨桩计算!$C$5
Name γ: [2]钢轨桩计算!$C$5
Name θ: [1]钢轨桩计算!$C$8
Name θ: [2]钢轨桩计算!$C$8
Name λ: [1]钢轨桩计算!$C$9
Name λ: [2]钢轨桩计算!$C$9
Name σh: [2]钢轨桩计算!$C$11
Name σh: [1]钢轨桩计算!$C$11
Name σh: [3]钢轨桩计算!$C$11
Name φ: [1]钢轨桩计算!$C$6
Name φ: [2]钢轨桩计算!$C$6
Name 边墙厚度: [3]框架结构!$C$10
Name 打入工作坑以下H: [2]钢轨桩计算!$C$3
Name 打入工作坑以下H: [1]钢轨桩计算!$C$3
Name 打入工作坑以下H: [3]钢轨桩计算!$C$3
Name 底板厚度: [3]框架结构!$C$9
Name 第1页________共1页: #REF!
Name 顶板厚度: [3]框架结构!$C$8
Name 钢筋直径: #REF!
Name 钢筋直径: #REF!
Name 钢筋直径: #REF!
Name 工字钢长度H: [1]钢轨桩计算!$C$2
Name 工字钢长度H: [2]钢轨桩计算!$C$2
Name 工作坑底面以上主动土动力P1: [1]钢轨桩计算!$C$10
Name 工作坑底面以上主动土动力P1: [2]钢轨桩计算!$C$10
Name 结构净高: [3]框架结构!$C$7
Name 结构总高: [3]框架结构!$C$4
Name 结构总宽: [3]框架结构!$C$3
Name 孔数: [2]框架结构!$F$1
Name 孔数: [1]框架结构!$F$1
Name 孔数: [3]框架结构!$F$1
Name 面坡斜度: #REF!
Name 内摩擦角φ: [1]钢轨桩计算!$C$6
Name 内摩擦角φ: [2]钢轨桩计算!$C$6
Name 破裂角θ: [1]钢轨桩计算!$C$8
Name 破裂角θ: [2]钢轨桩计算!$C$8
Name 刃角长度: [3]框架结构!$D$17
Name 填土高度h: [1]钢轨桩计算!$C$4
Name 填土高度h: [2]钢轨桩计算!$C$4
Name 土容重γ: [1]钢轨桩计算!$C$5
Name 土容重γ: [2]钢轨桩计算!$C$5
Name 推力系数λ: [1]钢轨桩计算!$C$9
Name 推力系数λ: [2]钢轨桩计算!$C$9

Sheet 0.结构参数
B2: 一、从CAD中读取平面、纵断面原始数据 单位：m
A3: 序号 | B3: U型槽编号 | C3: 里程L | E3: L | G3: 顶高程E1 | I3: 底板顶高程E2 | K3: 机非分隔带 | P3: 中央分隔带 | U3: 水位高程E5 | V3: 净宽
K4: 高程E3 | M4: 宽度b1 | O4: 数量 | P4: 高程E4 | R4: 宽度b2 | T4: 数量
A5: 1 | B5: ZU1-1 | C5: 109.94 | D5: 129.94 | E5: =ABS(D5-C5) -> 20 | F5: =E5 -> 20 | G5: 3.61863 | H5: 3.348 | I5: 1.82747 | J5: 1.23285 | K5: 3.42747 | L5: 2.98771 | M5: 1.75 | N5: 1.75 | O5: 0 | P5: 3.42747 | Q5: 2.98307 | R5: 0.45 | S5: 0.45 | T5: 0 | U5: 3.1 | V5: 12.5 | W5: 12.5
A6: 2 | B6: ZU2-1 | C6: 129.97 | D6: 149.97 | E6: =ABS(D6-C6) -> 20 | F6: =E6 -> 20 | G6: 3.348 | H6: 3.348 | I6: 1.23196 | J6: 0.63735 | K6: 2.98696 | L6: 2.48696 | M6: 1.75 | N6: 1.75 | O6: 0 | P6: 2.98226 | Q6: 2.33755 | R6: 0.45 | S6: 0.45 | T6: 0 | U6: 3.1 | V6: 12.5 | W6: 12.5
A7: 3 | B7: ZU3-1 | C7: 150 | D7: 170 | E7: =ABS(D7-C7) -> 20 | F7: =E7 -> 20 | G7: 3.348 | H7: 3.348 | I7: 0.63646 | J7: 0.04185 | K7: 2.48621 | L7: 1.98621 | M7: 1.75 | N7: 1.75 | O7: 0 | P7: 2.33644 | Q7: 1.5515 | R7: 0.45 | S7: 0.45 | T7: 0 | U7: 3.1 | V7: 12.5 | W7: 12.5
A8: 4 | B8: ZU4-1 | C8: 170.03 | D8: 190.03 | E8: =ABS(D8-C8) -> 20 | F8: =E8 -> 20 | G8: 3.348 | H8: 3.348 | I8: 0.04096 | J8: -0.55365 | K8: 1.98546 | L8: 1.48546 | M8: 1.75 | N8: 1.75 | O8: 0 | P8: 1.55032 | Q8: 0.76032 | R8: 0.45 | S8: 0.45 | T8: 0 | U8: 3.1 | V8: 12.5 | W8: 12.5
A9: 5 | B9: ZU5-1 | C9: 190.06 | D9: 210.06 | E9: =ABS(D9-C9) -> 20 | F9: =E9 -> 20 | G9: 3.348 | H9: 3.348 | I9: -0.55455 | J9: -1.14916 | K9: 1.48471 | L9: 0.98471 | M9: 1.75 | N9: 1.75 | O9: 0 | P9: 0.75913 | Q9: -0.03087 | R9: 0.45 | S9: 0.45 | T9: 0 | U9: 3.1 | V9: 12.5 | W9: 12.5
A10: 6 | B10: ZU6-1 | C10: 210.09 | D10: 230.09 | E10: =ABS(D10-C10) -> 20 | F10: =E10 -> 20 | G10: 3.348 | H10: 3.348 | I10: -1.15032 | J10: -1.928 | K10: 0.98396 | L10: 0.48396 | M10: 1.75 | N10: 1.75 | O10: 0 | P10: -0.03205 | Q10: -0.82205 | R10: 0.45 | S10: 0.45 | T10: 0 | U10: 3.1 | V10: 12.5 | W10: 12.5
A11: 7 | B11: ZU7-1 | C11: 230.12 | D11: 250.12 | E11: =ABS(D11-C11) -> 20 | F11: =E11 -> 20 | G11: 3.348 | H11: 3.348 | I11: -1.92917 | J11: -2.70684 | K11: 0.48321 | L11: -0.01679 | M11: 1.75 | N11: 1.75 | O11: 0 | P11: -0.82324 | Q11: -1.58337 | R11: 0.45 | S11: 0.45 | T11: 0 | U11: 3.1 | V11: 12.5 | W11: 12.5
A12: 8 | B12: ZU8-1 | C12: 250.15 | D12: 270.15 | E12: =ABS(D12-C12) -> 20 | F12: =E12 -> 20 | G12: 3.348 | H12: 3.348 | I12: -2.70774 | J12: -3.30793 | K12: -0.01754 | L12: -0.51754 | M12: 1.75 | N12: 1.75 | O12: 0 | P12: -1.58438 | Q12: -2.14772 | R12: 0.45 | S12: 0.45 | T12: 0 | U12: 3.1 | V12: 12.5 | W12: 12.5
A13: 9 | B13: ZU9-1 | C13: 270.18 | D13: 290.18 | E13: =ABS(D13-C13) -> 20 | F13: =E13 -> 20 | G13: 3.348 | H13: 3.348 | I13: -3.30883 | J13: -3.90902 | K13: -0.51829 | L13: -0.91873 | M13: 1.75 | N13: 1.75 | O13: 0 | P13: -2.14839 | Q13: -2.48918 | R13: 0.45 | S13: 0.45 | T13: 0 | U13: 3.1 | V13: 12.5 | W13: 12.5
A14: 10 | B14: ZU10-1 | C14: 290.21 | D14: 310.21 | E14: =ABS(D14-C14) -> 20 | F14: =E14 -> 20 | G14: 3.348 | H14: 3.348 | I14: -3.90902 | J14: -3.90902 | K14: -0.91918 | L14: -1.11933 | M14: 1.75 | N14: 1.75 | O14: 0 | P14: -2.48952 | Q14: -2.60775 | R14: 0.45 | S14: 0.45 | T14: 0 | U14: 3.1 | V14: 12.5 | W14: 12.5
A15: 11 | B15: ZU11-1 | C15: 429.29 | D15: 449.29 | E15: =ABS(D15-C15) -> 20 | F15: =E15 -> 20 | G15: 3.348 | H15: 3.348 | I15: -4.252 | J15: -3.62343 | K15: -0.8262 | L15: -0.73194 | M15: 1.75 | N15: 1.75 | O15: 0 | P15: -2.26064 | Q15: -2.14511 | R15: 0.45 | S15: 0.45 | T15: 0 | U15: 3.1 | V15: 12.5 | W15: 12.5
A16: 12 | B16: ZU12-1 | C16: 449.32 | D16: 469.32 | E16: =ABS(D16-C16) -> 20 | F16: =E16 -> 20 | G16: 3.348 | H16: 3.348 | I16: -3.62249 | J16: -2.99392 | K16: -0.73167 | L16: -0.45429 | M16: 1.75 | N16: 1.75 | O16: 0 | P16: -2.14478 | Q16: -1.81623 | R16: 0.45 | S16: 0.45 | T16: 0 | U16: 3.1 | V16: 12.5 | W16: 12.5
... A31: 27 | B31: 西U2-1 | C31: 271.8991 | D31: 291.8991 | E31: =ABS(D31-C31) -> 20 | F31: =E31 -> 20 | G31: 3.348 | H31: 3.348 | I31: -3.3461 | J31: -3.90902 | K31: -0.55289 | L31: -0.95704 | M31: 1.75 | N31: 1.75 | O31: 1 | P31: -2.13034 | Q31: -2.41868 | R31: 0.45 | S31: 0.45 | T31: 0 | U31: 3.1 | V31: 28.29 | W31: 22.25
A32: 28 | B32: 西U6-2 | C32: 191.7791 | D32: 211.7791 | E32: 20 | F32: 20 | G32: 3.348 | H32: 3.348 | I32: -0.40882 | J32: -1.19881 | K32: 1.45011 | L32: 0.95011 | M32: 1.75 | N32: 1.75 | O32: 0 | P32: 0.69122 | Q32: -0.09878 | R32: 0.45 | S32: 0.45 | T32: 0 | U32: 3.1 | V32: 8 | W32: 9.09
A33: 29 | B33: 西U5-2 | C33: 211.8091 | D33: 231.8091 | E33: 20 | F33: 20 | G33: 3.348 | H33: 3.348 | I33: -1.19999 | J33: -1.98997 | K33: 0.94936 | L33: 0.44936 | M33: 1.75 | N33: 1.75 | O33: 0 | P33: -0.09997 | Q33: -0.88997 | R33: 0.45 | S33: 0.45 | T33: 0 | U33: 3.1 | V33: 9.09 | W33: 8
A34: 30 | B34: 西U4-2 | C34: 231.8391 | D34: 251.8391 | E34: 20 | F34: 20 | G34: 3.348 | H34: 3.348 | I34: -1.99116 | J34: -2.78114 | K34: 0.44861 | L34: -0.05139 | M34: 1.75 | N34: 1.75 | O34: 0 | P34: -0.89115 | Q34: -1.61791 | R34: 0.45 | S34: 0.45 | T34: 0 | U34: 3.1 | V34: 8 | W34: 8
A35: 31 | B35: 西U3-2 | C35: 251.8691 | D35: 271.8691 | E35: 20 | F35: 20 | G35: 3.348 | H35: 3.348 | I35: -2.78233 | J35: -3.34525 | K35: -0.05214 | L35: -0.55214 | M35: 1.75 | N35: 1.75 | O35: 0 | P35: -1.61884 | Q35: -2.12974 | R35: 0.45 | S35: 0.45 | T35: 0 | U35: 3.1 | V35: 8 | W35: 14.06
A36: 32
X37: =SUM(X5:X36) -> 0
B38: 二、命名并形成U型槽结构参数表 单位：m
A39: U型槽编号 | B39: 起讫点里程 | D39: 中心长度L | E39: 顶高程E1 | G39: 底板顶高程E2 | I39: 结构净高H | K39: 底板厚T | L39: 边墙厚B | M39: D | O39: 机非分隔带 | U39: 中央分隔带
O40: 高度h1 | Q40: 宽度b1 | S40: 数量 | T40: 高度h2 | V40: 宽度b2 | X40: 数量
A41: =B5 -> ZU1-1 | B41: =C5 -> 109.94 | C41: =D5 -> 129.94 | D41: =ABS(C41-B41) -> 20 | E41: =G5 -> 3.61863 | F41: =H5 -> 3.348 | G41: =I5 -> 1.82747 | H41: =J5 -> 1.23285 | I41: =E41-G41 -> 1.79116 | J41: =F41-H41 -> 2.11515 | K41: =L41+0.1 -> 0.4 | L41: =LOOKUP(MAX(J41,I41),{0,3,4,5,6.5,7.5,9,10},{0.3,0.4,0.5,0.6,0.7,0.8,0.9}) -> 0.3 | M41: =V5+L41*2 -> 13.1 | N41: =W5+L41*2 -> 13.1 | O41: =K5-I5+0.2 -> 1.8 | P41: =L5-J5+0.2 -> 1.95486 | Q41: =M5 -> 1.75 | R41: =N5 -> 1.75 | S41: =O5 -> 0 | T41: =P5-I5+1 -> 2.6 | U41: =Q5-J5+1 -> 2.75022 | V41: =R5 -> 0.45 | W41: =S5 -> 0.45 | X41: =T5 -> 0 | Y41: =(O41+P41)/2*Q41*S41 -> 0 | Z41: =(T41+U41)/2*V41*X41 -> 0
A42: =B6 -> ZU2-1 | B42: =C6 -> 129.97 | C42: =D6 -> 149.97 | D42: =ABS(C42-B42) -> 20 | E42: =G6 -> 3.348 | F42: =H6 -> 3.348 | G42: =I6 -> 1.23196 | H42: =J6 -> 0.63735 | I42: =E42-G42 -> 2.11604 | J42: =F42-H42 -> 2.71065 | K42: =L42+0.1 -> 0.4 | L42: =LOOKUP(MAX(J42,I42),{0,3,4,5,6.5,7.5,9,10},{0.3,0.4,0.5,0.6,0.7,0.8,0.9}) -> 0.3 | M42: =V6+L42*2 -> 13.1 | N42: =W6+L42*2 -> 13.1 | O42: =K6-I6+0.2 -> 1.955 | P42: =L6-J6+0.2 -> 2.04961 | Q42: =M6 -> 1.75 | R42: =N6 -> 1.75 | S42: =O6 -> 0 | T42: =P6-I6+1 -> 2.7503 | U42: =Q6-J6+1 -> 2.7002 | V42: =R6 -> 0.45 | W42: =S6 -> 0.45 | X42: =T6 -> 0 | Y42: =(O42+P42)/2*Q42*S42 -> 0 | Z42: =(T42+U42)/2*V42*X42 -> 0
A43: =B7 -> ZU3-1 | B43: =C7 -> 150 | C43: =D7 -> 170 | D43: =ABS(C43-B43) -> 20 | E43: =G7 -> 3.348 | F43: =H7 -> 3.348 | G43: =I7 -> 0.63646 | H43: =J7 -> 0.04185 | I43: =E43-G43 -> 2.71154 | J43: =F43-H43 -> 3.30615 | K43: =L43+0.1 -> 0.5 | L43: =LOOKUP(MAX(J43,I43),{0,3,4,5,6.5,7.5,9,10},{0.3,0.4,0.5,0.6,0.7,0.8,0.9}) -> 0.4 | M43: =V7+L43*2 -> 13.3 | N43: =W7+L43*2 -> 13.3 | O43: =K7-I7+0.2 -> 2.04975 | P43: =L7-J7+0.2 -> 2.14436 | Q43: =M7 -> 1.75 | R43: =N7 -> 1.75 | S43: =O7 -> 0 | T43: =P7-I7+1 -> 2.69998 | U43: =Q7-J7+1 -> 2.50965 | V43: =R7 -> 0.45 | W43: =S7 -> 0.45 | X43: =T7 -> 0 | Y43: =(O43+P43)/2*Q43*S43 -> 0 | Z43: =(T43+U43)/2*V43*X43 -> 0
A44: =B8 -> ZU4-1 | B44: =C8 -> 170.03 | C44: =D8 -> 190.03 | D44: =ABS(C44-B44) -> 20 | E44: =G8 -> 3.348 | F44: =H8 -> 3.348 | G44: =I8 -> 0.04096 | H44: =J8 -> -0.55365 | I44: =E44-G44 -> 3.30704 | J44: =F44-H44 -> 3.90165 | K44: =L44+0.1 -> 0.5 | L44: =LOOKUP(MAX(J44,I44),{0,3,4,5,6.5,7.5,9,10},{0.3,0.4,0.5,0.6,0.7,0.8,0.9}) -> 0.4 | M44: =V8+L44*2 -> 13.3 | N44: =W8+L44*2 -> 13.3 | O44: =K8-I8+0.2 -> 2.1445 | P44: =L8-J8+0.2 -> 2.23911 | Q44: =M8 -> 1.75 | R44: =N8 -> 1.75 | S44: =O8 -> 0 | T44: =P8-I8+1 -> 2.50936 | U44: =Q8-J8+1 -> 2.31397 | V44: =R8 -> 0.45 | W44: =S8 -> 0.45 | X44: =T8 -> 0 | Y44: =(O44+P44)/2*Q44*S44 -> 0 | Z44: =(T44+U44)/2*V44*X44 -> 0
A45: =B9 -> ZU5-1 | B45: =C9 -> 190.06 | C45: =D9 -> 210.06 | D45: =ABS(C45-B45) -> 20 | E45: =G9 -> 3.348 | F45: =H9 -> 3.348 | G45: =I9 -> -0.55455 | H45: =J9 -> -1.14916 | I45: =E45-G45 -> 3.90255 | J45: =F45-H45 -> 4.49716 | K45: =L45+0.1 -> 0.6 | L45: =LOOKUP(MAX(J45,I45),{0,3,4,5,6.5,7.5,9,10},{0.3,0.4,0.5,0.6,0.7,0.8,0.9}) -> 0.5 | M45: =V9+L45*2 -> 13.5 | N45: =W9+L45*2 -> 13.5 | O45: =K9-I9+0.2 -> 2.23926 | P45: =L9-J9+0.2 -> 2.33387 | Q45: =M9 -> 1.75 | R45: =N9 -> 1.75 | S45: =O9 -> 0 | T45: =P9-I9+1 -> 2.31368 | U45: =Q9-J9+1 -> 2.11829 | V45: =R9 -> 0.45 | W45: =S9 -> 0.45 | X45: =T9 -> 0 | Y45: =(O45+P45)/2*Q45*S45 -> 0 | Z45: =(T45+U45)/2*V45*X45 -> 0
A46: =B10 -> ZU6-1 | B46: =C10 -> 210.09 | C46: =D10 -> 230.09 | D46: =ABS(C46-B46) -> 20 | E46: =G10 -> 3.348 | F46: =H10 -> 3.348 | G46: =I10 -> -1.15032 | H46: =J10 -> -1.928 | I46: =E46-G46 -> 4.49832 | J46: =F46-H46 -> 5.276 | K46: =L46+0.1 -> 0.7 | L46: =LOOKUP(MAX(J46,I46),{0,3,4,5,6.5,7.5,9,10},{0.3,0.4,0.5,0.6,0.7,0.8,0.9}) -> 0.6 | M46: =V10+L46*2 -> 13.7 | N46: =W10+L46*2 -> 13.7 | O46: =K10-I10+0.2 -> 2.33428 | P46: =L10-J10+0.2 -> 2.61196 | Q46: =M10 -> 1.75 | R46: =N10 -> 1.75 | S46: =O10 -> 0 | T46: =P10-I10+1 -> 2.11827 | U46: =Q10-J10+1 -> 2.10595 | V46: =R10 -> 0.45 | W46: =S10 -> 0.45 | X46: =T10 -> 0 | Y46: =(O46+P46)/2*Q46*S46 -> 0 | Z46: =(T46+U46)/2*V46*X46 -> 0
A47: =B11 -> ZU7-1 | B47: =C11 -> 230.12 | C47: =D11 -> 250.12 | D47: =ABS(C47-B47) -> 20 | E47: =G11 -> 3.348 | F47: =H11 -> 3.348 | G47: =I11 -> -1.92917 | H47: =J11 -> -2.70684 | I47: =E47-G47 -> 5.27717 | J47: =F47-H47 -> 6.05484 | K47: =L47+0.1 -> 0.6 | L47: 0.5 | M47: =V11+L47*2 -> 13.5 | N47: =W11+L47*2 -> 13.5 | O47: =K11-I11+0.2 -> 2.61238 | P47: =L11-J11+0.2 -> 2.89005 | Q47: =M11 -> 1.75 | R47: =N11 -> 1.75 | S47: =O11 -> 0 | T47: =P11-I11+1 -> 2.10593 | U47: =Q11-J11+1 -> 2.12347 | V47: =R11 -> 0.45 | W47: =S11 -> 0.45 | X47: =T11 -> 0 | Y47: =(O47+P47)/2*Q47*S47 -> 0 | Z47: =(T47+U47)/2*V47*X47 -> 0
A48: =B12 -> ZU8-1 | B48: =C12 -> 250.15 | C48: =D12 -> 270.15 | D48: =ABS(C48-B48) -> 20 | E48: =G12 -> 3.348 | F48: =H12 -> 3.348 | G48: =I12 -> -2.70774 | H48: =J12 -> -3.30793 | I48: =E48-G48 -> 6.05574 | J48: =F48-H48 -> 6.65593 | K48: =L48+0.1 -> 0.8 | L48: =LOOKUP(MAX(J48,I48),{0,3,4,5,6.5,7.5,9,10},{0.3,0.4,0.5,0.6,0.7,0.8,0.9}) -> 0.7 | M48: =V12+L48*2 -> 13.9 | N48: =W12+L48*2 -> 13.9 | O48: =K12-I12+0.2 -> 2.8902 | P48: =L12-J12+0.2 -> 2.99039 | Q48: =M12 -> 1.75 | R48: =N12 -> 1.75 | S48: =O12 -> 0 | T48: =P12-I12+1 -> 2.12336 | U48: =Q12-J12+1 -> 2.16021 | V48: =R12 -> 0.45 | W48: =S12 -> 0.45 | X48: =T12 -> 0 | Y48: =(O48+P48)/2*Q48*S48 -> 0 | Z48: =(T48+U48)/2*V48*X48 -> 0
A49: =B13 -> ZU9-1 | B49: =C13 -> 270.18 | C49: =D13 -> 290.18 | D49: =ABS(C49-B49) -> 20 | E49: =G13 -> 3.348 | F49: =H13 -> 3.348 | G49: =I13 -> -3.30883 | H49: =J13 -> -3.90902 | I49: =E49-G49 -> 6.65683 | J49: =F49-H49 -> 7.25702 | K49: =L49+0.1 -> 0.8 | L49: =LOOKUP(MAX(J49,I49),{0,3,4,5,6.5,7.5,9,10},{0.3,0.4,0.5,0.6,0.7,0.8,0.9}) -> 0.7 | M49: =V13+L49*2 -> 13.9 | N49: =W13+L49*2 -> 13.9 | O49: =K13-I13+0.2 -> 2.99054 | P49: =L13-J13+0.2 -> 3.19029 | Q49: =M13 -> 1.75 | R49: =N13 -> 1.75 | S49: =O13 -> 0 | T49: =P13-I13+1 -> 2.16044 | U49: =Q13-J13+1 -> 2.41984 | V49: =R13 -> 0.45 | W49: =S13 -> 0.45 | X49: =T13 -> 0 | Y49: =(O49+P49)/2*Q49*S49 -> 0 | Z49: =(T49+U49)/2*V49*X49 -> 0
A50: =B14 -> ZU10-1 | B50: =C14 -> 290.21 | C50: =D14 -> 310.21 | D50: =ABS(C50-B50) -> 20 | E50: =G14 -> 3.348 | F50: =H14 -> 3.348 | G50: =I14 -> -3.90902 | H50: =J14 -> -3.90902 | I50: =E50-G50 -> 7.25702 | J50: =F50-H50 -> 7.25702 | K50: =L50+0.1 -> 0.8 | L50: =LOOKUP(MAX(J50,I50),{0,3,4,5,6.5,7.5,9,10},{0.3,0.4,0.5,0.6,0.7,0.8,0.9}) -> 0.7 | M50: =V14+L50*2 -> 13.9 | N50: =W14+L50*2 -> 13.9 | O50: =K14-I14+0.2 -> 3.18984 | P50: =L14-J14+0.2 -> 2.98969 | Q50: =M14 -> 1.75 | R50: =N14 -> 1.75 | S50: =O14 -> 0 | T50: =P14-I14+1 -> 2.4195 | U50: =Q14-J14+1 -> 2.30127 | V50: =R14 -> 0.45 | W50: =S14 -> 0.45 | X50: =T14 -> 0 | Y50: =(O50+P50)/2*Q50*S50 -> 0 | Z50: =(T50+U50)/2*V50*X50 -> 0
A51: =B15 -> ZU11-1 | B51: =C15 -> 429.29 | C51: =D15 -> 449.29 | D51: =ABS(C51-B51) -> 20 | E51: =G15 -> 3.348 | F51: =H15 -> 3.348 | G51: =I15 -> -4.252 | H51: =J15 -> -3.62343 | I51: =E51-G51 -> 7.6 | J51: =F51-H51 -> 6.97143 | K51: =L51+0.1 -> 0.9 | L51: =LOOKUP(MAX(J51,I51),{0,3,4,5,6.5,7.5,9,10},{0.3,0.4,0.5,0.6,0.7,0.8,0.9}) -> 0.8 | M51: =V15+L51*2 -> 14.1 | N51: =W15+L51*2 -> 14.1 | O51: =K15-I15+0.2 -> 3.6258 | P51: =L15-J15+0.2 -> 3.09149 | Q51: =M15 -> 1.75 | R51: =N15 -> 1.75 | S51: =O15 -> 0 | T51: =P15-I15+1 -> 2.99136 | U51: =Q15-J15+1 -> 2.47832 | V51: =R15 -> 0.45 | W51: =S15 -> 0.45 | X51: =T15 -> 0 | Y51: =(O51+P51)/2*Q51*S51 -> 0 | Z51: =(T51+U51)/2*V51*X51 -> 0
A52: =B16 -> ZU12-1 | B52: =C16 -> 449.32 | C52: =D16 -> 469.32 | D52: =ABS(C52-B52) -> 20 | E52: =G16 -> 3.348 | F52: =H16 -> 3.348 | G52: =I16 -> -3.62249 | H52: =J16 -> -2.99392 | I52: =E52-G52 -> 6.97049 | J52: =F52-H52 -> 6.34192 | K52: =L52+0.1 -> 0.7 | L52: 0.6 | M52: =V16+L52*2 -> 13.7 | N52: =W16+L52*2 -> 13.7 | O52: =K16-I16+0.2 -> 3.09082 | P52: =L16-J16+0.2 -> 2.73963 | Q52: =M16 -> 1.75 | R52: =N16 -> 1.75 | S52: =O16 -> 0 | T52: =P16-I16+1 -> 2.47771 | U52: =Q16-J16+1 -> 2.17769 | V52: =R16 -> 0.45 | W52: =S16 -> 0.45 | X52: =T16 -> 0 | Y52: =(O52+P52)/2*Q52*S52 -> 0 | Z52: =(T52+U52)/2*V52*X52 -> 0
A53: =B17 -> ZU13-1 | B53: =C17 -> 469.35 | C53: =D17 -> 489.35 | D53: =ABS(C53-B53) -> 20 | E53: =G17 -> 3.348 | F53: =H17 -> 3.348 | G53: =I17 -> -2.99298 | H53: =J17 -> -2.36441 | I53: =E53-G53 -> 6.34098 | J53: =F53-H53 -> 5.71241 | K53: =L53+0.1 -> 0.7 | L53: =LOOKUP(MAX(J53,I53),{0,3,4,5,6.5,7.5,9,10},{0.3,0.4,0.5,0.6,0.7,0.8,0.9}) -> 0.6 | M53: =V17+L53*2 -> 13.7 | N53: =W17+L53*2 -> 13.7 | O53: =K17-I17+0.2 -> 2.73925 | P53: =L17-J17+0.2 -> 2.57327 | Q53: =M17 -> 1.75 | R53: =N17 -> 1.75 | S53: =O17 -> 0 | T53: =P17-I17+1 -> 2.17741 | U53: =Q17-J17+1 -> 2.09995 | V53: =R17 -> 0.45 | W53: =S17 -> 0.45 | X53: =T17 -> 0 | Y53: =(O53+P53)/2*Q53*S53 -> 0 | Z53: =(T53+U53)/2*V53*X53 -> 0
A54: =B18 -> ZU14-1 | B54: =C18 -> 489.38 | C54: =D18 -> 509.38 | D54: =ABS(C54-B54) -> 20 | E54: =G18 -> 3.348 | F54: =H18 -> 3.348 | G54: =I18 -> -2.36347 | H54: =J18 -> -1.80614 | I54: =E54-G54 -> 5.71147 | J54: =F54-H54 -> 5.15414 | K54: =L54+0.1 -> 0.7 | L54: =LOOKUP(MAX(J54,I54),{0,3,4,5,6.5,7.5,9,10},{0.3,0.4,0.5,0.6,0.7,0.8,0.9}) -> 0.6 | M54: =V18+L54*2 -> 13.7 | N54: =W18+L54*2 -> 13.7 | O54: =K18-I18+0.2 -> 2.57308 | P54: =L18-J18+0.2 -> 2.51575 | Q54: =M18 -> 1.75 | R54: =N18 -> 1.75 | S54: =O18 -> 0 | T54: =P18-I18+1 -> 2.1 | U54: =Q18-J18+1 -> 2.29612 | V54: =R18 -> 0.45 | W54: =S18 -> 0.45 | X54: =T18 -> 0 | Y54: =(O54+P54)/2*Q54*S54 -> 0 | Z54: =(T54+U54)/2*V54*X54 -> 0
A55: =B19 -> ZU15-1 | B55: =C19 -> 509.41 | C55: =D19 -> 529.41 | D55: =ABS(C55-B55) -> 20 | E55: =G19 -> 3.348 | F55: =H19 -> 3.348 | G55: =I19 -> -1.8053 | H55: =J19 -> -1.24798 | I55: =E55-G55 -> 5.1533 | J55: =F55-H55 -> 4.59598 | K55: =L55+0.1 -> 0.7 | L55: =LOOKUP(MAX(J55,I55),{0,3,4,5,6.5,7.5,9,10},{0.3,0.4,0.5,0.6,0.7,0.8,0.9}) -> 0.6 | M55: =V19+L55*2 -> 13.7 | N55: =W19+L55*2 -> 13.7 | O55: =K19-I19+0.2 -> 2.51566 | P55: =L19-J19+0.2 -> 2.45834 | Q55: =M19 -> 1.75 | R55: =N19 -> 1.75 | S55: =O19 -> 0 | T55: =P19-I19+1 -> 2.29647 | U55: =Q19-J19+1 -> 2.52915 | V55: =R19 -> 0.45 | W55: =S19 -> 0.45 | X55: =T19 -> 0 | Y55: =(O55+P55)/2*Q55*S55 -> 0 | Z55: =(T55+U55)/2*V55*X55 -> 0
...

Sheet 1.U型槽主筋验算
H1: 边墙厚度 | I1: 结构净高 | J1: 水位高 | K1: 钢筋
G2: ='0.结构参数'!A41 -> ZU1-1 | H2: ='0.结构参数'!L41 -> 0.3 | I2: =MAX('0.结构参数'!I41,'0.结构参数'!J41) -> 2.11515 | J2: =3.1-MIN('0.结构参数'!I5,'0.结构参数'!J5) -> 1.86715 | K2: 14
G3: ='0.结构参数'!A42 -> ZU2-1 | H3: ='0.结构参数'!L42 -> 0.3 | I3: =MAX('0.结构参数'!I42,'0.结构参数'!J42) -> 2.71065 | J3: =3.1-MIN('0.结构参数'!I6,'0.结构参数'!J6) -> 2.46265 | K3: 16
G4: ='0.结构参数'!A43 -> ZU3-1 | H4: ='0.结构参数'!L43 -> 0.4 | I4: =MAX('0.结构参数'!I43,'0.结构参数'!J43) -> 3.30615 | J4: =3.1-MIN('0.结构参数'!I7,'0.结构参数'!J7) -> 3.05815 | K4: 18
G5: ='0.结构参数'!A44 -> ZU4-1 | H5: ='0.结构参数'!L44 -> 0.4 | I5: =MAX('0.结构参数'!I44,'0.结构参数'!J44) -> 3.90165 | J5: =3.1-MIN('0.结构参数'!I8,'0.结构参数'!J8) -> 3.65365 | K5: 22
G6: ='0.结构参数'!A45 -> ZU5-1 | H6: ='0.结构参数'!L45 -> 0.5 | I6: =MAX('0.结构参数'!I45,'0.结构参数'!J45) -> 4.49716 | J6: =3.1-MIN('0.结构参数'!I9,'0.结构参数'!J9) -> 4.24916 | K6: 25
G7: ='0.结构参数'!A46 -> ZU6-1 | H7: ='0.结构参数'!L46 -> 0.6 | I7: =MAX('0.结构参数'!I46,'0.结构参数'!J46) -> 5.276 | J7: =3.1-MIN('0.结构参数'!I10,'0.结构参数'!J10) -> 5.028 | K7: 20 | L7: 2根
G8: ='0.结构参数'!A47 -> ZU7-1 | H8: ='0.结构参数'!L47 -> 0.5 | I8: =MAX('0.结构参数'!I47,'0.结构参数'!J47) -> 6.05484 | J8: =3.1-MIN('0.结构参数'!I11,'0.结构参数'!J11) -> 5.80684 | K8: 25 | L8: 2根
G9: ='0.结构参数'!A48 -> ZU8-1 | H9: ='0.结构参数'!L48 -> 0.7 | I9: =MAX('0.结构参数'!I48,'0.结构参数'!J48) -> 6.65593 | J9: =3.1-MIN('0.结构参数'!I12,'0.结构参数'!J12) -> 6.40793 | K9: 22 | L9: 3根
G10: ='0.结构参数'!A49 -> ZU9-1 | H10: ='0.结构参数'!L49 -> 0.7 | I10: =MAX('0.结构参数'!I49,'0.结构参数'!J49) -> 7.25702 | J10: =3.1-MIN('0.结构参数'!I13,'0.结构参数'!J13) -> 7.00902 | K10: 25 | L10: 3根
G11: ='0.结构参数'!A50 -> ZU10-1 | H11: ='0.结构参数'!L50 -> 0.7 | I11: =MAX('0.结构参数'!I50,'0.结构参数'!J50) -> 7.25702 | J11: =3.1-MIN('0.结构参数'!I14,'0.结构参数'!J14) -> 7.00902 | K11: 25 | L11: 3根
B12: ZU19-1计算书 | G12: ='0.结构参数'!A51 -> ZU11-1 | H12: ='0.结构参数'!L51 -> 0.8 | I12: =MAX('0.结构参数'!I51,'0.结构参数'!J51) -> 7.6 | J12: =3.1-MIN('0.结构参数'!I15,'0.结构参数'!J15) -> 7.352 | K12: 25 | L12: 3根
G13: ='0.结构参数'!A52 -> ZU12-1 | H13: ='0.结构参数'!L52 -> 0.6 | I13: =MAX('0.结构参数'!I52,'0.结构参数'!J52) -> 6.97049 | J13: =3.1-MIN('0.结构参数'!I16,'0.结构参数'!J16) -> 6.72249 | K13: 22 | L13: 3根
B14: 1、 | C14: 结构描述 | G14: ='0.结构参数'!A53 -> ZU13-1 | H14: ='0.结构参数'!L53 -> 0.6 | I14: =MAX('0.结构参数'!I53,'0.结构参数'!J53) -> 6.34098 | J14: =3.1-MIN('0.结构参数'!I17,'0.结构参数'!J17) -> 6.09298 | K14: 20 | L14: 3根
G15: ='0.结构参数'!A54 -> ZU14-1 | H15: ='0.结构参数'!L54 -> 0.6 | I15: =MAX('0.结构参数'!I54,'0.结构参数'!J54) -> 5.71147 | J15: =3.1-MIN('0.结构参数'!I18,'0.结构参数'!J18) -> 5.46347 | K15: 22 | L15: 2根
G16: ='0.结构参数'!A55 -> ZU15-1 | H16: ='0.结构参数'!L55 -> 0.6 | I16: =MAX('0.结构参数'!I55,'0.结构参数'!J55) -> 5.1533 | J16: =3.1-MIN('0.结构参数'!I19,'0.结构参数'!J19) -> 4.9053 | K16: 20 | L16: 2根
G17: ='0.结构参数'!A56 -> ZU16-1 | H17: ='0.结构参数'!L56 -> 0.5 | I17: =MAX('0.结构参数'!I56,'0.结构参数'!J56) -> 4.59514 | J17: =3.1-MIN('0.结构参数'!I20,'0.结构参数'!J20) -> 4.34714 | K17: 18 | L17: 2根
G18: ='0.结构参数'!A57 -> ZU17-1 | H18: ='0.结构参数'!L57 -> 0.5 | I18: =MAX('0.结构参数'!I57,'0.结构参数'!J57) -> 4.03698 | J18: =3.1-MIN('0.结构参数'!I21,'0.结构参数'!J21) -> 3.78898 | K18: 22
G19: ='0.结构参数'!A58 -> ZU18-1 | H19: ='0.结构参数'!L58 -> 0.4 | I19: =MAX('0.结构参数'!I58,'0.结构参数'!J58) -> 3.47881 | J19: =3.1-MIN('0.结构参数'!I22,'0.结构参数'!J22) -> 3.23081 | K19: 20
G20: ='0.结构参数'!A59 -> ZU19-1 | H20: ='0.结构参数'!L59 -> 0.3 | I20: =MAX('0.结构参数'!I59,'0.结构参数'!J59) -> 2.92065 | J20: =3.1-MIN('0.结构参数'!I23,'0.结构参数'!J23) -> 2.67265 | K20: 18
G21: ='0.结构参数'!A60 -> 东U10 | H21: ='0.结构参数'!L60 -> 0.3 | I21: =MAX('0.结构参数'!I60,'0.结构参数'!J60) -> 1.63657 | J21: =3.15-MIN('0.结构参数'!I24,'0.结构参数'!J24) -> 0.87257 | K21: 14
G22: ='0.结构参数'!A61 -> 西U10-1 | H22: ='0.结构参数'!L61 -> 0.3 | I22: =MAX('0.结构参数'!I61,'0.结构参数'!J61) -> 1.61126 | J22: =3.15-MIN('0.结构参数'!I25,'0.结构参数'!J25) -> 1.41326 | K22: 14
G23: ='0.结构参数'!A62 -> 西U9-1 | H23: ='0.结构参数'!L62 -> 0.3 | I23: =MAX('0.结构参数'!I62,'0.结构参数'!J62) -> 2.17365 | J23: =3.15-MIN('0.结构参数'!I26,'0.结构参数'!J26) -> 1.97565 | K23: 14
G24: ='0.结构参数'!A63 -> 西U6-1 | H24: ='0.结构参数'!L63 -> 0.5 | I24: =MAX('0.结构参数'!I63,'0.结构参数'!J63) -> 4.54681 | J24: =3.15-MIN('0.结构参数'!I27,'0.结构参数'!J27) -> 4.34881 | K24: 22
G25: ='0.结构参数'!A64 -> 西U5-1 | H25: ='0.结构参数'!L64 -> 0.6 | I25: =MAX('0.结构参数'!I64,'0.结构参数'!J64) -> 5.33797 | J25: =3.15-MIN('0.结构参数'!I28,'0.结构参数'!J28) -> 5.13997 | K25: 25
G26: ='0.结构参数'!A65 -> 西U4-1 | H26: ='0.结构参数'!L65 -> 0.6 | I26: =MAX('0.结构参数'!I65,'0.结构参数'!J65) -> 6.12914 | J26: =3.15-MIN('0.结构参数'!I29,'0.结构参数'!J29) -> 5.93114 | K26: 20
G27: ='0.结构参数'!A66 -> 西U3-1 | H27: ='0.结构参数'!L66 -> 0.7 | I27: =MAX('0.结构参数'!I66,'0.结构参数'!J66) -> 6.69325 | J27: =3.15-MIN('0.结构参数'!I30,'0.结构参数'!J30) -> 6.49525 | K27: 22
G28: ='0.结构参数'!A67 -> 西U2-1 | H28: ='0.结构参数'!L67 -> 0.7 | I28: =MAX('0.结构参数'!I67,'0.结构参数'!J67) -> 7.25702 | J28: =3.15-MIN('0.结构参数'!I31,'0.结构参数'!J31) -> 7.05902 | K28: 25
G29: ='0.结构参数'!A68 -> 西U6-2 | H29: ='0.结构参数'!L68 -> 0.5 | I29: =MAX('0.结构参数'!I68,'0.结构参数'!J68) -> 4.54681 | J29: =3.15-MIN('0.结构参数'!I32,'0.结构参数'!J32) -> 4.34881 | K29: 22
B30: 结构尺寸 | C30: 顶宽： | D30: b1= | E30: 0.3 | G30: ='0.结构参数'!A69 -> 西U5-2 | H30: ='0.结构参数'!L69 -> 0.6 | I30: =MAX('0.结构参数'!I69,'0.结构参数'!J69) -> 5.33797 | J30: =3.15-MIN('0.结构参数'!I33,'0.结构参数'!J33) -> 5.13997 | K30: 25
C31: 底宽： | D31: b2= | E31: =E30 -> 0.3 | G31: ='0.结构参数'!A70 -> 西U4-2 | H31: ='0.结构参数'!L70 -> 0.6 | I31: =MAX('0.结构参数'!I70,'0.结构参数'!J70) -> 6.12914 | J31: =3.15-MIN('0.结构参数'!I34,'0.结构参数'!J34) -> 5.93114 | K31: 20
C32: 桥高： | D32: h= | E32: 2.9 | G32: ='0.结构参数'!A71 -> 西U3-2 | H32: ='0.结构参数'!L71 -> 0.7 | I32: =MAX('0.结构参数'!I71,'0.结构参数'!J71) -> 6.69325 | J32: =3.15-MIN('0.结构参数'!I35,'0.结构参数'!J35) -> 6.49525 | K32: 22
C33: 水高： | D33: H= | E33: 2.7
B35: 2、 | C35: 荷载计算
C37: 结构重要性系数： | D37: r0= | E37: =IF(E32>5,IF(F37="二级及以下公路",1,1.05),IF(F37="二级及以下公路",0.95,1)) -> 1 | F37: 高速公路、一级公路 | G37: 结构重要性系数
C38: 土压力分项系数： | D38: γt= | E38: 1.4 | G38: 墙高 | H38: 高速公路、一级公路 | I38: 二级及以下公路
C39: 水压力分项系数： | D39: γs= | E39: 1 | G39: ≤5.0m | H39: 1 | I39: 0.95
C40: 活载分项系数： | D40: γQ= | E40: 1.4 | G40: >5.0m | H40: 1.05 | I40: 1
B42: 2.1 | C42: 土压力计算
B44: 土压力 参数 | C44: 填土坡角 | D44: β= | E44: 0
...

Sheet 2.U型槽钢筋
A2: U型槽尺寸表 | B2: 节段 | C2: 净高不含底板厚 | E2: 节段宽 | G2: 边墙厚B | H2: 底板厚T | I2: D | J2: hmin+T | K2: hmax+T | N2: 角度 | O2: 净保护层
C3: Hmin | D3: Hmax | E3: Lmax | F3: Lmin | N3: 90 | O3: 4 | P3: 4
B4: ='0.结构参数'!A41 -> ZU1-1 | C4: =MIN('0.结构参数'!I41,'0.结构参数'!J41)*100 -> 179.116 | D4: =MAX('0.结构参数'!I41,'0.结构参数'!J41)*100 -> 211.515 | E4: =MAX('0.结构参数'!E5,'0.结构参数'!F5)*100 -> 2000 | F4: =MIN('0.结构参数'!E5,'0.结构参数'!F5)*100 -> 2000 | G4: ='0.结构参数'!L41*100 -> 30 | H4: ='0.结构参数'!K41*100 -> 40 | I4: =('0.结构参数'!M41+'0.结构参数'!N41)/2*100 -> 1310 | J4: =(C4+$H4) -> 219.116 | K4: =(D4+$H4) -> 251.515
B5: ='0.结构参数'!A42 -> ZU2-1 | C5: =MIN('0.结构参数'!I42,'0.结构参数'!J42)*100 -> 211.604 | D5: =MAX('0.结构参数'!I42,'0.结构参数'!J42)*100 -> 271.065 | E5: =MAX('0.结构参数'!E6,'0.结构参数'!F6)*100 -> 2000 | F5: =MIN('0.结构参数'!E6,'0.结构参数'!F6)*100 -> 2000 | G5: ='0.结构参数'!L42*100 -> 30 | H5: ='0.结构参数'!K42*100 -> 40 | I5: =('0.结构参数'!M42+'0.结构参数'!N42)/2*100 -> 1310 | J5: =(C5+$H5) -> 251.604 | K5: =(D5+$H5) -> 311.065
B6: ='0.结构参数'!A43 -> ZU3-1 | C6: =MIN('0.结构参数'!I43,'0.结构参数'!J43)*100 -> 271.154 | D6: =MAX('0.结构参数'!I43,'0.结构参数'!J43)*100 -> 330.615 | E6: =MAX('0.结构参数'!E7,'0.结构参数'!F7)*100 -> 2000 | F6: =MIN('0.结构参数'!E7,'0.结构参数'!F7)*100 -> 2000 | G6: ='0.结构参数'!L43*100 -> 40 | H6: ='0.结构参数'!K43*100 -> 50 | I6: =('0.结构参数'!M43+'0.结构参数'!N43)/2*100 -> 1330 | J6: =(C6+$H6) -> 321.154 | K6: =(D6+$H6) -> 380.615
B7: ='0.结构参数'!A44 -> ZU4-1 | C7: =MIN('0.结构参数'!I44,'0.结构参数'!J44)*100 -> 330.704 | D7: =MAX('0.结构参数'!I44,'0.结构参数'!J44)*100 -> 390.165 | E7: =MAX('0.结构参数'!E8,'0.结构参数'!F8)*100 -> 2000 | F7: =MIN('0.结构参数'!E8,'0.结构参数'!F8)*100 -> 2000 | G7: ='0.结构参数'!L44*100 -> 40 | H7: ='0.结构参数'!K44*100 -> 50 | I7: =('0.结构参数'!M44+'0.结构参数'!N44)/2*100 -> 1330 | J7: =(C7+$H7) -> 380.704 | K7: =(D7+$H7) -> 440.165
B8: ='0.结构参数'!A45 -> ZU5-1 | C8: =MIN('0.结构参数'!I45,'0.结构参数'!J45)*100 -> 390.255 | D8: =MAX('0.结构参数'!I45,'0.结构参数'!J45)*100 -> 449.716 | E8: =MAX('0.结构参数'!E9,'0.结构参数'!F9)*100 -> 2000 | F8: =MIN('0.结构参数'!E9,'0.结构参数'!F9)*100 -> 2000 | G8: ='0.结构参数'!L45*100 -> 50 | H8: ='0.结构参数'!K45*100 -> 60 | I8: =('0.结构参数'!M45+'0.结构参数'!N45)/2*100 -> 1350 | J8: =(C8+$H8) -> 450.255 | K8: =(D8+$H8) -> 509.716 | N8: 4、e2数值改为定值8，但仍需注意表格外e2取值区间
B9: ='0.结构参数'!A46 -> ZU6-1 | C9: =MIN('0.结构参数'!I46,'0.结构参数'!J46)*100 -> 449.832 | D9: =MAX('0.结构参数'!I46,'0.结构参数'!J46)*100 -> 527.6 | E9: =MAX('0.结构参数'!E10,'0.结构参数'!F10)*100 -> 2000 | F9: =MIN('0.结构参数'!E10,'0.结构参数'!F10)*100 -> 2000 | G9: ='0.结构参数'!L46*100 -> 60 | H9: ='0.结构参数'!K46*100 -> 70 | I9: =('0.结构参数'!M46+'0.结构参数'!N46)/2*100 -> 1370 | J9: =(C9+$H9) -> 519.832 | K9: =(D9+$H9) -> 597.6
B10: ='0.结构参数'!A47 -> ZU7-1 | C10: =MIN('0.结构参数'!I47,'0.结构参数'!J47)*100 -> 527.717 | D10: =MAX('0.结构参数'!I47,'0.结构参数'!J47)*100 -> 605.484 | E10: =MAX('0.结构参数'!E11,'0.结构参数'!F11)*100 -> 2000 | F10: =MIN('0.结构参数'!E11,'0.结构参数'!F11)*100 -> 2000 | G10: ='0.结构参数'!L47*100 -> 50 | H10: ='0.结构参数'!K47*100 -> 60 | I10: =('0.结构参数'!M47+'0.结构参数'!N47)/2*100 -> 1350 | J10: =(C10+$H10) -> 587.717 | K10: =(D10+$H10) -> 665.484
B11: ='0.结构参数'!A48 -> ZU8-1 | C11: =MIN('0.结构参数'!I48,'0.结构参数'!J48)*100 -> 605.574 | D11: =MAX('0.结构参数'!I48,'0.结构参数'!J48)*100 -> 665.593 | E11: =MAX('0.结构参数'!E12,'0.结构参数'!F12)*100 -> 2000 | F11: =MIN('0.结构参数'!E12,'0.结构参数'!F12)*100 -> 2000 | G11: ='0.结构参数'!L48*100 -> 70 | H11: ='0.结构参数'!K48*100 -> 80 | I11: =('0.结构参数'!M48+'0.结构参数'!N48)/2*100 -> 1390 | J11: =(C11+$H11) -> 685.574 | K11: =(D11+$H11) -> 745.593
B12: ='0.结构参数'!A49 -> ZU9-1 | C12: =MIN('0.结构参数'!I49,'0.结构参数'!J49)*100 -> 665.683 | D12: =MAX('0.结构参数'!I49,'0.结构参数'!J49)*100 -> 725.702 | E12: =MAX('0.结构参数'!E13,'0.结构参数'!F13)*100 -> 2000 | F12: =MIN('0.结构参数'!E13,'0.结构参数'!F13)*100 -> 2000 | G12: ='0.结构参数'!L49*100 -> 70 | H12: ='0.结构参数'!K49*100 -> 80 | I12: =('0.结构参数'!M49+'0.结构参数'!N49)/2*100 -> 1390 | J12: =(C12+$H12) -> 745.683 | K12: =(D12+$H12) -> 805.702
B13: ='0.结构参数'!A50 -> ZU10-1 | C13: =MIN('0.结构参数'!I50,'0.结构参数'!J50)*100 -> 725.702 | D13: =MAX('0.结构参数'!I50,'0.结构参数'!J50)*100 -> 725.702 | E13: =MAX('0.结构参数'!E14,'0.结构参数'!F14)*100 -> 2000 | F13: =MIN('0.结构参数'!E14,'0.结构参数'!F14)*100 -> 2000 | G13: ='0.结构参数'!L50*100 -> 70 | H13: ='0.结构参数'!K50*100 -> 80 | I13: =('0.结构参数'!M50+'0.结构参数'!N50)/2*100 -> 1390 | J13: =(C13+$H13) -> 805.702 | K13: =(D13+$H13) -> 805.702
B14: ='0.结构参数'!A51 -> ZU11-1 | C14: =MIN('0.结构参数'!I51,'0.结构参数'!J51)*100 -> 697.143 | D14: =MAX('0.结构参数'!I51,'0.结构参数'!J51)*100 -> 760 | E14: =MAX('0.结构参数'!E15,'0.结构参数'!F15)*100 -> 2000 | F14: =MIN('0.结构参数'!E15,'0.结构参数'!F15)*100 -> 2000 | G14: ='0.结构参数'!L51*100 -> 80 | H14: ='0.结构参数'!K51*100 -> 90 | I14: =('0.结构参数'!M51+'0.结构参数'!N51)/2*100 -> 1410 | J14: =(C14+$H14) -> 787.143 | K14: =(D14+$H14) -> 850
B15: ='0.结构参数'!A52 -> ZU12-1 | C15: =MIN('0.结构参数'!I52,'0.结构参数'!J52)*100 -> 634.192 | D15: =MAX('0.结构参数'!I52,'0.结构参数'!J52)*100 -> 697.049 | E15: =MAX('0.结构参数'!E16,'0.结构参数'!F16)*100 -> 2000 | F15: =MIN('0.结构参数'!E16,'0.结构参数'!F16)*100 -> 2000 | G15: ='0.结构参数'!L52*100 -> 60 | H15: ='0.结构参数'!K52*100 -> 70 | I15: =('0.结构参数'!M52+'0.结构参数'!N52)/2*100 -> 1370 | J15: =(C15+$H15) -> 704.192 | K15: =(D15+$H15) -> 767.049
B16: ='0.结构参数'!A53 -> ZU13-1 | C16: =MIN('0.结构参数'!I53,'0.结构参数'!J53)*100 -> 571.241 | D16: =MAX('0.结构参数'!I53,'0.结构参数'!J53)*100 -> 634.098 | E16: =MAX('0.结构参数'!E17,'0.结构参数'!F17)*100 -> 2000 | F16: =MIN('0.结构参数'!E17,'0.结构参数'!F17)*100 -> 2000 | G16: ='0.结构参数'!L53*100 -> 60 | H16: ='0.结构参数'!K53*100 -> 70 | I16: =('0.结构参数'!M53+'0.结构参数'!N53)/2*100 -> 1370 | J16: =(C16+$H16) -> 641.241 | K16: =(D16+$H16) -> 704.098
B17: ='0.结构参数'!A54 -> ZU14-1 | C17: =MIN('0.结构参数'!I54,'0.结构参数'!J54)*100 -> 515.414 | D17: =MAX('0.结构参数'!I54,'0.结构参数'!J54)*100 -> 571.147 | E17: =MAX('0.结构参数'!E18,'0.结构参数'!F18)*100 -> 2000 | F17: =MIN('0.结构参数'!E18,'0.结构参数'!F18)*100 -> 2000 | G17: ='0.结构参数'!L54*100 -> 60 | H17: ='0.结构参数'!K54*100 -> 70 | I17: =('0.结构参数'!M54+'0.结构参数'!N54)/2*100 -> 1370 | J17: =(C17+$H17) -> 585.414 | K17: =(D17+$H17) -> 641.147
B18: ='0.结构参数'!A55 -> ZU15-1 | C18: =MIN('0.结构参数'!I55,'0.结构参数'!J55)*100 -> 459.598 | D18: =MAX('0.结构参数'!I55,'0.结构参数'!J55)*100 -> 515.33 | E18: =MAX('0.结构参数'!E19,'0.结构参数'!F19)*100 -> 2000 | F18: =MIN('0.结构参数'!E19,'0.结构参数'!F19)*100 -> 2000 | G18: ='0.结构参数'!L55*100 -> 60 | H18: ='0.结构参数'!K55*100 -> 70 | I18: =('0.结构参数'!M55+'0.结构参数'!N55)/2*100 -> 1370 | J18: =(C18+$H18) -> 529.598 | K18: =(D18+$H18) -> 585.33
B19: ='0.结构参数'!A56 -> ZU16-1 | C19: =MIN('0.结构参数'!I56,'0.结构参数'!J56)*100 -> 403.781 | D19: =MAX('0.结构参数'!I56,'0.结构参数'!J56)*100 -> 459.514 | E19: =MAX('0.结构参数'!E20,'0.结构参数'!F20)*100 -> 2000 | F19: =MIN('0.结构参数'!E20,'0.结构参数'!F20)*100 -> 2000 | G19: ='0.结构参数'!L56*100 -> 50 | H19: ='0.结构参数'!K56*100 -> 60 | I19: =('0.结构参数'!M56+'0.结构参数'!N56)/2*100 -> 1350 | J19: =(C19+$H19) -> 463.781 | K19: =(D19+$H19) -> 519.514
B20: ='0.结构参数'!A57 -> ZU17-1 | C20: =MIN('0.结构参数'!I57,'0.结构参数'!J57)*100 -> 347.965 | D20: =MAX('0.结构参数'!I57,'0.结构参数'!J57)*100 -> 403.698 | E20: =MAX('0.结构参数'!E21,'0.结构参数'!F21)*100 -> 2000 | F20: =MIN('0.结构参数'!E21,'0.结构参数'!F21)*100 -> 2000 | G20: ='0.结构参数'!L57*100 -> 50 | H20: ='0.结构参数'!K57*100 -> 60 | I20: =('0.结构参数'!M57+'0.结构参数'!N57)/2*100 -> 1350 | J20: =(C20+$H20) -> 407.965 | K20: =(D20+$H20) -> 463.698
... B35: ='0.结构参数'!A72 -> 0 | C35: =MIN('0.结构参数'!I72,'0.结构参数'!J72)*100 -> 0 | D35: =MAX('0.结构参数'!I72,'0.结构参数'!J72)*100 -> 0 | E35: =MAX('0.结构参数'!E36,'0.结构参数'!F36)*100 -> 0 | F35: =MIN('0.结构参数'!E36,'0.结构参数'!F36)*100 -> 0 | G35: ='0.结构参数'!L72*100 -> 30 | H35: ='0.结构参数'!K72*100 -> 40 | I35: =('0.结构参数'!M72+'0.结构参数'!N72)/2*100 -> 60 | J35: =(C35+$H35) -> 40 | K35: =(D35+$H35) -> 40
F37: 此处若为负值，则公式改为“B21/D21-2” | P37: 若e2小于8，则在n1公式后减1
A38: 钢筋图参数表 | B38: U型槽 编号 | C38: D (cm) | D38: n | E38: d (cm) | F38: a 0~12.5 | G38: B (cm) | H38: m | I38: b (cm) | J38: e1 (cm) | K38: Hmin (cm) | L38: Hmax (cm) | M38: n1 | N38: d1 (cm) | O38: d2 (cm) | P38: e2 | Q38: T | R38: n1' | S38: d1' | T38: L1 (cm) | U38: m1 | V38: b1 (cm) | W38: L2 (cm) | X38: m2 | Y38: b2 (cm) | Z38: e3 (cm) | AA38: e2 7~20.5
B39: =B4 -> ZU1-1 | C39: =VLOOKUP(B39,$B$4:$K$36,8,0) -> 1310 | D39: =ROUNDDOWN((C39/E39-1),0) -> 103 | E39: =12.5 -> 12.5 | F39: =C39-D39*E39-2*J39 -> 6.5 | G39: =VLOOKUP(B39,$B$4:$J$72,6,0) -> 30 | H39: 2 | I39: =(G39-J39*2)/H39 -> 7 | J39: 8 | K39: =VLOOKUP(B39,$B$4:$K$36,2,0) -> 179.116 | L39: =VLOOKUP(B39,$B$4:$K$36,3,0) -> 211.515 | M39: =ROUND((L39-5)/12.5,0)-1 -> 16 | N39: =(L39-5-P39)/M39 -> 12.407187 | O39: =(K39-P39-5)/M39 -> 10.38225 | P39: 8 | Q39: =VLOOKUP($B39,$B$4:$K$36,7,0) -> 40 | R39: =H39+1 -> 3 | S39: =(Q39-2*J39)/R39 -> 8 | T39: =VLOOKUP($B39,$B$4:$K$36,4,0) -> 2000 | U39: =ROUNDDOWN(T39/V39,0)-1 -> 159 | V39: 12.5 | W39: =VLOOKUP($B39,$B$4:$K$36,5,0) -> 2000 | X39: =U39 -> 159 | Y39: =(W39-Z39*2)/X39 -> 12.5 | Z39: =(T39-U39*V39)/2 -> 6.25 | AA39: =L39-M39*12.5-5 -> 6.515
B40: =B5 -> ZU2-1 | C40: =VLOOKUP(B40,$B$4:$K$36,8,0) -> 1310 | D40: =ROUNDDOWN((C40/E40-1),0) -> 103 | E40: =12.5 -> 12.5 | F40: =C40-D40*E40-2*J40 -> 6.5 | G40: =VLOOKUP(B40,$B$4:$J$72,6,0) -> 30 | H40: 2 | I40: =(G40-J40*2)/H40 -> 7 | J40: 8 | K40: =VLOOKUP(B40,$B$4:$K$36,2,0) -> 211.604 | L40: =VLOOKUP(B40,$B$4:$K$36,3,0) -> 271.065 | M40: =ROUND((L40-5)/12.5,0)-1 -> 20 | N40: =(L40-5-P40)/M40 -> 12.90325 | O40: =(K40-P40-5)/M40 -> 9.9302 | P40: 8 | Q40: =VLOOKUP($B40,$B$4:$K$36,7,0) -> 40 | R40: =H40+1 -> 3 | S40: =(Q40-2*J40)/R40 -> 8 | T40: =VLOOKUP($B40,$B$4:$K$36,4,0) -> 2000 | U40: =ROUNDDOWN(T40/V40,0)-1 -> 159 | V40: 12.5 | W40: =VLOOKUP($B40,$B$4:$K$36,5,0) -> 2000 | X40: =U40 -> 159 | Y40: =(W40-Z40*2)/X40 -> 12.5 | Z40: =(T40-U40*V40)/2 -> 6.25 | AA40: =L40-M40*12.5-5 -> 16.065
B41: =B6 -> ZU3-1 | C41: =VLOOKUP(B41,$B$4:$K$36,8,0) -> 1330 | D41: =ROUNDDOWN((C41/E41-1),0) -> 105 | E41: =12.5 -> 12.5 | F41: =C41-D41*E41-2*J41 -> 1.5 | G41: =VLOOKUP(B41,$B$4:$J$72,6,0) -> 40 | H41: 2 | I41: =(G41-J41*2)/H41 -> 12 | J41: 8 | K41: =VLOOKUP(B41,$B$4:$K$36,2,0) -> 271.154 | L41: =VLOOKUP(B41,$B$4:$K$36,3,0) -> 330.615 | M41: =ROUND((L41-5)/12.5,0)-1 -> 25 | N41: =(L41-5-P41)/M41 -> 12.7046 | O41: =(K41-P41-5)/M41 -> 10.32616 | P41: 8 | Q41: =VLOOKUP($B41,$B$4:$K$36,7,0) -> 50 | R41: 4 | S41: =(Q41-2*J41)/R41 -> 8.5 | T41: =VLOOKUP($B41,$B$4:$K$36,4,0) -> 2000 | U41: =ROUNDDOWN(T41/V41,0)-1 -> 159 | V41: 12.5 | W41: =VLOOKUP($B41,$B$4:$K$36,5,0) -> 2000 | X41: =U41 -> 159 | Y41: =(W41-Z41*2)/X41 -> 12.5 | Z41: =(T41-U41*V41)/2 -> 6.25 | AA41: =L41-M41*12.5-5 -> 13.115
B42: =B7 -> ZU4-1 | C42: =VLOOKUP(B42,$B$4:$K$36,8,0) -> 1330 | D42: =ROUNDDOWN((C42/E42-1),0) -> 105 | E42: =12.5 -> 12.5 | F42: =C42-D42*E42-2*J42 -> 1.5 | G42: =VLOOKUP(B42,$B$4:$J$72,6,0) -> 40 | H42: 3 | I42: =(G42-J42*2)/H42 -> 8 | J42: 8 | K42: =VLOOKUP(B42,$B$4:$K$36,2,0) -> 330.704 | L42: =VLOOKUP(B42,$B$4:$K$36,3,0) -> 390.165 | M42: =ROUND((L42-5)/12.5,0)-1 -> 30 | N42: =(L42-5-P42)/M42 -> 12.572167 | O42: =(K42-P42-5)/M42 -> 10.590133 | P42: 8 | Q42: =VLOOKUP($B42,$B$4:$K$36,7,0) -> 50 | R42: =H42+1 -> 4 | S42: =(Q42-2*J42)/R42 -> 8.5 | T42: =VLOOKUP($B42,$B$4:$K$36,4,0) -> 2000 | U42: =ROUNDDOWN(T42/V42,0)-1 -> 159 | V42: 12.5 | W42: =VLOOKUP($B42,$B$4:$K$36,5,0) -> 2000 | X42: =U42 -> 159 | Y42: =(W42-Z42*2)/X42 -> 12.5 | Z42: =(T42-U42*V42)/2 -> 6.25 | AA42: =L42-M42*12.5-5 -> 10.165
B43: =B8 -> ZU5-1 | C43: =VLOOKUP(B43,$B$4:$K$36,8,0) -> 1350 | D43: =ROUNDDOWN((C43/E43-2),0) -> 106 | E43: =12.5 -> 12.5 | F43: =C43-D43*E43-2*J43 -> 9 | G43: =VLOOKUP(B43,$B$4:$J$72,6,0) -> 50 | H43: 4 | I43: =(G43-J43*2)/H43 -> 8.5 | J43: 8 | K43: =VLOOKUP(B43,$B$4:$K$36,2,0) -> 390.255 | L43: =VLOOKUP(B43,$B$4:$K$36,3,0) -> 449.716 | M43: =ROUND((L43-5)/12.5,0)-1 -> 35 | N43: =(L43-5-P43)/M43 -> 12.4776 | O43: =(K43-P43-5)/M43 -> 10.778714 | P43: 8 | Q43: =VLOOKUP($B43,$B$4:$K$36,7,0) -> 60 | R43: 4 | S43: =(Q43-2*J43)/R43 -> 11 | T43: =VLOOKUP($B43,$B$4:$K$36,4,0) -> 2000 | U43: =ROUNDDOWN(T43/V43,0)-1 -> 159 | V43: 12.5 | W43: =VLOOKUP($B43,$B$4:$K$36,5,0) -> 2000 | X43: =U43 -> 159 | Y43: =(W43-Z43*2)/X43 -> 12.5 | Z43: =(T43-U43*V43)/2 -> 6.25 | AA43: =L43-M43*12.5-5 -> 7.216
B44: =B9 -> ZU6-1 | C44: =VLOOKUP(B44,$B$4:$K$36,8,0) -> 1370 | D44: =ROUNDDOWN((C44/E44-1),0) -> 108 | E44: =12.5 -> 12.5 | F44: =C44-D44*E44-2*J44 -> 4 | G44: =VLOOKUP(B44,$B$4:$J$72,6,0) -> 60 | H44: 4 | I44: =(G44-J44*2)/H44 -> 11 | J44: 8 | K44: =VLOOKUP(B44,$B$4:$K$36,2,0) -> 449.832 | L44: =VLOOKUP(B44,$B$4:$K$36,3,0) -> 527.6 | M44: =ROUND((L44-5)/12.5,0)-1 -> 41 | N44: =(L44-5-P44)/M44 -> 12.55122 | O44: =(K44-P44-5)/M44 -> 10.654439 | P44: 8 | Q44: =VLOOKUP($B44,$B$4:$K$36,7,0) -> 70 | R44: 6 | S44: =(Q44-2*J44)/R44 -> 9 | T44: =VLOOKUP($B44,$B$4:$K$36,4,0) -> 2000 | U44: =ROUNDDOWN(T44/V44,0)-1 -> 159 | V44: 12.5 | W44: =VLOOKUP($B44,$B$4:$K$36,5,0) -> 2000 | X44: =U44 -> 159 | Y44: =(W44-Z44*2)/X44 -> 12.5 | Z44: =(T44-U44*V44)/2 -> 6.25 | AA44: =L44-M44*12.5-5 -> 10.1
B45: =B10 -> ZU7-1 | C45: =VLOOKUP(B45,$B$4:$K$36,8,0) -> 1350 | D45: =ROUNDDOWN((C45/E45-2),0) -> 106 | E45: =12.5 -> 12.5 | F45: =C45-D45*E45-2*J45 -> 9 | G45: =VLOOKUP(B45,$B$4:$J$72,6,0) -> 50 | H45: 4 | I45: =(G45-J45*2)/H45 -> 8.5 | J45: 8 | K45: =VLOOKUP(B45,$B$4:$K$36,2,0) -> 527.717 | L45: =VLOOKUP(B45,$B$4:$K$36,3,0) -> 605.484 | M45: =ROUND((L45-5)/12.5,0)-1 -> 47 | N45: =(L45-5-P45)/M45 -> 12.606043 | O45: =(K45-P45-5)/M45 -> 10.951426 | P45: 8 | Q45: =VLOOKUP($B45,$B$4:$K$36,7,0) -> 60 | R45: 6 | S45: =(Q45-2*J45)/R45 -> 7.3333333 | T45: =VLOOKUP($B45,$B$4:$K$36,4,0) -> 2000 | U45: =ROUNDDOWN(T45/V45,0)-1 -> 159 | V45: 12.5 | W45: =VLOOKUP($B45,$B$4:$K$36,5,0) -> 2000 | X45: =U45 -> 159 | Y45: =(W45-Z45*2)/X45 -> 12.5 | Z45: =(T45-U45*V45)/2 -> 6.25 | AA45: =L45-M45*12.5-5 -> 12.984
B46: =B11 -> ZU8-1 | C46: =VLOOKUP(B46,$B$4:$K$36,8,0) -> 1390 | D46: =ROUNDDOWN((C46/E46-2),0) -> 109 | E46: =12.5 -> 12.5 | F46: =C46-D46*E46-2*J46 -> 11.5 | G46: =VLOOKUP(B46,$B$4:$J$72,6,0) -> 70 | H46: 6 | I46: =(G46-J46*2)/H46 -> 9 | J46: 8 | K46: =VLOOKUP(B46,$B$4:$K$36,2,0) -> 605.574 | L46: =VLOOKUP(B46,$B$4:$K$36,3,0) -> 665.593 | M46: =ROUND((L46-5)/12.5,0)-1 -> 52 | N46: =(L46-5-P46)/M46 -> 12.549865 | O46: =(K46-P46-5)/M46 -> 11.395654 | P46: 8 | Q46: =VLOOKUP($B46,$B$4:$K$36,7,0) -> 80 | R46: 8 | S46: =(Q46-2*J46)/R46 -> 8 | T46: =VLOOKUP($B46,$B$4:$K$36,4,0) -> 2000 | U46: =ROUNDDOWN(T46/V46,0)-1 -> 159 | V46: 12.5 | W46: =VLOOKUP($B46,$B$4:$K$36,5,0) -> 2000 | X46: =U46 -> 159 | Y46: =(W46-Z46*2)/X46 -> 12.5 | Z46: =(T46-U46*V46)/2 -> 6.25 | AA46: =L46-M46*12.5-5 -> 10.593
B47: =B12 -> ZU9-1 | C47: =VLOOKUP(B47,$B$4:$K$36,8,0) -> 1390 | D47: =ROUNDDOWN((C47/E47-2),0) -> 109 | E47: =12.5 -> 12.5 | F47: =C47-D47*E47-2*J47 -> 11.5 | G47: =VLOOKUP(B47,$B$4:$J$72,6,0) -> 70 | H47: 6 | I47: =(G47-J47*2)/H47 -> 9 | J47: 8 | K47: =VLOOKUP(B47,$B$4:$K$36,2,0) -> 665.683 | L47: =VLOOKUP(B47,$B$4:$K$36,3,0) -> 725.702 | M47: =ROUND((L47-5)/12.5,0)-1 -> 57 | N47: =(L47-5-P47)/M47 -> 12.503544 | O47: =(K47-P47-5)/M47 -> 11.450579 | P47: 8 | Q47: =VLOOKUP($B47,$B$4:$K$36,7,0) -> 80 | R47: 8 | S47: =(Q47-2*J47)/R47 -> 8 | T47: =VLOOKUP($B47,$B$4:$K$36,4,0) -> 2000 | U47: =ROUNDDOWN(T47/V47,0)-1 -> 159 | V47: 12.5 | W47: =VLOOKUP($B47,$B$4:$K$36,5,0) -> 2000 | X47: =U47 -> 159 | Y47: =(W47-Z47*2)/X47 -> 12.5 | Z47: =(T47-U47*V47)/2 -> 6.25 | AA47: =L47-M47*12.5-5 -> 8.202
B48: =B13 -> ZU10-1 | C48: =VLOOKUP(B48,$B$4:$K$36,8,0) -> 1390 | D48: =ROUNDDOWN((C48/E48-2),0) -> 109 | E48: =12.5 -> 12.5 | F48: =C48-D48*E48-2*J48 -> 11.5 | G48: =VLOOKUP(B48,$B$4:$J$72,6,0) -> 70 | H48: 6 | I48: =(G48-J48*2)/H48 -> 9 | J48: 8 | K48: =VLOOKUP(B48,$B$4:$K$36,2,0) -> 725.702 | L48: =VLOOKUP(B48,$B$4:$K$36,3,0) -> 725.702 | M48: =ROUND((L48-5)/12.5,0)-1 -> 57 | N48: =(L48-5-P48)/M48 -> 12.503544 | O48: =(K48-P48-5)/M48 -> 12.503544 | P48: 8 | Q48: =VLOOKUP($B48,$B$4:$K$36,7,0) -> 80 | R48: 8 | S48: =(Q48-2*J48)/R48 -> 8 | T48: =VLOOKUP($B48,$B$4:$K$36,4,0) -> 2000 | U48: =ROUNDDOWN(T48/V48,0)-1 -> 159 | V48: 12.5 | W48: =VLOOKUP($B48,$B$4:$K$36,5,0) -> 2000 | X48: =U48 -> 159 | Y48: =(W48-Z48*2)/X48 -> 12.5 | Z48: =(T48-U48*V48)/2 -> 6.25 | AA48: =L48-M48*12.5-5 -> 8.202
B49: =B14 -> ZU11-1 | C49: =VLOOKUP(B49,$B$4:$K$36,8,0) -> 1410 | D49: =ROUNDDOWN((C49/E49-1),0) -> 111 | E49: =12.5 -> 12.5 | F49: =C49-D49*E49-2*J49 -> 6.5 | G49: =VLOOKUP(B49,$B$4:$J$72,6,0) -> 80 | H49: 6 | I49: =(G49-J49*2)/H49 -> 10.666667 | J49: 8 | K49: =VLOOKUP(B49,$B$4:$K$36,2,0) -> 697.143 | L49: =VLOOKUP(B49,$B$4:$K$36,3,0) -> 760 | M49: =ROUND((L49-5)/12.5,0)-1 -> 59 | N49: =(L49-5-P49)/M49 -> 12.661017 | O49: =(K49-P49-5)/M49 -> 11.595644 | P49: 8 | Q49: =VLOOKUP($B49,$B$4:$K$36,7,0) -> 90 | R49: 8 | S49: =(Q49-2*J49)/R49 -> 9.25 | T49: =VLOOKUP($B49,$B$4:$K$36,4,0) -> 2000 | U49: =ROUNDDOWN(T49/V49,0)-1 -> 159 | V49: 12.5 | W49: =VLOOKUP($B49,$B$4:$K$36,5,0) -> 2000 | X49: =U49 -> 159 | Y49: =(W49-Z49*2)/X49 -> 12.5 | Z49: =(T49-U49*V49)/2 -> 6.25 | AA49: =L49-M49*12.5-5 -> 17.5
B50: =B15 -> ZU12-1 | C50: =VLOOKUP(B50,$B$4:$K$36,8,0) -> 1370 | D50: =ROUNDDOWN((C50/E50-1),0) -> 108 | E50: =12.5 -> 12.5 | F50: =C50-D50*E50-2*J50 -> 4 | G50: =VLOOKUP(B50,$B$4:$J$72,6,0) -> 60 | H50: 6 | I50: =(G50-J50*2)/H50 -> 7.3333333 | J50: 8 | K50: =VLOOKUP(B50,$B$4:$K$36,2,0) -> 634.192 | L50: =VLOOKUP(B50,$B$4:$K$36,3,0) -> 697.049 | M50: =ROUND((L50-5)/12.5,0)-1 -> 54 | N50: =(L50-5-P50)/M50 -> 12.667574 | O50: =(K50-P50-5)/M50 -> 11.503556 | P50: 8 | Q50: =VLOOKUP($B50,$B$4:$K$36,7,0) -> 70 | R50: 8 | S50: =(Q50-2*J50)/R50 -> 6.75 | T50: =VLOOKUP($B50,$B$4:$K$36,4,0) -> 2000 | U50: =ROUNDDOWN(T50/V50,0)-1 -> 159 | V50: 12.5 | W50: =VLOOKUP($B50,$B$4:$K$36,5,0) -> 2000 | X50: =U50 -> 159 | Y50: =(W50-Z50*2)/X50 -> 12.5 | Z50: =(T50-U50*V50)/2 -> 6.25 | AA50: =L50-M50*12.5-5 -> 17.049
B51: =B16 -> ZU13-1 | C51: =VLOOKUP(B51,$B$4:$K$36,8,0) -> 1370 | D51: =ROUNDDOWN((C51/E51-1),0) -> 108 | E51: =12.5 -> 12.5 | F51: =C51-D51*E51-2*J51 -> 4 | G51: =VLOOKUP(B51,$B$4:$J$72,6,0) -> 60 | H51: 6 | I51: =(G51-J51*2)/H51 -> 7.3333333 | J51: 8 | K51: =VLOOKUP(B51,$B$4:$K$36,2,0) -> 571.241 | L51: =VLOOKUP(B51,$B$4:$K$36,3,0) -> 634.098 | M51: =ROUND((L51-5)/12.5,0)-1 -> 49 | N51: =(L51-5-P51)/M51 -> 12.675469 | O51: =(K51-P51-5)/M51 -> 11.392673 | P51: 8 | Q51: =VLOOKUP($B51,$B$4:$K$36,7,0) -> 70 | R51: 6 | S51: =(Q51-2*J51)/R51 -> 9 | T51: =VLOOKUP($B51,$B$4:$K$36,4,0) -> 2000 | U51: =ROUNDDOWN(T51/V51,0)-1 -> 159 | V51: 12.5 | W51: =VLOOKUP($B51,$B$4:$K$36,5,0) -> 2000 | X51: =U51 -> 159 | Y51: =(W51-Z51*2)/X51 -> 12.5 | Z51: =(T51-U51*V51)/2 -> 6.25 | AA51: =L51-M51*12.5-5 -> 16.598
B52: =B17 -> ZU14-1 | C52: =VLOOKUP(B52,$B$4:$K$36,8,0) -> 1370 | D52: =ROUNDDOWN((C52/E52-1),0) -> 108 | E52: =12.5 -> 12.5 | F52: =C52-D52*E52-2*J52 -> 4 | G52: =VLOOKUP(B52,$B$4:$J$72,6,0) -> 60 | H52: 4 | I52: =(G52-J52*2)/H52 -> 11 | J52: 8 | K52: =VLOOKUP(B52,$B$4:$K$36,2,0) -> 515.414 | L52: =VLOOKUP(B52,$B$4:$K$36,3,0) -> 571.147 | M52: =ROUND((L52-5)/12.5,0)-1 -> 44 | N52: =(L52-5-P52)/M52 -> 12.685159 | O52: =(K52-P52-5)/M52 -> 11.4185 | P52: 8 | Q52: =VLOOKUP($B52,$B$4:$K$36,7,0) -> 70 | R52: 6 | S52: =(Q52-2*J52)/R52 -> 9 | T52: =VLOOKUP($B52,$B$4:$K$36,4,0) -> 2000 | U52: =ROUNDDOWN(T52/V52,0)-1 -> 159 | V52: 12.5 | W52: =VLOOKUP($B52,$B$4:$K$36,5,0) -> 2000 | X52: =U52 -> 159 | Y52: =(W52-Z52*2)/X52 -> 12.5 | Z52: =(T52-U52*V52)/2 -> 6.25 | AA52: =L52-M52*12.5-5 -> 16.147
B53: =B18 -> ZU15-1 | C53: =VLOOKUP(B53,$B$4:$K$36,8,0) -> 1370 | D53: =ROUNDDOWN((C53/E53-1),0) -> 108 | E53: =12.5 -> 12.5 | F53: =C53-D53*E53-2*J53 -> 4 | G53: =VLOOKUP(B53,$B$4:$J$72,6,0) -> 60 | H53: 4 | I53: =(G53-J53*2)/H53 -> 11 | J53: 8 | K53: =VLOOKUP(B53,$B$4:$K$36,2,0) -> 459.598 | L53: =VLOOKUP(B53,$B$4:$K$36,3,0) -> 515.33 | M53: =ROUND((L53-5)/12.5,0)-1 -> 40 | N53: =(L53-5-P53)/M53 -> 12.55825 | O53: =(K53-P53-5)/M53 -> 11.16495 | P53: 8 | Q53: =VLOOKUP($B53,$B$4:$K$36,7,0) -> 70 | R53: 6 | S53: =(Q53-2*J53)/R53 -> 9 | T53: =VLOOKUP($B53,$B$4:$K$36,4,0) -> 2000 | U53: 159 | V53: 12.5 | W53: =VLOOKUP($B53,$B$4:$K$36,5,0) -> 2000 | X53: =U53 -> 159 | Y53: =(W53-Z53*2)/X53 -> 12.5 | Z53: =(T53-U53*V53)/2 -> 6.25 | AA53: =L53-M53*12.5-5 -> 10.33
B54: =B19 -> ZU16-1 | C54: =VLOOKUP(B54,$B$4:$K$36,8,0) -> 1350 | D54: =ROUNDDOWN((C54/E54-2),0) -> 106 | E54: =12.5 -> 12.5 | F54: =C54-D54*E54-2*J54 -> 9 | G54: =VLOOKUP(B54,$B$4:$J$72,6,0) -> 50 | H54: 4 | I54: =(G54-J54*2)/H54 -> 8.5 | J54: 8 | K54: =VLOOKUP(B54,$B$4:$K$36,2,0) -> 403.781 | L54: =VLOOKUP(B54,$B$4:$K$36,3,0) -> 459.514 | M54: =ROUND((L54-5)/12.5,0)-1 -> 35 | N54: =(L54-5-P54)/M54 -> 12.757543 | O54: =(K54-P54-5)/M54 -> 11.165171 | P54: 8 | Q54: =VLOOKUP($B54,$B$4:$K$36,7,0) -> 60 | R54: 4 | S54: =(Q54-2*J54)/R54 -> 11 | T54: =VLOOKUP($B54,$B$4:$K$36,4,0) -> 2000 | U54: =ROUNDDOWN(T54/V54,0)-1 -> 159 | V54: 12.5 | W54: =VLOOKUP($B54,$B$4:$K$36,5,0) -> 2000 | X54: =U54 -> 159 | Y54: =(W54-Z54*2)/X54 -> 12.5 | Z54: =(T54-U54*V54)/2 -> 6.25 | AA54: =L54-M54*12.5-5 -> 17.014
B55: =B20 -> ZU17-1 | C55: =VLOOKUP(B55,$B$4:$K$36,8,0) -> 1350 | D55: =ROUNDDOWN((C55/E55-2),0) -> 106 | E55: =12.5 -> 12.5 | F55: =C55-D55*E55-2*J55 -> 9 | G55: =VLOOKUP(B55,$B$4:$J$72,6,0) -> 50 | H55: 4 | I55: =(G55-J55*2)/H55 -> 8.5 | J55: 8 | K55: =VLOOKUP(B55,$B$4:$K$36,2,0) -> 347.965 | L55: =VLOOKUP(B55,$B$4:$K$36,3,0) -> 403.698 | M55: =ROUND((L55-5)/12.5,0)-1 -> 31 | N55: =(L55-5-P55)/M55 -> 12.603161 | O55: =(K55-P55-5)/M55 -> 10.805323 | P55: 8 | Q55: =VLOOKUP($B55,$B$4:$K$36,7,0) -> 60 | R55: =H55+1 -> 5 | S55: =(Q55-2*J55)/R55 -> 8.8 | T55: =VLOOKUP($B55,$B$4:$K$36,4,0) -> 2000 | U55: =ROUNDDOWN(T55/V55,0)-1 -> 159 | V55: 12.5 | W55: =VLOOKUP($B55,$B$4:$K$36,5,0) -> 2000 | X55: =U55 -> 159 | Y55: =(W55-Z55*2)/X55 -> 12.5 | Z55: =(T55-U55*V55)/2 -> 6.25 | AA55: =L55-M55*12.5-5 -> 11.198
B56: =B21 -> ZU18-1 | C56: =VLOOKUP(B56,$B$4:$K$36,8,0) -> 1336.2 | D56: =ROUNDDOWN((C56/E56-1),0) -> 105 | E56: =12.5 -> 12.5 | F56: =C56-D56*E56-2*J56 -> 7.7 | G56: =VLOOKUP(B56,$B$4:$J$72,6,0) -> 40 | H56: 3 | I56: =(G56-J56*2)/H56 -> 8 | J56: 8 | K56: =VLOOKUP(B56,$B$4:$K$36,2,0) -> 292.149 | L56: =VLOOKUP(B56,$B$4:$K$36,3,0) -> 347.881 | M56: =ROUND((L56-5)/12.5,0)-1 -> 26 | N56: =(L56-5-P56)/M56 -> 12.880038 | O56: =(K56-P56-5)/M56 -> 10.7365 | P56: 8 | Q56: =VLOOKUP($B56,$B$4:$K$36,7,0) -> 50 | R56: =H56+1 -> 4 | S56: =(Q56-2*J56)/R56 -> 8.5 | T56: =VLOOKUP($B56,$B$4:$K$36,4,0) -> 2000 | U56: =ROUNDDOWN(T56/V56,0)-1 -> 159 | V56: 12.5 | W56: =VLOOKUP($B56,$B$4:$K$36,5,0) -> 2000 | X56: =U56 -> 159 | Y56: =(W56-Z56*2)/X56 -> 12.5 | Z56: =(T56-U56*V56)/2 -> 6.25 | AA56: =L56-M56*12.5-5 -> 17.881
...
