Workbook
Name _P1: [1]钢轨桩计算!$C$10
Name _P1: [2]钢轨桩计算!$C$10
Name D0: [2]钢轨桩计算!$H$25
Name D0: [1]钢轨桩计算!$H$25
Name D0: [3]钢轨桩计算!$H$25
Name gj: #REF!
Name gjzj: #REF!
Name H: [2]钢轨桩计算!$C$2
Name H: [1]钢轨桩计算!$C$2
Name H: [3]钢轨桩计算!$C$2
Name jd: SIN(RADIANS([3]框架结构!$B$2))
Name name: [4]工字钢数据!$A$2:$A$3
Name subject: [4]工字钢数据!$B$1:$C$1
Name x: [5]后背钢轨桩计算!$J$16
Name y: [2]钢轨桩计算!$D$17
Name y: [1]钢轨桩计算!$D$17
Name y: [3]钢轨桩计算!$D$17
Name γ: [1]钢轨桩计算!$C$5
Name γ: [2]钢轨桩计算!$C$5
Name θ: [1]钢轨桩计算!$C$8
Name θ: [2]钢轨桩计算!$C$8
Name λ: [1]钢轨桩计算!$C$9
Name λ: [2]钢轨桩计算!$C$9
Name σh: [2]钢轨桩计算!$C$11
Name σh: [1]钢轨桩计算!$C$11
Name σh: [3]钢轨桩计算!$C$11
Name φ: [1]钢轨桩计算!$C$6
Name φ: [2]钢轨桩计算!$C$6
Name 边墙厚度: [3]框架结构!$C$10
Name 打入工作坑以下H: [2]钢轨桩计算!$C$3
Name 打入工作坑以下H: [1]钢轨桩计算!$C$3
Name 打入工作坑以下H: [3]钢轨桩计算!$C$3
Name 底板厚度: [3]框架结构!$C$9
Name 第1页________共1页: #REF!
Name 顶板厚度: [3]框架结构!$C$8
Name 钢筋直径: #REF!
Name 钢筋直径: #REF!
Name 钢筋直径: #REF!
Name 工字钢长度H: [1]钢轨桩计算!$C$2
Name 工字钢长度H: [2]钢轨桩计算!$C$2
Name 工作坑底面以上主动土动力P1: [1]钢轨桩计算!$C$10
Name 工作坑底面以上主动土动力P1: [2]钢轨桩计算!$C$10
Name 结构净高: [3]框架结构!$C$7
Name 结构总高: [3]框架结构!$C$4
Name 结构总宽: [3]框架结构!$C$3
Name 孔数: [2]框架结构!$F$1
Name 孔数: [1]框架结构!$F$1
Name 孔数: [3]框架结构!$F$1
Name 面坡斜度: #REF!
Name 内摩擦角φ: [1]钢轨桩计算!$C$6
Name 内摩擦角φ: [2]钢轨桩计算!$C$6
Name 破裂角θ: [1]钢轨桩计算!$C$8
Name 破裂角θ: [2]钢轨桩计算!$C$8
Name 刃角长度: [3]框架结构!$D$17
Name 填土高度h: [1]钢轨桩计算!$C$4
Name 填土高度h: [2]钢轨桩计算!$C$4
Name 土容重γ: [1]钢轨桩计算!$C$5
Name 土容重γ: [2]钢轨桩计算!$C$5
Name 推力系数λ: [1]钢轨桩计算!$C$9
Name 推力系数λ: [2]钢轨桩计算!$C$9

Sheet 机非分隔带2023.1
B1: U型槽 编号 | C1: L (cm) | D1: H起 (cm) | E1: H终 (cm) | F1: B (cm) | G1: T (cm) | H1: n | I1: e1 (cm) | J1: n1 | K1: d1 (cm) | L1: n2 | M1: d2 (cm) | N1: a (cm) | O1: m | P1: b (cm) | Q1: e2 (cm) | R1: 数量 | S1: h1 (cm) | T1: h2 (cm) | V1: h3 (cm) | W1: h4 (cm) | X1: n3 | Y1: d3 (cm) | Z1: n4 | AA1: d4 (cm) | AB1: a1 | AC1: 混凝土
A2: 14 | B2: ='0.结构参数'!A41 -> YU1 | C2: ='0.结构参数'!D41*100 -> 2000 | D2: ='0.结构参数'!O41*100 -> 241 | E2: ='0.结构参数'!P41*100 -> 256.022 | F2: 30 | G2: ='0.结构参数'!K41*100 -> 40 | H2: =ROUNDDOWN((C2-12.5)/12.5,0) -> 159 | I2: =ROUND((C2-H2*12.5)/2,2) -> 6.25 | J2: =L2 -> 5 | K2: =ROUND((S2-8-N2)/J2,1) -> 12.5 | L2: =ROUNDDOWN(((S2+T2)/2-8)/12.5,0) -> 5 | M2: =ROUND((T2-N2-8)/L2,1) -> 12.5 | N2: =(S2+T2)/2-8-L2*12.5 -> 10.5 | O2: 1 | P2: =(F2-Q2*2)/O2 -> 14 | Q2: 8 | R2: 1 | S2: =IF(('0.结构参数'!K5+0.2-'0.结构参数'!P5)<=0.81,0.81,('0.结构参数'!K5+0.2-'0.结构参数'!P5))*100 -> 81 | T2: =IF(('0.结构参数'!L5+0.2-'0.结构参数'!Q5)<=0.81,0.81,('0.结构参数'!L5+0.2-'0.结构参数'!Q5))*100 -> 81 | U2: =12.5-N2 -> 2 | V2: =('0.结构参数'!P5-'0.结构参数'!I5)*100 -> 160 | W2: =('0.结构参数'!Q5-'0.结构参数'!J5)*100 -> 175.022 | X2: =ROUNDDOWN(((V2+W2)/2-(12.5-N2))/12.5,0) -> 13 | Y2: =ROUND((V2-(12.5-N2)-AB2)/X2,1) -> 11.9 | Z2: =X2 -> 13 | AA2: =ROUND((W2-(12.5-N2)-AB2)/Z2,1) -> 13.1 | AB2: =(V2+W2)/2-(12.5-N2)-X2*12.5 -> 3.011 | AC2: =(((E2+D2)/2*F2)+(45*(V2+W2+81)/2-753)+((S2+T2)/2-81)*30)/10000*C2/100 -> 32.12565 | AD2: 净保护层 | AE2: 4
A3: 14 | B3: ='0.结构参数'!A42 -> YU2 | C3: ='0.结构参数'!D42*100 -> 2000 | D3: ='0.结构参数'!O42*100 -> 256.03 | E3: ='0.结构参数'!P42*100 -> 251.02 | F3: 30 | G3: ='0.结构参数'!K42*100 -> 40 | H3: =ROUNDDOWN((C3-12.5)/12.5,0) -> 159 | I3: =ROUND((C3-H3*12.5)/2,2) -> 6.25 | J3: =L3 -> 5 | K3: =ROUND((S3-8-N3)/J3,1) -> 12.5 | L3: =ROUNDDOWN(((S3+T3)/2-8)/12.5,0) -> 5 | M3: =ROUND((T3-N3-8)/L3,1) -> 12.5 | N3: =(S3+T3)/2-8-L3*12.5 -> 10.5 | O3: 1 | P3: =(F3-Q3*2)/O3 -> 14 | Q3: 8 | R3: 1 | S3: =IF(('0.结构参数'!K6+0.2-'0.结构参数'!P6)<=0.81,0.81,('0.结构参数'!K6+0.2-'0.结构参数'!P6))*100 -> 81 | T3: =IF(('0.结构参数'!L6+0.2-'0.结构参数'!Q6)<=0.81,0.81,('0.结构参数'!L6+0.2-'0.结构参数'!Q6))*100 -> 81 | U3: =12.5-N3 -> 2 | V3: =('0.结构参数'!P6-'0.结构参数'!I6)*100 -> 175.03 | W3: =('0.结构参数'!Q6-'0.结构参数'!J6)*100 -> 170.02 | X3: =ROUNDDOWN(((V3+W3)/2-(12.5-N3))/12.5,0) -> 13 | Y3: =ROUND((V3-(12.5-N3)-AB3)/X3,1) -> 12.7 | Z3: =X3 -> 13 | AA3: =ROUND((W3-(12.5-N3)-AB3)/Z3,1) -> 12.3 | AB3: =(V3+W3)/2-(12.5-N3)-X3*12.5 -> 8.025 | AC3: =(((E3+D3)/2*F3)+(45*(V3+W3+81)/2-753)+((S3+T3)/2-81)*30)/10000*C3/100 -> 32.87775
A4: 14 | B4: ='0.结构参数'!A43 -> YU3 | C4: ='0.结构参数'!D43*100 -> 2000 | D4: ='0.结构参数'!O43*100 -> 250.998 | E4: ='0.结构参数'!P43*100 -> 231.965 | F4: 30 | G4: ='0.结构参数'!K43*100 -> 50 | H4: =ROUNDDOWN((C4-12.5)/12.5,0) -> 159 | I4: =ROUND((C4-H4*12.5)/2,2) -> 6.25 | J4: =L4 -> 5 | K4: =ROUND((S4-8-N4)/J4,1) -> 12.5 | L4: =ROUNDDOWN(((S4+T4)/2-8)/12.5,0) -> 5 | M4: =ROUND((T4-N4-8)/L4,1) -> 12.5 | N4: =(S4+T4)/2-8-L4*12.5 -> 10.5 | O4: 1 | P4: =(F4-Q4*2)/O4 -> 14 | Q4: 8 | R4: 1 | S4: =IF(('0.结构参数'!K7+0.2-'0.结构参数'!P7)<=0.81,0.81,('0.结构参数'!K7+0.2-'0.结构参数'!P7))*100 -> 81 | T4: =IF(('0.结构参数'!L7+0.2-'0.结构参数'!Q7)<=0.81,0.81,('0.结构参数'!L7+0.2-'0.结构参数'!Q7))*100 -> 81 | U4: =12.5-N4 -> 2 | V4: =('0.结构参数'!P7-'0.结构参数'!I7)*100 -> 169.998 | W4: =('0.结构参数'!Q7-'0.结构参数'!J7)*100 -> 150.965 | X4: =ROUNDDOWN(((V4+W4)/2-(12.5-N4))/12.5,0) -> 12 | Y4: =ROUND((V4-(12.5-N4)-AB4)/X4,1) -> 13.3 | Z4: =X4 -> 12 | AA4: =ROUND((W4-(12.5-N4)-AB4)/Z4,1) -> 11.7 | AB4: =(V4+W4)/2-(12.5-N4)-X4*12.5 -> 8.4815 | AC4: =(((E4+D4)/2*F4)+(45*(V4+W4+81)/2-753)+((S4+T4)/2-81)*30)/10000*C4/100 -> 31.071225
A5: 14 | B5: ='0.结构参数'!A44 -> YU4 | C5: ='0.结构参数'!D44*100 -> 2000 | D5: ='0.结构参数'!O44*100 -> 231.936 | E5: ='0.结构参数'!P44*100 -> 223.911 | F5: 30 | G5: ='0.结构参数'!K44*100 -> 50 | H5: =ROUNDDOWN((C5-12.5)/12.5,0) -> 159 | I5: =ROUND((C5-H5*12.5)/2,2) -> 6.25 | J5: =L5 -> 6 | K5: =ROUND((S5-8-N5)/J5,1) -> 11.5 | L5: =ROUNDDOWN(((S5+T5)/2-8)/12.5,0) -> 6 | M5: =ROUND((T5-N5-8)/L5,1) -> 13.5 | N5: =(S5+T5)/2-8-L5*12.5 -> 3.757 | O5: 1 | P5: =(F5-Q5*2)/O5 -> 14 | Q5: 8 | R5: 1 | S5: =IF(('0.结构参数'!K8+0.2-'0.结构参数'!P8)<=0.81,0.81,('0.结构参数'!K8+0.2-'0.结构参数'!P8))*100 -> 81 | T5: =IF(('0.结构参数'!L8+0.2-'0.结构参数'!Q8)<=0.81,0.81,('0.结构参数'!L8+0.2-'0.结构参数'!Q8))*100 -> 92.514 | U5: =12.5-N5 -> 8.743 | V5: =('0.结构参数'!P8-'0.结构参数'!I8)*100 -> 150.936 | W5: =('0.结构参数'!Q8-'0.结构参数'!J8)*100 -> 131.397 | X5: =ROUNDDOWN(((V5+W5)/2-(12.5-N5))/12.5,0) -> 10 | Y5: =ROUND((V5-(12.5-N5)-AB5)/X5,1) -> 13.5 | Z5: =X5 -> 10 | AA5: =ROUND((W5-(12.5-N5)-AB5)/Z5,1) -> 11.5 | AB5: =(V5+W5)/2-(12.5-N5)-X5*12.5 -> 7.4235 | AC5: =(((E5+D5)/2*F5)+(45*(V5+W5+81)/2-753)+((S5+T5)/2-81)*30)/10000*C5/100 -> 28.864815
A6: 14 | B6: ='0.结构参数'!A45 -> YU5 | C6: ='0.结构参数'!D45*100 -> 2000 | D6: ='0.结构参数'!O45*100 -> 223.926 | E6: ='0.结构参数'!P45*100 -> 233.387 | F6: 30 | G6: ='0.结构参数'!K45*100 -> 60 | H6: =ROUNDDOWN((C6-12.5)/12.5,0) -> 159 | I6: =ROUND((C6-H6*12.5)/2,2) -> 6.25 | J6: =L6 -> 7 | K6: =ROUND((S6-8-N6)/J6,1) -> 10.4 | L6: =ROUNDDOWN(((S6+T6)/2-8)/12.5,0) -> 7 | M6: =ROUND((T6-N6-8)/L6,1) -> 14.6 | N6: =(S6+T6)/2-8-L6*12.5 -> 11.558 | O6: 1 | P6: =(F6-Q6*2)/O6 -> 14 | Q6: 8 | R6: 1 | S6: =IF(('0.结构参数'!K9+0.2-'0.结构参数'!P9)<=0.81,0.81,('0.结构参数'!K9+0.2-'0.结构参数'!P9))*100 -> 92.558 | T6: =IF(('0.结构参数'!L9+0.2-'0.结构参数'!Q9)<=0.81,0.81,('0.结构参数'!L9+0.2-'0.结构参数'!Q9))*100 -> 121.558 | U6: =12.5-N6 -> 0.942 | V6: =('0.结构参数'!P9-'0.结构参数'!I9)*100 -> 131.368 | W6: =('0.结构参数'!Q9-'0.结构参数'!J9)*100 -> 111.829 | X6: =ROUNDDOWN(((V6+W6)/2-(12.5-N6))/12.5,0) -> 9 | Y6: =ROUND((V6-(12.5-N6)-AB6)/X6,1) -> 13.6 | Z6: =X6 -> 9 | AA6: =ROUND((W6-(12.5-N6)-AB6)/Z6,1) -> 11.4 | AB6: =(V6+W6)/2-(12.5-N6)-X6*12.5 -> 8.1565 | AC6: =(((E6+D6)/2*F6)+(45*(V6+W6+81)/2-753)+((S6+T6)/2-81)*30)/10000*C6/100 -> 28.365735
A7: 14 | B7: ='0.结构参数'!A46 -> YU6 | C7: ='0.结构参数'!D46*100 -> 2000 | D7: ='0.结构参数'!O46*100 -> 233.428 | E7: ='0.结构参数'!P46*100 -> 261.196 | F7: 30 | G7: ='0.结构参数'!K46*100 -> 70 | H7: =ROUNDDOWN((C7-12.5)/12.5,0) -> 159 | I7: =ROUND((C7-H7*12.5)/2,2) -> 6.25 | J7: =L7 -> 10 | K7: =ROUND((S7-8-N7)/J7,1) -> 11.1 | L7: =ROUNDDOWN(((S7+T7)/2-8)/12.5,0) -> 10 | M7: =ROUND((T7-N7-8)/L7,1) -> 14 | N7: =(S7+T7)/2-8-L7*12.5 -> 3.101 | O7: 1 | P7: =(F7-Q7*2)/O7 -> 14 | Q7: 8 | R7: 1 | S7: =IF(('0.结构参数'!K10+0.2-'0.结构参数'!P10)<=0.81,0.81,('0.结构参数'!K10+0.2-'0.结构参数'!P10))*100 -> 121.601 | T7: =IF(('0.结构参数'!L10+0.2-'0.结构参数'!Q10)<=0.81,0.81,('0.结构参数'!L10+0.2-'0.结构参数'!Q10))*100 -> 150.601 | U7: =12.5-N7 -> 9.399 | V7: =('0.结构参数'!P10-'0.结构参数'!I10)*100 -> 111.827 | W7: =('0.结构参数'!Q10-'0.结构参数'!J10)*100 -> 110.595 | X7: =ROUNDDOWN(((V7+W7)/2-(12.5-N7))/12.5,0) -> 8 | Y7: =ROUND((V7-(12.5-N7)-AB7)/X7,1) -> 12.6 | Z7: =X7 -> 8 | AA7: =ROUND((W7-(12.5-N7)-AB7)/Z7,1) -> 12.4 | AB7: =(V7+W7)/2-(12.5-N7)-X7*12.5 -> 1.812 | AC7: =(((E7+D7)/2*F7)+(45*(V7+W7+81)/2-753)+((S7+T7)/2-81)*30)/10000*C7/100 -> 30.29277
A8: 14 | B8: ='0.结构参数'!A47 -> YU7 | C8: ='0.结构参数'!D47*100 -> 2000 | D8: ='0.结构参数'!O47*100 -> 261.238 | E8: ='0.结构参数'!P47*100 -> 289.005 | F8: 30 | G8: ='0.结构参数'!K47*100 -> 60 | H8: =ROUNDDOWN((C8-12.5)/12.5,0) -> 159 | I8: =ROUND((C8-H8*12.5)/2,2) -> 6.25 | J8: =L8 -> 12 | K8: =ROUND((S8-8-N8)/J8,1) -> 11.4 | L8: =ROUNDDOWN(((S8+T8)/2-8)/12.5,0) -> 12 | M8: =ROUND((T8-N8-8)/L8,1) -> 13.6 | N8: =(S8+T8)/2-8-L8*12.5 -> 5.6515 | O8: 1 | P8: =(F8-Q8*2)/O8 -> 14 | Q8: 8 | R8: 1 | S8: =IF(('0.结构参数'!K11+0.2-'0.结构参数'!P11)<=0.81,0.81,('0.结构参数'!K11+0.2-'0.结构参数'!P11))*100 -> 150.645 | T8: =IF(('0.结构参数'!L11+0.2-'0.结构参数'!Q11)<=0.81,0.81,('0.结构参数'!L11+0.2-'0.结构参数'!Q11))*100 -> 176.658 | U8: =12.5-N8 -> 6.8485 | V8: =('0.结构参数'!P11-'0.结构参数'!I11)*100 -> 110.593 | W8: =('0.结构参数'!Q11-'0.结构参数'!J11)*100 -> 112.347 | X8: =ROUNDDOWN(((V8+W8)/2-(12.5-N8))/12.5,0) -> 8 | Y8: =ROUND((V8-(12.5-N8)-AB8)/X8,1) -> 12.4 | Z8: =X8 -> 8 | AA8: =ROUND((W8-(12.5-N8)-AB8)/Z8,1) -> 12.6 | AB8: =(V8+W8)/2-(12.5-N8)-X8*12.5 -> 4.6215 | AC8: =(((E8+D8)/2*F8)+(45*(V8+W8+81)/2-753)+((S8+T8)/2-81)*30)/10000*C8/100 -> 33.63768
A9: 14 | B9: ='0.结构参数'!A48 -> YU8 | C9: ='0.结构参数'!D48*100 -> 2000 | D9: ='0.结构参数'!O48*100 -> 289.02 | E9: ='0.结构参数'!P48*100 -> 299.039 | F9: 30 | G9: ='0.结构参数'!K48*100 -> 80 | H9: =ROUNDDOWN((C9-12.5)/12.5,0) -> 159 | I9: =ROUND((C9-H9*12.5)/2,2) -> 6.25 | J9: =L9 -> 13 | K9: =ROUND((S9-8-N9)/J9,1) -> 12.3 | L9: =ROUNDDOWN(((S9+T9)/2-8)/12.5,0) -> 13 | M9: =ROUND((T9-N9-8)/L9,1) -> 12.7 | N9: =(S9+T9)/2-8-L9*12.5 -> 9.351 | O9: 1 | P9: =(F9-Q9*2)/O9 -> 14 | Q9: 8 | R9: 1 | S9: =IF(('0.结构参数'!K12+0.2-'0.结构参数'!P12)<=0.81,0.81,('0.结构参数'!K12+0.2-'0.结构参数'!P12))*100 -> 176.684 | T9: =IF(('0.结构参数'!L12+0.2-'0.结构参数'!Q12)<=0.81,0.81,('0.结构参数'!L12+0.2-'0.结构参数'!Q12))*100 -> 183.018 | U9: =12.5-N9 -> 3.149 | V9: =('0.结构参数'!P12-'0.结构参数'!I12)*100 -> 112.336 | W9: =('0.结构参数'!Q12-'0.结构参数'!J12)*100 -> 116.021 | X9: =ROUNDDOWN(((V9+W9)/2-(12.5-N9))/12.5,0) -> 8 | Y9: =ROUND((V9-(12.5-N9)-AB9)/X9,1) -> 12.3 | Z9: =X9 -> 8 | AA9: =ROUND((W9-(12.5-N9)-AB9)/Z9,1) -> 12.7 | AB9: =(V9+W9)/2-(12.5-N9)-X9*12.5 -> 11.0295 | AC9: =(((E9+D9)/2*F9)+(45*(V9+W9+81)/2-753)+((S9+T9)/2-81)*30)/10000*C9/100 -> 35.987895
A10: 16 | B10: ='0.结构参数'!A49 -> YU9 | C10: ='0.结构参数'!D49*100 -> 2000 | D10: ='0.结构参数'!O49*100 -> 299.054 | E10: ='0.结构参数'!P49*100 -> 319.029 | F10: 30 | G10: ='0.结构参数'!K49*100 -> 80 | H10: =ROUNDDOWN((C10-12.5)/12.5,0) -> 159 | I10: =ROUND((C10-H10*12.5)/2,2) -> 6.25 | J10: =L10 -> 13 | K10: =ROUND((S10-8-N10)/J10,1) -> 12.7 | L10: =ROUNDDOWN(((S10+T10)/2-8)/12.5,0) -> 13 | M10: =ROUND((T10-N10-8)/L10,1) -> 12.3 | N10: =(S10+T10)/2-8-L10*12.5 -> 9.5275 | O10: 1 | P10: =(F10-Q10*2)/O10 -> 14 | Q10: 8 | R10: 1 | S10: =IF(('0.结构参数'!K13+0.2-'0.结构参数'!P13)<=0.81,0.81,('0.结构参数'!K13+0.2-'0.结构参数'!P13))*100 -> 183.01 | T10: =IF(('0.结构参数'!L13+0.2-'0.结构参数'!Q13)<=0.81,0.81,('0.结构参数'!L13+0.2-'0.结构参数'!Q13))*100 -> 177.045 | U10: =12.5-N10 -> 2.9725 | V10: =('0.结构参数'!P13-'0.结构参数'!I13)*100 -> 116.044 | W10: =('0.结构参数'!Q13-'0.结构参数'!J13)*100 -> 141.984 | X10: =ROUNDDOWN(((V10+W10)/2-(12.5-N10))/12.5,0) -> 10 | Y10: =ROUND((V10-(12.5-N10)-AB10)/X10,1) -> 11.2 | Z10: =X10 -> 10 | AA10: =ROUND((W10-(12.5-N10)-AB10)/Z10,1) -> 13.8 | AB10: =(V10+W10)/2-(12.5-N10)-X10*12.5 -> 1.0415 | AC10: =(((E10+D10)/2*F10)+(45*(V10+W10+81)/2-753)+((S10+T10)/2-81)*30)/10000*C10/100 -> 38.2344
A11: 16 | B11: ='0.结构参数'!A50 -> YU10 | C11: ='0.结构参数'!D50*100 -> 2000 | D11: ='0.结构参数'!O50*100 -> 318.984 | E11: ='0.结构参数'!P50*100 -> 298.969 | F11: 30 | G11: ='0.结构参数'!K50*100 -> 80 | H11: =ROUNDDOWN((C11-12.5)/12.5,0) -> 159 | I11: =ROUND((C11-H11*12.5)/2,2) -> 6.25 | J11: =L11 -> 13 | K11: =ROUND((S11-8-N11)/J11,1) -> 12.8 | L11: =ROUNDDOWN(((S11+T11)/2-8)/12.5,0) -> 13 | M11: =ROUND((T11-N11-8)/L11,1) -> 12.2 | N11: =(S11+T11)/2-8-L11*12.5 -> 2.438 | O11: 1 | P11: =(F11-Q11*2)/O11 -> 14 | Q11: 8 | R11: 1 | S11: =IF(('0.结构参数'!K14+0.2-'0.结构参数'!P14)<=0.81,0.81,('0.结构参数'!K14+0.2-'0.结构参数'!P14))*100 -> 177.034 | T11: =IF(('0.结构参数'!L14+0.2-'0.结构参数'!Q14)<=0.81,0.81,('0.结构参数'!L14+0.2-'0.结构参数'!Q14))*100 -> 168.842 | U11: =12.5-N11 -> 10.062 | V11: =('0.结构参数'!P14-'0.结构参数'!I14)*100 -> 141.95 | W11: =('0.结构参数'!Q14-'0.结构参数'!J14)*100 -> 130.127 | X11: =ROUNDDOWN(((V11+W11)/2-(12.5-N11))/12.5,0) -> 10 | Y11: =ROUND((V11-(12.5-N11)-AB11)/X11,1) -> 13.1 | Z11: =X11 -> 10 | AA11: =ROUND((W11-(12.5-N11)-AB11)/Z11,1) -> 11.9 | AB11: =(V11+W11)/2-(12.5-N11)-X11*12.5 -> 0.9765 | AC11: =(((E11+D11)/2*F11)+(45*(V11+W11+81)/2-753)+((S11+T11)/2-81)*30)/10000*C11/100 -> 38.437335
A12: 20 | B12: ='0.结构参数'!A51 -> YU11 | C12: ='0.结构参数'!D51*100 -> 2000 | D12: ='0.结构参数'!O51*100 -> 362.58 | E12: ='0.结构参数'!P51*100 -> 309.149 | F12: 30 | G12: ='0.结构参数'!K51*100 -> 90 | H12: =ROUNDDOWN((C12-12.5)/12.5,0) -> 159 | I12: =ROUND((C12-H12*12.5)/2,2) -> 6.25 | J12: =L12 -> 12 | K12: =ROUND((S12-8-N12)/J12,1) -> 12.6 | L12: =ROUNDDOWN(((S12+T12)/2-8)/12.5,0) -> 12 | M12: =ROUND((T12-N12-8)/L12,1) -> 12.4 | N12: =(S12+T12)/2-8-L12*12.5 -> 4.3805 | O12: 1 | P12: =(F12-Q12*2)/O12 -> 14 | Q12: 8 | R12: 1 | S12: =IF(('0.结构参数'!K15+0.2-'0.结构参数'!P15)<=0.81,0.81,('0.结构参数'!K15+0.2-'0.结构参数'!P15))*100 -> 163.444 | T12: =IF(('0.结构参数'!L15+0.2-'0.结构参数'!Q15)<=0.81,0.81,('0.结构参数'!L15+0.2-'0.结构参数'!Q15))*100 -> 161.317 | U12: =12.5-N12 -> 8.1195 | V12: =('0.结构参数'!P15-'0.结构参数'!I15)*100 -> 199.136 | W12: =('0.结构参数'!Q15-'0.结构参数'!J15)*100 -> 147.832 | X12: =ROUNDDOWN(((V12+W12)/2-(12.5-N12))/12.5,0) -> 13 | Y12: =ROUND((V12-(12.5-N12)-AB12)/X12,1) -> 14.5 | Z12: =X12 -> 13 | AA12: =ROUND((W12-(12.5-N12)-AB12)/Z12,1) -> 10.5 | AB12: =(V12+W12)/2-(12.5-N12)-X12*12.5 -> 2.8645 | AC12: =(((E12+D12)/2*F12)+(45*(V12+W12+81)/2-753)+((S12+T12)/2-81)*30)/10000*C12/100 -> 42.78726
A13: 16 | B13: ='0.结构参数'!A52 -> YU12 | C13: ='0.结构参数'!D52*100 -> 2000 | D13: ='0.结构参数'!O52*100 -> 309.082 | E13: ='0.结构参数'!P52*100 -> 273.963 | F13: 30 | G13: ='0.结构参数'!K52*100 -> 70 | H13: =ROUNDDOWN((C13-12.5)/12.5,0) -> 159 | I13: =ROUND((C13-H13*12.5)/2,2) -> 6.25 | J13: =L13 -> 12 | K13: =ROUND((S13-8-N13)/J13,1) -> 12.7 | L13: =ROUNDDOWN(((S13+T13)/2-8)/12.5,0) -> 12 | M13: =ROUND((T13-N13-8)/L13,1) -> 12.3 | N13: =(S13+T13)/2-8-L13*12.5 -> 0.7525 | O13: 1 | P13: =(F13-Q13*2)/O13 -> 14 | Q13: 8 | R13: 1 | S13: =IF(('0.结构参数'!K16+0.2-'0.结构参数'!P16)<=0.81,0.81,('0.结构参数'!K16+0.2-'0.结构参数'!P16))*100 -> 161.311 | T13: =IF(('0.结构参数'!L16+0.2-'0.结构参数'!Q16)<=0.81,0.81,('0.结构参数'!L16+0.2-'0.结构参数'!Q16))*100 -> 156.194 | U13: =12.5-N13 -> 11.7475 | V13: =('0.结构参数'!P16-'0.结构参数'!I16)*100 -> 147.771 | W13: =('0.结构参数'!Q16-'0.结构参数'!J16)*100 -> 117.769 | X13: =ROUNDDOWN(((V13+W13)/2-(12.5-N13))/12.5,0) -> 9 | Y13: =ROUND((V13-(12.5-N13)-AB13)/X13,1) -> 14.2 | Z13: =X13 -> 9 | AA13: =ROUND((W13-(12.5-N13)-AB13)/Z13,1) -> 10.8 | AB13: =(V13+W13)/2-(12.5-N13)-X13*12.5 -> 8.5225 | AC13: =(((E13+D13)/2*F13)+(45*(V13+W13+81)/2-753)+((S13+T13)/2-81)*30)/10000*C13/100 -> 36.2448
A14: 14 | B14: ='0.结构参数'!A53 -> YU13 | C14: ='0.结构参数'!D53*100 -> 2000 | D14: ='0.结构参数'!O53*100 -> 273.925 | E14: ='0.结构参数'!P53*100 -> 257.327 | F14: 30 | G14: ='0.结构参数'!K53*100 -> 70 | H14: =ROUNDDOWN((C14-12.5)/12.5,0) -> 159 | I14: =ROUND((C14-H14*12.5)/2,2) -> 6.25 | J14: =L14 -> 11 | K14: =ROUND((S14-8-N14)/J14,1) -> 12.9 | L14: =ROUNDDOWN(((S14+T14)/2-8)/12.5,0) -> 11 | M14: =ROUND((T14-N14-8)/L14,1) -> 12.1 | N14: =(S14+T14)/2-8-L14*12.5 -> 6.258 | O14: 1 | P14: =(F14-Q14*2)/O14 -> 14 | Q14: 8 | R14: 1 | S14: =IF(('0.结构参数'!K17+0.2-'0.结构参数'!P17)<=0.81,0.81,('0.结构参数'!K17+0.2-'0.结构参数'!P17))*100 -> 156.184 | T14: =IF(('0.结构参数'!L17+0.2-'0.结构参数'!Q17)<=0.81,0.81,('0.结构参数'!L17+0.2-'0.结构参数'!Q17))*100 -> 147.332 | U14: =12.5-N14 -> 6.242 | V14: =('0.结构参数'!P17-'0.结构参数'!I17)*100 -> 117.741 | W14: =('0.结构参数'!Q17-'0.结构参数'!J17)*100 -> 109.995 | X14: =ROUNDDOWN(((V14+W14)/2-(12.5-N14))/12.5,0) -> 8 | Y14: =ROUND((V14-(12.5-N14)-AB14)/X14,1) -> 13 | Z14: =X14 -> 8 | AA14: =ROUND((W14-(12.5-N14)-AB14)/Z14,1) -> 12 | AB14: =(V14+W14)/2-(12.5-N14)-X14*12.5 -> 7.626 | AC14: =(((E14+D14)/2*F14)+(45*(V14+W14+81)/2-753)+((S14+T14)/2-81)*30)/10000*C14/100 -> 32.57016
... A20: 14 | B20: ='0.结构参数'!A59 -> YU19 | C20: ='0.结构参数'!D59*100 -> 1547.05 | D20: ='0.结构参数'!O59*100 -> 289.315 | E20: ='0.结构参数'!P59*100 -> 281 | F20: 30 | G20: ='0.结构参数'!K59*100 -> 40 | H20: =ROUNDDOWN((C20-12.5)/12.5,0) -> 122 | I20: =ROUND((C20-H20*12.5)/2,2) -> 11.03 | J20: =L20 -> 5 | K20: =ROUND((S20-8-N20)/J20,1) -> 12.5 | L20: =ROUNDDOWN(((S20+T20)/2-8)/12.5,0) -> 5 | M20: =ROUND((T20-N20-8)/L20,1) -> 12.5 | N20: =(S20+T20)/2-8-L20*12.5 -> 10.5 | O20: 1 | P20: =(F20-Q20*2)/O20 -> 14 | Q20: 8 | R20: 1 | S20: =IF(('0.结构参数'!K23+0.2-'0.结构参数'!P23)<=0.81,0.81,('0.结构参数'!K23+0.2-'0.结构参数'!P23))*100 -> 81 | T20: =IF(('0.结构参数'!L23+0.2-'0.结构参数'!Q23)<=0.81,0.81,('0.结构参数'!L23+0.2-'0.结构参数'!Q23))*100 -> 81 | U20: =12.5-N20 -> 2 | V20: =('0.结构参数'!P23-'0.结构参数'!I23)*100 -> 208.315 | W20: =('0.结构参数'!Q23-'0.结构参数'!J23)*100 -> 200 | X20: =ROUNDDOWN(((V20+W20)/2-(12.5-N20))/12.5,0) -> 16 | Y20: =ROUND((V20-(12.5-N20)-AB20)/X20,1) -> 12.8 | Z20: =X20 -> 16 | AA20: =ROUND((W20-(12.5-N20)-AB20)/Z20,1) -> 12.2 | AB20: =(V20+W20)/2-(12.5-N20)-X20*12.5 -> 2.1575 | AC20: =(((E20+D20)/2*F20)+(45*(V20+W20+81)/2-753)+((S20+T20)/2-81)*30)/10000*C20/100 -> 29.102041
B22: =B2 -> YU1 | C22: =VLOOKUP($B22,$B$2:$AB$21,2,0) -> 2000 | D22: =VLOOKUP($B22,$B$2:$AB$21,3,0) -> 241 | E22: =VLOOKUP($B22,$B$2:$AB$21,4,0) -> 256.022 | F22: =VLOOKUP($B22,$B$2:$AB$21,5,0) -> 30 | G22: =VLOOKUP($B22,$B$2:$AB$21,6,0) -> 40 | H22: =VLOOKUP($B22,$B$2:$AB$21,7,0) -> 159 | I22: =VLOOKUP($B22,$B$2:$AB$21,8,0) -> 6.25 | J22: =VLOOKUP($B22,$B$2:$AB$21,9,0) -> 5 | K22: =VLOOKUP($B22,$B$2:$AB$21,10,0) -> 12.5 | L22: =VLOOKUP($B22,$B$2:$AB$21,11,0) -> 5 | M22: =VLOOKUP($B22,$B$2:$AB$21,12,0) -> 12.5 | N22: =VLOOKUP($B22,$B$2:$AB$21,13,0) -> 10.5 | O22: =VLOOKUP($B22,$B$2:$AB$21,14,0) -> 1 | P22: =VLOOKUP($B22,$B$2:$AB$21,15,0) -> 14 | Q22: =VLOOKUP($B22,$B$2:$AB$21,16,0) -> 8 | R22: =VLOOKUP($B22,$B$2:$AB$21,17,0) -> 1 | S22: =VLOOKUP($B22,$B$2:$AB$21,18,0) -> 81 | T22: =VLOOKUP($B22,$B$2:$AB$21,19,0) -> 81 | U22: =VLOOKUP($B22,$B$2:$AB$21,20,0) -> 2 | V22: =VLOOKUP($B22,$B$2:$AB$21,21,0) -> 160 | W22: =VLOOKUP($B22,$B$2:$AB$21,22,0) -> 175.022 | X22: =VLOOKUP($B22,$B$2:$AB$21,23,0) -> 13 | Y22: =VLOOKUP($B22,$B$2:$AB$21,24,0) -> 11.9 | Z22: =VLOOKUP($B22,$B$2:$AB$21,25,0) -> 13 | AA22: =VLOOKUP($B22,$B$2:$AB$21,26,0) -> 13.1 | AB22: =VLOOKUP($B22,$B$2:$AB$21,27,0) -> 3.011
B23: =B22 -> YU1 | C23: 编号 | D23: 规格 | E23: 大样 | H23: 单根长 | I23: 根数 | J23: 总长 | K23: 每米重 | L23: 总重
E24: a | F24: b | G24: c | P24: d | Q24: e
C25: N1 | D25: =A2 -> 14 | E25: 22 | F25: =O25 -> 273~288 | G25: =ROUNDUP((IF(D25<26,10.927,11.212))*D25/10,1) -> 15.3 | H25: =(M25+N25)/2+E25+G25+P25 -> 409.6 | I25: =H22+1 -> 160 | J25: =H25*I25/100 -> 655.36 | K25: =ROUND(D25^2*PI()/4/1000000*7850,3) -> 1.208 | L25: =J25*K25 -> 791.67488 | M25: =ROUND((D22+G22-$AE$2*2),1) -> 273 | N25: =ROUND((E22+G22-2*$AE$2),1) -> 288 | O25: =ROUND(M25,1)&"~"&ROUND(N25,1) -> 273~288 | P25: =56.8+25*D25/10 -> 91.8 | Q25: =ROUND(R25,1)&"~"&ROUND(S25,1) -> 0~0 | R25: =S22-81 -> 0 | S25: =T22-81 -> 0
C26: N2 | D26: =D25 -> 14 | E26: =22.5+D26*25/10 -> 57.5 | F26: =O26 -> 202.5~217.5 | G26: =ROUNDUP((IF(D26<26,10.927,11.212))*D26/10,1) -> 15.3 | H26: =(M26+N26)/2+E26+G26 -> 282.8 | I26: =I25 -> 160 | J26: =H26*I26/100 -> 452.48 | K26: =ROUND(D26^2*PI()/4/1000000*7850,3) -> 1.208 | L26: =J26*K26 -> 546.59584 | M26: =ROUND((D22+G22-$AE$2*2-70.5),1) -> 202.5 | N26: =ROUND((E22+G22-2*$AE$2-70.5),1) -> 217.5 | O26: =ROUND(M26,1)&"~"&ROUND(N26,1) -> 202.5~217.5
C27: N3 | D27: =D25 -> 14 | E27: =F22-2*$AE$2 -> 22 | F27: =F25 -> 273~288 | G27: 0 | H27: =(M27+N27)+E27 -> 583 | I27: =I25 -> 160 | J27: =H27*I27/100 -> 932.8 | K27: =ROUND(D27^2*PI()/4/1000000*7850,3) -> 1.208 | L27: =J27*K27 -> 1126.8224 | M27: =M25 -> 273 | N27: =N25 -> 288
C28: N4 | D28: 14 | E28: 0 | F28: =ROUND(((C22-2*$AE$2)^2+(E22-D22)^2)^0.5,1) -> 1992.1 | G28: =ROUNDUP((IF(D28<26,10.927,11.212))*D28/10,0) -> 16 | H28: =F28+G28*2 -> 2024.1 | I28: =(J22+1+X22+1)*2+(O22+1)*2 -> 44 | J28: =H28*I28/100 -> 890.604 | K28: =ROUND(D28^2*PI()/4/1000000*7850,3) -> 1.208 | L28: =J28*K28 -> 1075.8496
C29: N5 | D29: 8 | E29: 0 | F29: =F22-2*$AE$2 -> 22 | G29: 11 | H29: =F29+G29 -> 33 | I29: =ROUNDUP(H22/2,0)*(L22+X22+1)/2 -> 760 | J29: =H29*I29/100 -> 250.8 | K29: =ROUND(D29^2*PI()/4/1000000*7850,3) -> 0.395 | L29: =J29*K29 -> 99.066
C30: N5-1 | D30: 8 | E30: 0 | F30: 22 | G30: 11 | H30: =F30+G30 -> 33 | I30: =ROUNDUP(H22/2,0)*(((L22+1)/2)-2) -> 80 | J30: =H30*I30/100 -> 26.4 | K30: =ROUND(D30^2*PI()/4/1000000*7850,3) -> 0.395 | L30: =J30*K30 -> 10.428
C31: N5-2 | D31: 8 | E31: 0 | F31: 25.7~28.3 | G31: 11 | H31: =(25.7+28.3)/2+G31 -> 38 | I31: =H22+1 -> 160 | J31: =H31*I31/100 -> 60.8 | K31: =ROUND(D31^2*PI()/4/1000000*7850,3) -> 0.395 | L31: =J31*K31 -> 24.016
C32: N5-3 | D32: 8 | E32: 0 | F32: =45-2*$AE$2 -> 37 | G32: 11 | H32: =F32+G32 -> 48 | I32: =ROUNDUP(H22/2,0)*X22/2 -> 520 | J32: =H32*I32/100 -> 249.6 | K32: =ROUND(D32^2*PI()/4/1000000*7850,3) -> 0.395 | L32: =J32*K32 -> 98.592
B33: 合计： | C33: HPB300钢筋： | E33: =SUM(L29:L32) -> 232.102 | G33: HRB400钢筋： | I33: =SUM(L25:L28) -> 3540.9428 | J33: c40混凝土： | L33: =AC2 -> 32.12565 | M33: =(E33+I33)/L33 -> 117.44649
B34: 全桥合计： | E34: =E33*R22 -> 232.102 | I34: =I33*R22 -> 3540.9428 | L34: =L33*R22 -> 32.12565
B36: =B3 -> YU2 | C36: =VLOOKUP($B36,$B$2:$AB$21,2,0) -> 2000 | D36: =VLOOKUP($B36,$B$2:$AB$21,3,0) -> 256.03 | E36: =VLOOKUP($B36,$B$2:$AB$21,4,0) -> 251.02 | F36: =VLOOKUP($B36,$B$2:$AB$21,5,0) -> 30 | G36: =VLOOKUP($B36,$B$2:$AB$21,6,0) -> 40 | H36: =VLOOKUP($B36,$B$2:$AB$21,7,0) -> 159 | I36: =VLOOKUP($B36,$B$2:$AB$21,8,0) -> 6.25 | J36: =VLOOKUP($B36,$B$2:$AB$21,9,0) -> 5 | K36: =VLOOKUP($B36,$B$2:$AB$21,10,0) -> 12.5 | L36: =VLOOKUP($B36,$B$2:$AB$21,11,0) -> 5 | M36: =VLOOKUP($B36,$B$2:$AB$21,12,0) -> 12.5 | N36: =VLOOKUP($B36,$B$2:$AB$21,13,0) -> 10.5 | O36: =VLOOKUP($B36,$B$2:$AB$21,14,0) -> 1 | P36: =VLOOKUP($B36,$B$2:$AB$21,15,0) -> 14 | Q36: =VLOOKUP($B36,$B$2:$AB$21,16,0) -> 8 | R36: =VLOOKUP($B36,$B$2:$AB$21,17,0) -> 1 | S36: =VLOOKUP($B36,$B$2:$AB$21,18,0) -> 81 | T36: =VLOOKUP($B36,$B$2:$AB$21,19,0) -> 81 | U36: =VLOOKUP($B36,$B$2:$AB$21,20,0) -> 2 | V36: =VLOOKUP($B36,$B$2:$AB$21,21,0) -> 175.03 | W36: =VLOOKUP($B36,$B$2:$AB$21,22,0) -> 170.02 | X36: =VLOOKUP($B36,$B$2:$AB$21,23,0) -> 13 | Y36: =VLOOKUP($B36,$B$2:$AB$21,24,0) -> 12.7 | Z36: =VLOOKUP($B36,$B$2:$AB$21,25,0) -> 13 | AA36: =VLOOKUP($B36,$B$2:$AB$21,26,0) -> 12.3 | AB36: =VLOOKUP($B36,$B$2:$AB$21,27,0) -> 8.025
B37: =B36 -> YU2 | C37: 编号 | D37: 规格 | E37: 大样 | H37: 单根长 | I37: 根数 | J37: 总长 | K37: 每米重 | L37: 总重
E38: a | F38: b | G38: c | P38: d | Q38: e
C39: N1 | D39: =A3 -> 14 | E39: 22 | F39: =O39 -> 288~283 | G39: =ROUNDUP((IF(D39<26,10.927,11.212))*D39/10,1) -> 15.3 | H39: =(M39+N39)/2+E39+G39+P39 -> 414.6 | I39: =H36+1 -> 160 | J39: =H39*I39/100 -> 663.36 | K39: =ROUND(D39^2*PI()/4/1000000*7850,3) -> 1.208 | L39: =J39*K39 -> 801.33888 | M39: =ROUND((D36+G36-$AE$2*2),1) -> 288 | N39: =ROUND((E36+G36-2*$AE$2),1) -> 283 | O39: =ROUND(M39,1)&"~"&ROUND(N39,1) -> 288~283 | P39: =56.8+25*D39/10 -> 91.8 | Q39: =ROUND(R39,1)&"~"&ROUND(S39,1) -> 0~0 | R39: =S36-81 -> 0 | S39: =T36-81 -> 0
C40: N2 | D40: =D39 -> 14 | E40: =22.5+D40*25/10 -> 57.5 | F40: =O40 -> 217.5~212.5 | G40: =ROUNDUP((IF(D40<26,10.927,11.212))*D40/10,1) -> 15.3 | H40: =(M40+N40)/2+E40+G40 -> 287.8 | I40: =I39 -> 160 | J40: =H40*I40/100 -> 460.48 | K40: =ROUND(D40^2*PI()/4/1000000*7850,3) -> 1.208 | L40: =J40*K40 -> 556.25984 | M40: =ROUND((D36+G36-$AE$2*2-70.5),1) -> 217.5 | N40: =ROUND((E36+G36-2*$AE$2-70.5),1) -> 212.5 | O40: =ROUND(M40,1)&"~"&ROUND(N40,1) -> 217.5~212.5
C41: N3 | D41: =D39 -> 14 | E41: =F36-2*$AE$2 -> 22 | F41: =F39 -> 288~283 | G41: 0 | H41: =(M41+N41)+E41 -> 593 | I41: =I39 -> 160 | J41: =H41*I41/100 -> 948.8 | K41: =ROUND(D41^2*PI()/4/1000000*7850,3) -> 1.208 | L41: =J41*K41 -> 1146.1504 | M41: =M39 -> 288 | N41: =N39 -> 283
C42: N4 | D42: 14 | E42: 0 | F42: =ROUND(((C36-2*$AE$2)^2+(E36-D36)^2)^0.5,1) -> 1992 | G42: =ROUNDUP((IF(D42<26,10.927,11.212))*D42/10,0) -> 16 | H42: =F42+G42*2 -> 2024 | I42: =(J36+1+X36+1)*2+(O36+1)*2 -> 44 | J42: =H42*I42/100 -> 890.56 | K42: =ROUND(D42^2*PI()/4/1000000*7850,3) -> 1.208 | L42: =J42*K42 -> 1075.7965
C43: N5 | D43: 8 | E43: 0 | F43: =F36-2*$AE$2 -> 22 | G43: 11 | H43: =F43+G43 -> 33 | I43: =ROUNDUP(H36/2,0)*(L36+X36+1)/2 -> 760 | J43: =H43*I43/100 -> 250.8 | K43: =ROUND(D43^2*PI()/4/1000000*7850,3) -> 0.395 | L43: =J43*K43 -> 99.066
C44: N5-1 | D44: 8 | E44: 0 | F44: 22 | G44: 11 | H44: =F44+G44 -> 33 | I44: =ROUNDUP(H36/2,0)*(((L36+1)/2)-2) -> 80 | J44: =H44*I44/100 -> 26.4 | K44: =ROUND(D44^2*PI()/4/1000000*7850,3) -> 0.395 | L44: =J44*K44 -> 10.428
C45: N5-2 | D45: 8 | E45: 0 | F45: 25.7~28.3 | G45: 11 | H45: =(25.7+28.3)/2+G45 -> 38 | I45: =H36+1 -> 160 | J45: =H45*I45/100 -> 60.8 | K45: =ROUND(D45^2*PI()/4/1000000*7850,3) -> 0.395 | L45: =J45*K45 -> 24.016
C46: N5-3 | D46: 8 | E46: 0 | F46: =45-2*$AE$2 -> 37 | G46: 11 | H46: =F46+G46 -> 48 | I46: =ROUNDUP(H36/2,0)*X36/2 -> 520 | J46: =H46*I46/100 -> 249.6 | K46: =ROUND(D46^2*PI()/4/1000000*7850,3) -> 0.395 | L46: =J46*K46 -> 98.592
B47: 合计： | C47: HPB300钢筋： | E47: =SUM(L43:L46) -> 232.102 | G47: HRB400钢筋： | I47: =SUM(L39:L42) -> 3579.5456 | J47: c40混凝土： | L47: =AC3 -> 32.87775 | M47: =(E47+I47)/L47 -> 115.93396
...

Sheet 2.U型槽钢筋过渡方案
A2: U型槽尺寸表 | B2: 节段 | C2: 净高不含底板厚 | E2: 节段宽 | G2: 边墙厚B | H2: 底板厚T | I2: D | J2: hmin+T | K2: hmax+T | N2: 角度 | O2: 净保护层
C3: Hmin | D3: Hmax | E3: Lmax | F3: Lmin | N3: 90 | O3: 4 | P3: 4
B4: ='0.结构参数'!A41 -> YU1 | C4: =MIN('0.结构参数'!I41,'0.结构参数'!J41)*100 -> 179.116 | D4: =MAX('0.结构参数'!I41,'0.结构参数'!J41)*100 -> 211.515 | E4: =MAX('0.结构参数'!E5,'0.结构参数'!F5)*100 -> 2000 | F4: =MIN('0.结构参数'!E5,'0.结构参数'!F5)*100 -> 2000 | G4: ='0.结构参数'!L41*100 -> 30 | H4: ='0.结构参数'!K41*100 -> 40 | I4: =('0.结构参数'!M41+'0.结构参数'!N41)/2*100 -> 2170 | J4: =(C4+$H4) -> 219.116 | K4: =(D4+$H4) -> 251.515
B5: ='0.结构参数'!A42 -> YU2 | C5: =MIN('0.结构参数'!I42,'0.结构参数'!J42)*100 -> 211.604 | D5: =MAX('0.结构参数'!I42,'0.结构参数'!J42)*100 -> 271.065 | E5: =MAX('0.结构参数'!E6,'0.结构参数'!F6)*100 -> 2000 | F5: =MIN('0.结构参数'!E6,'0.结构参数'!F6)*100 -> 2000 | G5: ='0.结构参数'!L42*100 -> 30 | H5: ='0.结构参数'!K42*100 -> 40 | I5: =('0.结构参数'!M42+'0.结构参数'!N42)/2*100 -> 2170 | J5: =(C5+$H5) -> 251.604 | K5: =(D5+$H5) -> 311.065
B6: ='0.结构参数'!A43 -> YU3 | C6: =MIN('0.结构参数'!I43,'0.结构参数'!J43)*100 -> 271.154 | D6: =MAX('0.结构参数'!I43,'0.结构参数'!J43)*100 -> 330.615 | E6: =MAX('0.结构参数'!E7,'0.结构参数'!F7)*100 -> 2000 | F6: =MIN('0.结构参数'!E7,'0.结构参数'!F7)*100 -> 2000 | G6: ='0.结构参数'!L43*100 -> 40 | H6: ='0.结构参数'!K43*100 -> 50 | I6: =('0.结构参数'!M43+'0.结构参数'!N43)/2*100 -> 2190 | J6: =(C6+$H6) -> 321.154 | K6: =(D6+$H6) -> 380.615
B7: ='0.结构参数'!A44 -> YU4 | C7: =MIN('0.结构参数'!I44,'0.结构参数'!J44)*100 -> 330.704 | D7: =MAX('0.结构参数'!I44,'0.结构参数'!J44)*100 -> 390.165 | E7: =MAX('0.结构参数'!E8,'0.结构参数'!F8)*100 -> 2000 | F7: =MIN('0.结构参数'!E8,'0.结构参数'!F8)*100 -> 2000 | G7: ='0.结构参数'!L44*100 -> 40 | H7: ='0.结构参数'!K44*100 -> 50 | I7: =('0.结构参数'!M44+'0.结构参数'!N44)/2*100 -> 2190 | J7: =(C7+$H7) -> 380.704 | K7: =(D7+$H7) -> 440.165
B8: ='0.结构参数'!A45 -> YU5 | C8: =MIN('0.结构参数'!I45,'0.结构参数'!J45)*100 -> 390.255 | D8: =MAX('0.结构参数'!I45,'0.结构参数'!J45)*100 -> 449.716 | E8: =MAX('0.结构参数'!E9,'0.结构参数'!F9)*100 -> 2000 | F8: =MIN('0.结构参数'!E9,'0.结构参数'!F9)*100 -> 2000 | G8: ='0.结构参数'!L45*100 -> 50 | H8: ='0.结构参数'!K45*100 -> 60 | I8: =('0.结构参数'!M45+'0.结构参数'!N45)/2*100 -> 2210 | J8: =(C8+$H8) -> 450.255 | K8: =(D8+$H8) -> 509.716 | N8: 4、e2数值改为定值8，但仍需注意表格外e2取值区间
B9: ='0.结构参数'!A46 -> YU6 | C9: =MIN('0.结构参数'!I46,'0.结构参数'!J46)*100 -> 449.832 | D9: =MAX('0.结构参数'!I46,'0.结构参数'!J46)*100 -> 527.6 | E9: =MAX('0.结构参数'!E10,'0.结构参数'!F10)*100 -> 2000 | F9: =MIN('0.结构参数'!E10,'0.结构参数'!F10)*100 -> 2000 | G9: ='0.结构参数'!L46*100 -> 60 | H9: ='0.结构参数'!K46*100 -> 70 | I9: =('0.结构参数'!M46+'0.结构参数'!N46)/2*100 -> 2230 | J9: =(C9+$H9) -> 519.832 | K9: =(D9+$H9) -> 597.6
B10: ='0.结构参数'!A47 -> YU7 | C10: =MIN('0.结构参数'!I47,'0.结构参数'!J47)*100 -> 527.717 | D10: =MAX('0.结构参数'!I47,'0.结构参数'!J47)*100 -> 605.484 | E10: =MAX('0.结构参数'!E11,'0.结构参数'!F11)*100 -> 2000 | F10: =MIN('0.结构参数'!E11,'0.结构参数'!F11)*100 -> 2000 | G10: ='0.结构参数'!L47*100 -> 50 | H10: ='0.结构参数'!K47*100 -> 60 | I10: 1370 | J10: =(C10+$H10) -> 587.717 | K10: =(D10+$H10) -> 665.484
B11: ='0.结构参数'!A48 -> YU8 | C11: =MIN('0.结构参数'!I48,'0.结构参数'!J48)*100 -> 605.574 | D11: =MAX('0.结构参数'!I48,'0.结构参数'!J48)*100 -> 665.593 | E11: =MAX('0.结构参数'!E12,'0.结构参数'!F12)*100 -> 2000 | F11: =MIN('0.结构参数'!E12,'0.结构参数'!F12)*100 -> 2000 | G11: ='0.结构参数'!L48*100 -> 70 | H11: ='0.结构参数'!K48*100 -> 80 | I11: 1390 | J11: =(C11+$H11) -> 685.574 | K11: =(D11+$H11) -> 745.593
B12: ='0.结构参数'!A49 -> YU9 | C12: =MIN('0.结构参数'!I49,'0.结构参数'!J49)*100 -> 665.683 | D12: =MAX('0.结构参数'!I49,'0.结构参数'!J49)*100 -> 725.702 | E12: =MAX('0.结构参数'!E13,'0.结构参数'!F13)*100 -> 2000 | F12: =MIN('0.结构参数'!E13,'0.结构参数'!F13)*100 -> 2000 | G12: ='0.结构参数'!L49*100 -> 70 | H12: ='0.结构参数'!K49*100 -> 80 | I12: 1390 | J12: =(C12+$H12) -> 745.683 | K12: =(D12+$H12) -> 805.702
B13: ='0.结构参数'!A50 -> YU10 | C13: =MIN('0.结构参数'!I50,'0.结构参数'!J50)*100 -> 725.702 | D13: =MAX('0.结构参数'!I50,'0.结构参数'!J50)*100 -> 725.702 | E13: =MAX('0.结构参数'!E14,'0.结构参数'!F14)*100 -> 2000 | F13: =MIN('0.结构参数'!E14,'0.结构参数'!F14)*100 -> 2000 | G13: ='0.结构参数'!L50*100 -> 70 | H13: ='0.结构参数'!K50*100 -> 80 | I13: =('0.结构参数'!M50+'0.结构参数'!N50)/2*100 -> 2345.85 | J13: =(C13+$H13) -> 805.702 | K13: =(D13+$H13) -> 805.702
B14: ='0.结构参数'!A51 -> YU11 | C14: =MIN('0.结构参数'!I51,'0.结构参数'!J51)*100 -> 697.143 | D14: =MAX('0.结构参数'!I51,'0.结构参数'!J51)*100 -> 760 | E14: =MAX('0.结构参数'!E15,'0.结构参数'!F15)*100 -> 2000 | F14: =MIN('0.结构参数'!E15,'0.结构参数'!F15)*100 -> 2000 | G14: ='0.结构参数'!L51*100 -> 80 | H14: ='0.结构参数'!K51*100 -> 90 | I14: =('0.结构参数'!M51+'0.结构参数'!N51)/2*100 -> 2297.505 | J14: =(C14+$H14) -> 787.143 | K14: =(D14+$H14) -> 850
B15: ='0.结构参数'!A52 -> YU12 | C15: =MIN('0.结构参数'!I52,'0.结构参数'!J52)*100 -> 634.192 | D15: =MAX('0.结构参数'!I52,'0.结构参数'!J52)*100 -> 697.049 | E15: =MAX('0.结构参数'!E16,'0.结构参数'!F16)*100 -> 2000 | F15: =MIN('0.结构参数'!E16,'0.结构参数'!F16)*100 -> 2000 | G15: ='0.结构参数'!L52*100 -> 60 | H15: ='0.结构参数'!K52*100 -> 70 | I15: =('0.结构参数'!M52+'0.结构参数'!N52)/2*100 -> 2235.25 | J15: =(C15+$H15) -> 704.192 | K15: =(D15+$H15) -> 767.049
B16: ='0.结构参数'!A53 -> YU13 | C16: =MIN('0.结构参数'!I53,'0.结构参数'!J53)*100 -> 571.241 | D16: =MAX('0.结构参数'!I53,'0.结构参数'!J53)*100 -> 634.098 | E16: =MAX('0.结构参数'!E17,'0.结构参数'!F17)*100 -> 2000 | F16: =MIN('0.结构参数'!E17,'0.结构参数'!F17)*100 -> 2000 | G16: ='0.结构参数'!L53*100 -> 60 | H16: ='0.结构参数'!K53*100 -> 70 | I16: =('0.结构参数'!M53+'0.结构参数'!N53)/2*100 -> 2230 | J16: =(C16+$H16) -> 641.241 | K16: =(D16+$H16) -> 704.098
B17: ='0.结构参数'!A54 -> YU14 | C17: =MIN('0.结构参数'!I54,'0.结构参数'!J54)*100 -> 515.414 | D17: =MAX('0.结构参数'!I54,'0.结构参数'!J54)*100 -> 571.147 | E17: =MAX('0.结构参数'!E18,'0.结构参数'!F18)*100 -> 2000 | F17: =MIN('0.结构参数'!E18,'0.结构参数'!F18)*100 -> 2000 | G17: ='0.结构参数'!L54*100 -> 60 | H17: ='0.结构参数'!K54*100 -> 70 | I17: =('0.结构参数'!M54+'0.结构参数'!N54)/2*100 -> 2230 | J17: =(C17+$H17) -> 585.414 | K17: =(D17+$H17) -> 641.147
B18: ='0.结构参数'!A55 -> YU15 | C18: =MIN('0.结构参数'!I55,'0.结构参数'!J55)*100 -> 459.598 | D18: =MAX('0.结构参数'!I55,'0.结构参数'!J55)*100 -> 515.33 | E18: =MAX('0.结构参数'!E19,'0.结构参数'!F19)*100 -> 2000 | F18: =MIN('0.结构参数'!E19,'0.结构参数'!F19)*100 -> 2000 | G18: ='0.结构参数'!L55*100 -> 60 | H18: ='0.结构参数'!K55*100 -> 70 | I18: =('0.结构参数'!M55+'0.结构参数'!N55)/2*100 -> 2230.97 | J18: =(C18+$H18) -> 529.598 | K18: =(D18+$H18) -> 585.33
B19: ='0.结构参数'!A56 -> YU16 | C19: =MIN('0.结构参数'!I56,'0.结构参数'!J56)*100 -> 403.781 | D19: =MAX('0.结构参数'!I56,'0.结构参数'!J56)*100 -> 459.514 | E19: =MAX('0.结构参数'!E20,'0.结构参数'!F20)*100 -> 2000 | F19: =MIN('0.结构参数'!E20,'0.结构参数'!F20)*100 -> 2000 | G19: ='0.结构参数'!L56*100 -> 50 | H19: ='0.结构参数'!K56*100 -> 60 | I19: =('0.结构参数'!M56+'0.结构参数'!N56)/2*100 -> 2218.565 | J19: =(C19+$H19) -> 463.781 | K19: =(D19+$H19) -> 519.514
B20: ='0.结构参数'!A57 -> YU17 | C20: =MIN('0.结构参数'!I57,'0.结构参数'!J57)*100 -> 347.965 | D20: =MAX('0.结构参数'!I57,'0.结构参数'!J57)*100 -> 403.698 | E20: =MAX('0.结构参数'!E21,'0.结构参数'!F21)*100 -> 2000 | F20: =MIN('0.结构参数'!E21,'0.结构参数'!F21)*100 -> 2000 | G20: ='0.结构参数'!L57*100 -> 50 | H20: ='0.结构参数'!K57*100 -> 60 | I20: =('0.结构参数'!M57+'0.结构参数'!N57)/2*100 -> 2238.06 | J20: =(C20+$H20) -> 407.965 | K20: =(D20+$H20) -> 463.698
B21: ='0.结构参数'!A58 -> YU18 | C21: =MIN('0.结构参数'!I58,'0.结构参数'!J58)*100 -> 292.149 | D21: =MAX('0.结构参数'!I58,'0.结构参数'!J58)*100 -> 347.881 | E21: =MAX('0.结构参数'!E22,'0.结构参数'!F22)*100 -> 2000 | F21: =MIN('0.结构参数'!E22,'0.结构参数'!F22)*100 -> 2000 | G21: ='0.结构参数'!L58*100 -> 40 | H21: ='0.结构参数'!K58*100 -> 50 | I21: =('0.结构参数'!M58+'0.结构参数'!N58)/2*100 -> 2248.36 | J21: =(C21+$H21) -> 342.149 | K21: =(D21+$H21) -> 397.881
B22: ='0.结构参数'!A59 -> YU19 | C22: =MIN('0.结构参数'!I59,'0.结构参数'!J59)*100 -> 248.954 | D22: =MAX('0.结构参数'!I59,'0.结构参数'!J59)*100 -> 292.065 | E22: =MAX('0.结构参数'!E23,'0.结构参数'!F23)*100 -> 1547.05 | F22: =MIN('0.结构参数'!E23,'0.结构参数'!F23)*100 -> 1547.05 | G22: ='0.结构参数'!L59*100 -> 30 | H22: ='0.结构参数'!K59*100 -> 40 | I22: =('0.结构参数'!M59+'0.结构参数'!N59)/2*100 -> 2256.045 | J22: =(C22+$H22) -> 288.954 | K22: =(D22+$H22) -> 332.065
B23: ='0.结构参数'!A60 -> 东U10 | C23: =MIN('0.结构参数'!I60,'0.结构参数'!J60)*100 -> 125.466 | D23: =MAX('0.结构参数'!I60,'0.结构参数'!J60)*100 -> 163.657 | E23: =MAX('0.结构参数'!E24,'0.结构参数'!F24)*100 -> 2000 | F23: =MIN('0.结构参数'!E24,'0.结构参数'!F24)*100 -> 2000 | G23: ='0.结构参数'!L60*100 -> 30 | H23: ='0.结构参数'!K60*100 -> 40 | I23: =('0.结构参数'!M60+'0.结构参数'!N60)/2*100 -> 860 | J23: =(C23+$H23) -> 165.466 | K23: =(D23+$H23) -> 203.657
B24: ='0.结构参数'!A61 -> 西U10-1 | C24: =MIN('0.结构参数'!I61,'0.结构参数'!J61)*100 -> 130 | D24: =MAX('0.结构参数'!I61,'0.结构参数'!J61)*100 -> 161.126 | E24: =MAX('0.结构参数'!E25,'0.结构参数'!F25)*100 -> 2000 | F24: =MIN('0.结构参数'!E25,'0.结构参数'!F25)*100 -> 2000 | G24: ='0.结构参数'!L61*100 -> 30 | H24: ='0.结构参数'!K61*100 -> 40 | I24: =('0.结构参数'!M61+'0.结构参数'!N61)/2*100 -> 2285 | J24: =(C24+$H24) -> 170 | K24: =(D24+$H24) -> 201.126
... B35: ='0.结构参数'!A72 -> 0 | C35: =MIN('0.结构参数'!I72,'0.结构参数'!J72)*100 -> 0 | D35: =MAX('0.结构参数'!I72,'0.结构参数'!J72)*100 -> 0 | E35: =MAX('0.结构参数'!E36,'0.结构参数'!F36)*100 -> 0 | F35: =MIN('0.结构参数'!E36,'0.结构参数'!F36)*100 -> 0 | G35: ='0.结构参数'!L72*100 -> 30 | H35: ='0.结构参数'!K72*100 -> 40 | I35: =('0.结构参数'!M72+'0.结构参数'!N72)/2*100 -> 60 | J35: =(C35+$H35) -> 40 | K35: =(D35+$H35) -> 40
F37: 此处若为负值，则公式改为“B21/D21-2” | P37: 若e2小于8，则在n1公式后减1
A38: 钢筋图参数表 | B38: U型槽 编号 | C38: D (cm) | D38: n | E38: d (cm) | F38: a 0~12.5 | G38: B (cm) | H38: m | I38: b (cm) | J38: e1 (cm) | K38: Hmin (cm) | L38: Hmax (cm) | M38: n1 | N38: d1 (cm) | O38: d2 (cm) | P38: e2 | Q38: T | R38: n1' | S38: d1' | T38: L1 (cm) | U38: m1 | V38: b1 (cm) | W38: L2 (cm) | X38: m2 | Y38: b2 (cm) | Z38: e3 (cm) | AA38: e2 7~20.5
B39: =B4 -> YU1 | C39: =VLOOKUP(B39,$B$4:$K$36,8,0) -> 2170 | D39: =ROUNDDOWN((C39/E39-1),0) -> 172 | E39: =12.5 -> 12.5 | F39: =C39-D39*E39-2*J39 -> 4 | G39: =VLOOKUP(B39,$B$4:$J$72,6,0) -> 30 | H39: 2 | I39: =(G39-J39*2)/H39 -> 7 | J39: 8 | K39: =VLOOKUP(B39,$B$4:$K$36,2,0) -> 179.116 | L39: =VLOOKUP(B39,$B$4:$K$36,3,0) -> 211.515 | M39: =ROUND((L39-5)/12.5,0)-1 -> 16 | N39: =(L39-5-P39)/M39 -> 12.407187 | O39: =(K39-P39-5)/M39 -> 10.38225 | P39: 8 | Q39: =VLOOKUP($B39,$B$4:$K$36,7,0) -> 40 | R39: 3 | S39: =(Q39-2*J39)/R39 -> 8 | T39: =VLOOKUP($B39,$B$4:$K$36,4,0) -> 2000 | U39: =ROUNDDOWN(T39/V39,0)-1 -> 159 | V39: 12.5 | W39: =VLOOKUP($B39,$B$4:$K$36,5,0) -> 2000 | X39: =U39 -> 159 | Y39: =(W39-Z39*2)/X39 -> 12.5 | Z39: =(T39-U39*V39)/2 -> 6.25 | AA39: =L39-M39*12.5-5 -> 6.515
B40: =B5 -> YU2 | C40: =VLOOKUP(B40,$B$4:$K$36,8,0) -> 2170 | D40: =ROUNDDOWN((C40/E40-1),0) -> 172 | E40: =12.5 -> 12.5 | F40: =C40-D40*E40-2*J40 -> 4 | G40: =VLOOKUP(B40,$B$4:$J$72,6,0) -> 30 | H40: 2 | I40: =(G40-J40*2)/H40 -> 7 | J40: 8 | K40: =VLOOKUP(B40,$B$4:$K$36,2,0) -> 211.604 | L40: =VLOOKUP(B40,$B$4:$K$36,3,0) -> 271.065 | M40: =ROUND((L40-5)/12.5,0)-1 -> 20 | N40: =(L40-5-P40)/M40 -> 12.90325 | O40: =(K40-P40-5)/M40 -> 9.9302 | P40: 8 | Q40: =VLOOKUP($B40,$B$4:$K$36,7,0) -> 40 | R40: 3 | S40: =(Q40-2*J40)/R40 -> 8 | T40: =VLOOKUP($B40,$B$4:$K$36,4,0) -> 2000 | U40: =ROUNDDOWN(T40/V40,0)-1 -> 159 | V40: 12.5 | W40: =VLOOKUP($B40,$B$4:$K$36,5,0) -> 2000 | X40: =U40 -> 159 | Y40: =(W40-Z40*2)/X40 -> 12.5 | Z40: =(T40-U40*V40)/2 -> 6.25 | AA40: =L40-M40*12.5-5 -> 16.065
B41: =B6 -> YU3 | C41: =VLOOKUP(B41,$B$4:$K$36,8,0) -> 2190 | D41: =ROUNDDOWN((C41/E41-1),0) -> 174 | E41: =12.5 -> 12.5 | F41: =C41-D41*E41-2*J41 -> -1 | G41: =VLOOKUP(B41,$B$4:$J$72,6,0) -> 40 | H41: 3 | I41: =(G41-J41*2)/H41 -> 8 | J41: 8 | K41: =VLOOKUP(B41,$B$4:$K$36,2,0) -> 271.154 | L41: =VLOOKUP(B41,$B$4:$K$36,3,0) -> 330.615 | M41: =ROUND((L41-5)/12.5,0)-1 -> 25 | N41: =(L41-5-P41)/M41 -> 12.7046 | O41: =(K41-P41-5)/M41 -> 10.32616 | P41: 8 | Q41: =VLOOKUP($B41,$B$4:$K$36,7,0) -> 50 | R41: 4 | S41: =(Q41-2*J41)/R41 -> 8.5 | T41: =VLOOKUP($B41,$B$4:$K$36,4,0) -> 2000 | U41: =ROUNDDOWN(T41/V41,0)-1 -> 159 | V41: 12.5 | W41: =VLOOKUP($B41,$B$4:$K$36,5,0) -> 2000 | X41: =U41 -> 159 | Y41: =(W41-Z41*2)/X41 -> 12.5 | Z41: =(T41-U41*V41)/2 -> 6.25 | AA41: =L41-M41*12.5-5 -> 13.115
B42: =B7 -> YU4 | C42: =VLOOKUP(B42,$B$4:$K$36,8,0) -> 2190 | D42: =ROUNDDOWN((C42/E42-1),0) -> 174 | E42: =12.5 -> 12.5 | F42: =C42-D42*E42-2*J42 -> -1 | G42: =VLOOKUP(B42,$B$4:$J$72,6,0) -> 40 | H42: 3 | I42: =(G42-J42*2)/H42 -> 8 | J42: 8 | K42: =VLOOKUP(B42,$B$4:$K$36,2,0) -> 330.704 | L42: =VLOOKUP(B42,$B$4:$K$36,3,0) -> 390.165 | M42: =ROUND((L42-5)/12.5,0)-1 -> 30 | N42: =(L42-5-P42)/M42 -> 12.572167 | O42: =(K42-P42-5)/M42 -> 10.590133 | P42: 8 | Q42: =VLOOKUP($B42,$B$4:$K$36,7,0) -> 50 | R42: 4 | S42: =(Q42-2*J42)/R42 -> 8.5 | T42: =VLOOKUP($B42,$B$4:$K$36,4,0) -> 2000 | U42: =ROUNDDOWN(T42/V42,0)-1 -> 159 | V42: 12.5 | W42: =VLOOKUP($B42,$B$4:$K$36,5,0) -> 2000 | X42: =U42 -> 159 | Y42: =(W42-Z42*2)/X42 -> 12.5 | Z42: =(T42-U42*V42)/2 -> 6.25 | AA42: =L42-M42*12.5-5 -> 10.165
B43: =B8 -> YU5 | C43: =VLOOKUP(B43,$B$4:$K$36,8,0) -> 2210 | D43: =ROUNDDOWN((C43/E43-2),0) -> 174 | E43: =12.5 -> 12.5 | F43: =C43-D43*E43-2*J43 -> 19 | G43: =VLOOKUP(B43,$B$4:$J$72,6,0) -> 50 | H43: 4 | I43: =(G43-J43*2)/H43 -> 8.5 | J43: 8 | K43: =VLOOKUP(B43,$B$4:$K$36,2,0) -> 390.255 | L43: =VLOOKUP(B43,$B$4:$K$36,3,0) -> 449.716 | M43: =ROUND((L43-5)/12.5,0)-1 -> 35 | N43: =(L43-5-P43)/M43 -> 12.4776 | O43: =(K43-P43-5)/M43 -> 10.778714 | P43: 8 | Q43: =VLOOKUP($B43,$B$4:$K$36,7,0) -> 60 | R43: 4 | S43: =(Q43-2*J43)/R43 -> 11 | T43: =VLOOKUP($B43,$B$4:$K$36,4,0) -> 2000 | U43: =ROUNDDOWN(T43/V43,0)-1 -> 159 | V43: 12.5 | W43: =VLOOKUP($B43,$B$4:$K$36,5,0) -> 2000 | X43: =U43 -> 159 | Y43: =(W43-Z43*2)/X43 -> 12.5 | Z43: =(T43-U43*V43)/2 -> 6.25 | AA43: =L43-M43*12.5-5 -> 7.216
B44: =B9 -> YU6 | C44: =VLOOKUP(B44,$B$4:$K$36,8,0) -> 2230 | D44: =ROUNDDOWN((C44/E44-1),0) -> 177 | E44: =12.5 -> 12.5 | F44: =C44-D44*E44-2*J44 -> 1.5 | G44: =VLOOKUP(B44,$B$4:$J$72,6,0) -> 60 | H44: 4 | I44: =(G44-J44*2)/H44 -> 11 | J44: 8 | K44: =VLOOKUP(B44,$B$4:$K$36,2,0) -> 449.832 | L44: =VLOOKUP(B44,$B$4:$K$36,3,0) -> 527.6 | M44: =ROUND((L44-5)/12.5,0)-1 -> 41 | N44: =(L44-5-P44)/M44 -> 12.55122 | O44: =(K44-P44-5)/M44 -> 10.654439 | P44: 8 | Q44: =VLOOKUP($B44,$B$4:$K$36,7,0) -> 70 | R44: 6 | S44: =(Q44-2*J44)/R44 -> 9 | T44: =VLOOKUP($B44,$B$4:$K$36,4,0) -> 2000 | U44: =ROUNDDOWN(T44/V44,0)-1 -> 159 | V44: 12.5 | W44: =VLOOKUP($B44,$B$4:$K$36,5,0) -> 2000 | X44: =U44 -> 159 | Y44: =(W44-Z44*2)/X44 -> 12.5 | Z44: =(T44-U44*V44)/2 -> 6.25 | AA44: =L44-M44*12.5-5 -> 10.1
B45: =B10 -> YU7 | C45: =VLOOKUP(B45,$B$4:$K$36,8,0) -> 1370 | D45: =ROUNDDOWN((C45/E45-1),0) -> 108 | E45: =12.5 -> 12.5 | F45: =C45-D45*E45-2*J45 -> 4 | G45: =VLOOKUP(B45,$B$4:$J$72,6,0) -> 50 | H45: 4 | I45: =(G45-J45*2)/H45 -> 8.5 | J45: 8 | K45: =VLOOKUP(B45,$B$4:$K$36,2,0) -> 527.717 | L45: =VLOOKUP(B45,$B$4:$K$36,3,0) -> 605.484 | M45: =ROUND((L45-5)/12.5,0)-1 -> 47 | N45: =(L45-5-P45)/M45 -> 12.606043 | O45: =(K45-P45-5)/M45 -> 10.951426 | P45: 8 | Q45: =VLOOKUP($B45,$B$4:$K$36,7,0) -> 60 | R45: 6 | S45: =(Q45-2*J45)/R45 -> 7.3333333 | T45: =VLOOKUP($B45,$B$4:$K$36,4,0) -> 2000 | U45: =ROUNDDOWN(T45/V45,0)-1 -> 159 | V45: 12.5 | W45: =VLOOKUP($B45,$B$4:$K$36,5,0) -> 2000 | X45: =U45 -> 159 | Y45: =(W45-Z45*2)/X45 -> 12.5 | Z45: =(T45-U45*V45)/2 -> 6.25 | AA45: =L45-M45*12.5-5 -> 12.984
B46: =B11 -> YU8 | C46: =VLOOKUP(B46,$B$4:$K$36,8,0) -> 1390 | D46: =ROUNDDOWN((C46/E46-2),0) -> 109 | E46: =12.5 -> 12.5 | F46: =C46-D46*E46-2*J46 -> 11.5 | G46: =VLOOKUP(B46,$B$4:$J$72,6,0) -> 70 | H46: 6 | I46: =(G46-J46*2)/H46 -> 9 | J46: 8 | K46: =VLOOKUP(B46,$B$4:$K$36,2,0) -> 605.574 | L46: =VLOOKUP(B46,$B$4:$K$36,3,0) -> 665.593 | M46: =ROUND((L46-5)/12.5,0)-1 -> 52 | N46: =(L46-5-P46)/M46 -> 12.549865 | O46: =(K46-P46-5)/M46 -> 11.395654 | P46: 8 | Q46: =VLOOKUP($B46,$B$4:$K$36,7,0) -> 80 | R46: 8 | S46: =(Q46-2*J46)/R46 -> 8 | T46: =VLOOKUP($B46,$B$4:$K$36,4,0) -> 2000 | U46: =ROUNDDOWN(T46/V46,0)-1 -> 159 | V46: 12.5 | W46: =VLOOKUP($B46,$B$4:$K$36,5,0) -> 2000 | X46: =U46 -> 159 | Y46: =(W46-Z46*2)/X46 -> 12.5 | Z46: =(T46-U46*V46)/2 -> 6.25 | AA46: =L46-M46*12.5-5 -> 10.593
B47: =B12 -> YU9 | C47: =VLOOKUP(B47,$B$4:$K$36,8,0) -> 1390 | D47: =ROUNDDOWN((C47/E47-2),0) -> 109 | E47: =12.5 -> 12.5 | F47: =C47-D47*E47-2*J47 -> 11.5 | G47: =VLOOKUP(B47,$B$4:$J$72,6,0) -> 70 | H47: 6 | I47: =(G47-J47*2)/H47 -> 9 | J47: 8 | K47: =VLOOKUP(B47,$B$4:$K$36,2,0) -> 665.683 | L47: =VLOOKUP(B47,$B$4:$K$36,3,0) -> 725.702 | M47: =ROUND((L47-5)/12.5,0)-1 -> 57 | N47: =(L47-5-P47)/M47 -> 12.503544 | O47: =(K47-P47-5)/M47 -> 11.450579 | P47: 8 | Q47: =VLOOKUP($B47,$B$4:$K$36,7,0) -> 80 | R47: 8 | S47: =(Q47-2*J47)/R47 -> 8 | T47: =VLOOKUP($B47,$B$4:$K$36,4,0) -> 2000 | U47: =ROUNDDOWN(T47/V47,0)-1 -> 159 | V47: 12.5 | W47: =VLOOKUP($B47,$B$4:$K$36,5,0) -> 2000 | X47: =U47 -> 159 | Y47: =(W47-Z47*2)/X47 -> 12.5 | Z47: =(T47-U47*V47)/2 -> 6.25 | AA47: =L47-M47*12.5-5 -> 8.202
B48: =B13 -> YU10 | C48: =VLOOKUP(B48,$B$4:$K$36,8,0) -> 2345.85 | D48: =ROUNDDOWN((C48/E48-2),0) -> 185 | E48: =12.5 -> 12.5 | F48: =C48-D48*E48-2*J48 -> 17.35 | G48: =VLOOKUP(B48,$B$4:$J$72,6,0) -> 70 | H48: 6 | I48: =(G48-J48*2)/H48 -> 9 | J48: 8 | K48: =VLOOKUP(B48,$B$4:$K$36,2,0) -> 725.702 | L48: =VLOOKUP(B48,$B$4:$K$36,3,0) -> 725.702 | M48: =ROUND((L48-5)/12.5,0)-1 -> 57 | N48: =(L48-5-P48)/M48 -> 12.503544 | O48: =(K48-P48-5)/M48 -> 12.503544 | P48: 8 | Q48: =VLOOKUP($B48,$B$4:$K$36,7,0) -> 80 | R48: 8 | S48: =(Q48-2*J48)/R48 -> 8 | T48: =VLOOKUP($B48,$B$4:$K$36,4,0) -> 2000 | U48: =ROUNDDOWN(T48/V48,0)-1 -> 159 | V48: 12.5 | W48: =VLOOKUP($B48,$B$4:$K$36,5,0) -> 2000 | X48: =U48 -> 159 | Y48: =(W48-Z48*2)/X48 -> 12.5 | Z48: =(T48-U48*V48)/2 -> 6.25 | AA48: =L48-M48*12.5-5 -> 8.202
B49: =B14 -> YU11 | C49: =VLOOKUP(B49,$B$4:$K$36,8,0) -> 2297.505 | D49: =ROUNDDOWN((C49/E49-1),0) -> 182 | E49: =12.5 -> 12.5 | F49: =C49-D49*E49-2*J49 -> 6.505 | G49: =VLOOKUP(B49,$B$4:$J$72,6,0) -> 80 | H49: 8 | I49: =(G49-J49*2)/H49 -> 8 | J49: 8 | K49: =VLOOKUP(B49,$B$4:$K$36,2,0) -> 697.143 | L49: =VLOOKUP(B49,$B$4:$K$36,3,0) -> 760 | M49: =ROUND((L49-5)/12.5,0)-1 -> 59 | N49: =(L49-5-P49)/M49 -> 12.661017 | O49: =(K49-P49-5)/M49 -> 11.595644 | P49: 8 | Q49: =VLOOKUP($B49,$B$4:$K$36,7,0) -> 90 | R49: 8 | S49: =(Q49-2*J49)/R49 -> 9.25 | T49: =VLOOKUP($B49,$B$4:$K$36,4,0) -> 2000 | U49: =ROUNDDOWN(T49/V49,0)-1 -> 159 | V49: 12.5 | W49: =VLOOKUP($B49,$B$4:$K$36,5,0) -> 2000 | X49: =U49 -> 159 | Y49: =(W49-Z49*2)/X49 -> 12.5 | Z49: =(T49-U49*V49)/2 -> 6.25 | AA49: =L49-M49*12.5-5 -> 17.5
B50: =B15 -> YU12 | C50: =VLOOKUP(B50,$B$4:$K$36,8,0) -> 2235.25 | D50: =ROUNDDOWN((C50/E50-2),0) -> 176 | E50: =12.5 -> 12.5 | F50: =C50-D50*E50-2*J50 -> 19.25 | G50: =VLOOKUP(B50,$B$4:$J$72,6,0) -> 60 | H50: 6 | I50: =(G50-J50*2)/H50 -> 7.3333333 | J50: 8 | K50: =VLOOKUP(B50,$B$4:$K$36,2,0) -> 634.192 | L50: =VLOOKUP(B50,$B$4:$K$36,3,0) -> 697.049 | M50: =ROUND((L50-5)/12.5,0)-1 -> 54 | N50: =(L50-5-P50)/M50 -> 12.667574 | O50: =(K50-P50-5)/M50 -> 11.503556 | P50: 8 | Q50: =VLOOKUP($B50,$B$4:$K$36,7,0) -> 70 | R50: 8 | S50: =(Q50-2*J50)/R50 -> 6.75 | T50: =VLOOKUP($B50,$B$4:$K$36,4,0) -> 2000 | U50: =ROUNDDOWN(T50/V50,0)-1 -> 159 | V50: 12.5 | W50: =VLOOKUP($B50,$B$4:$K$36,5,0) -> 2000 | X50: =U50 -> 159 | Y50: =(W50-Z50*2)/X50 -> 12.5 | Z50: =(T50-U50*V50)/2 -> 6.25 | AA50: =L50-M50*12.5-5 -> 17.049
B51: =B16 -> YU13 | C51: =VLOOKUP(B51,$B$4:$K$36,8,0) -> 2230 | D51: =ROUNDDOWN((C51/E51-1),0) -> 177 | E51: =12.5 -> 12.5 | F51: =C51-D51*E51-2*J51 -> 1.5 | G51: =VLOOKUP(B51,$B$4:$J$72,6,0) -> 60 | H51: 4 | I51: =(G51-J51*2)/H51 -> 11 | J51: 8 | K51: =VLOOKUP(B51,$B$4:$K$36,2,0) -> 571.241 | L51: =VLOOKUP(B51,$B$4:$K$36,3,0) -> 634.098 | M51: =ROUND((L51-5)/12.5,0)-1 -> 49 | N51: =(L51-5-P51)/M51 -> 12.675469 | O51: =(K51-P51-5)/M51 -> 11.392673 | P51: 8 | Q51: =VLOOKUP($B51,$B$4:$K$36,7,0) -> 70 | R51: 8 | S51: =(Q51-2*J51)/R51 -> 6.75 | T51: =VLOOKUP($B51,$B$4:$K$36,4,0) -> 2000 | U51: =ROUNDDOWN(T51/V51,0)-1 -> 159 | V51: 12.5 | W51: =VLOOKUP($B51,$B$4:$K$36,5,0) -> 2000 | X51: =U51 -> 159 | Y51: =(W51-Z51*2)/X51 -> 12.5 | Z51: =(T51-U51*V51)/2 -> 6.25 | AA51: =L51-M51*12.5-5 -> 16.598
B52: =B17 -> YU14 | C52: =VLOOKUP(B52,$B$4:$K$36,8,0) -> 2230 | D52: =ROUNDDOWN((C52/E52-1),0) -> 177 | E52: =12.5 -> 12.5 | F52: =C52-D52*E52-2*J52 -> 1.5 | G52: =VLOOKUP(B52,$B$4:$J$72,6,0) -> 60 | H52: 4 | I52: =(G52-J52*2)/H52 -> 11 | J52: 8 | K52: =VLOOKUP(B52,$B$4:$K$36,2,0) -> 515.414 | L52: =VLOOKUP(B52,$B$4:$K$36,3,0) -> 571.147 | M52: =ROUND((L52-5)/12.5,0)-1 -> 44 | N52: =(L52-5-P52)/M52 -> 12.685159 | O52: =(K52-P52-5)/M52 -> 11.4185 | P52: 8 | Q52: =VLOOKUP($B52,$B$4:$K$36,7,0) -> 70 | R52: 6 | S52: =(Q52-2*J52)/R52 -> 9 | T52: =VLOOKUP($B52,$B$4:$K$36,4,0) -> 2000 | U52: =ROUNDDOWN(T52/V52,0)-1 -> 159 | V52: 12.5 | W52: =VLOOKUP($B52,$B$4:$K$36,5,0) -> 2000 | X52: =U52 -> 159 | Y52: =(W52-Z52*2)/X52 -> 12.5 | Z52: =(T52-U52*V52)/2 -> 6.25 | AA52: =L52-M52*12.5-5 -> 16.147
...

Sheet 新增管沟
A1: U型槽 编号 | B1: L (cm) | C1: Hmin (cm) | D1: Hmax (cm) | E1: B1 (cm) | F1: B2 (cm) | G1: T (cm) | H1: n | I1: a (cm) | J1: m (cm) | K1: Hmin (cm) | L1: Hmax (cm) | M1: e
A2: ='[7]0.结构参数'!B5 -> YU1 | B2: ='0.结构参数'!D41*100 -> 2000 | C2: =MIN(('0.结构参数'!K5-'0.结构参数'!I5),('0.结构参数'!L5-'0.结构参数'!J5))*100-70 -> 90 | D2: =MAX(('0.结构参数'!K5-'0.结构参数'!I5),('0.结构参数'!L5-'0.结构参数'!J5))*100-70 -> 105.486 | E2: 25 | F2: 20 | G2: 35 | H2: =ROUNDDOWN((D2-M2)/15,0) -> 6 | I2: =D2-M2-H2*15 -> 8.986 | J2: =(C2-M2-I2)/H2 -> 12.419 | K2: =C2+30 -> 120 | L2: =D2+30 -> 135.486 | M2: =$R$2+$R$5 -> 6.5 | Q2: 净保护层 | R2: 4
A3: ='[7]0.结构参数'!B6 -> YU2 | B3: ='0.结构参数'!D42*100 -> 2000 | C3: =MIN(('0.结构参数'!K6-'0.结构参数'!I6),('0.结构参数'!L6-'0.结构参数'!J6))*100-70 -> 105.5 | D3: =MAX(('0.结构参数'!K6-'0.结构参数'!I6),('0.结构参数'!L6-'0.结构参数'!J6))*100-70 -> 114.961 | E3: 25 | F3: 20 | G3: 35 | H3: =ROUNDDOWN((D3-M3)/15,0) -> 7 | I3: =D3-M3-H3*15 -> 3.461 | J3: =(C3-M3-I3)/H3 -> 13.648429 | K3: =C3+30 -> 135.5 | L3: =D3+30 -> 144.961 | M3: =$R$2+$R$5 -> 6.5 | Q3: 盖板厚度 | R3: 30
A4: ='[7]0.结构参数'!B7 -> YU3 | B4: ='0.结构参数'!D43*100 -> 2000 | C4: =MIN(('0.结构参数'!K7-'0.结构参数'!I7),('0.结构参数'!L7-'0.结构参数'!J7))*100-70 -> 114.975 | D4: =MAX(('0.结构参数'!K7-'0.结构参数'!I7),('0.结构参数'!L7-'0.结构参数'!J7))*100-70 -> 124.436 | E4: 25 | F4: 20 | G4: 35 | H4: =ROUNDDOWN((D4-M4)/15,0) -> 7 | I4: =D4-M4-H4*15 -> 12.936 | J4: =(C4-M4-I4)/H4 -> 13.648429 | K4: =C4+30 -> 144.975 | L4: =D4+30 -> 154.436 | M4: =$R$2+$R$5 -> 6.5 | Q4: 主筋直径 | R4: 1.8
A5: ='[7]0.结构参数'!B8 -> YU4 | B5: ='0.结构参数'!D44*100 -> 2000 | C5: =MIN(('0.结构参数'!K8-'0.结构参数'!I8),('0.结构参数'!L8-'0.结构参数'!J8))*100-70 -> 124.45 | D5: =MAX(('0.结构参数'!K8-'0.结构参数'!I8),('0.结构参数'!L8-'0.结构参数'!J8))*100-70 -> 133.911 | E5: 25 | F5: 20 | G5: 35 | H5: =ROUNDDOWN((D5-M5)/15,0) -> 8 | I5: =D5-M5-H5*15 -> 7.411 | J5: =(C5-M5-I5)/H5 -> 13.817375 | K5: =C5+30 -> 154.45 | L5: =D5+30 -> 163.911 | M5: =$R$2+$R$5 -> 6.5 | R5: =R4+1.4/2 -> 2.5
A6: ='[7]0.结构参数'!B9 -> YU5 | B6: ='0.结构参数'!D45*100 -> 2000 | C6: =MIN(('0.结构参数'!K9-'0.结构参数'!I9),('0.结构参数'!L9-'0.结构参数'!J9))*100-70 -> 133.926 | D6: =MAX(('0.结构参数'!K9-'0.结构参数'!I9),('0.结构参数'!L9-'0.结构参数'!J9))*100-70 -> 143.387 | E6: 25 | F6: 20 | G6: 35 | H6: =ROUNDDOWN((D6-M6)/15,0) -> 9 | I6: =D6-M6-H6*15 -> 1.887 | J6: =(C6-M6-I6)/H6 -> 13.948778 | K6: =C6+30 -> 163.926 | L6: =D6+30 -> 173.387 | M6: =$R$2+$R$5 -> 6.5
A7: ='[7]0.结构参数'!B10 -> YU6 | B7: ='0.结构参数'!D46*100 -> 2000 | C7: =MIN(('0.结构参数'!K10-'0.结构参数'!I10),('0.结构参数'!L10-'0.结构参数'!J10))*100-70 -> 143.428 | D7: =MAX(('0.结构参数'!K10-'0.结构参数'!I10),('0.结构参数'!L10-'0.结构参数'!J10))*100-70 -> 171.196 | E7: 25 | F7: 20 | G7: 35 | H7: =ROUNDDOWN((D7-M7)/15,0) -> 10 | I7: =D7-M7-H7*15 -> 14.696 | J7: =(C7-M7-I7)/H7 -> 12.2232 | K7: =C7+30 -> 173.428 | L7: =D7+30 -> 201.196 | M7: =$R$2+$R$5 -> 6.5
A8: ='[7]0.结构参数'!B11 -> YU7 | B8: ='0.结构参数'!D47*100 -> 2000 | C8: =MIN(('0.结构参数'!K11-'0.结构参数'!I11),('0.结构参数'!L11-'0.结构参数'!J11))*100-70 -> 171.238 | D8: =MAX(('0.结构参数'!K11-'0.结构参数'!I11),('0.结构参数'!L11-'0.结构参数'!J11))*100-70 -> 199.005 | E8: 25 | F8: 20 | G8: 35 | H8: =ROUNDDOWN((D8-M8)/15,0) -> 12 | I8: =D8-M8-H8*15 -> 12.505 | J8: =(C8-M8-I8)/H8 -> 12.686083 | K8: =C8+30 -> 201.238 | L8: =D8+30 -> 229.005 | M8: =$R$2+$R$5 -> 6.5
A9: ='[7]0.结构参数'!B12 -> YU8 | B9: ='0.结构参数'!D48*100 -> 2000 | C9: =MIN(('0.结构参数'!K12-'0.结构参数'!I12),('0.结构参数'!L12-'0.结构参数'!J12))*100-70 -> 199.02 | D9: =MAX(('0.结构参数'!K12-'0.结构参数'!I12),('0.结构参数'!L12-'0.结构参数'!J12))*100-70 -> 209.039 | E9: 25 | F9: 20 | G9: 35 | H9: =ROUNDDOWN((D9-M9)/15,0) -> 13 | I9: =D9-M9-H9*15 -> 7.539 | J9: =(C9-M9-I9)/H9 -> 14.229308 | K9: =C9+30 -> 229.02 | L9: =D9+30 -> 239.039 | M9: =$R$2+$R$5 -> 6.5
A10: ='[7]0.结构参数'!B13 -> YU9 | B10: 1000 | C10: 148.9 | D10: 209.1 | E10: 25 | F10: 20 | G10: 35 | H10: =ROUNDDOWN((D10-M10)/15,0) -> 13 | I10: =D10-M10-H10*15 -> 7.6 | J10: =(C10-M10-I10)/H10 -> 10.369231 | K10: =C10+30 -> 178.9 | L10: =D10+30 -> 239.1 | M10: =$R$2+$R$5 -> 6.5
A11: ='[7]0.结构参数'!B14 -> YU10 | B11: ='0.结构参数'!D50*100 -> 2000 | C11: 188.9 | D11: 208.9 | E11: 25 | F11: 20 | G11: 35 | H11: =ROUNDDOWN((D11-M11)/15,0) -> 13 | I11: =D11-M11-H11*15 -> 7.4 | J11: =(C11-M11-I11)/H11 -> 13.461538 | K11: =C11+30 -> 218.9 | L11: =D11+30 -> 238.9 | M11: =$R$2+$R$5 -> 6.5
A12: ='[7]0.结构参数'!B15 -> YU11 | B12: ='0.结构参数'!D51*100 -> 2000 | C12: =MIN(('0.结构参数'!K15-'0.结构参数'!I15),('0.结构参数'!L15-'0.结构参数'!J15))*100-70 -> 219.149 | D12: =MAX(('0.结构参数'!K15-'0.结构参数'!I15),('0.结构参数'!L15-'0.结构参数'!J15))*100-70 -> 272.58 | E12: 25 | F12: 20 | G12: 35 | H12: =ROUNDDOWN((D12-M12)/15,0) -> 17 | I12: =D12-M12-H12*15 -> 11.08 | J12: =(C12-M12-I12)/H12 -> 11.857 | K12: =C12+30 -> 249.149 | L12: =D12+30 -> 302.58 | M12: =$R$2+$R$5 -> 6.5
A13: ='[7]0.结构参数'!B16 -> YU12 | B13: ='0.结构参数'!D52*100 -> 2000 | C13: =MIN(('0.结构参数'!K16-'0.结构参数'!I16),('0.结构参数'!L16-'0.结构参数'!J16))*100-70 -> 183.963 | D13: =MAX(('0.结构参数'!K16-'0.结构参数'!I16),('0.结构参数'!L16-'0.结构参数'!J16))*100-70 -> 219.082 | E13: 25 | F13: 20 | G13: 35 | H13: =ROUNDDOWN((D13-M13)/15,0) -> 14 | I13: =D13-M13-H13*15 -> 2.582 | J13: =(C13-M13-I13)/H13 -> 12.4915 | K13: =C13+30 -> 213.963 | L13: =D13+30 -> 249.082 | M13: =$R$2+$R$5 -> 6.5
A14: ='[7]0.结构参数'!B17 -> YU13 | B14: ='0.结构参数'!D53*100 -> 2000 | C14: =MIN(('0.结构参数'!K17-'0.结构参数'!I17),('0.结构参数'!L17-'0.结构参数'!J17))*100-70 -> 167.327 | D14: =MAX(('0.结构参数'!K17-'0.结构参数'!I17),('0.结构参数'!L17-'0.结构参数'!J17))*100-70 -> 183.925 | E14: 25 | F14: 20 | G14: 35 | H14: =ROUNDDOWN((D14-M14)/15,0) -> 11 | I14: =D14-M14-H14*15 -> 12.425 | J14: =(C14-M14-I14)/H14 -> 13.491091 | K14: =C14+30 -> 197.327 | L14: =D14+30 -> 213.925 | M14: =$R$2+$R$5 -> 6.5
A15: ='[7]0.结构参数'!B18 -> YU14 | B15: ='0.结构参数'!D54*100 -> 2000 | C15: =MIN(('0.结构参数'!K18-'0.结构参数'!I18),('0.结构参数'!L18-'0.结构参数'!J18))*100-70 -> 161.575 | D15: =MAX(('0.结构参数'!K18-'0.结构参数'!I18),('0.结构参数'!L18-'0.结构参数'!J18))*100-70 -> 167.308 | E15: 25 | F15: 20 | G15: 35 | H15: =ROUNDDOWN((D15-M15)/15,0) -> 10 | I15: =D15-M15-H15*15 -> 10.808 | J15: =(C15-M15-I15)/H15 -> 14.4267 | K15: =C15+30 -> 191.575 | L15: =D15+30 -> 197.308 | M15: =$R$2+$R$5 -> 6.5
A16: ='[7]0.结构参数'!B19 -> YU15 | B16: ='0.结构参数'!D55*100 -> 2000 | C16: =MIN(('0.结构参数'!K19-'0.结构参数'!I19),('0.结构参数'!L19-'0.结构参数'!J19))*100-70 -> 155.834 | D16: =MAX(('0.结构参数'!K19-'0.结构参数'!I19),('0.结构参数'!L19-'0.结构参数'!J19))*100-70 -> 161.566 | E16: 25 | F16: 20 | G16: 35 | H16: =ROUNDDOWN((D16-M16)/15,0) -> 10 | I16: =D16-M16-H16*15 -> 5.066 | J16: =(C16-M16-I16)/H16 -> 14.4268 | K16: =C16+30 -> 185.834 | L16: =D16+30 -> 191.566 | M16: =$R$2+$R$5 -> 6.5
A17: ='[7]0.结构参数'!B20 -> YU16 | B17: ='0.结构参数'!D56*100 -> 2000 | C17: =MIN(('0.结构参数'!K20-'0.结构参数'!I20),('0.结构参数'!L20-'0.结构参数'!J20))*100-70 -> 150.092 | D17: =MAX(('0.结构参数'!K20-'0.结构参数'!I20),('0.结构参数'!L20-'0.结构参数'!J20))*100-70 -> 155.825 | E17: 25 | F17: 20 | G17: 35 | H17: =ROUNDDOWN((D17-M17)/15,0) -> 9 | I17: =D17-M17-H17*15 -> 14.325 | J17: =(C17-M17-I17)/H17 -> 14.363 | K17: =C17+30 -> 180.092 | L17: =D17+30 -> 185.825 | M17: =$R$2+$R$5 -> 6.5
A18: ='[7]0.结构参数'!B21 -> YU17 | B18: ='0.结构参数'!D57*100 -> 2000 | C18: =MIN(('0.结构参数'!K21-'0.结构参数'!I21),('0.结构参数'!L21-'0.结构参数'!J21))*100-70 -> 144.351 | D18: =MAX(('0.结构参数'!K21-'0.结构参数'!I21),('0.结构参数'!L21-'0.结构参数'!J21))*100-70 -> 150.084 | E18: 25 | F18: 20 | G18: 35 | H18: =ROUNDDOWN((D18-M18)/15,0) -> 9 | I18: =D18-M18-H18*15 -> 8.584 | J18: =(C18-M18-I18)/H18 -> 14.363 | K18: =C18+30 -> 174.351 | L18: =D18+30 -> 180.084 | M18: =$R$2+$R$5 -> 6.5
A19: ='[7]0.结构参数'!B22 -> YU18 | B19: ='0.结构参数'!D58*100 -> 2000 | C19: =MIN(('0.结构参数'!K22-'0.结构参数'!I22),('0.结构参数'!L22-'0.结构参数'!J22))*100-70 -> 138.61 | D19: =MAX(('0.结构参数'!K22-'0.结构参数'!I22),('0.结构参数'!L22-'0.结构参数'!J22))*100-70 -> 144.342 | E19: 25 | F19: 20 | G19: 35 | H19: =ROUNDDOWN((D19-M19)/15,0) -> 9 | I19: =D19-M19-H19*15 -> 2.842 | J19: =(C19-M19-I19)/H19 -> 14.363111 | K19: =C19+30 -> 168.61 | L19: =D19+30 -> 174.342 | M19: =$R$2+$R$5 -> 6.5
A20: ='[7]0.结构参数'!B23 -> YU19 | B20: ='0.结构参数'!D59*100 -> 1547.05 | C20: =MIN(('0.结构参数'!K23-'0.结构参数'!I23),('0.结构参数'!L23-'0.结构参数'!J23))*100-70 -> 130 | D20: =MAX(('0.结构参数'!K23-'0.结构参数'!I23),('0.结构参数'!L23-'0.结构参数'!J23))*100-70 -> 138.601 | E20: 25 | F20: 20 | G20: 35 | H20: =ROUNDDOWN((D20-M20)/15,0) -> 8 | I20: =D20-M20-H20*15 -> 12.101 | J20: =(C20-M20-I20)/H20 -> 13.924875 | K20: =C20+30 -> 160 | L20: =D20+30 -> 168.601 | M20: =$R$2+$R$5 -> 6.5
A21: 既有U型槽1 | B21: 1000 | C21: =2.09*100 -> 209 | D21: 220.8 | E21: 25 | F21: 20 | G21: 35 | H21: =ROUNDDOWN((D21-M21)/15,0) -> 14 | I21: =D21-M21-H21*15 -> 4.3 | J21: =(C21-M21-I21)/H21 -> 14.157143 | K21: =C21+30 -> 239 | L21: =D21+30 -> 250.8 | M21: =$R$2+$R$5 -> 6.5 | O21: =(C21+D21)/200+0.9 -> 3.049 | P21: =O21*B21/100 -> 30.49
A22: 既有框架1 | B22: 5390 | C22: =220.8 -> 220.8 | D22: 236 | E22: 25 | F22: 20 | G22: 35 | H22: =ROUNDDOWN((D22-M22)/15,0) -> 15 | I22: =D22-M22-H22*15 -> 4.5 | J22: =(C22-M22-I22)/H22 -> 13.986667 | K22: =C22+30 -> 250.8 | L22: =D22+30 -> 266 | M22: =$R$2+$R$5 -> 6.5 | O22: =(C22+D22)/200+0.9 -> 3.184 | P22: =O22*B22/100 -> 171.6176
A23: 既有U型槽2 | B23: 1500 | C23: =236.1 -> 236.1 | D23: 261.9 | E23: 25 | F23: 20 | G23: 35 | H23: =ROUNDDOWN((D23-M23)/15,0) -> 17 | I23: =D23-M23-H23*15 -> 0.4 | J23: =(C23-M23-I23)/H23 -> 13.482353 | K23: =C23+30 -> 266.1 | L23: =D23+30 -> 291.9 | M23: =$R$2+$R$5 -> 6.5 | O23: =(C23+D23)/200+0.9 -> 3.39 | P23: =O23*B23/100 -> 50.85
A24: YU9-1 | B24: 1000 | C24: 148.9 | D24: 188.9 | E24: 25 | F24: 20 | G24: 35 | H24: =ROUNDDOWN((D24-M24)/15,0) -> 12 | I24: =D24-M24-H24*15 -> 2.4 | J24: =(C24-M24-I24)/H24 -> 11.666667 | K24: =C24+30 -> 178.9 | L24: =D24+30 -> 218.9 | M24: =$R$2+$R$5 -> 6.5 | P24: =SUM(P21:P23) -> 252.9576
K25: 2022.5.2
A29: =A2 -> YU1 | B29: =VLOOKUP($A29,$A$2:$N$28,2,0) -> 2000 | C29: =VLOOKUP($A29,$A$2:$N$28,3,0) -> 90 | D29: =VLOOKUP($A29,$A$2:$N$28,4,0) -> 105.486 | E29: =VLOOKUP($A29,$A$2:$N$28,5,0) -> 25 | F29: =VLOOKUP($A29,$A$2:$N$28,6,0) -> 20 | G29: =VLOOKUP($A29,$A$2:$N$28,7,0) -> 35 | H29: =VLOOKUP($A29,$A$2:$N$28,8,0) -> 6 | I29: =VLOOKUP($A29,$A$2:$N$28,9,0) -> 8.986 | J29: =VLOOKUP($A29,$A$2:$N$28,10,0) -> 12.419 | K29: =VLOOKUP($A29,$A$2:$N$28,11,0) -> 120 | L29: =VLOOKUP($A29,$A$2:$N$28,12,0) -> 135.486 | M29: =VLOOKUP($A29,$A$2:$N$28,13,0) -> 6.5
A30: =A29 -> YU1 | B30: 编号 | C30: 规格 | D30: 大样(cm) | G30: 单根长(cm) | H30: 根数 | I30: 总长(m) | J30: 每米重(kg/m) | K30: 总重(kg)
B31: N1 | C31: 16 | D31: =ROUND((C29+G29-$R$2-(C31+2)/10/2),1)&"~"&ROUND((D29+G29-$R$2-(C31+2)/10/2),1) -> 120.1~135.6 | E31: =F29-$R$2*2-(C31+2)/10 -> 10.2 | F31: - | G31: =(C29+G29-$R$2-(C31+2)/10/2)+(D29+G29-$R$2-(C31+2)/10/2)+E31 -> 265.886 | H31: =ROUND(B29/15,0)+1 -> 134 | I31: =G31*H31/100 -> 356.28724 | J31: =ROUND(C31^2*PI()/4/1000000*7850,3) -> 1.578 | K31: =I31*J31 -> 562.22126
B32: N2 | C32: 16 | D32: =ROUND((C29+G29-$R$2-(C31+2)/10/2),1)&"~"&ROUND((D29+G29-$R$2-(C31+2)/10/2),1) -> 120.1~135.6 | E32: =F29-$R$2*2-(C31+2)/10 -> 10.2 | F32: - | G32: =(C29+G29-$R$2-(C31+2)/10/2)+(D29+G29-$R$2-(C31+2)/10/2)+E31 -> 265.886 | H32: =ROUND(B29/15,0)+1 -> 134 | I32: =G32*H32/100 -> 356.28724 | J32: =ROUND(C32^2*PI()/4/1000000*7850,3) -> 1.578 | K32: =I32*J32 -> 562.22126
B33: N3 | C33: 12 | D33: =B29-$R$2*2 -> 1992 | E33: - | F33: =ROUNDUP((IF(C33<26,10.927,11.212))*C33/10,0) -> 14 | G33: =D33+F33*2 -> 2020 | H33: =(H29+1)*8-2 -> 54 | I33: =G33*H33/100 -> 1090.8 | J33: =ROUND(C33^2*PI()/4/1000000*7850,3) -> 0.888 | K33: =I33*J33 -> 968.6304
B34: N4 | C34: 16 | D34: =ROUND((C29+G29-$R$2-(C34+2)/10/2),1)&"~"&ROUND((D29+G29-$R$2-(C34+2)/10/2),1) -> 120.1~135.6 | E34: =E29-$R$2*2-(C34+2)/10 -> 15.2 | F34: - | G34: =(C29+G29-$R$2-(C34+2)/10/2)+(D29+G29-$R$2-(C34+2)/10/2)+E34 -> 270.886 | H34: =(ROUND(B29/15,0)+1)*2 -> 268 | I34: =G34*H34/100 -> 725.97448 | J34: =ROUND(C34^2*PI()/4/1000000*7850,3) -> 1.578 | K34: =I34*J34 -> 1145.5877
B35: N5 | C35: 8 | D35: =F29-$R$2*2 -> 12 | E35: - | F35: - | G35: =D35+11 -> 23 | H35: =(ROUND(B29/15,0)+1)*H29 -> 804 | I35: =G35*H35/100 -> 184.92 | J35: =ROUND(C35^2*PI()/4/1000000*7850,3) -> 0.395 | K35: =I35*J35 -> 73.0434
B36: N6 | C36: 8 | D36: =E29-$R$2*2 -> 17 | E36: - | F36: - | G36: =D36+11 -> 28 | H36: =(ROUND(B29/15,0)+1)*H29 -> 804 | I36: =G36*H36/100 -> 225.12 | J36: =ROUND(C36^2*PI()/4/1000000*7850,3) -> 0.395 | K36: =I36*J36 -> 88.9224
A37: 合计： | B37: HPB300钢筋： | D37: =K36+K35 -> 161.9658 | E37: HRB400钢筋： | G37: =SUM(K31:K34) -> 3238.6607 | H37: c40混凝土： | J37: =((C29+D29)/2*(E29*2+F29*2)/10000-0.2*0.2)*B29/100 -> 16.79374 | L37: =(D37+G37)/J37 -> 202.49369
A39: =A3 -> YU2 | B39: =VLOOKUP($A39,$A$2:$N$28,2,0) -> 2000 | C39: =VLOOKUP($A39,$A$2:$N$28,3,0) -> 105.5 | D39: =VLOOKUP($A39,$A$2:$N$28,4,0) -> 114.961 | E39: =VLOOKUP($A39,$A$2:$N$28,5,0) -> 25 | F39: =VLOOKUP($A39,$A$2:$N$28,6,0) -> 20 | G39: =VLOOKUP($A39,$A$2:$N$28,7,0) -> 35 | H39: =VLOOKUP($A39,$A$2:$N$28,8,0) -> 7 | I39: =VLOOKUP($A39,$A$2:$N$28,9,0) -> 3.461 | J39: =VLOOKUP($A39,$A$2:$N$28,10,0) -> 13.648429 | K39: =VLOOKUP($A39,$A$2:$N$28,11,0) -> 135.5 | L39: =VLOOKUP($A39,$A$2:$N$28,12,0) -> 144.961
A40: =A39 -> YU2 | B40: 编号 | C40: 规格 | D40: 大样 | G40: 单根长 | H40: 根数 | I40: 总长 | J40: 每米重 | K40: 总重
B41: N1 | C41: 16 | D41: =ROUND((C39+G39-$R$2-(C41+2)/10/2),1)&"~"&ROUND((D39+G39-$R$2-(C41+2)/10/2),1) -> 135.6~145.1 | E41: =F39-$R$2*2-(C41+2)/10 -> 10.2 | F41: - | G41: =(C39+G39-$R$2-(C41+2)/10/2)+(D39+G39-$R$2-(C41+2)/10/2)+E41 -> 290.861 | H41: =ROUND(B39/15,0)+1 -> 134 | I41: =G41*H41/100 -> 389.75374 | J41: =ROUND(C41^2*PI()/4/1000000*7850,3) -> 1.578 | K41: =I41*J41 -> 615.0314
